{
  "version": 8,
  "blockIdVersion": 11,
  "anchorX": 0,
  "anchorY": 0,
  "anchorZ": 0,
  "blocks": [
    {
      "x": -4,
      "y": 0,
      "z": -9,
      "name": "BO_Pool_Surface00",
      "rotation": 4
    },
    {
      "x": -4,
      "y": 1,
      "z": -9,
      "name": "BO_Pool_Surface00",
      "rotation": 4
    },
    {
      "x": -4,
      "y": 2,
      "z": -9,
      "name": "BO_Pool_Surface00",
      "rotation": 4
    },
    {
      "x": -4,
      "y": 3,
      "z": -9,
      "name": "BO_Pool_Surface00",
      "rotation": 4
    },
    {
      "x": -4,
      "y": 4,
      "z": -9,
      "name": "BO_Pool_Surface00",
      "rotation": 4
    },
    {
      "x": -4,
      "y": 5,
      "z": -9,
      "name": "BO_Pool_Surface00",
      "rotation": 4
    },
    {
      "x": -4,
      "y": 6,
      "z": -9,
      "name": "BO_Pool_Surface00",
      "rotation": 4
    },
    {
      "x": -4,
      "y": 7,
      "z": -9,
      "name": "BO_Pool_Surface00",
      "rotation": 4
    },
    {
      "x": -4,
      "y": 8,
      "z": -9,
      "name": "BO_Pool_Surface00",
      "rotation": 4
    },
    {
      "x": -4,
      "y": 9,
      "z": -9,
      "name": "BO_Pool_Surface00",
      "rotation": 4
    },
    {
      "x": -4,
      "y": 10,
      "z": -9,
      "name": "BO_Pool_Surface00",
      "rotation": 4
    },
    {
      "x": -4,
      "y": 14,
      "z": -9,
      "name": "BO_Pool_Surface00"
    },
    {
      "x": -4,
      "y": 15,
      "z": -9,
      "name": "Build_Black_Cube"
    },
    {
      "x": -4,
      "y": 16,
      "z": -9,
      "name": "Soil_Dirt_Tilled",
      "components": {
        "Components": {
          "PlacedByInteraction": {
            "WhoPlacedUuid": {
              "$binary": "KMPE5JWxSQGC8WI/IkVLQQ==",
              "$type": "04"
            }
          },
          "TilledSoil": {
            "Version": 1,
            "DecayTime": "0001-01-02T22:44:51Z"
          }
        }
      }
    },
    {
      "x": -4,
      "y": 17,
      "z": -9,
      "name": "*Plant_Crop_Wheat_Block_Eternal_State_Definitions_StageFinal"
    },
    {
      "x": -4,
      "y": 0,
      "z": -8,
      "name": "BO_Pool_Surface00",
      "rotation": 4
    },
    {
      "x": -4,
      "y": 1,
      "z": -8,
      "name": "BO_Pool_Surface00",
      "rotation": 4
    },
    {
      "x": -4,
      "y": 2,
      "z": -8,
      "name": "BO_Pool_Surface00",
      "rotation": 4
    },
    {
      "x": -4,
      "y": 3,
      "z": -8,
      "name": "BO_Pool_Surface00",
      "rotation": 4
    },
    {
      "x": -4,
      "y": 4,
      "z": -8,
      "name": "BO_Pool_Surface00",
      "rotation": 4
    },
    {
      "x": -4,
      "y": 5,
      "z": -8,
      "name": "BO_Pool_Surface00",
      "rotation": 4
    },
    {
      "x": -4,
      "y": 6,
      "z": -8,
      "name": "BO_Pool_Surface00",
      "rotation": 4
    },
    {
      "x": -4,
      "y": 7,
      "z": -8,
      "name": "BO_Pool_Surface00",
      "rotation": 4
    },
    {
      "x": -4,
      "y": 8,
      "z": -8,
      "name": "BO_Pool_Surface00",
      "rotation": 4
    },
    {
      "x": -4,
      "y": 9,
      "z": -8,
      "name": "BO_Pool_Surface00",
      "rotation": 4
    },
    {
      "x": -4,
      "y": 10,
      "z": -8,
      "name": "BO_Pool_Surface00",
      "rotation": 4
    },
    {
      "x": -4,
      "y": 14,
      "z": -8,
      "name": "BO_Pool_Surface00"
    },
    {
      "x": -4,
      "y": 15,
      "z": -8,
      "name": "Build_Black_Cube"
    },
    {
      "x": -4,
      "y": 16,
      "z": -8,
      "name": "Soil_Dirt_Tilled",
      "components": {
        "Components": {
          "PlacedByInteraction": {
            "WhoPlacedUuid": {
              "$binary": "KMPE5JWxSQGC8WI/IkVLQQ==",
              "$type": "04"
            }
          },
          "TilledSoil": {
            "Version": 1,
            "DecayTime": "0001-01-02T22:44:51Z"
          }
        }
      }
    },
    {
      "x": -4,
      "y": 17,
      "z": -8,
      "name": "*Plant_Crop_Wheat_Block_Eternal_State_Definitions_StageFinal"
    },
    {
      "x": -4,
      "y": 0,
      "z": -7,
      "name": "BO_Pool_Surface00",
      "rotation": 4
    },
    {
      "x": -4,
      "y": 1,
      "z": -7,
      "name": "BO_Pool_Surface00",
      "rotation": 4
    },
    {
      "x": -4,
      "y": 9,
      "z": -7,
      "name": "BO_Pool_Surface00",
      "rotation": 4
    },
    {
      "x": -4,
      "y": 10,
      "z": -7,
      "name": "BO_Pool_Surface00",
      "rotation": 4
    },
    {
      "x": -4,
      "y": 14,
      "z": -7,
      "name": "BO_Pool_Surface00"
    },
    {
      "x": -4,
      "y": 15,
      "z": -7,
      "name": "Build_Black_Cube"
    },
    {
      "x": -4,
      "y": 16,
      "z": -7,
      "name": "Soil_Dirt_Tilled",
      "components": {
        "Components": {
          "PlacedByInteraction": {
            "WhoPlacedUuid": {
              "$binary": "KMPE5JWxSQGC8WI/IkVLQQ==",
              "$type": "04"
            }
          },
          "TilledSoil": {
            "Version": 1,
            "DecayTime": "0001-01-02T22:44:51Z"
          }
        }
      }
    },
    {
      "x": -4,
      "y": 17,
      "z": -7,
      "name": "*Plant_Crop_Wheat_Block_Eternal_State_Definitions_StageFinal"
    },
    {
      "x": -4,
      "y": 0,
      "z": -6,
      "name": "BO_Pool_Surface00",
      "rotation": 4
    },
    {
      "x": -4,
      "y": 9,
      "z": -6,
      "name": "BO_Pool_Surface00",
      "rotation": 4
    },
    {
      "x": -4,
      "y": 10,
      "z": -6,
      "name": "BO_Pool_Surface00",
      "rotation": 4
    },
    {
      "x": -4,
      "y": 14,
      "z": -6,
      "name": "BO_Pool_Surface00"
    },
    {
      "x": -4,
      "y": 15,
      "z": -6,
      "name": "Build_Black_Cube"
    },
    {
      "x": -4,
      "y": 16,
      "z": -6,
      "name": "Soil_Dirt_Tilled",
      "components": {
        "Components": {
          "PlacedByInteraction": {
            "WhoPlacedUuid": {
              "$binary": "KMPE5JWxSQGC8WI/IkVLQQ==",
              "$type": "04"
            }
          },
          "TilledSoil": {
            "Version": 1,
            "DecayTime": "0001-01-02T22:44:51Z"
          }
        }
      }
    },
    {
      "x": -4,
      "y": 17,
      "z": -6,
      "name": "*Plant_Crop_Wheat_Block_Eternal_State_Definitions_StageFinal"
    },
    {
      "x": -4,
      "y": 0,
      "z": -5,
      "name": "BO_Pool_Surface00",
      "rotation": 4
    },
    {
      "x": -4,
      "y": 9,
      "z": -5,
      "name": "BO_Pool_Surface00",
      "rotation": 4
    },
    {
      "x": -4,
      "y": 10,
      "z": -5,
      "name": "BO_Pool_Surface00",
      "rotation": 4
    },
    {
      "x": -4,
      "y": 14,
      "z": -5,
      "name": "BO_Pool_Surface00"
    },
    {
      "x": -4,
      "y": 15,
      "z": -5,
      "name": "Build_Black_Cube"
    },
    {
      "x": -4,
      "y": 16,
      "z": -5,
      "name": "Soil_Dirt_Tilled",
      "components": {
        "Components": {
          "PlacedByInteraction": {
            "WhoPlacedUuid": {
              "$binary": "KMPE5JWxSQGC8WI/IkVLQQ==",
              "$type": "04"
            }
          },
          "TilledSoil": {
            "Version": 1,
            "DecayTime": "0001-01-02T22:44:51Z"
          }
        }
      }
    },
    {
      "x": -4,
      "y": 17,
      "z": -5,
      "name": "*Plant_Crop_Wheat_Block_Eternal_State_Definitions_StageFinal"
    },
    {
      "x": -4,
      "y": 0,
      "z": -4,
      "name": "BO_Pool_Surface00",
      "rotation": 4
    },
    {
      "x": -4,
      "y": 9,
      "z": -4,
      "name": "BO_Pool_Surface00",
      "rotation": 4
    },
    {
      "x": -4,
      "y": 10,
      "z": -4,
      "name": "BO_Pool_Surface00",
      "rotation": 4
    },
    {
      "x": -4,
      "y": 14,
      "z": -4,
      "name": "BO_Pool_Surface00"
    },
    {
      "x": -4,
      "y": 15,
      "z": -4,
      "name": "Build_Black_Cube"
    },
    {
      "x": -4,
      "y": 16,
      "z": -4,
      "name": "Soil_Dirt_Tilled",
      "components": {
        "Components": {
          "PlacedByInteraction": {
            "WhoPlacedUuid": {
              "$binary": "KMPE5JWxSQGC8WI/IkVLQQ==",
              "$type": "04"
            }
          },
          "TilledSoil": {
            "Version": 1,
            "DecayTime": "0001-01-02T22:44:51Z"
          }
        }
      }
    },
    {
      "x": -4,
      "y": 17,
      "z": -4,
      "name": "*Plant_Crop_Wheat_Block_Eternal_State_Definitions_StageFinal"
    },
    {
      "x": -4,
      "y": 0,
      "z": -3,
      "name": "BO_Pool_Surface00",
      "rotation": 4
    },
    {
      "x": -4,
      "y": 9,
      "z": -3,
      "name": "BO_Pool_Surface00",
      "support": 15
    },
    {
      "x": -4,
      "y": 10,
      "z": -3,
      "name": "BO_Pool_Surface00"
    },
    {
      "x": -4,
      "y": 14,
      "z": -3,
      "name": "BO_Pool_Surface00"
    },
    {
      "x": -4,
      "y": 15,
      "z": -3,
      "name": "Build_Black_Cube"
    },
    {
      "x": -4,
      "y": 16,
      "z": -3,
      "name": "Soil_Dirt_Tilled",
      "components": {
        "Components": {
          "PlacedByInteraction": {
            "WhoPlacedUuid": {
              "$binary": "KMPE5JWxSQGC8WI/IkVLQQ==",
              "$type": "04"
            }
          },
          "TilledSoil": {
            "Version": 1,
            "DecayTime": "0001-01-02T22:44:51Z"
          }
        }
      }
    },
    {
      "x": -4,
      "y": 17,
      "z": -3,
      "name": "*Plant_Crop_Wheat_Block_Eternal_State_Definitions_StageFinal"
    },
    {
      "x": -4,
      "y": 0,
      "z": -2,
      "name": "BO_Pool_Surface00",
      "rotation": 4
    },
    {
      "x": -4,
      "y": 9,
      "z": -2,
      "name": "BO_Pool_Surface00",
      "support": 15
    },
    {
      "x": -4,
      "y": 10,
      "z": -2,
      "name": "BO_Pool_Surface00"
    },
    {
      "x": -4,
      "y": 14,
      "z": -2,
      "name": "BO_Pool_Surface00"
    },
    {
      "x": -4,
      "y": 15,
      "z": -2,
      "name": "Build_Black_Cube"
    },
    {
      "x": -4,
      "y": 16,
      "z": -2,
      "name": "Soil_Dirt_Tilled",
      "components": {
        "Components": {
          "PlacedByInteraction": {
            "WhoPlacedUuid": {
              "$binary": "KMPE5JWxSQGC8WI/IkVLQQ==",
              "$type": "04"
            }
          },
          "TilledSoil": {
            "Version": 1,
            "DecayTime": "0001-01-02T22:44:51Z"
          }
        }
      }
    },
    {
      "x": -4,
      "y": 17,
      "z": -2,
      "name": "*Plant_Crop_Wheat_Block_Eternal_State_Definitions_StageFinal"
    },
    {
      "x": -4,
      "y": 0,
      "z": -1,
      "name": "BO_Pool_Surface00",
      "rotation": 4
    },
    {
      "x": -4,
      "y": 9,
      "z": -1,
      "name": "BO_Pool_Surface00"
    },
    {
      "x": -4,
      "y": 10,
      "z": -1,
      "name": "BO_Pool_Surface00"
    },
    {
      "x": -4,
      "y": 14,
      "z": -1,
      "name": "BO_Pool_Surface00"
    },
    {
      "x": -4,
      "y": 15,
      "z": -1,
      "name": "Build_Black_Cube"
    },
    {
      "x": -4,
      "y": 16,
      "z": -1,
      "name": "Soil_Dirt_Tilled",
      "components": {
        "Components": {
          "PlacedByInteraction": {
            "WhoPlacedUuid": {
              "$binary": "KMPE5JWxSQGC8WI/IkVLQQ==",
              "$type": "04"
            }
          },
          "TilledSoil": {
            "Version": 1,
            "DecayTime": "0001-01-02T22:44:51Z"
          }
        }
      }
    },
    {
      "x": -4,
      "y": 17,
      "z": -1,
      "name": "*Plant_Crop_Wheat_Block_Eternal_State_Definitions_StageFinal"
    },
    {
      "x": -4,
      "y": 0,
      "z": 0,
      "name": "BO_Pool_Surface00",
      "rotation": 4
    },
    {
      "x": -4,
      "y": 2,
      "z": 0,
      "name": "BO_Pool_Surface00"
    },
    {
      "x": -4,
      "y": 3,
      "z": 0,
      "name": "BO_Pool_Surface00"
    },
    {
      "x": -4,
      "y": 4,
      "z": 0,
      "name": "BO_Pool_Surface00",
      "support": 15
    },
    {
      "x": -4,
      "y": 5,
      "z": 0,
      "name": "BO_Pool_Surface00"
    },
    {
      "x": -4,
      "y": 6,
      "z": 0,
      "name": "BO_Pool_Surface00"
    },
    {
      "x": -4,
      "y": 7,
      "z": 0,
      "name": "BO_Pool_Surface00"
    },
    {
      "x": -4,
      "y": 8,
      "z": 0,
      "name": "BO_Pool_Surface00"
    },
    {
      "x": -4,
      "y": 9,
      "z": 0,
      "name": "BO_Pool_Surface00"
    },
    {
      "x": -4,
      "y": 10,
      "z": 0,
      "name": "BO_Pool_Surface00"
    },
    {
      "x": -4,
      "y": 14,
      "z": 0,
      "name": "BO_Pool_Surface00"
    },
    {
      "x": -4,
      "y": 15,
      "z": 0,
      "name": "Build_Black_Cube"
    },
    {
      "x": -4,
      "y": 16,
      "z": 0,
      "name": "Soil_Dirt_Tilled",
      "components": {
        "Components": {
          "PlacedByInteraction": {
            "WhoPlacedUuid": {
              "$binary": "KMPE5JWxSQGC8WI/IkVLQQ==",
              "$type": "04"
            }
          },
          "TilledSoil": {
            "Version": 1,
            "DecayTime": "0001-01-02T22:44:51Z"
          }
        }
      }
    },
    {
      "x": -4,
      "y": 17,
      "z": 0,
      "name": "*Plant_Crop_Wheat_Block_Eternal_State_Definitions_StageFinal"
    },
    {
      "x": -4,
      "y": 0,
      "z": 1,
      "name": "BO_Pool_Surface00",
      "rotation": 4
    },
    {
      "x": -4,
      "y": 2,
      "z": 1,
      "name": "BO_Pool_Surface00"
    },
    {
      "x": -4,
      "y": 3,
      "z": 1,
      "name": "BO_Pool_Surface00"
    },
    {
      "x": -4,
      "y": 4,
      "z": 1,
      "name": "Pool_Surface_Arrow",
      "support": 15
    },
    {
      "x": -4,
      "y": 5,
      "z": 1,
      "name": "BO_Pool_Surface00"
    },
    {
      "x": -4,
      "y": 6,
      "z": 1,
      "name": "BO_Pool_Surface00"
    },
    {
      "x": -4,
      "y": 7,
      "z": 1,
      "name": "BO_Pool_Surface00"
    },
    {
      "x": -4,
      "y": 8,
      "z": 1,
      "name": "BO_Pool_Surface00"
    },
    {
      "x": -4,
      "y": 9,
      "z": 1,
      "name": "BO_Pool_Surface00"
    },
    {
      "x": -4,
      "y": 10,
      "z": 1,
      "name": "BO_Pool_Surface00"
    },
    {
      "x": -4,
      "y": 14,
      "z": 1,
      "name": "BO_Pool_Surface00"
    },
    {
      "x": -4,
      "y": 15,
      "z": 1,
      "name": "Build_Black_Cube"
    },
    {
      "x": -4,
      "y": 16,
      "z": 1,
      "name": "Soil_Dirt_Tilled",
      "components": {
        "Components": {
          "PlacedByInteraction": {
            "WhoPlacedUuid": {
              "$binary": "KMPE5JWxSQGC8WI/IkVLQQ==",
              "$type": "04"
            }
          },
          "TilledSoil": {
            "Version": 1,
            "DecayTime": "0001-01-02T22:44:51Z"
          }
        }
      }
    },
    {
      "x": -4,
      "y": 17,
      "z": 1,
      "name": "*Plant_Crop_Wheat_Block_Eternal_State_Definitions_StageFinal"
    },
    {
      "x": -4,
      "y": 0,
      "z": 2,
      "name": "BO_Pool_Surface00",
      "rotation": 4
    },
    {
      "x": -4,
      "y": 9,
      "z": 2,
      "name": "BO_Pool_Surface00"
    },
    {
      "x": -4,
      "y": 10,
      "z": 2,
      "name": "BO_Pool_Surface00"
    },
    {
      "x": -4,
      "y": 14,
      "z": 2,
      "name": "BO_Pool_Surface00"
    },
    {
      "x": -4,
      "y": 15,
      "z": 2,
      "name": "Build_Black_Cube"
    },
    {
      "x": -4,
      "y": 16,
      "z": 2,
      "name": "Soil_Dirt_Tilled",
      "components": {
        "Components": {
          "PlacedByInteraction": {
            "WhoPlacedUuid": {
              "$binary": "KMPE5JWxSQGC8WI/IkVLQQ==",
              "$type": "04"
            }
          },
          "TilledSoil": {
            "Version": 1,
            "DecayTime": "0001-01-02T22:44:51Z"
          }
        }
      }
    },
    {
      "x": -4,
      "y": 17,
      "z": 2,
      "name": "*Plant_Crop_Wheat_Block_Eternal_State_Definitions_StageFinal"
    },
    {
      "x": -4,
      "y": 0,
      "z": 3,
      "name": "BO_Pool_Surface00",
      "rotation": 4
    },
    {
      "x": -4,
      "y": 9,
      "z": 3,
      "name": "BO_Pool_Surface00",
      "support": 15
    },
    {
      "x": -4,
      "y": 10,
      "z": 3,
      "name": "BO_Pool_Surface00"
    },
    {
      "x": -4,
      "y": 14,
      "z": 3,
      "name": "BO_Pool_Surface00"
    },
    {
      "x": -4,
      "y": 15,
      "z": 3,
      "name": "Build_Black_Cube"
    },
    {
      "x": -4,
      "y": 16,
      "z": 3,
      "name": "Soil_Dirt_Tilled",
      "components": {
        "Components": {
          "PlacedByInteraction": {
            "WhoPlacedUuid": {
              "$binary": "KMPE5JWxSQGC8WI/IkVLQQ==",
              "$type": "04"
            }
          },
          "TilledSoil": {
            "Version": 1,
            "DecayTime": "0001-01-02T22:44:51Z"
          }
        }
      }
    },
    {
      "x": -4,
      "y": 17,
      "z": 3,
      "name": "*Plant_Crop_Wheat_Block_Eternal_State_Definitions_StageFinal"
    },
    {
      "x": -4,
      "y": 0,
      "z": 4,
      "name": "BO_Pool_Surface00",
      "rotation": 4
    },
    {
      "x": -4,
      "y": 9,
      "z": 4,
      "name": "BO_Pool_Surface00",
      "support": 15
    },
    {
      "x": -4,
      "y": 10,
      "z": 4,
      "name": "BO_Pool_Surface00"
    },
    {
      "x": -4,
      "y": 14,
      "z": 4,
      "name": "BO_Pool_Surface00"
    },
    {
      "x": -4,
      "y": 15,
      "z": 4,
      "name": "Build_Black_Cube"
    },
    {
      "x": -4,
      "y": 16,
      "z": 4,
      "name": "Soil_Dirt_Tilled",
      "components": {
        "Components": {
          "PlacedByInteraction": {
            "WhoPlacedUuid": {
              "$binary": "KMPE5JWxSQGC8WI/IkVLQQ==",
              "$type": "04"
            }
          },
          "TilledSoil": {
            "Version": 1,
            "DecayTime": "0001-01-02T22:44:51Z"
          }
        }
      }
    },
    {
      "x": -4,
      "y": 17,
      "z": 4,
      "name": "*Plant_Crop_Wheat_Block_Eternal_State_Definitions_StageFinal"
    },
    {
      "x": -4,
      "y": 0,
      "z": 5,
      "name": "BO_Pool_Surface00",
      "rotation": 4
    },
    {
      "x": -4,
      "y": 9,
      "z": 5,
      "name": "BO_Pool_Surface00",
      "rotation": 4
    },
    {
      "x": -4,
      "y": 10,
      "z": 5,
      "name": "BO_Pool_Surface00",
      "rotation": 4
    },
    {
      "x": -4,
      "y": 14,
      "z": 5,
      "name": "BO_Pool_Surface00"
    },
    {
      "x": -4,
      "y": 15,
      "z": 5,
      "name": "Build_Black_Cube"
    },
    {
      "x": -4,
      "y": 16,
      "z": 5,
      "name": "Soil_Dirt_Tilled",
      "components": {
        "Components": {
          "PlacedByInteraction": {
            "WhoPlacedUuid": {
              "$binary": "KMPE5JWxSQGC8WI/IkVLQQ==",
              "$type": "04"
            }
          },
          "TilledSoil": {
            "Version": 1,
            "DecayTime": "0001-01-02T22:44:51Z"
          }
        }
      }
    },
    {
      "x": -4,
      "y": 17,
      "z": 5,
      "name": "*Plant_Crop_Wheat_Block_Eternal_State_Definitions_StageFinal"
    },
    {
      "x": -4,
      "y": 0,
      "z": 6,
      "name": "BO_Pool_Surface00",
      "rotation": 4
    },
    {
      "x": -4,
      "y": 9,
      "z": 6,
      "name": "BO_Pool_Surface00",
      "rotation": 4
    },
    {
      "x": -4,
      "y": 10,
      "z": 6,
      "name": "BO_Pool_Surface00",
      "rotation": 4
    },
    {
      "x": -4,
      "y": 14,
      "z": 6,
      "name": "BO_Pool_Surface00"
    },
    {
      "x": -4,
      "y": 15,
      "z": 6,
      "name": "Build_Black_Cube"
    },
    {
      "x": -4,
      "y": 16,
      "z": 6,
      "name": "Soil_Dirt_Tilled",
      "components": {
        "Components": {
          "PlacedByInteraction": {
            "WhoPlacedUuid": {
              "$binary": "KMPE5JWxSQGC8WI/IkVLQQ==",
              "$type": "04"
            }
          },
          "TilledSoil": {
            "Version": 1,
            "DecayTime": "0001-01-02T22:44:51Z"
          }
        }
      }
    },
    {
      "x": -4,
      "y": 17,
      "z": 6,
      "name": "*Plant_Crop_Wheat_Block_Eternal_State_Definitions_StageFinal"
    },
    {
      "x": -4,
      "y": 0,
      "z": 7,
      "name": "BO_Pool_Surface00",
      "rotation": 4
    },
    {
      "x": -4,
      "y": 9,
      "z": 7,
      "name": "BO_Pool_Surface00",
      "rotation": 4
    },
    {
      "x": -4,
      "y": 10,
      "z": 7,
      "name": "BO_Pool_Surface00",
      "rotation": 4
    },
    {
      "x": -4,
      "y": 14,
      "z": 7,
      "name": "BO_Pool_Surface00"
    },
    {
      "x": -4,
      "y": 15,
      "z": 7,
      "name": "Build_Black_Cube"
    },
    {
      "x": -4,
      "y": 16,
      "z": 7,
      "name": "Soil_Dirt_Tilled",
      "components": {
        "Components": {
          "PlacedByInteraction": {
            "WhoPlacedUuid": {
              "$binary": "KMPE5JWxSQGC8WI/IkVLQQ==",
              "$type": "04"
            }
          },
          "TilledSoil": {
            "Version": 1,
            "DecayTime": "0001-01-02T22:44:51Z"
          }
        }
      }
    },
    {
      "x": -4,
      "y": 17,
      "z": 7,
      "name": "*Plant_Crop_Wheat_Block_Eternal_State_Definitions_StageFinal"
    },
    {
      "x": -4,
      "y": 0,
      "z": 8,
      "name": "BO_Pool_Surface00",
      "rotation": 4
    },
    {
      "x": -4,
      "y": 1,
      "z": 8,
      "name": "BO_Pool_Surface00",
      "rotation": 5
    },
    {
      "x": -4,
      "y": 9,
      "z": 8,
      "name": "BO_Pool_Surface00",
      "rotation": 4
    },
    {
      "x": -4,
      "y": 10,
      "z": 8,
      "name": "BO_Pool_Surface00",
      "rotation": 4
    },
    {
      "x": -4,
      "y": 14,
      "z": 8,
      "name": "BO_Pool_Surface00"
    },
    {
      "x": -4,
      "y": 15,
      "z": 8,
      "name": "Build_Black_Cube"
    },
    {
      "x": -4,
      "y": 16,
      "z": 8,
      "name": "Soil_Dirt_Tilled",
      "components": {
        "Components": {
          "PlacedByInteraction": {
            "WhoPlacedUuid": {
              "$binary": "KMPE5JWxSQGC8WI/IkVLQQ==",
              "$type": "04"
            }
          },
          "TilledSoil": {
            "Version": 1,
            "DecayTime": "0001-01-02T22:44:51Z"
          }
        }
      }
    },
    {
      "x": -4,
      "y": 17,
      "z": 8,
      "name": "*Plant_Crop_Wheat_Block_Eternal_State_Definitions_StageFinal"
    },
    {
      "x": -4,
      "y": 0,
      "z": 9,
      "name": "BO_Pool_Surface00",
      "rotation": 4
    },
    {
      "x": -4,
      "y": 1,
      "z": 9,
      "name": "BO_Pool_Surface00",
      "rotation": 4
    },
    {
      "x": -4,
      "y": 2,
      "z": 9,
      "name": "BO_Pool_Surface00",
      "rotation": 4
    },
    {
      "x": -4,
      "y": 3,
      "z": 9,
      "name": "BO_Pool_Surface00",
      "rotation": 4
    },
    {
      "x": -4,
      "y": 4,
      "z": 9,
      "name": "BO_Pool_Surface00",
      "rotation": 4
    },
    {
      "x": -4,
      "y": 5,
      "z": 9,
      "name": "BO_Pool_Surface00",
      "rotation": 4
    },
    {
      "x": -4,
      "y": 6,
      "z": 9,
      "name": "BO_Pool_Surface00",
      "rotation": 4
    },
    {
      "x": -4,
      "y": 7,
      "z": 9,
      "name": "BO_Pool_Surface00",
      "rotation": 4
    },
    {
      "x": -4,
      "y": 8,
      "z": 9,
      "name": "BO_Pool_Surface00",
      "rotation": 4
    },
    {
      "x": -4,
      "y": 9,
      "z": 9,
      "name": "BO_Pool_Surface00",
      "rotation": 4
    },
    {
      "x": -4,
      "y": 10,
      "z": 9,
      "name": "BO_Pool_Surface00",
      "rotation": 4
    },
    {
      "x": -4,
      "y": 14,
      "z": 9,
      "name": "BO_Pool_Surface00"
    },
    {
      "x": -4,
      "y": 15,
      "z": 9,
      "name": "Build_Black_Cube"
    },
    {
      "x": -4,
      "y": 16,
      "z": 9,
      "name": "Soil_Dirt_Tilled",
      "components": {
        "Components": {
          "PlacedByInteraction": {
            "WhoPlacedUuid": {
              "$binary": "KMPE5JWxSQGC8WI/IkVLQQ==",
              "$type": "04"
            }
          },
          "TilledSoil": {
            "Version": 1,
            "DecayTime": "0001-01-02T22:44:51Z"
          }
        }
      }
    },
    {
      "x": -4,
      "y": 17,
      "z": 9,
      "name": "*Plant_Crop_Wheat_Block_Eternal_State_Definitions_StageFinal"
    },
    {
      "x": -4,
      "y": 0,
      "z": 10,
      "name": "BO_Pool_Surface00",
      "rotation": 4
    },
    {
      "x": -4,
      "y": 1,
      "z": 10,
      "name": "BO_Pool_Surface00",
      "rotation": 4
    },
    {
      "x": -4,
      "y": 2,
      "z": 10,
      "name": "BO_Pool_Surface00",
      "rotation": 4
    },
    {
      "x": -4,
      "y": 3,
      "z": 10,
      "name": "BO_Pool_Surface00",
      "rotation": 4
    },
    {
      "x": -4,
      "y": 4,
      "z": 10,
      "name": "BO_Pool_Surface00",
      "rotation": 4
    },
    {
      "x": -4,
      "y": 5,
      "z": 10,
      "name": "BO_Pool_Surface00",
      "rotation": 4
    },
    {
      "x": -4,
      "y": 6,
      "z": 10,
      "name": "BO_Pool_Surface00",
      "rotation": 4
    },
    {
      "x": -4,
      "y": 7,
      "z": 10,
      "name": "BO_Pool_Surface00",
      "rotation": 4
    },
    {
      "x": -4,
      "y": 8,
      "z": 10,
      "name": "BO_Pool_Surface00",
      "rotation": 4
    },
    {
      "x": -4,
      "y": 9,
      "z": 10,
      "name": "BO_Pool_Surface00",
      "rotation": 4
    },
    {
      "x": -4,
      "y": 10,
      "z": 10,
      "name": "BO_Pool_Surface00",
      "rotation": 4
    },
    {
      "x": -4,
      "y": 14,
      "z": 10,
      "name": "BO_Pool_Surface00"
    },
    {
      "x": -4,
      "y": 15,
      "z": 10,
      "name": "Build_Black_Cube"
    },
    {
      "x": -4,
      "y": 16,
      "z": 10,
      "name": "Soil_Dirt_Tilled",
      "components": {
        "Components": {
          "PlacedByInteraction": {
            "WhoPlacedUuid": {
              "$binary": "KMPE5JWxSQGC8WI/IkVLQQ==",
              "$type": "04"
            }
          },
          "TilledSoil": {
            "Version": 1,
            "DecayTime": "0001-01-02T22:44:51Z"
          }
        }
      }
    },
    {
      "x": -4,
      "y": 17,
      "z": 10,
      "name": "*Plant_Crop_Wheat_Block_Eternal_State_Definitions_StageFinal"
    },
    {
      "x": -3,
      "y": 0,
      "z": -9,
      "name": "BO_Pool_Surface00",
      "rotation": 4
    },
    {
      "x": -3,
      "y": 1,
      "z": -9,
      "name": "BO_Pool_Surface00",
      "rotation": 4
    },
    {
      "x": -3,
      "y": 2,
      "z": -9,
      "name": "BO_Pool_Surface00",
      "rotation": 4
    },
    {
      "x": -3,
      "y": 3,
      "z": -9,
      "name": "BO_Pool_Surface00",
      "rotation": 4
    },
    {
      "x": -3,
      "y": 4,
      "z": -9,
      "name": "BO_Pool_Surface00",
      "rotation": 4
    },
    {
      "x": -3,
      "y": 5,
      "z": -9,
      "name": "BO_Pool_Surface00",
      "rotation": 4
    },
    {
      "x": -3,
      "y": 6,
      "z": -9,
      "name": "BO_Pool_Surface00",
      "rotation": 4
    },
    {
      "x": -3,
      "y": 7,
      "z": -9,
      "name": "BO_Pool_Surface00",
      "rotation": 4
    },
    {
      "x": -3,
      "y": 8,
      "z": -9,
      "name": "BO_Pool_Surface00",
      "rotation": 4
    },
    {
      "x": -3,
      "y": 9,
      "z": -9,
      "name": "BO_Pool_Surface00",
      "rotation": 4
    },
    {
      "x": -3,
      "y": 10,
      "z": -9,
      "name": "BO_Pool_Surface00",
      "rotation": 4
    },
    {
      "x": -3,
      "y": 14,
      "z": -9,
      "name": "BO_Pool_Surface00"
    },
    {
      "x": -3,
      "y": 15,
      "z": -9,
      "name": "Build_Black_Cube"
    },
    {
      "x": -3,
      "y": 16,
      "z": -9,
      "name": "Soil_Dirt_Tilled",
      "components": {
        "Components": {
          "PlacedByInteraction": {
            "WhoPlacedUuid": {
              "$binary": "KMPE5JWxSQGC8WI/IkVLQQ==",
              "$type": "04"
            }
          },
          "TilledSoil": {
            "Version": 1,
            "DecayTime": "0001-01-02T22:44:51Z"
          }
        }
      }
    },
    {
      "x": -3,
      "y": 17,
      "z": -9,
      "name": "*Plant_Crop_Wheat_Block_Eternal_State_Definitions_StageFinal"
    },
    {
      "x": -3,
      "y": 0,
      "z": -8,
      "name": "BO_Pool_Surface00",
      "rotation": 4
    },
    {
      "x": -3,
      "y": 1,
      "z": -8,
      "name": "BO_Pool_Surface00",
      "rotation": 4
    },
    {
      "x": -3,
      "y": 2,
      "z": -8,
      "name": "BO_Pool_Surface00",
      "rotation": 4
    },
    {
      "x": -3,
      "y": 3,
      "z": -8,
      "name": "BO_Pool_Surface00",
      "rotation": 4
    },
    {
      "x": -3,
      "y": 4,
      "z": -8,
      "name": "BO_Pool_Surface00",
      "rotation": 4
    },
    {
      "x": -3,
      "y": 5,
      "z": -8,
      "name": "BO_Pool_Surface00",
      "rotation": 4
    },
    {
      "x": -3,
      "y": 6,
      "z": -8,
      "name": "BO_Pool_Surface00",
      "rotation": 4
    },
    {
      "x": -3,
      "y": 7,
      "z": -8,
      "name": "BO_Pool_Surface00",
      "rotation": 4
    },
    {
      "x": -3,
      "y": 8,
      "z": -8,
      "name": "BO_Pool_Surface00",
      "rotation": 4
    },
    {
      "x": -3,
      "y": 9,
      "z": -8,
      "name": "BO_Pool_Surface00",
      "rotation": 4
    },
    {
      "x": -3,
      "y": 10,
      "z": -8,
      "name": "BO_Pool_Surface00",
      "rotation": 4
    },
    {
      "x": -3,
      "y": 14,
      "z": -8,
      "name": "BO_Pool_Surface00"
    },
    {
      "x": -3,
      "y": 15,
      "z": -8,
      "name": "Build_Black_Cube"
    },
    {
      "x": -3,
      "y": 16,
      "z": -8,
      "name": "Soil_Dirt_Tilled",
      "components": {
        "Components": {
          "PlacedByInteraction": {
            "WhoPlacedUuid": {
              "$binary": "KMPE5JWxSQGC8WI/IkVLQQ==",
              "$type": "04"
            }
          },
          "TilledSoil": {
            "Version": 1,
            "DecayTime": "0001-01-02T22:44:51Z"
          }
        }
      }
    },
    {
      "x": -3,
      "y": 17,
      "z": -8,
      "name": "*Plant_Crop_Wheat_Block_Eternal_State_Definitions_StageFinal"
    },
    {
      "x": -3,
      "y": 0,
      "z": -7,
      "name": "BO_Pool_Surface00",
      "rotation": 4
    },
    {
      "x": -3,
      "y": 1,
      "z": -7,
      "name": "BO_Pool_Surface00",
      "rotation": 4
    },
    {
      "x": -3,
      "y": 9,
      "z": -7,
      "name": "BO_Pool_Surface00",
      "rotation": 4
    },
    {
      "x": -3,
      "y": 10,
      "z": -7,
      "name": "BO_Pool_Surface00",
      "rotation": 4
    },
    {
      "x": -3,
      "y": 14,
      "z": -7,
      "name": "BO_Pool_Surface00"
    },
    {
      "x": -3,
      "y": 15,
      "z": -7,
      "name": "Build_Black_Cube"
    },
    {
      "x": -3,
      "y": 16,
      "z": -7,
      "name": "Soil_Dirt_Tilled",
      "components": {
        "Components": {
          "PlacedByInteraction": {
            "WhoPlacedUuid": {
              "$binary": "KMPE5JWxSQGC8WI/IkVLQQ==",
              "$type": "04"
            }
          },
          "TilledSoil": {
            "Version": 1,
            "DecayTime": "0001-01-02T22:44:51Z"
          }
        }
      }
    },
    {
      "x": -3,
      "y": 17,
      "z": -7,
      "name": "*Plant_Crop_Wheat_Block_Eternal_State_Definitions_StageFinal"
    },
    {
      "x": -3,
      "y": 0,
      "z": -6,
      "name": "BO_Pool_Surface00",
      "rotation": 4
    },
    {
      "x": -3,
      "y": 9,
      "z": -6,
      "name": "BO_Pool_Surface00",
      "rotation": 4
    },
    {
      "x": -3,
      "y": 10,
      "z": -6,
      "name": "BO_Pool_Surface00",
      "rotation": 4
    },
    {
      "x": -3,
      "y": 14,
      "z": -6,
      "name": "BO_Pool_Surface00"
    },
    {
      "x": -3,
      "y": 15,
      "z": -6,
      "name": "Build_Black_Cube"
    },
    {
      "x": -3,
      "y": 16,
      "z": -6,
      "name": "Soil_Dirt_Tilled",
      "components": {
        "Components": {
          "PlacedByInteraction": {
            "WhoPlacedUuid": {
              "$binary": "KMPE5JWxSQGC8WI/IkVLQQ==",
              "$type": "04"
            }
          },
          "TilledSoil": {
            "Version": 1,
            "DecayTime": "0001-01-02T22:44:51Z"
          }
        }
      }
    },
    {
      "x": -3,
      "y": 17,
      "z": -6,
      "name": "*Plant_Crop_Wheat_Block_Eternal_State_Definitions_StageFinal"
    },
    {
      "x": -3,
      "y": 0,
      "z": -5,
      "name": "BO_Pool_Surface00",
      "rotation": 4
    },
    {
      "x": -3,
      "y": 9,
      "z": -5,
      "name": "BO_Pool_Surface00",
      "rotation": 4
    },
    {
      "x": -3,
      "y": 10,
      "z": -5,
      "name": "BO_Pool_Surface00",
      "rotation": 4
    },
    {
      "x": -3,
      "y": 14,
      "z": -5,
      "name": "BO_Pool_Surface00"
    },
    {
      "x": -3,
      "y": 15,
      "z": -5,
      "name": "Build_Black_Cube"
    },
    {
      "x": -3,
      "y": 16,
      "z": -5,
      "name": "Soil_Dirt_Tilled",
      "components": {
        "Components": {
          "PlacedByInteraction": {
            "WhoPlacedUuid": {
              "$binary": "KMPE5JWxSQGC8WI/IkVLQQ==",
              "$type": "04"
            }
          },
          "TilledSoil": {
            "Version": 1,
            "DecayTime": "0001-01-02T22:44:51Z"
          }
        }
      }
    },
    {
      "x": -3,
      "y": 17,
      "z": -5,
      "name": "*Plant_Crop_Wheat_Block_Eternal_State_Definitions_StageFinal"
    },
    {
      "x": -3,
      "y": 0,
      "z": -4,
      "name": "BO_Pool_Surface00",
      "rotation": 4
    },
    {
      "x": -3,
      "y": 9,
      "z": -4,
      "name": "BO_Pool_Surface00",
      "rotation": 4
    },
    {
      "x": -3,
      "y": 10,
      "z": -4,
      "name": "BO_Pool_Surface00",
      "rotation": 4
    },
    {
      "x": -3,
      "y": 14,
      "z": -4,
      "name": "BO_Pool_Surface00"
    },
    {
      "x": -3,
      "y": 15,
      "z": -4,
      "name": "Build_Black_Cube"
    },
    {
      "x": -3,
      "y": 16,
      "z": -4,
      "name": "Soil_Dirt_Tilled",
      "components": {
        "Components": {
          "PlacedByInteraction": {
            "WhoPlacedUuid": {
              "$binary": "KMPE5JWxSQGC8WI/IkVLQQ==",
              "$type": "04"
            }
          },
          "TilledSoil": {
            "Version": 1,
            "DecayTime": "0001-01-02T22:44:51Z"
          }
        }
      }
    },
    {
      "x": -3,
      "y": 17,
      "z": -4,
      "name": "*Plant_Crop_Wheat_Block_Eternal_State_Definitions_StageFinal"
    },
    {
      "x": -3,
      "y": 0,
      "z": -3,
      "name": "BO_Pool_Surface00",
      "rotation": 4
    },
    {
      "x": -3,
      "y": 9,
      "z": -3,
      "name": "BO_Pool_Surface00",
      "support": 15
    },
    {
      "x": -3,
      "y": 10,
      "z": -3,
      "name": "BO_Pool_Surface00"
    },
    {
      "x": -3,
      "y": 14,
      "z": -3,
      "name": "BO_Pool_Surface00"
    },
    {
      "x": -3,
      "y": 15,
      "z": -3,
      "name": "Build_Black_Cube"
    },
    {
      "x": -3,
      "y": 16,
      "z": -3,
      "name": "Soil_Dirt_Tilled",
      "components": {
        "Components": {
          "PlacedByInteraction": {
            "WhoPlacedUuid": {
              "$binary": "KMPE5JWxSQGC8WI/IkVLQQ==",
              "$type": "04"
            }
          },
          "TilledSoil": {
            "Version": 1,
            "DecayTime": "0001-01-02T22:44:51Z"
          }
        }
      }
    },
    {
      "x": -3,
      "y": 17,
      "z": -3,
      "name": "*Plant_Crop_Wheat_Block_Eternal_State_Definitions_StageFinal"
    },
    {
      "x": -3,
      "y": 0,
      "z": -2,
      "name": "BO_Pool_Surface00",
      "rotation": 4
    },
    {
      "x": -3,
      "y": 9,
      "z": -2,
      "name": "BO_Pool_Surface00",
      "support": 15
    },
    {
      "x": -3,
      "y": 10,
      "z": -2,
      "name": "BO_Pool_Surface00"
    },
    {
      "x": -3,
      "y": 14,
      "z": -2,
      "name": "BO_Pool_Surface00"
    },
    {
      "x": -3,
      "y": 15,
      "z": -2,
      "name": "Build_Black_Cube"
    },
    {
      "x": -3,
      "y": 16,
      "z": -2,
      "name": "Soil_Dirt_Tilled",
      "components": {
        "Components": {
          "PlacedByInteraction": {
            "WhoPlacedUuid": {
              "$binary": "KMPE5JWxSQGC8WI/IkVLQQ==",
              "$type": "04"
            }
          },
          "TilledSoil": {
            "Version": 1,
            "DecayTime": "0001-01-02T22:44:51Z"
          }
        }
      }
    },
    {
      "x": -3,
      "y": 17,
      "z": -2,
      "name": "*Plant_Crop_Wheat_Block_Eternal_State_Definitions_StageFinal"
    },
    {
      "x": -3,
      "y": 0,
      "z": -1,
      "name": "BO_Pool_Surface00",
      "rotation": 4
    },
    {
      "x": -3,
      "y": 9,
      "z": -1,
      "name": "BO_Pool_Surface00"
    },
    {
      "x": -3,
      "y": 10,
      "z": -1,
      "name": "BO_Pool_Surface00"
    },
    {
      "x": -3,
      "y": 14,
      "z": -1,
      "name": "BO_Pool_Surface00"
    },
    {
      "x": -3,
      "y": 15,
      "z": -1,
      "name": "Build_Black_Cube"
    },
    {
      "x": -3,
      "y": 16,
      "z": -1,
      "name": "Soil_Dirt_Tilled",
      "components": {
        "Components": {
          "PlacedByInteraction": {
            "WhoPlacedUuid": {
              "$binary": "KMPE5JWxSQGC8WI/IkVLQQ==",
              "$type": "04"
            }
          },
          "TilledSoil": {
            "Version": 1,
            "DecayTime": "0001-01-02T22:44:51Z"
          }
        }
      }
    },
    {
      "x": -3,
      "y": 17,
      "z": -1,
      "name": "*Plant_Crop_Wheat_Block_Eternal_State_Definitions_StageFinal"
    },
    {
      "x": -3,
      "y": 0,
      "z": 0,
      "name": "BO_Pool_Surface00",
      "rotation": 4
    },
    {
      "x": -3,
      "y": 9,
      "z": 0,
      "name": "BO_Pool_Surface00"
    },
    {
      "x": -3,
      "y": 10,
      "z": 0,
      "name": "BO_Pool_Surface00"
    },
    {
      "x": -3,
      "y": 14,
      "z": 0,
      "name": "BO_Pool_Surface00"
    },
    {
      "x": -3,
      "y": 15,
      "z": 0,
      "name": "Build_Black_Cube"
    },
    {
      "x": -3,
      "y": 16,
      "z": 0,
      "name": "Soil_Dirt_Tilled",
      "components": {
        "Components": {
          "PlacedByInteraction": {
            "WhoPlacedUuid": {
              "$binary": "KMPE5JWxSQGC8WI/IkVLQQ==",
              "$type": "04"
            }
          },
          "TilledSoil": {
            "Version": 1,
            "DecayTime": "0001-01-02T22:44:51Z"
          }
        }
      }
    },
    {
      "x": -3,
      "y": 17,
      "z": 0,
      "name": "*Plant_Crop_Wheat_Block_Eternal_State_Definitions_StageFinal"
    },
    {
      "x": -3,
      "y": 0,
      "z": 1,
      "name": "BO_Pool_Surface00",
      "rotation": 4
    },
    {
      "x": -3,
      "y": 9,
      "z": 1,
      "name": "BO_Pool_Surface00"
    },
    {
      "x": -3,
      "y": 10,
      "z": 1,
      "name": "BO_Pool_Surface00"
    },
    {
      "x": -3,
      "y": 14,
      "z": 1,
      "name": "BO_Pool_Surface00"
    },
    {
      "x": -3,
      "y": 15,
      "z": 1,
      "name": "Build_Black_Cube"
    },
    {
      "x": -3,
      "y": 16,
      "z": 1,
      "name": "Soil_Dirt_Tilled",
      "components": {
        "Components": {
          "PlacedByInteraction": {
            "WhoPlacedUuid": {
              "$binary": "KMPE5JWxSQGC8WI/IkVLQQ==",
              "$type": "04"
            }
          },
          "TilledSoil": {
            "Version": 1,
            "DecayTime": "0001-01-02T22:44:51Z"
          }
        }
      }
    },
    {
      "x": -3,
      "y": 17,
      "z": 1,
      "name": "*Plant_Crop_Wheat_Block_Eternal_State_Definitions_StageFinal"
    },
    {
      "x": -3,
      "y": 0,
      "z": 2,
      "name": "BO_Pool_Surface00",
      "rotation": 4
    },
    {
      "x": -3,
      "y": 9,
      "z": 2,
      "name": "BO_Pool_Surface00"
    },
    {
      "x": -3,
      "y": 10,
      "z": 2,
      "name": "BO_Pool_Surface00"
    },
    {
      "x": -3,
      "y": 14,
      "z": 2,
      "name": "BO_Pool_Surface00"
    },
    {
      "x": -3,
      "y": 15,
      "z": 2,
      "name": "Build_Black_Cube"
    },
    {
      "x": -3,
      "y": 16,
      "z": 2,
      "name": "Soil_Dirt_Tilled",
      "components": {
        "Components": {
          "PlacedByInteraction": {
            "WhoPlacedUuid": {
              "$binary": "KMPE5JWxSQGC8WI/IkVLQQ==",
              "$type": "04"
            }
          },
          "TilledSoil": {
            "Version": 1,
            "DecayTime": "0001-01-02T22:44:51Z"
          }
        }
      }
    },
    {
      "x": -3,
      "y": 17,
      "z": 2,
      "name": "*Plant_Crop_Wheat_Block_Eternal_State_Definitions_StageFinal"
    },
    {
      "x": -3,
      "y": 0,
      "z": 3,
      "name": "BO_Pool_Surface00",
      "rotation": 4
    },
    {
      "x": -3,
      "y": 9,
      "z": 3,
      "name": "BO_Pool_Surface00",
      "support": 15
    },
    {
      "x": -3,
      "y": 10,
      "z": 3,
      "name": "BO_Pool_Surface00"
    },
    {
      "x": -3,
      "y": 14,
      "z": 3,
      "name": "BO_Pool_Surface00"
    },
    {
      "x": -3,
      "y": 15,
      "z": 3,
      "name": "Build_Black_Cube"
    },
    {
      "x": -3,
      "y": 16,
      "z": 3,
      "name": "Soil_Dirt_Tilled",
      "components": {
        "Components": {
          "PlacedByInteraction": {
            "WhoPlacedUuid": {
              "$binary": "KMPE5JWxSQGC8WI/IkVLQQ==",
              "$type": "04"
            }
          },
          "TilledSoil": {
            "Version": 1,
            "DecayTime": "0001-01-02T22:44:51Z"
          }
        }
      }
    },
    {
      "x": -3,
      "y": 17,
      "z": 3,
      "name": "*Plant_Crop_Wheat_Block_Eternal_State_Definitions_StageFinal"
    },
    {
      "x": -3,
      "y": 0,
      "z": 4,
      "name": "BO_Pool_Surface00",
      "rotation": 4
    },
    {
      "x": -3,
      "y": 9,
      "z": 4,
      "name": "BO_Pool_Surface00",
      "support": 15
    },
    {
      "x": -3,
      "y": 10,
      "z": 4,
      "name": "BO_Pool_Surface00"
    },
    {
      "x": -3,
      "y": 14,
      "z": 4,
      "name": "BO_Pool_Surface00"
    },
    {
      "x": -3,
      "y": 15,
      "z": 4,
      "name": "Build_Black_Cube"
    },
    {
      "x": -3,
      "y": 16,
      "z": 4,
      "name": "Soil_Dirt_Tilled",
      "components": {
        "Components": {
          "PlacedByInteraction": {
            "WhoPlacedUuid": {
              "$binary": "KMPE5JWxSQGC8WI/IkVLQQ==",
              "$type": "04"
            }
          },
          "TilledSoil": {
            "Version": 1,
            "DecayTime": "0001-01-02T22:44:51Z"
          }
        }
      }
    },
    {
      "x": -3,
      "y": 17,
      "z": 4,
      "name": "*Plant_Crop_Wheat_Block_Eternal_State_Definitions_StageFinal"
    },
    {
      "x": -3,
      "y": 0,
      "z": 5,
      "name": "BO_Pool_Surface00",
      "rotation": 4
    },
    {
      "x": -3,
      "y": 9,
      "z": 5,
      "name": "BO_Pool_Surface00",
      "rotation": 4
    },
    {
      "x": -3,
      "y": 10,
      "z": 5,
      "name": "BO_Pool_Surface00",
      "rotation": 4
    },
    {
      "x": -3,
      "y": 14,
      "z": 5,
      "name": "BO_Pool_Surface00"
    },
    {
      "x": -3,
      "y": 15,
      "z": 5,
      "name": "Build_Black_Cube"
    },
    {
      "x": -3,
      "y": 16,
      "z": 5,
      "name": "Soil_Dirt_Tilled",
      "components": {
        "Components": {
          "PlacedByInteraction": {
            "WhoPlacedUuid": {
              "$binary": "KMPE5JWxSQGC8WI/IkVLQQ==",
              "$type": "04"
            }
          },
          "TilledSoil": {
            "Version": 1,
            "DecayTime": "0001-01-02T22:44:51Z"
          }
        }
      }
    },
    {
      "x": -3,
      "y": 17,
      "z": 5,
      "name": "*Plant_Crop_Wheat_Block_Eternal_State_Definitions_StageFinal"
    },
    {
      "x": -3,
      "y": 0,
      "z": 6,
      "name": "BO_Pool_Surface00",
      "rotation": 4
    },
    {
      "x": -3,
      "y": 9,
      "z": 6,
      "name": "BO_Pool_Surface00",
      "rotation": 4
    },
    {
      "x": -3,
      "y": 10,
      "z": 6,
      "name": "BO_Pool_Surface00",
      "rotation": 4
    },
    {
      "x": -3,
      "y": 14,
      "z": 6,
      "name": "BO_Pool_Surface00"
    },
    {
      "x": -3,
      "y": 15,
      "z": 6,
      "name": "Build_Black_Cube"
    },
    {
      "x": -3,
      "y": 16,
      "z": 6,
      "name": "Soil_Dirt_Tilled",
      "components": {
        "Components": {
          "PlacedByInteraction": {
            "WhoPlacedUuid": {
              "$binary": "KMPE5JWxSQGC8WI/IkVLQQ==",
              "$type": "04"
            }
          },
          "TilledSoil": {
            "Version": 1,
            "DecayTime": "0001-01-02T22:44:51Z"
          }
        }
      }
    },
    {
      "x": -3,
      "y": 17,
      "z": 6,
      "name": "*Plant_Crop_Wheat_Block_Eternal_State_Definitions_StageFinal"
    },
    {
      "x": -3,
      "y": 0,
      "z": 7,
      "name": "BO_Pool_Surface00",
      "rotation": 4
    },
    {
      "x": -3,
      "y": 9,
      "z": 7,
      "name": "BO_Pool_Surface00",
      "rotation": 4
    },
    {
      "x": -3,
      "y": 10,
      "z": 7,
      "name": "BO_Pool_Surface00",
      "rotation": 4
    },
    {
      "x": -3,
      "y": 14,
      "z": 7,
      "name": "BO_Pool_Surface00"
    },
    {
      "x": -3,
      "y": 15,
      "z": 7,
      "name": "Build_Black_Cube"
    },
    {
      "x": -3,
      "y": 16,
      "z": 7,
      "name": "Soil_Dirt_Tilled",
      "components": {
        "Components": {
          "PlacedByInteraction": {
            "WhoPlacedUuid": {
              "$binary": "KMPE5JWxSQGC8WI/IkVLQQ==",
              "$type": "04"
            }
          },
          "TilledSoil": {
            "Version": 1,
            "DecayTime": "0001-01-02T22:44:51Z"
          }
        }
      }
    },
    {
      "x": -3,
      "y": 17,
      "z": 7,
      "name": "*Plant_Crop_Wheat_Block_Eternal_State_Definitions_StageFinal"
    },
    {
      "x": -3,
      "y": 0,
      "z": 8,
      "name": "BO_Pool_Surface00",
      "rotation": 4
    },
    {
      "x": -3,
      "y": 1,
      "z": 8,
      "name": "BO_Pool_Surface00",
      "rotation": 5
    },
    {
      "x": -3,
      "y": 9,
      "z": 8,
      "name": "BO_Pool_Surface00",
      "rotation": 4
    },
    {
      "x": -3,
      "y": 10,
      "z": 8,
      "name": "BO_Pool_Surface00",
      "rotation": 4
    },
    {
      "x": -3,
      "y": 14,
      "z": 8,
      "name": "BO_Pool_Surface00"
    },
    {
      "x": -3,
      "y": 15,
      "z": 8,
      "name": "Build_Black_Cube"
    },
    {
      "x": -3,
      "y": 16,
      "z": 8,
      "name": "Soil_Dirt_Tilled",
      "components": {
        "Components": {
          "PlacedByInteraction": {
            "WhoPlacedUuid": {
              "$binary": "KMPE5JWxSQGC8WI/IkVLQQ==",
              "$type": "04"
            }
          },
          "TilledSoil": {
            "Version": 1,
            "DecayTime": "0001-01-02T22:44:51Z"
          }
        }
      }
    },
    {
      "x": -3,
      "y": 17,
      "z": 8,
      "name": "*Plant_Crop_Wheat_Block_Eternal_State_Definitions_StageFinal"
    },
    {
      "x": -3,
      "y": 0,
      "z": 9,
      "name": "BO_Pool_Surface00",
      "rotation": 4
    },
    {
      "x": -3,
      "y": 1,
      "z": 9,
      "name": "BO_Pool_Surface00",
      "rotation": 4
    },
    {
      "x": -3,
      "y": 2,
      "z": 9,
      "name": "BO_Pool_Surface00",
      "rotation": 4
    },
    {
      "x": -3,
      "y": 3,
      "z": 9,
      "name": "BO_Pool_Surface00",
      "rotation": 4
    },
    {
      "x": -3,
      "y": 4,
      "z": 9,
      "name": "BO_Pool_Surface00",
      "rotation": 4
    },
    {
      "x": -3,
      "y": 5,
      "z": 9,
      "name": "BO_Pool_Surface00",
      "rotation": 4
    },
    {
      "x": -3,
      "y": 6,
      "z": 9,
      "name": "BO_Pool_Surface00",
      "rotation": 4
    },
    {
      "x": -3,
      "y": 7,
      "z": 9,
      "name": "BO_Pool_Surface00",
      "rotation": 4
    },
    {
      "x": -3,
      "y": 8,
      "z": 9,
      "name": "BO_Pool_Surface00",
      "rotation": 4
    },
    {
      "x": -3,
      "y": 9,
      "z": 9,
      "name": "BO_Pool_Surface00",
      "rotation": 4
    },
    {
      "x": -3,
      "y": 10,
      "z": 9,
      "name": "BO_Pool_Surface00",
      "rotation": 4
    },
    {
      "x": -3,
      "y": 14,
      "z": 9,
      "name": "BO_Pool_Surface00"
    },
    {
      "x": -3,
      "y": 15,
      "z": 9,
      "name": "Build_Black_Cube"
    },
    {
      "x": -3,
      "y": 16,
      "z": 9,
      "name": "Soil_Dirt_Tilled",
      "components": {
        "Components": {
          "PlacedByInteraction": {
            "WhoPlacedUuid": {
              "$binary": "KMPE5JWxSQGC8WI/IkVLQQ==",
              "$type": "04"
            }
          },
          "TilledSoil": {
            "Version": 1,
            "DecayTime": "0001-01-02T22:44:51Z"
          }
        }
      }
    },
    {
      "x": -3,
      "y": 17,
      "z": 9,
      "name": "*Plant_Crop_Wheat_Block_Eternal_State_Definitions_StageFinal"
    },
    {
      "x": -3,
      "y": 0,
      "z": 10,
      "name": "BO_Pool_Surface00",
      "rotation": 4
    },
    {
      "x": -3,
      "y": 1,
      "z": 10,
      "name": "BO_Pool_Surface00",
      "rotation": 4
    },
    {
      "x": -3,
      "y": 2,
      "z": 10,
      "name": "BO_Pool_Surface00",
      "rotation": 4
    },
    {
      "x": -3,
      "y": 3,
      "z": 10,
      "name": "BO_Pool_Surface00",
      "rotation": 4
    },
    {
      "x": -3,
      "y": 4,
      "z": 10,
      "name": "BO_Pool_Surface00",
      "rotation": 4
    },
    {
      "x": -3,
      "y": 5,
      "z": 10,
      "name": "BO_Pool_Surface00",
      "rotation": 4
    },
    {
      "x": -3,
      "y": 6,
      "z": 10,
      "name": "BO_Pool_Surface00",
      "rotation": 4
    },
    {
      "x": -3,
      "y": 7,
      "z": 10,
      "name": "BO_Pool_Surface00",
      "rotation": 4
    },
    {
      "x": -3,
      "y": 8,
      "z": 10,
      "name": "BO_Pool_Surface00",
      "rotation": 4
    },
    {
      "x": -3,
      "y": 9,
      "z": 10,
      "name": "BO_Pool_Surface00",
      "rotation": 4
    },
    {
      "x": -3,
      "y": 10,
      "z": 10,
      "name": "BO_Pool_Surface00",
      "rotation": 4
    },
    {
      "x": -3,
      "y": 14,
      "z": 10,
      "name": "BO_Pool_Surface00"
    },
    {
      "x": -3,
      "y": 15,
      "z": 10,
      "name": "Build_Black_Cube"
    },
    {
      "x": -3,
      "y": 16,
      "z": 10,
      "name": "Soil_Dirt_Tilled",
      "components": {
        "Components": {
          "PlacedByInteraction": {
            "WhoPlacedUuid": {
              "$binary": "KMPE5JWxSQGC8WI/IkVLQQ==",
              "$type": "04"
            }
          },
          "TilledSoil": {
            "Version": 1,
            "DecayTime": "0001-01-02T22:44:51Z"
          }
        }
      }
    },
    {
      "x": -3,
      "y": 17,
      "z": 10,
      "name": "*Plant_Crop_Wheat_Block_Eternal_State_Definitions_StageFinal"
    },
    {
      "x": -2,
      "y": 0,
      "z": -9,
      "name": "BO_Pool_Surface00",
      "rotation": 4
    },
    {
      "x": -2,
      "y": 1,
      "z": -9,
      "name": "BO_Pool_Surface00",
      "rotation": 4
    },
    {
      "x": -2,
      "y": 9,
      "z": -9,
      "name": "BO_Pool_Surface00",
      "rotation": 4
    },
    {
      "x": -2,
      "y": 10,
      "z": -9,
      "name": "BO_Pool_Surface00",
      "rotation": 4
    },
    {
      "x": -2,
      "y": 14,
      "z": -9,
      "name": "BO_Pool_Surface00"
    },
    {
      "x": -2,
      "y": 15,
      "z": -9,
      "name": "Build_Black_Cube"
    },
    {
      "x": -2,
      "y": 16,
      "z": -9,
      "name": "Soil_Dirt_Tilled",
      "components": {
        "Components": {
          "PlacedByInteraction": {
            "WhoPlacedUuid": {
              "$binary": "KMPE5JWxSQGC8WI/IkVLQQ==",
              "$type": "04"
            }
          },
          "TilledSoil": {
            "Version": 1,
            "DecayTime": "0001-01-02T22:44:51Z"
          }
        }
      }
    },
    {
      "x": -2,
      "y": 17,
      "z": -9,
      "name": "*Plant_Crop_Wheat_Block_Eternal_State_Definitions_StageFinal"
    },
    {
      "x": -2,
      "y": 0,
      "z": -8,
      "name": "BO_Pool_Surface00",
      "rotation": 4
    },
    {
      "x": -2,
      "y": 1,
      "z": -8,
      "name": "BO_Pool_Surface00",
      "rotation": 4
    },
    {
      "x": -2,
      "y": 9,
      "z": -8,
      "name": "BO_Pool_Surface00",
      "rotation": 4
    },
    {
      "x": -2,
      "y": 10,
      "z": -8,
      "name": "BO_Pool_Surface00",
      "rotation": 4
    },
    {
      "x": -2,
      "y": 14,
      "z": -8,
      "name": "BO_Pool_Surface00"
    },
    {
      "x": -2,
      "y": 15,
      "z": -8,
      "name": "Build_Black_Cube"
    },
    {
      "x": -2,
      "y": 16,
      "z": -8,
      "name": "Soil_Dirt_Tilled",
      "components": {
        "Components": {
          "PlacedByInteraction": {
            "WhoPlacedUuid": {
              "$binary": "KMPE5JWxSQGC8WI/IkVLQQ==",
              "$type": "04"
            }
          },
          "TilledSoil": {
            "Version": 1,
            "DecayTime": "0001-01-02T22:44:51Z"
          }
        }
      }
    },
    {
      "x": -2,
      "y": 17,
      "z": -8,
      "name": "*Plant_Crop_Wheat_Block_Eternal_State_Definitions_StageFinal"
    },
    {
      "x": -2,
      "y": 0,
      "z": -7,
      "name": "BO_Pool_Surface00",
      "rotation": 4
    },
    {
      "x": -2,
      "y": 1,
      "z": -7,
      "name": "BO_Pool_Surface00",
      "rotation": 4
    },
    {
      "x": -2,
      "y": 9,
      "z": -7,
      "name": "BO_Pool_Surface00",
      "rotation": 4
    },
    {
      "x": -2,
      "y": 10,
      "z": -7,
      "name": "BO_Pool_Surface00",
      "rotation": 4
    },
    {
      "x": -2,
      "y": 14,
      "z": -7,
      "name": "BO_Pool_Surface00"
    },
    {
      "x": -2,
      "y": 15,
      "z": -7,
      "name": "Build_Black_Cube"
    },
    {
      "x": -2,
      "y": 16,
      "z": -7,
      "name": "Soil_Dirt_Tilled",
      "components": {
        "Components": {
          "PlacedByInteraction": {
            "WhoPlacedUuid": {
              "$binary": "KMPE5JWxSQGC8WI/IkVLQQ==",
              "$type": "04"
            }
          },
          "TilledSoil": {
            "Version": 1,
            "DecayTime": "0001-01-02T22:44:51Z"
          }
        }
      }
    },
    {
      "x": -2,
      "y": 17,
      "z": -7,
      "name": "*Plant_Crop_Wheat_Block_Eternal_State_Definitions_StageFinal"
    },
    {
      "x": -2,
      "y": 0,
      "z": -6,
      "name": "BO_Pool_Surface00",
      "rotation": 4
    },
    {
      "x": -2,
      "y": 9,
      "z": -6,
      "name": "BO_Pool_Surface00",
      "rotation": 4
    },
    {
      "x": -2,
      "y": 10,
      "z": -6,
      "name": "BO_Pool_Surface00",
      "rotation": 4
    },
    {
      "x": -2,
      "y": 14,
      "z": -6,
      "name": "BO_Pool_Surface00"
    },
    {
      "x": -2,
      "y": 15,
      "z": -6,
      "name": "Build_Black_Cube"
    },
    {
      "x": -2,
      "y": 16,
      "z": -6,
      "name": "Soil_Dirt_Tilled",
      "components": {
        "Components": {
          "PlacedByInteraction": {
            "WhoPlacedUuid": {
              "$binary": "KMPE5JWxSQGC8WI/IkVLQQ==",
              "$type": "04"
            }
          },
          "TilledSoil": {
            "Version": 1,
            "DecayTime": "0001-01-02T22:44:51Z"
          }
        }
      }
    },
    {
      "x": -2,
      "y": 17,
      "z": -6,
      "name": "*Plant_Crop_Wheat_Block_Eternal_State_Definitions_StageFinal"
    },
    {
      "x": -2,
      "y": 0,
      "z": -5,
      "name": "BO_Pool_Surface00",
      "rotation": 4
    },
    {
      "x": -2,
      "y": 9,
      "z": -5,
      "name": "BO_Pool_Surface00",
      "rotation": 4
    },
    {
      "x": -2,
      "y": 10,
      "z": -5,
      "name": "BO_Pool_Surface00",
      "rotation": 4
    },
    {
      "x": -2,
      "y": 14,
      "z": -5,
      "name": "BO_Pool_Surface00"
    },
    {
      "x": -2,
      "y": 15,
      "z": -5,
      "name": "Build_Black_Cube"
    },
    {
      "x": -2,
      "y": 16,
      "z": -5,
      "name": "Soil_Dirt_Tilled",
      "components": {
        "Components": {
          "PlacedByInteraction": {
            "WhoPlacedUuid": {
              "$binary": "KMPE5JWxSQGC8WI/IkVLQQ==",
              "$type": "04"
            }
          },
          "TilledSoil": {
            "Version": 1,
            "DecayTime": "0001-01-02T22:44:51Z"
          }
        }
      }
    },
    {
      "x": -2,
      "y": 17,
      "z": -5,
      "name": "*Plant_Crop_Wheat_Block_Eternal_State_Definitions_StageFinal"
    },
    {
      "x": -2,
      "y": 0,
      "z": -4,
      "name": "BO_Pool_Surface00",
      "rotation": 4
    },
    {
      "x": -2,
      "y": 9,
      "z": -4,
      "name": "BO_Pool_Surface00",
      "rotation": 4
    },
    {
      "x": -2,
      "y": 10,
      "z": -4,
      "name": "BO_Pool_Surface00",
      "rotation": 4
    },
    {
      "x": -2,
      "y": 14,
      "z": -4,
      "name": "BO_Pool_Surface00"
    },
    {
      "x": -2,
      "y": 15,
      "z": -4,
      "name": "Build_Black_Cube"
    },
    {
      "x": -2,
      "y": 16,
      "z": -4,
      "name": "Soil_Dirt_Tilled",
      "components": {
        "Components": {
          "PlacedByInteraction": {
            "WhoPlacedUuid": {
              "$binary": "KMPE5JWxSQGC8WI/IkVLQQ==",
              "$type": "04"
            }
          },
          "TilledSoil": {
            "Version": 1,
            "DecayTime": "0001-01-02T22:44:51Z"
          }
        }
      }
    },
    {
      "x": -2,
      "y": 17,
      "z": -4,
      "name": "*Plant_Crop_Wheat_Block_Eternal_State_Definitions_StageFinal"
    },
    {
      "x": -2,
      "y": 0,
      "z": -3,
      "name": "BO_Pool_Surface00",
      "rotation": 4
    },
    {
      "x": -2,
      "y": 9,
      "z": -3,
      "name": "BO_Pool_Surface00",
      "rotation": 4
    },
    {
      "x": -2,
      "y": 10,
      "z": -3,
      "name": "BO_Pool_Surface00",
      "rotation": 4
    },
    {
      "x": -2,
      "y": 14,
      "z": -3,
      "name": "BO_Pool_Surface00"
    },
    {
      "x": -2,
      "y": 15,
      "z": -3,
      "name": "Build_Black_Cube"
    },
    {
      "x": -2,
      "y": 16,
      "z": -3,
      "name": "Soil_Dirt_Tilled",
      "components": {
        "Components": {
          "PlacedByInteraction": {
            "WhoPlacedUuid": {
              "$binary": "KMPE5JWxSQGC8WI/IkVLQQ==",
              "$type": "04"
            }
          },
          "TilledSoil": {
            "Version": 1,
            "DecayTime": "0001-01-02T22:44:51Z"
          }
        }
      }
    },
    {
      "x": -2,
      "y": 17,
      "z": -3,
      "name": "*Plant_Crop_Wheat_Block_Eternal_State_Definitions_StageFinal"
    },
    {
      "x": -2,
      "y": 0,
      "z": -2,
      "name": "BO_Pool_Surface00",
      "rotation": 4
    },
    {
      "x": -2,
      "y": 9,
      "z": -2,
      "name": "BO_Pool_Surface00",
      "rotation": 4
    },
    {
      "x": -2,
      "y": 10,
      "z": -2,
      "name": "BO_Pool_Surface00",
      "rotation": 4
    },
    {
      "x": -2,
      "y": 14,
      "z": -2,
      "name": "BO_Pool_Surface00"
    },
    {
      "x": -2,
      "y": 15,
      "z": -2,
      "name": "Build_Black_Cube"
    },
    {
      "x": -2,
      "y": 16,
      "z": -2,
      "name": "Soil_Dirt_Tilled",
      "components": {
        "Components": {
          "PlacedByInteraction": {
            "WhoPlacedUuid": {
              "$binary": "KMPE5JWxSQGC8WI/IkVLQQ==",
              "$type": "04"
            }
          },
          "TilledSoil": {
            "Version": 1,
            "DecayTime": "0001-01-02T22:44:51Z"
          }
        }
      }
    },
    {
      "x": -2,
      "y": 17,
      "z": -2,
      "name": "*Plant_Crop_Wheat_Block_Eternal_State_Definitions_StageFinal"
    },
    {
      "x": -2,
      "y": 0,
      "z": -1,
      "name": "BO_Pool_Surface00",
      "rotation": 4
    },
    {
      "x": -2,
      "y": 9,
      "z": -1,
      "name": "BO_Pool_Surface00",
      "rotation": 4
    },
    {
      "x": -2,
      "y": 10,
      "z": -1,
      "name": "BO_Pool_Surface00",
      "rotation": 4
    },
    {
      "x": -2,
      "y": 14,
      "z": -1,
      "name": "BO_Pool_Surface00"
    },
    {
      "x": -2,
      "y": 15,
      "z": -1,
      "name": "Build_Black_Cube"
    },
    {
      "x": -2,
      "y": 16,
      "z": -1,
      "name": "Soil_Dirt_Tilled",
      "components": {
        "Components": {
          "PlacedByInteraction": {
            "WhoPlacedUuid": {
              "$binary": "KMPE5JWxSQGC8WI/IkVLQQ==",
              "$type": "04"
            }
          },
          "TilledSoil": {
            "Version": 1,
            "DecayTime": "0001-01-02T22:44:51Z"
          }
        }
      }
    },
    {
      "x": -2,
      "y": 17,
      "z": -1,
      "name": "*Plant_Crop_Wheat_Block_Eternal_State_Definitions_StageFinal"
    },
    {
      "x": -2,
      "y": 0,
      "z": 0,
      "name": "BO_Pool_Surface00",
      "rotation": 4
    },
    {
      "x": -2,
      "y": 9,
      "z": 0,
      "name": "BO_Pool_Surface00",
      "rotation": 4
    },
    {
      "x": -2,
      "y": 10,
      "z": 0,
      "name": "BO_Pool_Surface00",
      "rotation": 4
    },
    {
      "x": -2,
      "y": 14,
      "z": 0,
      "name": "BO_Pool_Surface00"
    },
    {
      "x": -2,
      "y": 15,
      "z": 0,
      "name": "Build_Black_Cube"
    },
    {
      "x": -2,
      "y": 16,
      "z": 0,
      "name": "Soil_Dirt_Tilled",
      "components": {
        "Components": {
          "PlacedByInteraction": {
            "WhoPlacedUuid": {
              "$binary": "KMPE5JWxSQGC8WI/IkVLQQ==",
              "$type": "04"
            }
          },
          "TilledSoil": {
            "Version": 1,
            "DecayTime": "0001-01-02T22:44:51Z"
          }
        }
      }
    },
    {
      "x": -2,
      "y": 17,
      "z": 0,
      "name": "*Plant_Crop_Wheat_Block_Eternal_State_Definitions_StageFinal"
    },
    {
      "x": -2,
      "y": 0,
      "z": 1,
      "name": "BO_Pool_Surface00",
      "rotation": 4
    },
    {
      "x": -2,
      "y": 9,
      "z": 1,
      "name": "BO_Pool_Surface00",
      "rotation": 4
    },
    {
      "x": -2,
      "y": 10,
      "z": 1,
      "name": "BO_Pool_Surface00",
      "rotation": 4
    },
    {
      "x": -2,
      "y": 14,
      "z": 1,
      "name": "BO_Pool_Surface00"
    },
    {
      "x": -2,
      "y": 15,
      "z": 1,
      "name": "Build_Black_Cube"
    },
    {
      "x": -2,
      "y": 16,
      "z": 1,
      "name": "Soil_Dirt_Tilled",
      "components": {
        "Components": {
          "PlacedByInteraction": {
            "WhoPlacedUuid": {
              "$binary": "KMPE5JWxSQGC8WI/IkVLQQ==",
              "$type": "04"
            }
          },
          "TilledSoil": {
            "Version": 1,
            "DecayTime": "0001-01-02T22:44:51Z"
          }
        }
      }
    },
    {
      "x": -2,
      "y": 17,
      "z": 1,
      "name": "*Plant_Crop_Wheat_Block_Eternal_State_Definitions_StageFinal"
    },
    {
      "x": -2,
      "y": 0,
      "z": 2,
      "name": "BO_Pool_Surface00",
      "rotation": 4
    },
    {
      "x": -2,
      "y": 9,
      "z": 2,
      "name": "BO_Pool_Surface00",
      "rotation": 4
    },
    {
      "x": -2,
      "y": 10,
      "z": 2,
      "name": "BO_Pool_Surface00",
      "rotation": 4
    },
    {
      "x": -2,
      "y": 14,
      "z": 2,
      "name": "BO_Pool_Surface00"
    },
    {
      "x": -2,
      "y": 15,
      "z": 2,
      "name": "Build_Black_Cube"
    },
    {
      "x": -2,
      "y": 16,
      "z": 2,
      "name": "Soil_Dirt_Tilled",
      "components": {
        "Components": {
          "PlacedByInteraction": {
            "WhoPlacedUuid": {
              "$binary": "KMPE5JWxSQGC8WI/IkVLQQ==",
              "$type": "04"
            }
          },
          "TilledSoil": {
            "Version": 1,
            "DecayTime": "0001-01-02T22:44:51Z"
          }
        }
      }
    },
    {
      "x": -2,
      "y": 17,
      "z": 2,
      "name": "*Plant_Crop_Wheat_Block_Eternal_State_Definitions_StageFinal"
    },
    {
      "x": -2,
      "y": 0,
      "z": 3,
      "name": "BO_Pool_Surface00",
      "rotation": 4
    },
    {
      "x": -2,
      "y": 9,
      "z": 3,
      "name": "BO_Pool_Surface00",
      "rotation": 4
    },
    {
      "x": -2,
      "y": 10,
      "z": 3,
      "name": "BO_Pool_Surface00",
      "rotation": 4
    },
    {
      "x": -2,
      "y": 14,
      "z": 3,
      "name": "BO_Pool_Surface00"
    },
    {
      "x": -2,
      "y": 15,
      "z": 3,
      "name": "Build_Black_Cube"
    },
    {
      "x": -2,
      "y": 16,
      "z": 3,
      "name": "Soil_Dirt_Tilled",
      "components": {
        "Components": {
          "PlacedByInteraction": {
            "WhoPlacedUuid": {
              "$binary": "KMPE5JWxSQGC8WI/IkVLQQ==",
              "$type": "04"
            }
          },
          "TilledSoil": {
            "Version": 1,
            "DecayTime": "0001-01-02T22:44:51Z"
          }
        }
      }
    },
    {
      "x": -2,
      "y": 17,
      "z": 3,
      "name": "*Plant_Crop_Wheat_Block_Eternal_State_Definitions_StageFinal"
    },
    {
      "x": -2,
      "y": 0,
      "z": 4,
      "name": "BO_Pool_Surface00",
      "rotation": 4
    },
    {
      "x": -2,
      "y": 9,
      "z": 4,
      "name": "BO_Pool_Surface00",
      "rotation": 4
    },
    {
      "x": -2,
      "y": 10,
      "z": 4,
      "name": "BO_Pool_Surface00",
      "rotation": 4
    },
    {
      "x": -2,
      "y": 14,
      "z": 4,
      "name": "BO_Pool_Surface00"
    },
    {
      "x": -2,
      "y": 15,
      "z": 4,
      "name": "Build_Black_Cube"
    },
    {
      "x": -2,
      "y": 16,
      "z": 4,
      "name": "Soil_Dirt_Tilled",
      "components": {
        "Components": {
          "PlacedByInteraction": {
            "WhoPlacedUuid": {
              "$binary": "KMPE5JWxSQGC8WI/IkVLQQ==",
              "$type": "04"
            }
          },
          "TilledSoil": {
            "Version": 1,
            "DecayTime": "0001-01-02T22:44:51Z"
          }
        }
      }
    },
    {
      "x": -2,
      "y": 17,
      "z": 4,
      "name": "*Plant_Crop_Wheat_Block_Eternal_State_Definitions_StageFinal"
    },
    {
      "x": -2,
      "y": 0,
      "z": 5,
      "name": "BO_Pool_Surface00",
      "rotation": 4
    },
    {
      "x": -2,
      "y": 9,
      "z": 5,
      "name": "BO_Pool_Surface00",
      "rotation": 4
    },
    {
      "x": -2,
      "y": 10,
      "z": 5,
      "name": "BO_Pool_Surface00",
      "rotation": 4
    },
    {
      "x": -2,
      "y": 14,
      "z": 5,
      "name": "BO_Pool_Surface00"
    },
    {
      "x": -2,
      "y": 15,
      "z": 5,
      "name": "Build_Black_Cube"
    },
    {
      "x": -2,
      "y": 16,
      "z": 5,
      "name": "Soil_Dirt_Tilled",
      "components": {
        "Components": {
          "PlacedByInteraction": {
            "WhoPlacedUuid": {
              "$binary": "KMPE5JWxSQGC8WI/IkVLQQ==",
              "$type": "04"
            }
          },
          "TilledSoil": {
            "Version": 1,
            "DecayTime": "0001-01-02T22:44:51Z"
          }
        }
      }
    },
    {
      "x": -2,
      "y": 17,
      "z": 5,
      "name": "*Plant_Crop_Wheat_Block_Eternal_State_Definitions_StageFinal"
    },
    {
      "x": -2,
      "y": 0,
      "z": 6,
      "name": "BO_Pool_Surface00",
      "rotation": 4
    },
    {
      "x": -2,
      "y": 9,
      "z": 6,
      "name": "BO_Pool_Surface00",
      "rotation": 4
    },
    {
      "x": -2,
      "y": 10,
      "z": 6,
      "name": "BO_Pool_Surface00",
      "rotation": 4
    },
    {
      "x": -2,
      "y": 14,
      "z": 6,
      "name": "BO_Pool_Surface00"
    },
    {
      "x": -2,
      "y": 15,
      "z": 6,
      "name": "Build_Black_Cube"
    },
    {
      "x": -2,
      "y": 16,
      "z": 6,
      "name": "Soil_Dirt_Tilled",
      "components": {
        "Components": {
          "PlacedByInteraction": {
            "WhoPlacedUuid": {
              "$binary": "KMPE5JWxSQGC8WI/IkVLQQ==",
              "$type": "04"
            }
          },
          "TilledSoil": {
            "Version": 1,
            "DecayTime": "0001-01-02T22:44:51Z"
          }
        }
      }
    },
    {
      "x": -2,
      "y": 17,
      "z": 6,
      "name": "*Plant_Crop_Wheat_Block_Eternal_State_Definitions_StageFinal"
    },
    {
      "x": -2,
      "y": 0,
      "z": 7,
      "name": "BO_Pool_Surface00",
      "rotation": 4
    },
    {
      "x": -2,
      "y": 9,
      "z": 7,
      "name": "BO_Pool_Surface00",
      "rotation": 4
    },
    {
      "x": -2,
      "y": 10,
      "z": 7,
      "name": "BO_Pool_Surface00",
      "rotation": 4
    },
    {
      "x": -2,
      "y": 14,
      "z": 7,
      "name": "BO_Pool_Surface00"
    },
    {
      "x": -2,
      "y": 15,
      "z": 7,
      "name": "Build_Black_Cube"
    },
    {
      "x": -2,
      "y": 16,
      "z": 7,
      "name": "Soil_Dirt_Tilled",
      "components": {
        "Components": {
          "PlacedByInteraction": {
            "WhoPlacedUuid": {
              "$binary": "KMPE5JWxSQGC8WI/IkVLQQ==",
              "$type": "04"
            }
          },
          "TilledSoil": {
            "Version": 1,
            "DecayTime": "0001-01-02T22:44:51Z"
          }
        }
      }
    },
    {
      "x": -2,
      "y": 17,
      "z": 7,
      "name": "*Plant_Crop_Wheat_Block_Eternal_State_Definitions_StageFinal"
    },
    {
      "x": -2,
      "y": 0,
      "z": 8,
      "name": "BO_Pool_Surface00",
      "rotation": 4
    },
    {
      "x": -2,
      "y": 1,
      "z": 8,
      "name": "BO_Pool_Surface00",
      "rotation": 4
    },
    {
      "x": -2,
      "y": 9,
      "z": 8,
      "name": "BO_Pool_Surface00",
      "rotation": 4
    },
    {
      "x": -2,
      "y": 10,
      "z": 8,
      "name": "BO_Pool_Surface00",
      "rotation": 4
    },
    {
      "x": -2,
      "y": 14,
      "z": 8,
      "name": "BO_Pool_Surface00"
    },
    {
      "x": -2,
      "y": 15,
      "z": 8,
      "name": "Build_Black_Cube"
    },
    {
      "x": -2,
      "y": 16,
      "z": 8,
      "name": "Soil_Dirt_Tilled",
      "components": {
        "Components": {
          "PlacedByInteraction": {
            "WhoPlacedUuid": {
              "$binary": "KMPE5JWxSQGC8WI/IkVLQQ==",
              "$type": "04"
            }
          },
          "TilledSoil": {
            "Version": 1,
            "DecayTime": "0001-01-02T22:44:51Z"
          }
        }
      }
    },
    {
      "x": -2,
      "y": 17,
      "z": 8,
      "name": "*Plant_Crop_Wheat_Block_Eternal_State_Definitions_StageFinal"
    },
    {
      "x": -2,
      "y": 0,
      "z": 9,
      "name": "BO_Pool_Surface00",
      "rotation": 4
    },
    {
      "x": -2,
      "y": 1,
      "z": 9,
      "name": "BO_Pool_Surface00",
      "rotation": 4
    },
    {
      "x": -2,
      "y": 9,
      "z": 9,
      "name": "BO_Pool_Surface00",
      "rotation": 4
    },
    {
      "x": -2,
      "y": 10,
      "z": 9,
      "name": "BO_Pool_Surface00",
      "rotation": 4
    },
    {
      "x": -2,
      "y": 14,
      "z": 9,
      "name": "BO_Pool_Surface00"
    },
    {
      "x": -2,
      "y": 15,
      "z": 9,
      "name": "Build_Black_Cube"
    },
    {
      "x": -2,
      "y": 16,
      "z": 9,
      "name": "Soil_Dirt_Tilled",
      "components": {
        "Components": {
          "PlacedByInteraction": {
            "WhoPlacedUuid": {
              "$binary": "KMPE5JWxSQGC8WI/IkVLQQ==",
              "$type": "04"
            }
          },
          "TilledSoil": {
            "Version": 1,
            "DecayTime": "0001-01-02T22:44:51Z"
          }
        }
      }
    },
    {
      "x": -2,
      "y": 17,
      "z": 9,
      "name": "*Plant_Crop_Wheat_Block_Eternal_State_Definitions_StageFinal"
    },
    {
      "x": -2,
      "y": 0,
      "z": 10,
      "name": "BO_Pool_Surface00",
      "rotation": 4
    },
    {
      "x": -2,
      "y": 1,
      "z": 10,
      "name": "BO_Pool_Surface00",
      "rotation": 4
    },
    {
      "x": -2,
      "y": 9,
      "z": 10,
      "name": "BO_Pool_Surface00",
      "rotation": 4
    },
    {
      "x": -2,
      "y": 10,
      "z": 10,
      "name": "BO_Pool_Surface00",
      "rotation": 4
    },
    {
      "x": -2,
      "y": 14,
      "z": 10,
      "name": "BO_Pool_Surface00"
    },
    {
      "x": -2,
      "y": 15,
      "z": 10,
      "name": "Build_Black_Cube"
    },
    {
      "x": -2,
      "y": 16,
      "z": 10,
      "name": "Soil_Dirt_Tilled",
      "components": {
        "Components": {
          "PlacedByInteraction": {
            "WhoPlacedUuid": {
              "$binary": "KMPE5JWxSQGC8WI/IkVLQQ==",
              "$type": "04"
            }
          },
          "TilledSoil": {
            "Version": 1,
            "DecayTime": "0001-01-02T22:44:51Z"
          }
        }
      }
    },
    {
      "x": -2,
      "y": 17,
      "z": 10,
      "name": "*Plant_Crop_Wheat_Block_Eternal_State_Definitions_StageFinal"
    },
    {
      "x": -1,
      "y": 0,
      "z": -9,
      "name": "BO_Pool_Surface00",
      "rotation": 4
    },
    {
      "x": -1,
      "y": 9,
      "z": -9,
      "name": "BO_Pool_Surface00",
      "rotation": 4
    },
    {
      "x": -1,
      "y": 10,
      "z": -9,
      "name": "BO_Pool_Surface00",
      "rotation": 4
    },
    {
      "x": -1,
      "y": 14,
      "z": -9,
      "name": "BO_Pool_Surface00"
    },
    {
      "x": -1,
      "y": 15,
      "z": -9,
      "name": "Build_Black_Cube"
    },
    {
      "x": -1,
      "y": 16,
      "z": -9,
      "name": "Soil_Dirt_Tilled",
      "components": {
        "Components": {
          "PlacedByInteraction": {
            "WhoPlacedUuid": {
              "$binary": "KMPE5JWxSQGC8WI/IkVLQQ==",
              "$type": "04"
            }
          },
          "TilledSoil": {
            "Version": 1,
            "DecayTime": "0001-01-02T22:44:51Z"
          }
        }
      }
    },
    {
      "x": -1,
      "y": 17,
      "z": -9,
      "name": "*Plant_Crop_Wheat_Block_Eternal_State_Definitions_StageFinal"
    },
    {
      "x": -1,
      "y": 0,
      "z": -8,
      "name": "BO_Pool_Surface00",
      "rotation": 4
    },
    {
      "x": -1,
      "y": 9,
      "z": -8,
      "name": "BO_Pool_Surface00",
      "rotation": 4
    },
    {
      "x": -1,
      "y": 10,
      "z": -8,
      "name": "BO_Pool_Surface00",
      "rotation": 4
    },
    {
      "x": -1,
      "y": 14,
      "z": -8,
      "name": "BO_Pool_Surface00"
    },
    {
      "x": -1,
      "y": 15,
      "z": -8,
      "name": "Build_Black_Cube"
    },
    {
      "x": -1,
      "y": 16,
      "z": -8,
      "name": "Soil_Dirt_Tilled",
      "components": {
        "Components": {
          "PlacedByInteraction": {
            "WhoPlacedUuid": {
              "$binary": "KMPE5JWxSQGC8WI/IkVLQQ==",
              "$type": "04"
            }
          },
          "TilledSoil": {
            "Version": 1,
            "DecayTime": "0001-01-02T22:44:51Z"
          }
        }
      }
    },
    {
      "x": -1,
      "y": 17,
      "z": -8,
      "name": "*Plant_Crop_Wheat_Block_Eternal_State_Definitions_StageFinal"
    },
    {
      "x": -1,
      "y": 0,
      "z": -7,
      "name": "BO_Pool_Surface00",
      "rotation": 4
    },
    {
      "x": -1,
      "y": 9,
      "z": -7,
      "name": "BO_Pool_Surface00",
      "rotation": 4
    },
    {
      "x": -1,
      "y": 10,
      "z": -7,
      "name": "BO_Pool_Surface00",
      "rotation": 4
    },
    {
      "x": -1,
      "y": 14,
      "z": -7,
      "name": "BO_Pool_Surface00"
    },
    {
      "x": -1,
      "y": 15,
      "z": -7,
      "name": "Build_Black_Cube"
    },
    {
      "x": -1,
      "y": 16,
      "z": -7,
      "name": "Soil_Dirt_Tilled",
      "components": {
        "Components": {
          "PlacedByInteraction": {
            "WhoPlacedUuid": {
              "$binary": "KMPE5JWxSQGC8WI/IkVLQQ==",
              "$type": "04"
            }
          },
          "TilledSoil": {
            "Version": 1,
            "DecayTime": "0001-01-02T22:44:51Z"
          }
        }
      }
    },
    {
      "x": -1,
      "y": 17,
      "z": -7,
      "name": "*Plant_Crop_Wheat_Block_Eternal_State_Definitions_StageFinal"
    },
    {
      "x": -1,
      "y": 0,
      "z": -6,
      "name": "BO_Pool_Surface00",
      "rotation": 4
    },
    {
      "x": -1,
      "y": 10,
      "z": -6,
      "name": "*BO_Lightsource_Cycle_State_Definitions_Day",
      "components": {
        "Components": {
          "BlackoutCycleState": {
            "OnState": "Day",
            "OffState": "Night"
          }
        }
      }
    },
    {
      "x": -1,
      "y": 14,
      "z": -6,
      "name": "BO_Pool_Surface00"
    },
    {
      "x": -1,
      "y": 15,
      "z": -6,
      "name": "Build_Black_Cube"
    },
    {
      "x": -1,
      "y": 16,
      "z": -6,
      "name": "Soil_Dirt_Tilled",
      "components": {
        "Components": {
          "PlacedByInteraction": {
            "WhoPlacedUuid": {
              "$binary": "KMPE5JWxSQGC8WI/IkVLQQ==",
              "$type": "04"
            }
          },
          "TilledSoil": {
            "Version": 1,
            "DecayTime": "0001-01-02T22:44:51Z"
          }
        }
      }
    },
    {
      "x": -1,
      "y": 17,
      "z": -6,
      "name": "*Plant_Crop_Wheat_Block_Eternal_State_Definitions_StageFinal"
    },
    {
      "x": -1,
      "y": 0,
      "z": -5,
      "name": "BO_Pool_Surface00",
      "rotation": 4
    },
    {
      "x": -1,
      "y": 10,
      "z": -5,
      "name": "*BO_Lightsource_Cycle_State_Definitions_Day",
      "components": {
        "Components": {
          "BlackoutCycleState": {
            "OnState": "Day",
            "OffState": "Night"
          }
        }
      }
    },
    {
      "x": -1,
      "y": 14,
      "z": -5,
      "name": "BO_Pool_Surface00"
    },
    {
      "x": -1,
      "y": 15,
      "z": -5,
      "name": "Build_Black_Cube"
    },
    {
      "x": -1,
      "y": 16,
      "z": -5,
      "name": "Soil_Dirt_Tilled",
      "components": {
        "Components": {
          "PlacedByInteraction": {
            "WhoPlacedUuid": {
              "$binary": "KMPE5JWxSQGC8WI/IkVLQQ==",
              "$type": "04"
            }
          },
          "TilledSoil": {
            "Version": 1,
            "DecayTime": "0001-01-02T22:44:51Z"
          }
        }
      }
    },
    {
      "x": -1,
      "y": 17,
      "z": -5,
      "name": "*Plant_Crop_Wheat_Block_Eternal_State_Definitions_StageFinal"
    },
    {
      "x": -1,
      "y": 0,
      "z": -4,
      "name": "BO_Pool_Surface00",
      "rotation": 4
    },
    {
      "x": -1,
      "y": 10,
      "z": -4,
      "name": "*BO_Lightsource_Cycle_State_Definitions_Day",
      "components": {
        "Components": {
          "BlackoutCycleState": {
            "OnState": "Day",
            "OffState": "Night"
          }
        }
      }
    },
    {
      "x": -1,
      "y": 14,
      "z": -4,
      "name": "BO_Pool_Surface00"
    },
    {
      "x": -1,
      "y": 15,
      "z": -4,
      "name": "Build_Black_Cube"
    },
    {
      "x": -1,
      "y": 16,
      "z": -4,
      "name": "Soil_Dirt_Tilled",
      "components": {
        "Components": {
          "PlacedByInteraction": {
            "WhoPlacedUuid": {
              "$binary": "KMPE5JWxSQGC8WI/IkVLQQ==",
              "$type": "04"
            }
          },
          "TilledSoil": {
            "Version": 1,
            "DecayTime": "0001-01-02T22:44:51Z"
          }
        }
      }
    },
    {
      "x": -1,
      "y": 17,
      "z": -4,
      "name": "*Plant_Crop_Wheat_Block_Eternal_State_Definitions_StageFinal"
    },
    {
      "x": -1,
      "y": 0,
      "z": -3,
      "name": "BO_Pool_Surface00",
      "rotation": 4
    },
    {
      "x": -1,
      "y": 10,
      "z": -3,
      "name": "*BO_Lightsource_Cycle_State_Definitions_Day",
      "components": {
        "Components": {
          "BlackoutCycleState": {
            "OnState": "Day",
            "OffState": "Night"
          }
        }
      }
    },
    {
      "x": -1,
      "y": 14,
      "z": -3,
      "name": "BO_Pool_Surface00"
    },
    {
      "x": -1,
      "y": 15,
      "z": -3,
      "name": "Build_Black_Cube"
    },
    {
      "x": -1,
      "y": 16,
      "z": -3,
      "name": "Soil_Dirt_Tilled",
      "components": {
        "Components": {
          "PlacedByInteraction": {
            "WhoPlacedUuid": {
              "$binary": "KMPE5JWxSQGC8WI/IkVLQQ==",
              "$type": "04"
            }
          },
          "TilledSoil": {
            "Version": 1,
            "DecayTime": "0001-01-02T22:44:51Z"
          }
        }
      }
    },
    {
      "x": -1,
      "y": 17,
      "z": -3,
      "name": "*Plant_Crop_Wheat_Block_Eternal_State_Definitions_StageFinal"
    },
    {
      "x": -1,
      "y": 0,
      "z": -2,
      "name": "BO_Pool_Surface00",
      "rotation": 4
    },
    {
      "x": -1,
      "y": 10,
      "z": -2,
      "name": "*BO_Lightsource_Cycle_State_Definitions_Day",
      "components": {
        "Components": {
          "BlackoutCycleState": {
            "OnState": "Day",
            "OffState": "Night"
          }
        }
      }
    },
    {
      "x": -1,
      "y": 14,
      "z": -2,
      "name": "BO_Pool_Surface00"
    },
    {
      "x": -1,
      "y": 15,
      "z": -2,
      "name": "Build_Black_Cube"
    },
    {
      "x": -1,
      "y": 16,
      "z": -2,
      "name": "Soil_Dirt_Tilled",
      "components": {
        "Components": {
          "PlacedByInteraction": {
            "WhoPlacedUuid": {
              "$binary": "KMPE5JWxSQGC8WI/IkVLQQ==",
              "$type": "04"
            }
          },
          "TilledSoil": {
            "Version": 1,
            "DecayTime": "0001-01-02T22:44:51Z"
          }
        }
      }
    },
    {
      "x": -1,
      "y": 17,
      "z": -2,
      "name": "*Plant_Crop_Wheat_Block_Eternal_State_Definitions_StageFinal"
    },
    {
      "x": -1,
      "y": 0,
      "z": -1,
      "name": "BO_Pool_Surface00",
      "rotation": 4
    },
    {
      "x": -1,
      "y": 10,
      "z": -1,
      "name": "*BO_Lightsource_Cycle_State_Definitions_Day",
      "components": {
        "Components": {
          "BlackoutCycleState": {
            "OnState": "Day",
            "OffState": "Night"
          }
        }
      }
    },
    {
      "x": -1,
      "y": 14,
      "z": -1,
      "name": "BO_Pool_Surface00"
    },
    {
      "x": -1,
      "y": 15,
      "z": -1,
      "name": "Build_Black_Cube"
    },
    {
      "x": -1,
      "y": 16,
      "z": -1,
      "name": "Soil_Dirt_Tilled",
      "components": {
        "Components": {
          "PlacedByInteraction": {
            "WhoPlacedUuid": {
              "$binary": "KMPE5JWxSQGC8WI/IkVLQQ==",
              "$type": "04"
            }
          },
          "TilledSoil": {
            "Version": 1,
            "DecayTime": "0001-01-02T22:44:51Z"
          }
        }
      }
    },
    {
      "x": -1,
      "y": 17,
      "z": -1,
      "name": "*Plant_Crop_Wheat_Block_Eternal_State_Definitions_StageFinal"
    },
    {
      "x": -1,
      "y": 0,
      "z": 0,
      "name": "BO_Pool_Surface00",
      "rotation": 4
    },
    {
      "x": -1,
      "y": 10,
      "z": 0,
      "name": "*BO_Lightsource_Cycle_State_Definitions_Day",
      "components": {
        "Components": {
          "BlackoutCycleState": {
            "OnState": "Day",
            "OffState": "Night"
          }
        }
      }
    },
    {
      "x": -1,
      "y": 14,
      "z": 0,
      "name": "BO_Pool_Surface00"
    },
    {
      "x": -1,
      "y": 15,
      "z": 0,
      "name": "Build_Black_Cube"
    },
    {
      "x": -1,
      "y": 16,
      "z": 0,
      "name": "Soil_Dirt_Tilled",
      "components": {
        "Components": {
          "PlacedByInteraction": {
            "WhoPlacedUuid": {
              "$binary": "KMPE5JWxSQGC8WI/IkVLQQ==",
              "$type": "04"
            }
          },
          "TilledSoil": {
            "Version": 1,
            "DecayTime": "0001-01-02T22:44:51Z"
          }
        }
      }
    },
    {
      "x": -1,
      "y": 17,
      "z": 0,
      "name": "*Plant_Crop_Wheat_Block_Eternal_State_Definitions_StageFinal"
    },
    {
      "x": -1,
      "y": 0,
      "z": 1,
      "name": "BO_Pool_Surface00",
      "rotation": 4
    },
    {
      "x": -1,
      "y": 10,
      "z": 1,
      "name": "*BO_Lightsource_Cycle_State_Definitions_Day",
      "components": {
        "Components": {
          "BlackoutCycleState": {
            "OnState": "Day",
            "OffState": "Night"
          }
        }
      }
    },
    {
      "x": -1,
      "y": 14,
      "z": 1,
      "name": "BO_Pool_Surface00"
    },
    {
      "x": -1,
      "y": 15,
      "z": 1,
      "name": "Build_Black_Cube"
    },
    {
      "x": -1,
      "y": 16,
      "z": 1,
      "name": "Soil_Dirt_Tilled",
      "components": {
        "Components": {
          "PlacedByInteraction": {
            "WhoPlacedUuid": {
              "$binary": "KMPE5JWxSQGC8WI/IkVLQQ==",
              "$type": "04"
            }
          },
          "TilledSoil": {
            "Version": 1,
            "DecayTime": "0001-01-02T22:44:51Z"
          }
        }
      }
    },
    {
      "x": -1,
      "y": 17,
      "z": 1,
      "name": "*Plant_Crop_Wheat_Block_Eternal_State_Definitions_StageFinal"
    },
    {
      "x": -1,
      "y": 0,
      "z": 2,
      "name": "BO_Pool_Surface00",
      "rotation": 4
    },
    {
      "x": -1,
      "y": 10,
      "z": 2,
      "name": "*BO_Lightsource_Cycle_State_Definitions_Day",
      "components": {
        "Components": {
          "BlackoutCycleState": {
            "OnState": "Day",
            "OffState": "Night"
          }
        }
      }
    },
    {
      "x": -1,
      "y": 14,
      "z": 2,
      "name": "BO_Pool_Surface00"
    },
    {
      "x": -1,
      "y": 15,
      "z": 2,
      "name": "Build_Black_Cube"
    },
    {
      "x": -1,
      "y": 16,
      "z": 2,
      "name": "Soil_Dirt_Tilled",
      "components": {
        "Components": {
          "PlacedByInteraction": {
            "WhoPlacedUuid": {
              "$binary": "KMPE5JWxSQGC8WI/IkVLQQ==",
              "$type": "04"
            }
          },
          "TilledSoil": {
            "Version": 1,
            "DecayTime": "0001-01-02T22:44:51Z"
          }
        }
      }
    },
    {
      "x": -1,
      "y": 17,
      "z": 2,
      "name": "*Plant_Crop_Wheat_Block_Eternal_State_Definitions_StageFinal"
    },
    {
      "x": -1,
      "y": 0,
      "z": 3,
      "name": "BO_Pool_Surface00",
      "rotation": 4
    },
    {
      "x": -1,
      "y": 10,
      "z": 3,
      "name": "*BO_Lightsource_Cycle_State_Definitions_Day",
      "components": {
        "Components": {
          "BlackoutCycleState": {
            "OnState": "Day",
            "OffState": "Night"
          }
        }
      }
    },
    {
      "x": -1,
      "y": 14,
      "z": 3,
      "name": "BO_Pool_Surface00"
    },
    {
      "x": -1,
      "y": 15,
      "z": 3,
      "name": "Build_Black_Cube"
    },
    {
      "x": -1,
      "y": 16,
      "z": 3,
      "name": "Soil_Dirt_Tilled",
      "components": {
        "Components": {
          "PlacedByInteraction": {
            "WhoPlacedUuid": {
              "$binary": "KMPE5JWxSQGC8WI/IkVLQQ==",
              "$type": "04"
            }
          },
          "TilledSoil": {
            "Version": 1,
            "DecayTime": "0001-01-02T22:44:51Z"
          }
        }
      }
    },
    {
      "x": -1,
      "y": 17,
      "z": 3,
      "name": "*Plant_Crop_Wheat_Block_Eternal_State_Definitions_StageFinal"
    },
    {
      "x": -1,
      "y": 0,
      "z": 4,
      "name": "BO_Pool_Surface00",
      "rotation": 4
    },
    {
      "x": -1,
      "y": 10,
      "z": 4,
      "name": "*BO_Lightsource_Cycle_State_Definitions_Day",
      "components": {
        "Components": {
          "BlackoutCycleState": {
            "OnState": "Day",
            "OffState": "Night"
          }
        }
      }
    },
    {
      "x": -1,
      "y": 14,
      "z": 4,
      "name": "BO_Pool_Surface00"
    },
    {
      "x": -1,
      "y": 15,
      "z": 4,
      "name": "Build_Black_Cube"
    },
    {
      "x": -1,
      "y": 16,
      "z": 4,
      "name": "Soil_Dirt_Tilled",
      "components": {
        "Components": {
          "PlacedByInteraction": {
            "WhoPlacedUuid": {
              "$binary": "KMPE5JWxSQGC8WI/IkVLQQ==",
              "$type": "04"
            }
          },
          "TilledSoil": {
            "Version": 1,
            "DecayTime": "0001-01-02T22:44:51Z"
          }
        }
      }
    },
    {
      "x": -1,
      "y": 17,
      "z": 4,
      "name": "*Plant_Crop_Wheat_Block_Eternal_State_Definitions_StageFinal"
    },
    {
      "x": -1,
      "y": 0,
      "z": 5,
      "name": "BO_Pool_Surface00",
      "rotation": 4
    },
    {
      "x": -1,
      "y": 10,
      "z": 5,
      "name": "*BO_Lightsource_Cycle_State_Definitions_Day",
      "components": {
        "Components": {
          "BlackoutCycleState": {
            "OnState": "Day",
            "OffState": "Night"
          }
        }
      }
    },
    {
      "x": -1,
      "y": 14,
      "z": 5,
      "name": "BO_Pool_Surface00"
    },
    {
      "x": -1,
      "y": 15,
      "z": 5,
      "name": "Build_Black_Cube"
    },
    {
      "x": -1,
      "y": 16,
      "z": 5,
      "name": "Soil_Dirt_Tilled",
      "components": {
        "Components": {
          "PlacedByInteraction": {
            "WhoPlacedUuid": {
              "$binary": "KMPE5JWxSQGC8WI/IkVLQQ==",
              "$type": "04"
            }
          },
          "TilledSoil": {
            "Version": 1,
            "DecayTime": "0001-01-02T22:44:51Z"
          }
        }
      }
    },
    {
      "x": -1,
      "y": 17,
      "z": 5,
      "name": "*Plant_Crop_Wheat_Block_Eternal_State_Definitions_StageFinal"
    },
    {
      "x": -1,
      "y": 0,
      "z": 6,
      "name": "BO_Pool_Surface00",
      "rotation": 4
    },
    {
      "x": -1,
      "y": 10,
      "z": 6,
      "name": "*BO_Lightsource_Cycle_State_Definitions_Day",
      "components": {
        "Components": {
          "BlackoutCycleState": {
            "OnState": "Day",
            "OffState": "Night"
          }
        }
      }
    },
    {
      "x": -1,
      "y": 14,
      "z": 6,
      "name": "BO_Pool_Surface00"
    },
    {
      "x": -1,
      "y": 15,
      "z": 6,
      "name": "Build_Black_Cube"
    },
    {
      "x": -1,
      "y": 16,
      "z": 6,
      "name": "Soil_Dirt_Tilled",
      "components": {
        "Components": {
          "PlacedByInteraction": {
            "WhoPlacedUuid": {
              "$binary": "KMPE5JWxSQGC8WI/IkVLQQ==",
              "$type": "04"
            }
          },
          "TilledSoil": {
            "Version": 1,
            "DecayTime": "0001-01-02T22:44:51Z"
          }
        }
      }
    },
    {
      "x": -1,
      "y": 17,
      "z": 6,
      "name": "*Plant_Crop_Wheat_Block_Eternal_State_Definitions_StageFinal"
    },
    {
      "x": -1,
      "y": 0,
      "z": 7,
      "name": "BO_Pool_Surface00",
      "rotation": 4
    },
    {
      "x": -1,
      "y": 10,
      "z": 7,
      "name": "*BO_Lightsource_Cycle_State_Definitions_Day",
      "components": {
        "Components": {
          "BlackoutCycleState": {
            "OnState": "Day",
            "OffState": "Night"
          }
        }
      }
    },
    {
      "x": -1,
      "y": 14,
      "z": 7,
      "name": "BO_Pool_Surface00"
    },
    {
      "x": -1,
      "y": 15,
      "z": 7,
      "name": "Build_Black_Cube"
    },
    {
      "x": -1,
      "y": 16,
      "z": 7,
      "name": "Soil_Dirt_Tilled",
      "components": {
        "Components": {
          "PlacedByInteraction": {
            "WhoPlacedUuid": {
              "$binary": "KMPE5JWxSQGC8WI/IkVLQQ==",
              "$type": "04"
            }
          },
          "TilledSoil": {
            "Version": 1,
            "DecayTime": "0001-01-02T22:44:51Z"
          }
        }
      }
    },
    {
      "x": -1,
      "y": 17,
      "z": 7,
      "name": "*Plant_Crop_Wheat_Block_Eternal_State_Definitions_StageFinal"
    },
    {
      "x": -1,
      "y": 0,
      "z": 8,
      "name": "BO_Pool_Surface00",
      "rotation": 4
    },
    {
      "x": -1,
      "y": 9,
      "z": 8,
      "name": "BO_Pool_Surface00",
      "rotation": 4
    },
    {
      "x": -1,
      "y": 10,
      "z": 8,
      "name": "BO_Pool_Surface00",
      "rotation": 4
    },
    {
      "x": -1,
      "y": 14,
      "z": 8,
      "name": "BO_Pool_Surface00"
    },
    {
      "x": -1,
      "y": 15,
      "z": 8,
      "name": "Build_Black_Cube"
    },
    {
      "x": -1,
      "y": 16,
      "z": 8,
      "name": "Soil_Dirt_Tilled",
      "components": {
        "Components": {
          "PlacedByInteraction": {
            "WhoPlacedUuid": {
              "$binary": "KMPE5JWxSQGC8WI/IkVLQQ==",
              "$type": "04"
            }
          },
          "TilledSoil": {
            "Version": 1,
            "DecayTime": "0001-01-02T22:44:51Z"
          }
        }
      }
    },
    {
      "x": -1,
      "y": 17,
      "z": 8,
      "name": "*Plant_Crop_Wheat_Block_Eternal_State_Definitions_StageFinal"
    },
    {
      "x": -1,
      "y": 0,
      "z": 9,
      "name": "BO_Pool_Surface00",
      "rotation": 4
    },
    {
      "x": -1,
      "y": 9,
      "z": 9,
      "name": "BO_Pool_Surface00",
      "rotation": 4
    },
    {
      "x": -1,
      "y": 10,
      "z": 9,
      "name": "BO_Pool_Surface00",
      "rotation": 4
    },
    {
      "x": -1,
      "y": 14,
      "z": 9,
      "name": "BO_Pool_Surface00"
    },
    {
      "x": -1,
      "y": 15,
      "z": 9,
      "name": "Build_Black_Cube"
    },
    {
      "x": -1,
      "y": 16,
      "z": 9,
      "name": "Soil_Dirt_Tilled",
      "components": {
        "Components": {
          "PlacedByInteraction": {
            "WhoPlacedUuid": {
              "$binary": "KMPE5JWxSQGC8WI/IkVLQQ==",
              "$type": "04"
            }
          },
          "TilledSoil": {
            "Version": 1,
            "DecayTime": "0001-01-02T22:44:51Z"
          }
        }
      }
    },
    {
      "x": -1,
      "y": 17,
      "z": 9,
      "name": "*Plant_Crop_Wheat_Block_Eternal_State_Definitions_StageFinal"
    },
    {
      "x": -1,
      "y": 0,
      "z": 10,
      "name": "BO_Pool_Surface00",
      "rotation": 4
    },
    {
      "x": -1,
      "y": 9,
      "z": 10,
      "name": "BO_Pool_Surface00",
      "rotation": 4
    },
    {
      "x": -1,
      "y": 10,
      "z": 10,
      "name": "BO_Pool_Surface00",
      "rotation": 4
    },
    {
      "x": -1,
      "y": 14,
      "z": 10,
      "name": "BO_Pool_Surface00"
    },
    {
      "x": -1,
      "y": 15,
      "z": 10,
      "name": "Build_Black_Cube"
    },
    {
      "x": -1,
      "y": 16,
      "z": 10,
      "name": "Soil_Dirt_Tilled",
      "components": {
        "Components": {
          "PlacedByInteraction": {
            "WhoPlacedUuid": {
              "$binary": "KMPE5JWxSQGC8WI/IkVLQQ==",
              "$type": "04"
            }
          },
          "TilledSoil": {
            "Version": 1,
            "DecayTime": "0001-01-02T22:44:51Z"
          }
        }
      }
    },
    {
      "x": -1,
      "y": 17,
      "z": 10,
      "name": "*Plant_Crop_Wheat_Block_Eternal_State_Definitions_StageFinal"
    },
    {
      "x": 0,
      "y": 0,
      "z": -9,
      "name": "BO_Pool_Surface00",
      "rotation": 4
    },
    {
      "x": 0,
      "y": 9,
      "z": -9,
      "name": "BO_Pool_Surface00",
      "rotation": 4
    },
    {
      "x": 0,
      "y": 10,
      "z": -9,
      "name": "BO_Pool_Surface00",
      "rotation": 4
    },
    {
      "x": 0,
      "y": 14,
      "z": -9,
      "name": "BO_Pool_Surface00"
    },
    {
      "x": 0,
      "y": 15,
      "z": -9,
      "name": "Build_Black_Cube"
    },
    {
      "x": 0,
      "y": 16,
      "z": -9,
      "name": "Soil_Dirt_Tilled",
      "components": {
        "Components": {
          "PlacedByInteraction": {
            "WhoPlacedUuid": {
              "$binary": "KMPE5JWxSQGC8WI/IkVLQQ==",
              "$type": "04"
            }
          },
          "TilledSoil": {
            "Version": 1,
            "DecayTime": "0001-01-02T22:44:51Z"
          }
        }
      }
    },
    {
      "x": 0,
      "y": 17,
      "z": -9,
      "name": "*Plant_Crop_Wheat_Block_Eternal_State_Definitions_StageFinal"
    },
    {
      "x": 0,
      "y": 0,
      "z": -8,
      "name": "BO_Pool_Surface00",
      "rotation": 4
    },
    {
      "x": 0,
      "y": 9,
      "z": -8,
      "name": "BO_Pool_Surface00",
      "rotation": 4
    },
    {
      "x": 0,
      "y": 10,
      "z": -8,
      "name": "BO_Pool_Surface00",
      "rotation": 4
    },
    {
      "x": 0,
      "y": 14,
      "z": -8,
      "name": "BO_Pool_Surface00"
    },
    {
      "x": 0,
      "y": 15,
      "z": -8,
      "name": "Build_Black_Cube"
    },
    {
      "x": 0,
      "y": 16,
      "z": -8,
      "name": "Soil_Dirt_Tilled",
      "components": {
        "Components": {
          "PlacedByInteraction": {
            "WhoPlacedUuid": {
              "$binary": "KMPE5JWxSQGC8WI/IkVLQQ==",
              "$type": "04"
            }
          },
          "TilledSoil": {
            "Version": 1,
            "DecayTime": "0001-01-02T22:44:51Z"
          }
        }
      }
    },
    {
      "x": 0,
      "y": 17,
      "z": -8,
      "name": "*Plant_Crop_Wheat_Block_Eternal_State_Definitions_StageFinal"
    },
    {
      "x": 0,
      "y": 0,
      "z": -7,
      "name": "BO_Pool_Surface00",
      "rotation": 4
    },
    {
      "x": 0,
      "y": 9,
      "z": -7,
      "name": "BO_Pool_Surface00",
      "rotation": 4
    },
    {
