{
  "version": 8,
  "blockIdVersion": 11,
  "anchorX": 0,
  "anchorY": 0,
  "anchorZ": 0,
  "blocks": [
    {
      "x": -4,
      "y": 0,
      "z": -4,
      "name": "BO_Pool_Surface00",
      "rotation": 4
    },
    {
      "x": -4,
      "y": 1,
      "z": -4,
      "name": "BO_Pool_Surface00",
      "rotation": 4
    },
    {
      "x": -4,
      "y": 2,
      "z": -4,
      "name": "BO_Pool_Surface00",
      "rotation": 4
    },
    {
      "x": -4,
      "y": 3,
      "z": -4,
      "name": "BO_Pool_Surface00",
      "rotation": 4
    },
    {
      "x": -4,
      "y": 4,
      "z": -4,
      "name": "BO_Pool_Surface00",
      "rotation": 4
    },
    {
      "x": -4,
      "y": 5,
      "z": -4,
      "name": "BO_Pool_Surface00",
      "rotation": 4
    },
    {
      "x": -4,
      "y": 6,
      "z": -4,
      "name": "BO_Pool_Surface00",
      "rotation": 4
    },
    {
      "x": -4,
      "y": 7,
      "z": -4,
      "name": "BO_Pool_Surface00",
      "rotation": 4
    },
    {
      "x": -4,
      "y": 8,
      "z": -4,
      "name": "BO_Pool_Surface00",
      "rotation": 4
    },
    {
      "x": -4,
      "y": 9,
      "z": -4,
      "name": "BO_Pool_Surface00",
      "rotation": 4
    },
    {
      "x": -4,
      "y": 10,
      "z": -4,
      "name": "*BO_Lightsource_Cycle_State_Definitions_Day",
      "components": {
        "Components": {
          "BlackoutCycleState": {
            "OnState": "Day",
            "OffState": "Night"
          }
        }
      },
      "rotation": 2
    },
    {
      "x": -4,
      "y": 14,
      "z": -4,
      "name": "BO_Pool_Surface00",
      "rotation": 2
    },
    {
      "x": -4,
      "y": 15,
      "z": -4,
      "name": "Build_Black_Cube"
    },
    {
      "x": -4,
      "y": 16,
      "z": -4,
      "name": "Soil_Dirt_Tilled",
      "components": {
        "Components": {
          "PlacedByInteraction": {
            "WhoPlacedUuid": {
              "$binary": "KMPE5JWxSQGC8WI/IkVLQQ==",
              "$type": "04"
            }
          },
          "TilledSoil": {
            "Version": 1,
            "DecayTime": "0001-01-02T22:44:51Z"
          }
        }
      }
    },
    {
      "x": -4,
      "y": 17,
      "z": -4,
      "name": "*Plant_Crop_Wheat_Block_Eternal_State_Definitions_StageFinal"
    },
    {
      "x": -4,
      "y": 0,
      "z": -3,
      "name": "BO_Pool_Surface00",
      "rotation": 4
    },
    {
      "x": -4,
      "y": 1,
      "z": -3,
      "name": "BO_Pool_Surface00",
      "rotation": 4
    },
    {
      "x": -4,
      "y": 2,
      "z": -3,
      "name": "BO_Pool_Surface00",
      "rotation": 4
    },
    {
      "x": -4,
      "y": 3,
      "z": -3,
      "name": "BO_Pool_Surface00",
      "rotation": 4
    },
    {
      "x": -4,
      "y": 4,
      "z": -3,
      "name": "BO_Pool_Surface00",
      "rotation": 4
    },
    {
      "x": -4,
      "y": 5,
      "z": -3,
      "name": "BO_Pool_Surface00",
      "rotation": 4
    },
    {
      "x": -4,
      "y": 6,
      "z": -3,
      "name": "BO_Pool_Surface00",
      "rotation": 4
    },
    {
      "x": -4,
      "y": 7,
      "z": -3,
      "name": "BO_Pool_Surface00",
      "rotation": 4
    },
    {
      "x": -4,
      "y": 8,
      "z": -3,
      "name": "BO_Pool_Surface00",
      "rotation": 4
    },
    {
      "x": -4,
      "y": 9,
      "z": -3,
      "name": "BO_Pool_Surface00",
      "rotation": 4
    },
    {
      "x": -4,
      "y": 10,
      "z": -3,
      "name": "*BO_Lightsource_Cycle_State_Definitions_Day",
      "components": {
        "Components": {
          "BlackoutCycleState": {
            "OnState": "Day",
            "OffState": "Night"
          }
        }
      },
      "rotation": 2
    },
    {
      "x": -4,
      "y": 14,
      "z": -3,
      "name": "BO_Pool_Surface00",
      "rotation": 2
    },
    {
      "x": -4,
      "y": 15,
      "z": -3,
      "name": "Build_Black_Cube"
    },
    {
      "x": -4,
      "y": 16,
      "z": -3,
      "name": "Soil_Dirt_Tilled",
      "components": {
        "Components": {
          "PlacedByInteraction": {
            "WhoPlacedUuid": {
              "$binary": "KMPE5JWxSQGC8WI/IkVLQQ==",
              "$type": "04"
            }
          },
          "TilledSoil": {
            "Version": 1,
            "DecayTime": "0001-01-02T22:44:51Z"
          }
        }
      }
    },
    {
      "x": -4,
      "y": 17,
      "z": -3,
      "name": "*Plant_Crop_Wheat_Block_Eternal_State_Definitions_StageFinal"
    },
    {
      "x": -4,
      "y": 0,
      "z": -2,
      "name": "BO_Pool_Surface00",
      "rotation": 4
    },
    {
      "x": -4,
      "y": 1,
      "z": -2,
      "name": "BO_Pool_Surface00",
      "rotation": 4
    },
    {
      "x": -4,
      "y": 2,
      "z": -2,
      "name": "BO_Pool_Surface00",
      "rotation": 4
    },
    {
      "x": -4,
      "y": 3,
      "z": -2,
      "name": "BO_Pool_Surface00",
      "rotation": 4
    },
    {
      "x": -4,
      "y": 4,
      "z": -2,
      "name": "BO_Pool_Surface00",
      "rotation": 4
    },
    {
      "x": -4,
      "y": 5,
      "z": -2,
      "name": "BO_Pool_Surface00",
      "rotation": 4
    },
    {
      "x": -4,
      "y": 6,
      "z": -2,
      "name": "BO_Pool_Surface00",
      "rotation": 4
    },
    {
      "x": -4,
      "y": 7,
      "z": -2,
      "name": "BO_Pool_Surface00",
      "rotation": 4
    },
    {
      "x": -4,
      "y": 8,
      "z": -2,
      "name": "BO_Pool_Surface00",
      "rotation": 4
    },
    {
      "x": -4,
      "y": 9,
      "z": -2,
      "name": "BO_Pool_Surface00",
      "rotation": 4
    },
    {
      "x": -4,
      "y": 10,
      "z": -2,
      "name": "*BO_Lightsource_Cycle_State_Definitions_Day",
      "components": {
        "Components": {
          "BlackoutCycleState": {
            "OnState": "Day",
            "OffState": "Night"
          }
        }
      },
      "rotation": 2
    },
    {
      "x": -4,
      "y": 14,
      "z": -2,
      "name": "BO_Pool_Surface00",
      "rotation": 2
    },
    {
      "x": -4,
      "y": 15,
      "z": -2,
      "name": "Build_Black_Cube"
    },
    {
      "x": -4,
      "y": 16,
      "z": -2,
      "name": "Soil_Dirt_Tilled",
      "components": {
        "Components": {
          "PlacedByInteraction": {
            "WhoPlacedUuid": {
              "$binary": "KMPE5JWxSQGC8WI/IkVLQQ==",
              "$type": "04"
            }
          },
          "TilledSoil": {
            "Version": 1,
            "DecayTime": "0001-01-02T22:44:51Z"
          }
        }
      }
    },
    {
      "x": -4,
      "y": 17,
      "z": -2,
      "name": "*Plant_Crop_Wheat_Block_Eternal_State_Definitions_StageFinal"
    },
    {
      "x": -4,
      "y": 0,
      "z": -1,
      "name": "BO_Pool_Surface00",
      "rotation": 4
    },
    {
      "x": -4,
      "y": 1,
      "z": -1,
      "name": "BO_Pool_Surface00",
      "rotation": 4
    },
    {
      "x": -4,
      "y": 4,
      "z": -1,
      "name": "BO_Pool_Surface00",
      "rotation": 4
    },
    {
      "x": -4,
      "y": 5,
      "z": -1,
      "name": "BO_Pool_Surface00",
      "rotation": 4
    },
    {
      "x": -4,
      "y": 6,
      "z": -1,
      "name": "BO_Pool_Surface00",
      "rotation": 4
    },
    {
      "x": -4,
      "y": 7,
      "z": -1,
      "name": "BO_Pool_Surface00",
      "rotation": 4
    },
    {
      "x": -4,
      "y": 8,
      "z": -1,
      "name": "BO_Pool_Surface00",
      "rotation": 4
    },
    {
      "x": -4,
      "y": 9,
      "z": -1,
      "name": "BO_Pool_Surface00",
      "rotation": 4
    },
    {
      "x": -4,
      "y": 10,
      "z": -1,
      "name": "*BO_Lightsource_Cycle_State_Definitions_Day",
      "components": {
        "Components": {
          "BlackoutCycleState": {
            "OnState": "Day",
            "OffState": "Night"
          }
        }
      },
      "rotation": 2
    },
    {
      "x": -4,
      "y": 14,
      "z": -1,
      "name": "BO_Pool_Surface00",
      "rotation": 2
    },
    {
      "x": -4,
      "y": 15,
      "z": -1,
      "name": "Build_Black_Cube"
    },
    {
      "x": -4,
      "y": 16,
      "z": -1,
      "name": "Soil_Dirt_Tilled",
      "components": {
        "Components": {
          "PlacedByInteraction": {
            "WhoPlacedUuid": {
              "$binary": "KMPE5JWxSQGC8WI/IkVLQQ==",
              "$type": "04"
            }
          },
          "TilledSoil": {
            "Version": 1,
            "DecayTime": "0001-01-02T22:44:51Z"
          }
        }
      }
    },
    {
      "x": -4,
      "y": 17,
      "z": -1,
      "name": "*Plant_Crop_Wheat_Block_Eternal_State_Definitions_StageFinal"
    },
    {
      "x": -4,
      "y": 0,
      "z": 0,
      "name": "BO_Pool_Surface00",
      "rotation": 4
    },
    {
      "x": -4,
      "y": 1,
      "z": 0,
      "name": "BO_Pool_Surface00",
      "rotation": 4
    },
    {
      "x": -4,
      "y": 4,
      "z": 0,
      "name": "BO_Pool_Surface00",
      "rotation": 4
    },
    {
      "x": -4,
      "y": 5,
      "z": 0,
      "name": "BO_Pool_Surface00",
      "rotation": 4
    },
    {
      "x": -4,
      "y": 6,
      "z": 0,
      "name": "BO_Pool_Surface00",
      "rotation": 4
    },
    {
      "x": -4,
      "y": 7,
      "z": 0,
      "name": "BO_Pool_Surface00",
      "rotation": 4
    },
    {
      "x": -4,
      "y": 8,
      "z": 0,
      "name": "BO_Pool_Surface00",
      "rotation": 4
    },
    {
      "x": -4,
      "y": 9,
      "z": 0,
      "name": "BO_Pool_Surface00",
      "rotation": 4
    },
    {
      "x": -4,
      "y": 10,
      "z": 0,
      "name": "*BO_Lightsource_Cycle_State_Definitions_Day",
      "components": {
        "Components": {
          "BlackoutCycleState": {
            "OnState": "Day",
            "OffState": "Night"
          }
        }
      },
      "rotation": 2
    },
    {
      "x": -4,
      "y": 14,
      "z": 0,
      "name": "BO_Pool_Surface00",
      "rotation": 2
    },
    {
      "x": -4,
      "y": 15,
      "z": 0,
      "name": "Build_Black_Cube"
    },
    {
      "x": -4,
      "y": 16,
      "z": 0,
      "name": "Soil_Dirt_Tilled",
      "components": {
        "Components": {
          "PlacedByInteraction": {
            "WhoPlacedUuid": {
              "$binary": "KMPE5JWxSQGC8WI/IkVLQQ==",
              "$type": "04"
            }
          },
          "TilledSoil": {
            "Version": 1,
            "DecayTime": "0001-01-02T22:44:51Z"
          }
        }
      }
    },
    {
      "x": -4,
      "y": 17,
      "z": 0,
      "name": "*Plant_Crop_Wheat_Block_Eternal_State_Definitions_StageFinal"
    },
    {
      "x": -4,
      "y": 0,
      "z": 1,
      "name": "BO_Pool_Surface00",
      "rotation": 4
    },
    {
      "x": -4,
      "y": 1,
      "z": 1,
      "name": "BO_Pool_Surface00",
      "rotation": 4
    },
    {
      "x": -4,
      "y": 4,
      "z": 1,
      "name": "BO_Pool_Surface00",
      "rotation": 4
    },
    {
      "x": -4,
      "y": 5,
      "z": 1,
      "name": "BO_Pool_Surface00",
      "rotation": 4
    },
    {
      "x": -4,
      "y": 6,
      "z": 1,
      "name": "BO_Pool_Surface00",
      "rotation": 4
    },
    {
      "x": -4,
      "y": 7,
      "z": 1,
      "name": "BO_Pool_Surface00",
      "rotation": 4
    },
    {
      "x": -4,
      "y": 8,
      "z": 1,
      "name": "BO_Pool_Surface00",
      "rotation": 4
    },
    {
      "x": -4,
      "y": 9,
      "z": 1,
      "name": "BO_Pool_Surface00",
      "rotation": 4
    },
    {
      "x": -4,
      "y": 10,
      "z": 1,
      "name": "*BO_Lightsource_Cycle_State_Definitions_Day",
      "components": {
        "Components": {
          "BlackoutCycleState": {
            "OnState": "Day",
            "OffState": "Night"
          }
        }
      },
      "rotation": 2
    },
    {
      "x": -4,
      "y": 14,
      "z": 1,
      "name": "BO_Pool_Surface00",
      "rotation": 2
    },
    {
      "x": -4,
      "y": 15,
      "z": 1,
      "name": "Build_Black_Cube"
    },
    {
      "x": -4,
      "y": 16,
      "z": 1,
      "name": "Soil_Dirt_Tilled",
      "components": {
        "Components": {
          "PlacedByInteraction": {
            "WhoPlacedUuid": {
              "$binary": "KMPE5JWxSQGC8WI/IkVLQQ==",
              "$type": "04"
            }
          },
          "TilledSoil": {
            "Version": 1,
            "DecayTime": "0001-01-02T22:44:51Z"
          }
        }
      }
    },
    {
      "x": -4,
      "y": 17,
      "z": 1,
      "name": "*Plant_Crop_Wheat_Block_Eternal_State_Definitions_StageFinal"
    },
    {
      "x": -4,
      "y": 0,
      "z": 2,
      "name": "BO_Pool_Surface00",
      "rotation": 4
    },
    {
      "x": -4,
      "y": 1,
      "z": 2,
      "name": "BO_Pool_Surface00",
      "rotation": 4
    },
    {
      "x": -4,
      "y": 4,
      "z": 2,
      "name": "BO_Pool_Surface00",
      "rotation": 4
    },
    {
      "x": -4,
      "y": 5,
      "z": 2,
      "name": "BO_Pool_Surface00",
      "rotation": 4
    },
    {
      "x": -4,
      "y": 6,
      "z": 2,
      "name": "BO_Pool_Surface00",
      "rotation": 4
    },
    {
      "x": -4,
      "y": 7,
      "z": 2,
      "name": "BO_Pool_Surface00",
      "rotation": 4
    },
    {
      "x": -4,
      "y": 8,
      "z": 2,
      "name": "BO_Pool_Surface00",
      "rotation": 4
    },
    {
      "x": -4,
      "y": 9,
      "z": 2,
      "name": "BO_Pool_Surface00",
      "rotation": 4
    },
    {
      "x": -4,
      "y": 10,
      "z": 2,
      "name": "*BO_Lightsource_Cycle_State_Definitions_Day",
      "components": {
        "Components": {
          "BlackoutCycleState": {
            "OnState": "Day",
            "OffState": "Night"
          }
        }
      },
      "rotation": 2
    },
    {
      "x": -4,
      "y": 14,
      "z": 2,
      "name": "BO_Pool_Surface00",
      "rotation": 2
    },
    {
      "x": -4,
      "y": 15,
      "z": 2,
      "name": "Build_Black_Cube"
    },
    {
      "x": -4,
      "y": 16,
      "z": 2,
      "name": "Soil_Dirt_Tilled",
      "components": {
        "Components": {
          "PlacedByInteraction": {
            "WhoPlacedUuid": {
              "$binary": "KMPE5JWxSQGC8WI/IkVLQQ==",
              "$type": "04"
            }
          },
          "TilledSoil": {
            "Version": 1,
            "DecayTime": "0001-01-02T22:44:51Z"
          }
        }
      }
    },
    {
      "x": -4,
      "y": 17,
      "z": 2,
      "name": "*Plant_Crop_Wheat_Block_Eternal_State_Definitions_StageFinal"
    },
    {
      "x": -4,
      "y": 0,
      "z": 3,
      "name": "BO_Pool_Surface00",
      "rotation": 4
    },
    {
      "x": -4,
      "y": 1,
      "z": 3,
      "name": "BO_Pool_Surface00",
      "rotation": 4
    },
    {
      "x": -4,
      "y": 2,
      "z": 3,
      "name": "BO_Pool_Surface00",
      "rotation": 4
    },
    {
      "x": -4,
      "y": 3,
      "z": 3,
      "name": "BO_Pool_Surface00",
      "rotation": 4
    },
    {
      "x": -4,
      "y": 4,
      "z": 3,
      "name": "BO_Pool_Surface00",
      "rotation": 4
    },
    {
      "x": -4,
      "y": 5,
      "z": 3,
      "name": "BO_Pool_Surface00",
      "rotation": 4
    },
    {
      "x": -4,
      "y": 6,
      "z": 3,
      "name": "BO_Pool_Surface00",
      "rotation": 4
    },
    {
      "x": -4,
      "y": 7,
      "z": 3,
      "name": "BO_Pool_Surface00",
      "rotation": 4
    },
    {
      "x": -4,
      "y": 8,
      "z": 3,
      "name": "BO_Pool_Surface00",
      "rotation": 4
    },
    {
      "x": -4,
      "y": 9,
      "z": 3,
      "name": "BO_Pool_Surface00",
      "rotation": 4
    },
    {
      "x": -4,
      "y": 10,
      "z": 3,
      "name": "*BO_Lightsource_Cycle_State_Definitions_Day",
      "components": {
        "Components": {
          "BlackoutCycleState": {
            "OnState": "Day",
            "OffState": "Night"
          }
        }
      },
      "rotation": 2
    },
    {
      "x": -4,
      "y": 14,
      "z": 3,
      "name": "BO_Pool_Surface00",
      "rotation": 2
    },
    {
      "x": -4,
      "y": 15,
      "z": 3,
      "name": "Build_Black_Cube"
    },
    {
      "x": -4,
      "y": 16,
      "z": 3,
      "name": "Soil_Dirt_Tilled",
      "components": {
        "Components": {
          "PlacedByInteraction": {
            "WhoPlacedUuid": {
              "$binary": "KMPE5JWxSQGC8WI/IkVLQQ==",
              "$type": "04"
            }
          },
          "TilledSoil": {
            "Version": 1,
            "DecayTime": "0001-01-02T22:44:51Z"
          }
        }
      }
    },
    {
      "x": -4,
      "y": 17,
      "z": 3,
      "name": "*Plant_Crop_Wheat_Block_Eternal_State_Definitions_StageFinal"
    },
    {
      "x": -4,
      "y": 0,
      "z": 4,
      "name": "BO_Pool_Surface00",
      "rotation": 4
    },
    {
      "x": -4,
      "y": 1,
      "z": 4,
      "name": "BO_Pool_Surface00",
      "rotation": 4
    },
    {
      "x": -4,
      "y": 2,
      "z": 4,
      "name": "BO_Pool_Surface00",
      "rotation": 4
    },
    {
      "x": -4,
      "y": 3,
      "z": 4,
      "name": "BO_Pool_Surface00",
      "rotation": 4
    },
    {
      "x": -4,
      "y": 4,
      "z": 4,
      "name": "BO_Pool_Surface00",
      "rotation": 4
    },
    {
      "x": -4,
      "y": 5,
      "z": 4,
      "name": "BO_Pool_Surface00",
      "rotation": 4
    },
    {
      "x": -4,
      "y": 6,
      "z": 4,
      "name": "BO_Pool_Surface00",
      "rotation": 4
    },
    {
      "x": -4,
      "y": 7,
      "z": 4,
      "name": "BO_Pool_Surface00",
      "rotation": 4
    },
    {
      "x": -4,
      "y": 8,
      "z": 4,
      "name": "BO_Pool_Surface00",
      "rotation": 4
    },
    {
      "x": -4,
      "y": 9,
      "z": 4,
      "name": "BO_Pool_Surface00",
      "rotation": 4
    },
    {
      "x": -4,
      "y": 10,
      "z": 4,
      "name": "*BO_Lightsource_Cycle_State_Definitions_Day",
      "components": {
        "Components": {
          "BlackoutCycleState": {
            "OnState": "Day",
            "OffState": "Night"
          }
        }
      },
      "rotation": 2
    },
    {
      "x": -4,
      "y": 14,
      "z": 4,
      "name": "BO_Pool_Surface00",
      "rotation": 2
    },
    {
      "x": -4,
      "y": 15,
      "z": 4,
      "name": "Build_Black_Cube"
    },
    {
      "x": -4,
      "y": 16,
      "z": 4,
      "name": "Soil_Dirt_Tilled",
      "components": {
        "Components": {
          "PlacedByInteraction": {
            "WhoPlacedUuid": {
              "$binary": "KMPE5JWxSQGC8WI/IkVLQQ==",
              "$type": "04"
            }
          },
          "TilledSoil": {
            "Version": 1,
            "DecayTime": "0001-01-02T22:44:51Z"
          }
        }
      }
    },
    {
      "x": -4,
      "y": 17,
      "z": 4,
      "name": "*Plant_Crop_Wheat_Block_Eternal_State_Definitions_StageFinal"
    },
    {
      "x": -4,
      "y": 0,
      "z": 5,
      "name": "BO_Pool_Surface00",
      "rotation": 4
    },
    {
      "x": -4,
      "y": 1,
      "z": 5,
      "name": "BO_Pool_Surface00",
      "rotation": 4
    },
    {
      "x": -4,
      "y": 2,
      "z": 5,
      "name": "BO_Pool_Surface00",
      "rotation": 4
    },
    {
      "x": -4,
      "y": 3,
      "z": 5,
      "name": "BO_Pool_Surface00",
      "rotation": 4
    },
    {
      "x": -4,
      "y": 4,
      "z": 5,
      "name": "BO_Pool_Surface00",
      "rotation": 4
    },
    {
      "x": -4,
      "y": 5,
      "z": 5,
      "name": "BO_Pool_Surface00",
      "rotation": 4
    },
    {
      "x": -4,
      "y": 6,
      "z": 5,
      "name": "BO_Pool_Surface00",
      "rotation": 4
    },
    {
      "x": -4,
      "y": 7,
      "z": 5,
      "name": "BO_Pool_Surface00",
      "rotation": 4
    },
    {
      "x": -4,
      "y": 8,
      "z": 5,
      "name": "BO_Pool_Surface00",
      "rotation": 4
    },
    {
      "x": -4,
      "y": 9,
      "z": 5,
      "name": "BO_Pool_Surface00",
      "rotation": 4
    },
    {
      "x": -4,
      "y": 10,
      "z": 5,
      "name": "*BO_Lightsource_Cycle_State_Definitions_Day",
      "components": {
        "Components": {
          "BlackoutCycleState": {
            "OnState": "Day",
            "OffState": "Night"
          }
        }
      },
      "rotation": 2
    },
    {
      "x": -4,
      "y": 14,
      "z": 5,
      "name": "BO_Pool_Surface00",
      "rotation": 2
    },
    {
      "x": -4,
      "y": 15,
      "z": 5,
      "name": "Build_Black_Cube"
    },
    {
      "x": -4,
      "y": 16,
      "z": 5,
      "name": "Soil_Dirt_Tilled",
      "components": {
        "Components": {
          "PlacedByInteraction": {
            "WhoPlacedUuid": {
              "$binary": "KMPE5JWxSQGC8WI/IkVLQQ==",
              "$type": "04"
            }
          },
          "TilledSoil": {
            "Version": 1,
            "DecayTime": "0001-01-02T22:44:51Z"
          }
        }
      }
    },
    {
      "x": -4,
      "y": 17,
      "z": 5,
      "name": "*Plant_Crop_Wheat_Block_Eternal_State_Definitions_StageFinal"
    },
    {
      "x": -3,
      "y": 0,
      "z": -4,
      "name": "BO_Pool_Surface00",
      "rotation": 4
    },
    {
      "x": -3,
      "y": 1,
      "z": -4,
      "name": "BO_Pool_Surface00",
      "rotation": 4
    },
    {
      "x": -3,
      "y": 2,
      "z": -4,
      "name": "BO_Pool_Surface00",
      "rotation": 4
    },
    {
      "x": -3,
      "y": 3,
      "z": -4,
      "name": "BO_Pool_Surface00",
      "rotation": 4
    },
    {
      "x": -3,
      "y": 4,
      "z": -4,
      "name": "BO_Pool_Surface00",
      "rotation": 4
    },
    {
      "x": -3,
      "y": 5,
      "z": -4,
      "name": "BO_Pool_Surface00",
      "rotation": 4
    },
    {
      "x": -3,
      "y": 6,
      "z": -4,
      "name": "BO_Pool_Surface00",
      "rotation": 4
    },
    {
      "x": -3,
      "y": 7,
      "z": -4,
      "name": "BO_Pool_Surface00",
      "rotation": 4
    },
    {
      "x": -3,
      "y": 8,
      "z": -4,
      "name": "BO_Pool_Surface00",
      "rotation": 4
    },
    {
      "x": -3,
      "y": 9,
      "z": -4,
      "name": "BO_Pool_Surface00",
      "rotation": 4
    },
    {
      "x": -3,
      "y": 10,
      "z": -4,
      "name": "*BO_Lightsource_Cycle_State_Definitions_Day",
      "components": {
        "Components": {
          "BlackoutCycleState": {
            "OnState": "Day",
            "OffState": "Night"
          }
        }
      },
      "rotation": 2
    },
    {
      "x": -3,
      "y": 14,
      "z": -4,
      "name": "BO_Pool_Surface00",
      "rotation": 2
    },
    {
      "x": -3,
      "y": 15,
      "z": -4,
      "name": "Build_Black_Cube",
      "rotation": 2
    },
    {
      "x": -3,
      "y": 16,
      "z": -4,
      "name": "Soil_Dirt_Tilled",
      "components": {
        "Components": {
          "PlacedByInteraction": {
            "WhoPlacedUuid": {
              "$binary": "KMPE5JWxSQGC8WI/IkVLQQ==",
              "$type": "04"
            }
          },
          "TilledSoil": {
            "Version": 1,
            "DecayTime": "0001-01-02T22:44:51Z"
          }
        }
      }
    },
    {
      "x": -3,
      "y": 17,
      "z": -4,
      "name": "*Plant_Crop_Wheat_Block_Eternal_State_Definitions_StageFinal"
    },
    {
      "x": -3,
      "y": 0,
      "z": -3,
      "name": "BO_Pool_Surface00",
      "rotation": 4
    },
    {
      "x": -3,
      "y": 1,
      "z": -3,
      "name": "BO_Pool_Surface00",
      "rotation": 4
    },
    {
      "x": -3,
      "y": 2,
      "z": -3,
      "name": "BO_Pool_Surface00",
      "rotation": 4
    },
    {
      "x": -3,
      "y": 3,
      "z": -3,
      "name": "BO_Pool_Surface00",
      "rotation": 4
    },
    {
      "x": -3,
      "y": 4,
      "z": -3,
      "name": "BO_Pool_Surface00",
      "rotation": 4
    },
    {
      "x": -3,
      "y": 5,
      "z": -3,
      "name": "BO_Pool_Surface00",
      "rotation": 4
    },
    {
      "x": -3,
      "y": 6,
      "z": -3,
      "name": "BO_Pool_Surface00",
      "rotation": 4
    },
    {
      "x": -3,
      "y": 7,
      "z": -3,
      "name": "BO_Pool_Surface00",
      "rotation": 4
    },
    {
      "x": -3,
      "y": 8,
      "z": -3,
      "name": "BO_Pool_Surface00",
      "rotation": 4
    },
    {
      "x": -3,
      "y": 9,
      "z": -3,
      "name": "BO_Pool_Surface00",
      "rotation": 4
    },
    {
      "x": -3,
      "y": 10,
      "z": -3,
      "name": "*BO_Lightsource_Cycle_State_Definitions_Day",
      "components": {
        "Components": {
          "BlackoutCycleState": {
            "OnState": "Day",
            "OffState": "Night"
          }
        }
      },
      "rotation": 2
    },
    {
      "x": -3,
      "y": 14,
      "z": -3,
      "name": "BO_Pool_Surface00",
      "rotation": 2
    },
    {
      "x": -3,
      "y": 15,
      "z": -3,
      "name": "Build_Black_Cube",
      "rotation": 2
    },
    {
      "x": -3,
      "y": 16,
      "z": -3,
      "name": "Soil_Dirt_Tilled",
      "components": {
        "Components": {
          "PlacedByInteraction": {
            "WhoPlacedUuid": {
              "$binary": "KMPE5JWxSQGC8WI/IkVLQQ==",
              "$type": "04"
            }
          },
          "TilledSoil": {
            "Version": 1,
            "DecayTime": "0001-01-02T22:44:51Z"
          }
        }
      }
    },
    {
      "x": -3,
      "y": 17,
      "z": -3,
      "name": "*Plant_Crop_Wheat_Block_Eternal_State_Definitions_StageFinal"
    },
    {
      "x": -3,
      "y": 0,
      "z": -2,
      "name": "BO_Pool_Surface00",
      "rotation": 4
    },
    {
      "x": -3,
      "y": 1,
      "z": -2,
      "name": "BO_Pool_Surface00",
      "rotation": 4
    },
    {
      "x": -3,
      "y": 2,
      "z": -2,
      "name": "BO_Pool_Surface00",
      "rotation": 4
    },
    {
      "x": -3,
      "y": 3,
      "z": -2,
      "name": "BO_Pool_Surface00",
      "rotation": 4
    },
    {
      "x": -3,
      "y": 4,
      "z": -2,
      "name": "BO_Pool_Surface00",
      "rotation": 4
    },
    {
      "x": -3,
      "y": 5,
      "z": -2,
      "name": "BO_Pool_Surface00",
      "rotation": 4
    },
    {
      "x": -3,
      "y": 6,
      "z": -2,
      "name": "BO_Pool_Surface00",
      "rotation": 4
    },
    {
      "x": -3,
      "y": 7,
      "z": -2,
      "name": "BO_Pool_Surface00",
      "rotation": 4
    },
    {
      "x": -3,
      "y": 8,
      "z": -2,
      "name": "BO_Pool_Surface00",
      "rotation": 4
    },
    {
      "x": -3,
      "y": 9,
      "z": -2,
      "name": "BO_Pool_Surface00",
      "rotation": 4
    },
    {
      "x": -3,
      "y": 10,
      "z": -2,
      "name": "*BO_Lightsource_Cycle_State_Definitions_Day",
      "components": {
        "Components": {
          "BlackoutCycleState": {
            "OnState": "Day",
            "OffState": "Night"
          }
        }
      },
      "rotation": 2
    },
    {
      "x": -3,
      "y": 14,
      "z": -2,
      "name": "BO_Pool_Surface00",
      "rotation": 2
    },
    {
      "x": -3,
      "y": 15,
      "z": -2,
      "name": "Build_Black_Cube",
      "rotation": 2
    },
    {
      "x": -3,
      "y": 16,
      "z": -2,
      "name": "Soil_Dirt_Tilled",
      "components": {
        "Components": {
          "PlacedByInteraction": {
            "WhoPlacedUuid": {
              "$binary": "KMPE5JWxSQGC8WI/IkVLQQ==",
              "$type": "04"
            }
          },
          "TilledSoil": {
            "Version": 1,
            "DecayTime": "0001-01-02T22:44:51Z"
          }
        }
      }
    },
    {
      "x": -3,
      "y": 17,
      "z": -2,
      "name": "*Plant_Crop_Wheat_Block_Eternal_State_Definitions_StageFinal"
    },
    {
      "x": -3,
      "y": 0,
      "z": -1,
      "name": "BO_Pool_Surface00",
      "rotation": 4
    },
    {
      "x": -3,
      "y": 1,
      "z": -1,
      "name": "BO_Pool_Surface00",
      "rotation": 4
    },
    {
      "x": -3,
      "y": 4,
      "z": -1,
      "name": "BO_Pool_Surface00",
      "rotation": 4
    },
    {
      "x": -3,
      "y": 5,
      "z": -1,
      "name": "BO_Pool_Surface00",
      "rotation": 4
    },
    {
      "x": -3,
      "y": 6,
      "z": -1,
      "name": "BO_Pool_Surface00",
      "rotation": 4
    },
    {
      "x": -3,
      "y": 7,
      "z": -1,
      "name": "BO_Pool_Surface00",
      "rotation": 4
    },
    {
      "x": -3,
      "y": 8,
      "z": -1,
      "name": "BO_Pool_Surface00",
      "rotation": 4
    },
    {
      "x": -3,
      "y": 9,
      "z": -1,
      "name": "BO_Pool_Surface00",
      "rotation": 4
    },
    {
      "x": -3,
      "y": 10,
      "z": -1,
      "name": "*BO_Lightsource_Cycle_State_Definitions_Day",
      "components": {
        "Components": {
          "BlackoutCycleState": {
            "OnState": "Day",
            "OffState": "Night"
          }
        }
      },
      "rotation": 2
    },
    {
      "x": -3,
      "y": 14,
      "z": -1,
      "name": "BO_Pool_Surface00",
      "rotation": 2
    },
    {
      "x": -3,
      "y": 15,
      "z": -1,
      "name": "Build_Black_Cube",
      "rotation": 2
    },
    {
      "x": -3,
      "y": 16,
      "z": -1,
      "name": "Soil_Dirt_Tilled",
      "components": {
        "Components": {
          "PlacedByInteraction": {
            "WhoPlacedUuid": {
              "$binary": "KMPE5JWxSQGC8WI/IkVLQQ==",
              "$type": "04"
            }
          },
          "TilledSoil": {
            "Version": 1,
            "DecayTime": "0001-01-02T22:44:51Z"
          }
        }
      }
    },
    {
      "x": -3,
      "y": 17,
      "z": -1,
      "name": "*Plant_Crop_Wheat_Block_Eternal_State_Definitions_StageFinal"
    },
    {
      "x": -3,
      "y": 0,
      "z": 0,
      "name": "BO_Pool_Surface00",
      "rotation": 4
    },
    {
      "x": -3,
      "y": 1,
      "z": 0,
      "name": "BO_Pool_Surface00",
      "rotation": 4
    },
    {
      "x": -3,
      "y": 4,
      "z": 0,
      "name": "BO_Pool_Surface00",
      "rotation": 4
    },
    {
      "x": -3,
      "y": 5,
      "z": 0,
      "name": "BO_Pool_Surface00",
      "rotation": 4
    },
    {
      "x": -3,
      "y": 6,
      "z": 0,
      "name": "BO_Pool_Surface00",
      "rotation": 4
    },
    {
      "x": -3,
      "y": 7,
      "z": 0,
      "name": "BO_Pool_Surface00",
      "rotation": 4
    },
    {
      "x": -3,
      "y": 8,
      "z": 0,
      "name": "BO_Pool_Surface00",
      "rotation": 4
    },
    {
      "x": -3,
      "y": 9,
      "z": 0,
      "name": "BO_Pool_Surface00",
      "rotation": 4
    },
    {
      "x": -3,
      "y": 10,
      "z": 0,
      "name": "*BO_Lightsource_Cycle_State_Definitions_Day",
      "components": {
        "Components": {
          "BlackoutCycleState": {
            "OnState": "Day",
            "OffState": "Night"
          }
        }
      },
      "rotation": 2
    },
    {
      "x": -3,
      "y": 14,
      "z": 0,
      "name": "BO_Pool_Surface00",
      "rotation": 2
    },
    {
      "x": -3,
      "y": 15,
      "z": 0,
      "name": "Build_Black_Cube",
      "rotation": 2
    },
    {
      "x": -3,
      "y": 16,
      "z": 0,
      "name": "Soil_Dirt_Tilled",
      "components": {
        "Components": {
          "PlacedByInteraction": {
            "WhoPlacedUuid": {
              "$binary": "KMPE5JWxSQGC8WI/IkVLQQ==",
              "$type": "04"
            }
          },
          "TilledSoil": {
            "Version": 1,
            "DecayTime": "0001-01-02T22:44:51Z"
          }
        }
      }
    },
    {
      "x": -3,
      "y": 17,
      "z": 0,
      "name": "*Plant_Crop_Wheat_Block_Eternal_State_Definitions_StageFinal"
    },
    {
      "x": -3,
      "y": 0,
      "z": 1,
      "name": "BO_Pool_Surface00",
      "rotation": 4
    },
    {
      "x": -3,
      "y": 1,
      "z": 1,
      "name": "BO_Pool_Surface00",
      "rotation": 4
    },
    {
      "x": -3,
      "y": 4,
      "z": 1,
      "name": "BO_Pool_Surface00",
      "rotation": 4
    },
    {
      "x": -3,
      "y": 5,
      "z": 1,
      "name": "BO_Pool_Surface00",
      "rotation": 4
    },
    {
      "x": -3,
      "y": 6,
      "z": 1,
      "name": "BO_Pool_Surface00",
      "rotation": 4
    },
    {
      "x": -3,
      "y": 7,
      "z": 1,
      "name": "BO_Pool_Surface00",
      "rotation": 4
    },
    {
      "x": -3,
      "y": 8,
      "z": 1,
      "name": "BO_Pool_Surface00",
      "rotation": 4
    },
    {
      "x": -3,
      "y": 9,
      "z": 1,
      "name": "BO_Pool_Surface00",
      "rotation": 4
    },
    {
      "x": -3,
      "y": 10,
      "z": 1,
      "name": "*BO_Lightsource_Cycle_State_Definitions_Day",
      "components": {
        "Components": {
          "BlackoutCycleState": {
            "OnState": "Day",
            "OffState": "Night"
          }
        }
      },
      "rotation": 2
    },
    {
      "x": -3,
      "y": 14,
      "z": 1,
      "name": "BO_Pool_Surface00",
      "rotation": 2
    },
    {
      "x": -3,
      "y": 15,
      "z": 1,
      "name": "Build_Black_Cube",
      "rotation": 2
    },
    {
      "x": -3,
      "y": 16,
      "z": 1,
      "name": "Soil_Dirt_Tilled",
      "components": {
        "Components": {
          "PlacedByInteraction": {
            "WhoPlacedUuid": {
              "$binary": "KMPE5JWxSQGC8WI/IkVLQQ==",
              "$type": "04"
            }
          },
          "TilledSoil": {
            "Version": 1,
            "DecayTime": "0001-01-02T22:44:51Z"
          }
        }
      }
    },
    {
      "x": -3,
      "y": 17,
      "z": 1,
      "name": "*Plant_Crop_Wheat_Block_Eternal_State_Definitions_StageFinal"
    },
    {
      "x": -3,
      "y": 0,
      "z": 2,
      "name": "BO_Pool_Surface00",
      "rotation": 4
    },
    {
      "x": -3,
      "y": 1,
      "z": 2,
      "name": "BO_Pool_Surface00",
      "rotation": 4
    },
    {
      "x": -3,
      "y": 4,
      "z": 2,
      "name": "BO_Pool_Surface00",
      "rotation": 4
    },
    {
      "x": -3,
      "y": 5,
      "z": 2,
      "name": "BO_Pool_Surface00",
      "rotation": 4
    },
    {
      "x": -3,
      "y": 6,
      "z": 2,
      "name": "BO_Pool_Surface00",
      "rotation": 4
    },
    {
      "x": -3,
      "y": 7,
      "z": 2,
      "name": "BO_Pool_Surface00",
      "rotation": 4
    },
    {
      "x": -3,
      "y": 8,
      "z": 2,
      "name": "BO_Pool_Surface00",
      "rotation": 4
    },
    {
      "x": -3,
      "y": 9,
      "z": 2,
      "name": "BO_Pool_Surface00",
      "rotation": 4
    },
    {
      "x": -3,
      "y": 10,
      "z": 2,
      "name": "*BO_Lightsource_Cycle_State_Definitions_Day",
      "components": {
        "Components": {
          "BlackoutCycleState": {
            "OnState": "Day",
            "OffState": "Night"
          }
        }
      },
      "rotation": 2
    },
    {
      "x": -3,
      "y": 14,
      "z": 2,
      "name": "BO_Pool_Surface00",
      "rotation": 2
    },
    {
      "x": -3,
      "y": 15,
      "z": 2,
      "name": "Build_Black_Cube",
      "rotation": 2
    },
    {
      "x": -3,
      "y": 16,
      "z": 2,
      "name": "Soil_Dirt_Tilled",
      "components": {
        "Components": {
          "PlacedByInteraction": {
            "WhoPlacedUuid": {
              "$binary": "KMPE5JWxSQGC8WI/IkVLQQ==",
              "$type": "04"
            }
          },
          "TilledSoil": {
            "Version": 1,
            "DecayTime": "0001-01-02T22:44:51Z"
          }
        }
      }
    },
    {
      "x": -3,
      "y": 17,
      "z": 2,
      "name": "*Plant_Crop_Wheat_Block_Eternal_State_Definitions_StageFinal"
    },
    {
      "x": -3,
      "y": 0,
      "z": 3,
      "name": "BO_Pool_Surface00",
      "rotation": 4
    },
    {
      "x": -3,
      "y": 1,
      "z": 3,
      "name": "BO_Pool_Surface00",
      "rotation": 4
    },
    {
      "x": -3,
      "y": 2,
      "z": 3,
      "name": "BO_Pool_Surface00",
      "rotation": 4
    },
    {
      "x": -3,
      "y": 3,
      "z": 3,
      "name": "BO_Pool_Surface00",
      "rotation": 4
    },
    {
      "x": -3,
      "y": 4,
      "z": 3,
      "name": "BO_Pool_Surface00",
      "rotation": 4
    },
    {
      "x": -3,
      "y": 5,
      "z": 3,
      "name": "BO_Pool_Surface00",
      "rotation": 4
    },
    {
      "x": -3,
      "y": 6,
      "z": 3,
      "name": "BO_Pool_Surface00",
      "rotation": 4
    },
    {
      "x": -3,
      "y": 7,
      "z": 3,
      "name": "BO_Pool_Surface00",
      "rotation": 4
    },
    {
      "x": -3,
      "y": 8,
      "z": 3,
      "name": "BO_Pool_Surface00",
      "rotation": 4
    },
    {
      "x": -3,
      "y": 9,
      "z": 3,
      "name": "BO_Pool_Surface00",
      "rotation": 4
    },
    {
      "x": -3,
      "y": 10,
      "z": 3,
      "name": "*BO_Lightsource_Cycle_State_Definitions_Day",
      "components": {
        "Components": {
          "BlackoutCycleState": {
            "OnState": "Day",
            "OffState": "Night"
          }
        }
      },
      "rotation": 2
    },
    {
      "x": -3,
      "y": 14,
      "z": 3,
      "name": "BO_Pool_Surface00",
      "rotation": 2
    },
    {
      "x": -3,
      "y": 15,
      "z": 3,
      "name": "Build_Black_Cube",
      "rotation": 2
    },
    {
      "x": -3,
      "y": 16,
      "z": 3,
      "name": "Soil_Dirt_Tilled",
      "components": {
        "Components": {
          "PlacedByInteraction": {
            "WhoPlacedUuid": {
              "$binary": "KMPE5JWxSQGC8WI/IkVLQQ==",
              "$type": "04"
            }
          },
          "TilledSoil": {
            "Version": 1,
            "DecayTime": "0001-01-02T22:44:51Z"
          }
        }
      }
    },
    {
      "x": -3,
      "y": 17,
      "z": 3,
      "name": "*Plant_Crop_Wheat_Block_Eternal_State_Definitions_StageFinal"
    },
    {
      "x": -3,
      "y": 0,
      "z": 4,
      "name": "BO_Pool_Surface00",
      "rotation": 4
    },
    {
      "x": -3,
      "y": 1,
      "z": 4,
      "name": "BO_Pool_Surface00",
      "rotation": 4
    },
    {
      "x": -3,
      "y": 2,
      "z": 4,
      "name": "BO_Pool_Surface00",
      "rotation": 4
    },
    {
      "x": -3,
      "y": 3,
      "z": 4,
      "name": "BO_Pool_Surface00",
      "rotation": 4
    },
    {
      "x": -3,
      "y": 4,
      "z": 4,
      "name": "BO_Pool_Surface00",
      "rotation": 4
    },
    {
      "x": -3,
      "y": 5,
      "z": 4,
      "name": "BO_Pool_Surface00",
      "rotation": 4
    },
    {
      "x": -3,
      "y": 6,
      "z": 4,
      "name": "BO_Pool_Surface00",
      "rotation": 4
    },
    {
      "x": -3,
      "y": 7,
      "z": 4,
      "name": "BO_Pool_Surface00",
      "rotation": 4
    },
    {
      "x": -3,
      "y": 8,
      "z": 4,
      "name": "BO_Pool_Surface00",
      "rotation": 4
    },
    {
      "x": -3,
      "y": 9,
      "z": 4,
      "name": "BO_Pool_Surface00",
      "rotation": 4
    },
    {
      "x": -3,
      "y": 10,
      "z": 4,
      "name": "*BO_Lightsource_Cycle_State_Definitions_Day",
      "components": {
        "Components": {
          "BlackoutCycleState": {
            "OnState": "Day",
            "OffState": "Night"
          }
        }
      },
      "rotation": 2
    },
    {
      "x": -3,
      "y": 14,
      "z": 4,
      "name": "BO_Pool_Surface00",
      "rotation": 2
    },
    {
      "x": -3,
      "y": 15,
      "z": 4,
      "name": "Build_Black_Cube",
      "rotation": 2
    },
    {
      "x": -3,
      "y": 16,
      "z": 4,
      "name": "Soil_Dirt_Tilled",
      "components": {
        "Components": {
          "PlacedByInteraction": {
            "WhoPlacedUuid": {
              "$binary": "KMPE5JWxSQGC8WI/IkVLQQ==",
              "$type": "04"
            }
          },
          "TilledSoil": {
            "Version": 1,
            "DecayTime": "0001-01-02T22:44:51Z"
          }
        }
      }
    },
    {
      "x": -3,
      "y": 17,
      "z": 4,
      "name": "*Plant_Crop_Wheat_Block_Eternal_State_Definitions_StageFinal"
    },
    {
      "x": -3,
      "y": 0,
      "z": 5,
      "name": "BO_Pool_Surface00",
      "rotation": 4
    },
    {
      "x": -3,
      "y": 1,
      "z": 5,
      "name": "BO_Pool_Surface00",
      "rotation": 4
    },
    {
      "x": -3,
      "y": 2,
      "z": 5,
      "name": "BO_Pool_Surface00",
      "rotation": 4
    },
    {
      "x": -3,
      "y": 3,
      "z": 5,
      "name": "BO_Pool_Surface00",
      "rotation": 4
    },
    {
      "x": -3,
      "y": 4,
      "z": 5,
      "name": "BO_Pool_Surface00",
      "rotation": 4
    },
    {
      "x": -3,
      "y": 5,
      "z": 5,
      "name": "BO_Pool_Surface00",
      "rotation": 4
    },
    {
      "x": -3,
      "y": 6,
      "z": 5,
      "name": "BO_Pool_Surface00",
      "rotation": 4
    },
    {
      "x": -3,
      "y": 7,
      "z": 5,
      "name": "BO_Pool_Surface00",
      "rotation": 4
    },
    {
      "x": -3,
      "y": 8,
      "z": 5,
      "name": "BO_Pool_Surface00",
      "rotation": 4
    },
    {
      "x": -3,
      "y": 9,
      "z": 5,
      "name": "BO_Pool_Surface00",
      "rotation": 4
    },
    {
      "x": -3,
      "y": 10,
      "z": 5,
      "name": "*BO_Lightsource_Cycle_State_Definitions_Day",
      "components": {
        "Components": {
          "BlackoutCycleState": {
            "OnState": "Day",
            "OffState": "Night"
          }
        }
      },
      "rotation": 2
    },
    {
      "x": -3,
      "y": 14,
      "z": 5,
      "name": "BO_Pool_Surface00",
      "rotation": 2
    },
    {
      "x": -3,
      "y": 15,
      "z": 5,
      "name": "Build_Black_Cube",
      "rotation": 2
    },
    {
      "x": -3,
      "y": 16,
      "z": 5,
      "name": "Soil_Dirt_Tilled",
      "components": {
        "Components": {
          "PlacedByInteraction": {
            "WhoPlacedUuid": {
              "$binary": "KMPE5JWxSQGC8WI/IkVLQQ==",
              "$type": "04"
            }
          },
          "TilledSoil": {
            "Version": 1,
            "DecayTime": "0001-01-02T22:44:51Z"
          }
        }
      }
    },
    {
      "x": -3,
      "y": 17,
      "z": 5,
      "name": "*Plant_Crop_Wheat_Block_Eternal_State_Definitions_StageFinal"
    },
    {
      "x": -2,
      "y": 0,
      "z": -4,
      "name": "BO_Pool_Surface00",
      "rotation": 4
    },
    {
      "x": -2,
      "y": 1,
      "z": -4,
      "name": "BO_Pool_Surface00",
      "rotation": 4
    },
    {
      "x": -2,
      "y": 9,
      "z": -4,
      "name": "BO_Pool_Surface00",
      "rotation": 4
    },
    {
      "x": -2,
      "y": 10,
      "z": -4,
      "name": "*BO_Lightsource_Cycle_State_Definitions_Day",
      "components": {
        "Components": {
          "BlackoutCycleState": {
            "OnState": "Day",
            "OffState": "Night"
          }
        }
      },
      "rotation": 2
    },
    {
      "x": -2,
      "y": 14,
      "z": -4,
      "name": "BO_Pool_Surface00",
      "rotation": 2
    },
    {
      "x": -2,
      "y": 15,
      "z": -4,
      "name": "Build_Black_Cube"
    },
    {
      "x": -2,
      "y": 16,
      "z": -4,
      "name": "Soil_Dirt_Tilled",
      "components": {
        "Components": {
          "PlacedByInteraction": {
            "WhoPlacedUuid": {
              "$binary": "KMPE5JWxSQGC8WI/IkVLQQ==",
              "$type": "04"
            }
          },
          "TilledSoil": {
            "Version": 1,
            "DecayTime": "0001-01-02T22:44:51Z"
          }
        }
      }
    },
    {
      "x": -2,
      "y": 17,
      "z": -4,
      "name": "*Plant_Crop_Wheat_Block_Eternal_State_Definitions_StageFinal"
    },
    {
      "x": -2,
      "y": 0,
      "z": -3,
      "name": "BO_Pool_Surface00",
      "rotation": 4
    },
    {
      "x": -2,
      "y": 1,
      "z": -3,
      "name": "BO_Pool_Surface00",
      "rotation": 4
    },
    {
      "x": -2,
      "y": 9,
      "z": -3,
      "name": "BO_Pool_Surface00",
      "rotation": 4
    },
    {
      "x": -2,
      "y": 10,
      "z": -3,
      "name": "*BO_Lightsource_Cycle_State_Definitions_Day",
      "components": {
        "Components": {
          "BlackoutCycleState": {
            "OnState": "Day",
            "OffState": "Night"
          }
        }
      },
      "rotation": 2
    },
    {
      "x": -2,
      "y": 14,
      "z": -3,
      "name": "BO_Pool_Surface00",
      "rotation": 2
    },
    {
      "x": -2,
      "y": 15,
      "z": -3,
      "name": "Build_Black_Cube"
    },
    {
      "x": -2,
      "y": 16,
      "z": -3,
      "name": "Soil_Dirt_Tilled",
      "components": {
        "Components": {
          "PlacedByInteraction": {
            "WhoPlacedUuid": {
              "$binary": "KMPE5JWxSQGC8WI/IkVLQQ==",
              "$type": "04"
            }
          },
          "TilledSoil": {
            "Version": 1,
            "DecayTime": "0001-01-02T22:44:51Z"
          }
        }
      }
    },
    {
      "x": -2,
      "y": 17,
      "z": -3,
      "name": "*Plant_Crop_Wheat_Block_Eternal_State_Definitions_StageFinal"
    },
    {
      "x": -2,
      "y": 0,
      "z": -2,
      "name": "BO_Pool_Surface00",
      "rotation": 4
    },
    {
      "x": -2,
      "y": 1,
      "z": -2,
      "name": "BO_Pool_Surface00",
      "rotation": 4
    },
    {
      "x": -2,
      "y": 9,
      "z": -2,
      "name": "BO_Pool_Surface00",
      "rotation": 4
    },
    {
      "x": -2,
      "y": 10,
      "z": -2,
      "name": "*BO_Lightsource_Cycle_State_Definitions_Day",
      "components": {
        "Components": {
          "BlackoutCycleState": {
            "OnState": "Day",
            "OffState": "Night"
          }
        }
      },
      "rotation": 2
    },
    {
      "x": -2,
      "y": 14,
      "z": -2,
      "name": "BO_Pool_Surface00",
      "rotation": 2
    },
    {
      "x": -2,
      "y": 15,
      "z": -2,
      "name": "Build_Black_Cube"
    },
    {
      "x": -2,
      "y": 16,
      "z": -2,
      "name": "Soil_Dirt_Tilled",
      "components": {
        "Components": {
          "PlacedByInteraction": {
            "WhoPlacedUuid": {
              "$binary": "KMPE5JWxSQGC8WI/IkVLQQ==",
              "$type": "04"
            }
          },
          "TilledSoil": {
            "Version": 1,
            "DecayTime": "0001-01-02T22:44:51Z"
          }
        }
      }
    },
    {
      "x": -2,
      "y": 17,
      "z": -2,
      "name": "*Plant_Crop_Wheat_Block_Eternal_State_Definitions_StageFinal"
    },
    {
      "x": -2,
      "y": 0,
      "z": -1,
      "name": "BO_Pool_Surface00",
      "rotation": 4
    },
    {
      "x": -2,
      "y": 1,
      "z": -1,
      "name": "BO_Pool_Surface00",
      "rotation": 4
    },
    {
      "x": -2,
      "y": 9,
      "z": -1,
      "name": "BO_Pool_Surface00",
      "rotation": 4
    },
    {
      "x": -2,
      "y": 10,
      "z": -1,
      "name": "*BO_Lightsource_Cycle_State_Definitions_Day",
      "components": {
        "Components": {
          "BlackoutCycleState": {
            "OnState": "Day",
            "OffState": "Night"
          }
        }
      },
      "rotation": 2
    },
    {
      "x": -2,
      "y": 14,
      "z": -1,
      "name": "BO_Pool_Surface00",
      "rotation": 2
    },
    {
      "x": -2,
      "y": 15,
      "z": -1,
      "name": "Build_Black_Cube"
    },
    {
      "x": -2,
      "y": 16,
      "z": -1,
      "name": "Soil_Dirt_Tilled",
      "components": {
        "Components": {
          "PlacedByInteraction": {
            "WhoPlacedUuid": {
              "$binary": "KMPE5JWxSQGC8WI/IkVLQQ==",
              "$type": "04"
            }
          },
          "TilledSoil": {
            "Version": 1,
            "DecayTime": "0001-01-02T22:44:51Z"
          }
        }
      }
    },
    {
      "x": -2,
      "y": 17,
      "z": -1,
      "name": "*Plant_Crop_Wheat_Block_Eternal_State_Definitions_StageFinal"
    },
    {
      "x": -2,
      "y": 0,
      "z": 0,
      "name": "BO_Pool_Surface00",
      "rotation": 4
    },
    {
      "x": -2,
      "y": 1,
      "z": 0,
      "name": "BO_Pool_Surface00",
      "rotation": 4
    },
    {
      "x": -2,
      "y": 9,
      "z": 0,
      "name": "BO_Pool_Surface00",
      "rotation": 4
    },
    {
      "x": -2,
      "y": 10,
      "z": 0,
      "name": "*BO_Lightsource_Cycle_State_Definitions_Day",
      "components": {
        "Components": {
          "BlackoutCycleState": {
            "OnState": "Day",
            "OffState": "Night"
          }
        }
      },
      "rotation": 2
    },
    {
      "x": -2,
      "y": 14,
      "z": 0,
      "name": "BO_Pool_Surface00",
      "rotation": 2
    },
    {
      "x": -2,
      "y": 15,
      "z": 0,
      "name": "Build_Black_Cube"
    },
    {
      "x": -2,
      "y": 16,
      "z": 0,
      "name": "Soil_Dirt_Tilled",
      "components": {
        "Components": {
          "PlacedByInteraction": {
            "WhoPlacedUuid": {
              "$binary": "KMPE5JWxSQGC8WI/IkVLQQ==",
              "$type": "04"
            }
          },
          "TilledSoil": {
            "Version": 1,
            "DecayTime": "0001-01-02T22:44:51Z"
          }
        }
      }
    },
    {
      "x": -2,
      "y": 17,
      "z": 0,
      "name": "*Plant_Crop_Wheat_Block_Eternal_State_Definitions_StageFinal"
    },
    {
      "x": -2,
      "y": 0,
      "z": 1,
      "name": "BO_Pool_Surface00",
      "rotation": 4
    },
    {
      "x": -2,
      "y": 1,
      "z": 1,
      "name": "BO_Pool_Surface00",
      "rotation": 4
    },
    {
      "x": -2,
      "y": 9,
      "z": 1,
      "name": "BO_Pool_Surface00",
      "rotation": 4
    },
    {
      "x": -2,
      "y": 10,
      "z": 1,
      "name": "*BO_Lightsource_Cycle_State_Definitions_Day",
      "components": {
        "Components": {
          "BlackoutCycleState": {
            "OnState": "Day",
            "OffState": "Night"
          }
        }
      },
      "rotation": 2
    },
    {
      "x": -2,
      "y": 14,
      "z": 1,
      "name": "BO_Pool_Surface00",
      "rotation": 2
    },
    {
      "x": -2,
      "y": 15,
      "z": 1,
      "name": "Build_Black_Cube"
    },
    {
      "x": -2,
      "y": 16,
      "z": 1,
      "name": "Soil_Dirt_Tilled",
      "components": {
        "Components": {
          "PlacedByInteraction": {
            "WhoPlacedUuid": {
              "$binary": "KMPE5JWxSQGC8WI/IkVLQQ==",
              "$type": "04"
            }
          },
          "TilledSoil": {
            "Version": 1,
            "DecayTime": "0001-01-02T22:44:51Z"
          }
        }
      }
    },
    {
      "x": -2,
      "y": 17,
      "z": 1,
      "name": "*Plant_Crop_Wheat_Block_Eternal_State_Definitions_StageFinal"
    },
    {
      "x": -2,
      "y": 0,
      "z": 2,
      "name": "BO_Pool_Surface00",
      "rotation": 4
    },
    {
      "x": -2,
      "y": 1,
      "z": 2,
      "name": "BO_Pool_Surface00",
      "rotation": 4
    },
    {
      "x": -2,
      "y": 9,
      "z": 2,
      "name": "BO_Pool_Surface00",
      "rotation": 4
    },
    {
      "x": -2,
      "y": 10,
      "z": 2,
      "name": "*BO_Lightsource_Cycle_State_Definitions_Day",
      "components": {
        "Components": {
          "BlackoutCycleState": {
            "OnState": "Day",
            "OffState": "Night"
          }
        }
      },
      "rotation": 2
    },
    {
      "x": -2,
      "y": 14,
      "z": 2,
      "name": "BO_Pool_Surface00",
      "rotation": 2
    },
    {
      "x": -2,
      "y": 15,
      "z": 2,
      "name": "Build_Black_Cube"
    },
    {
      "x": -2,
      "y": 16,
      "z": 2,
      "name": "Soil_Dirt_Tilled",
      "components": {
        "Components": {
          "PlacedByInteraction": {
            "WhoPlacedUuid": {
              "$binary": "KMPE5JWxSQGC8WI/IkVLQQ==",
              "$type": "04"
            }
          },
          "TilledSoil": {
            "Version": 1,
            "DecayTime": "0001-01-02T22:44:51Z"
          }
        }
      }
    },
    {
      "x": -2,
      "y": 17,
      "z": 2,
      "name": "*Plant_Crop_Wheat_Block_Eternal_State_Definitions_StageFinal"
    },
    {
      "x": -2,
      "y": 0,
      "z": 3,
      "name": "BO_Pool_Surface00",
      "rotation": 4
    },
    {
      "x": -2,
      "y": 1,
      "z": 3,
      "name": "BO_Pool_Surface00",
      "rotation": 4
    },
    {
      "x": -2,
      "y": 9,
      "z": 3,
      "name": "BO_Pool_Surface00",
      "rotation": 4
    },
    {
      "x": -2,
      "y": 10,
      "z": 3,
      "name": "*BO_Lightsource_Cycle_State_Definitions_Day",
      "components": {
        "Components": {
          "BlackoutCycleState": {
            "OnState": "Day",
            "OffState": "Night"
          }
        }
      },
      "rotation": 2
    },
    {
      "x": -2,
      "y": 14,
      "z": 3,
      "name": "BO_Pool_Surface00",
      "rotation": 2
    },
    {
      "x": -2,
      "y": 15,
      "z": 3,
      "name": "Build_Black_Cube"
    },
    {
      "x": -2,
      "y": 16,
      "z": 3,
      "name": "Soil_Dirt_Tilled",
      "components": {
        "Components": {
          "PlacedByInteraction": {
            "WhoPlacedUuid": {
              "$binary": "KMPE5JWxSQGC8WI/IkVLQQ==",
              "$type": "04"
            }
          },
          "TilledSoil": {
            "Version": 1,
            "DecayTime": "0001-01-02T22:44:51Z"
          }
        }
      }
    },
    {
      "x": -2,
      "y": 17,
      "z": 3,
      "name": "*Plant_Crop_Wheat_Block_Eternal_State_Definitions_StageFinal"
    },
    {
      "x": -2,
      "y": 0,
      "z": 4,
      "name": "BO_Pool_Surface00",
      "rotation": 4
    },
    {
      "x": -2,
      "y": 1,
      "z": 4,
      "name": "BO_Pool_Surface00",
      "rotation": 4
    },
    {
      "x": -2,
      "y": 9,
      "z": 4,
      "name": "BO_Pool_Surface00",
      "rotation": 4
    },
    {
      "x": -2,
      "y": 10,
      "z": 4,
      "name": "*BO_Lightsource_Cycle_State_Definitions_Day",
      "components": {
        "Components": {
          "BlackoutCycleState": {
            "OnState": "Day",
            "OffState": "Night"
          }
        }
      },
      "rotation": 2
    },
    {
      "x": -2,
      "y": 14,
      "z": 4,
      "name": "BO_Pool_Surface00",
      "rotation": 2
    },
    {
      "x": -2,
      "y": 15,
      "z": 4,
      "name": "Build_Black_Cube"
    },
    {
      "x": -2,
      "y": 16,
      "z": 4,
      "name": "Soil_Dirt_Tilled",
      "components": {
        "Components": {
          "PlacedByInteraction": {
            "WhoPlacedUuid": {
              "$binary": "KMPE5JWxSQGC8WI/IkVLQQ==",
              "$type": "04"
            }
          },
          "TilledSoil": {
            "Version": 1,
            "DecayTime": "0001-01-02T22:44:51Z"
          }
        }
      }
    },
    {
      "x": -2,
      "y": 17,
      "z": 4,
      "name": "*Plant_Crop_Wheat_Block_Eternal_State_Definitions_StageFinal"
    },
    {
      "x": -2,
      "y": 0,
      "z": 5,
      "name": "BO_Pool_Surface00",
      "rotation": 4
    },
    {
      "x": -2,
      "y": 1,
      "z": 5,
      "name": "BO_Pool_Surface00",
      "rotation": 4
    },
    {
      "x": -2,
      "y": 9,
      "z": 5,
      "name": "BO_Pool_Surface00",
      "rotation": 4
    },
    {
      "x": -2,
      "y": 10,
      "z": 5,
      "name": "*BO_Lightsource_Cycle_State_Definitions_Day",
      "components": {
        "Components": {
          "BlackoutCycleState": {
            "OnState": "Day",
            "OffState": "Night"
          }
        }
      },
      "rotation": 2
    },
    {
      "x": -2,
      "y": 14,
      "z": 5,
      "name": "BO_Pool_Surface00",
      "rotation": 2
    },
    {
      "x": -2,
      "y": 15,
      "z": 5,
      "name": "Build_Black_Cube"
    },
    {
      "x": -2,
      "y": 16,
      "z": 5,
      "name": "Soil_Dirt_Tilled",
      "components": {
        "Components": {
          "PlacedByInteraction": {
            "WhoPlacedUuid": {
              "$binary": "KMPE5JWxSQGC8WI/IkVLQQ==",
              "$type": "04"
            }
          },
          "TilledSoil": {
            "Version": 1,
            "DecayTime": "0001-01-02T22:44:51Z"
          }
        }
      }
    },
    {
      "x": -2,
      "y": 17,
      "z": 5,
      "name": "*Plant_Crop_Wheat_Block_Eternal_State_Definitions_StageFinal"
    },
    {
      "x": -1,
      "y": 0,
      "z": -4,
      "name": "BO_Pool_Surface00",
      "rotation": 4
    },
    {
      "x": -1,
      "y": 9,
      "z": -4,
      "name": "BO_Pool_Surface00",
      "rotation": 4
    },
    {
      "x": -1,
      "y": 10,
      "z": -4,
      "name": "*BO_Lightsource_Cycle_State_Definitions_Day",
      "components": {
        "Components": {
          "BlackoutCycleState": {
            "OnState": "Day",
            "OffState": "Night"
          }
        }
      },
      "rotation": 2
    },
    {
      "x": -1,
      "y": 14,
      "z": -4,
      "name": "BO_Pool_Surface00",
      "rotation": 2
    },
    {
      "x": -1,
      "y": 15,
      "z": -4,
      "name": "Build_Black_Cube"
    },
    {
      "x": -1,
      "y": 16,
      "z": -4,
      "name": "Soil_Dirt_Tilled",
      "components": {
        "Components": {
          "PlacedByInteraction": {
            "WhoPlacedUuid": {
              "$binary": "KMPE5JWxSQGC8WI/IkVLQQ==",
              "$type": "04"
            }
          },
          "TilledSoil": {
            "Version": 1,
            "DecayTime": "0001-01-02T22:44:51Z"
          }
        }
      }
    },
    {
      "x": -1,
      "y": 17,
      "z": -4,
      "name": "*Plant_Crop_Wheat_Block_Eternal_State_Definitions_StageFinal"
    },
    {
      "x": -1,
      "y": 0,
      "z": -3,
      "name": "BO_Pool_Surface00",
      "rotation": 4
    },
    {
      "x": -1,
      "y": 9,
      "z": -3,
      "name": "BO_Pool_Surface00",
      "rotation": 4
    },
    {
      "x": -1,
      "y": 10,
      "z": -3,
      "name": "*BO_Lightsource_Cycle_State_Definitions_Day",
      "components": {
        "Components": {
          "BlackoutCycleState": {
            "OnState": "Day",
            "OffState": "Night"
          }
        }
      },
      "rotation": 2
    },
    {
      "x": -1,
      "y": 14,
      "z": -3,
      "name": "BO_Pool_Surface00",
      "rotation": 2
    },
    {
      "x": -1,
      "y": 15,
      "z": -3,
      "name": "Build_Black_Cube"
    },
    {
      "x": -1,
      "y": 16,
      "z": -3,
      "name": "Soil_Dirt_Tilled",
      "components": {
        "Components": {
          "PlacedByInteraction": {
            "WhoPlacedUuid": {
              "$binary": "KMPE5JWxSQGC8WI/IkVLQQ==",
              "$type": "04"
            }
          },
          "TilledSoil": {
            "Version": 1,
            "DecayTime": "0001-01-02T22:44:51Z"
          }
        }
      }
    },
    {
      "x": -1,
      "y": 17,
      "z": -3,
      "name": "*Plant_Crop_Wheat_Block_Eternal_State_Definitions_StageFinal"
    },
    {
      "x": -1,
      "y": 0,
      "z": -2,
      "name": "BO_Pool_Surface00",
      "rotation": 4
    },
    {
      "x": -1,
      "y": 9,
      "z": -2,
      "name": "BO_Pool_Surface00",
      "rotation": 4
    },
    {
      "x": -1,
      "y": 10,
      "z": -2,
      "name": "*BO_Lightsource_Cycle_State_Definitions_Day",
      "components": {
        "Components": {
          "BlackoutCycleState": {
            "OnState": "Day",
            "OffState": "Night"
          }
        }
      },
      "rotation": 2
    },
    {
      "x": -1,
      "y": 14,
      "z": -2,
      "name": "BO_Pool_Surface00",
      "rotation": 2
    },
    {
      "x": -1,
      "y": 15,
      "z": -2,
      "name": "Build_Black_Cube"
    },
    {
      "x": -1,
      "y": 16,
      "z": -2,
      "name": "Soil_Dirt_Tilled",
      "components": {
        "Components": {
          "PlacedByInteraction": {
            "WhoPlacedUuid": {
              "$binary": "KMPE5JWxSQGC8WI/IkVLQQ==",
              "$type": "04"
            }
          },
          "TilledSoil": {
            "Version": 1,
            "DecayTime": "0001-01-02T22:44:51Z"
          }
        }
      }
    },
    {
      "x": -1,
      "y": 17,
      "z": -2,
      "name": "*Plant_Crop_Wheat_Block_Eternal_State_Definitions_StageFinal"
    },
    {
      "x": -1,
      "y": 0,
      "z": -1,
      "name": "BO_Pool_Surface00",
      "rotation": 4
    },
    {
      "x": -1,
      "y": 9,
      "z": -1,
      "name": "BO_Pool_Surface00",
      "rotation": 4
    },
    {
      "x": -1,
      "y": 10,
      "z": -1,
      "name": "*BO_Lightsource_Cycle_State_Definitions_Day",
      "components": {
        "Components": {
          "BlackoutCycleState": {
            "OnState": "Day",
            "OffState": "Night"
          }
        }
      },
      "rotation": 2
    },
    {
      "x": -1,
      "y": 14,
      "z": -1,
      "name": "BO_Pool_Surface00",
      "rotation": 2
    },
    {
      "x": -1,
      "y": 15,
      "z": -1,
      "name": "Build_Black_Cube"
    },
    {
      "x": -1,
      "y": 16,
      "z": -1,
      "name": "Soil_Dirt_Tilled",
      "components": {
        "Components": {
          "PlacedByInteraction": {
            "WhoPlacedUuid": {
              "$binary": "KMPE5JWxSQGC8WI/IkVLQQ==",
              "$type": "04"
            }
          },
          "TilledSoil": {
            "Version": 1,
            "DecayTime": "0001-01-02T22:44:51Z"
          }
        }
      }
    },
    {
      "x": -1,
      "y": 17,
      "z": -1,
      "name": "*Plant_Crop_Wheat_Block_Eternal_State_Definitions_StageFinal"
    },
    {
      "x": -1,
      "y": 0,
      "z": 0,
      "name": "BO_Pool_Surface00",
      "rotation": 4
    },
    {
      "x": -1,
      "y": 9,
      "z": 0,
      "name": "BO_Pool_Surface00",
      "rotation": 4
    },
    {
      "x": -1,
      "y": 10,
      "z": 0,
      "name": "*BO_Lightsource_Cycle_State_Definitions_Day",
      "components": {
        "Components": {
          "BlackoutCycleState": {
            "OnState": "Day",
            "OffState": "Night"
          }
        }
      },
      "rotation": 2
    },
    {
      "x": -1,
      "y": 14,
      "z": 0,
      "name": "BO_Pool_Surface00",
      "rotation": 2
    },
    {
      "x": -1,
      "y": 15,
      "z": 0,
      "name": "Build_Black_Cube"
    },
    {
      "x": -1,
      "y": 16,
      "z": 0,
      "name": "Soil_Dirt_Tilled",
      "components": {
        "Components": {
          "PlacedByInteraction": {
            "WhoPlacedUuid": {
              "$binary": "KMPE5JWxSQGC8WI/IkVLQQ==",
              "$type": "04"
            }
          },
          "TilledSoil": {
            "Version": 1,
            "DecayTime": "0001-01-02T22:44:51Z"
          }
        }
      }
    },
    {
      "x": -1,
      "y": 17,
      "z": 0,
      "name": "*Plant_Crop_Wheat_Block_Eternal_State_Definitions_StageFinal"
    },
    {
      "x": -1,
      "y": 0,
      "z": 1,
      "name": "BO_Pool_Surface00",
      "rotation": 4
    },
    {
      "x": -1,
      "y": 9,
      "z": 1,
      "name": "BO_Pool_Surface00",
      "rotation": 4
    },
    {
      "x": -1,
      "y": 10,
      "z": 1,
      "name": "*BO_Lightsource_Cycle_State_Definitions_Day",
      "components": {
        "Components": {
          "BlackoutCycleState": {
            "OnState": "Day",
            "OffState": "Night"
          }
        }
      },
      "rotation": 2
    },
    {
      "x": -1,
      "y": 14,
      "z": 1,
      "name": "BO_Pool_Surface00",
      "rotation": 2
    },
    {
      "x": -1,
      "y": 15,
      "z": 1,
      "name": "Build_Black_Cube"
    },
    {
      "x": -1,
      "y": 16,
      "z": 1,
      "name": "Soil_Dirt_Tilled",
      "components": {
        "Components": {
          "PlacedByInteraction": {
            "WhoPlacedUuid": {
              "$binary": "KMPE5JWxSQGC8WI/IkVLQQ==",
              "$type": "04"
            }
          },
          "TilledSoil": {
            "Version": 1,
            "DecayTime": "0001-01-02T22:44:51Z"
          }
        }
      }
    },
    {
      "x": -1,
      "y": 17,
      "z": 1,
      "name": "*Plant_Crop_Wheat_Block_Eternal_State_Definitions_StageFinal"
    },
    {
      "x": -1,
      "y": 0,
      "z": 2,
      "name": "BO_Pool_Surface00",
      "rotation": 4
    },
    {
      "x": -1,
      "y": 9,
      "z": 2,
      "name": "BO_Pool_Surface00",
      "rotation": 4
    },
    {
      "x": -1,
      "y": 10,
      "z": 2,
      "name": "*BO_Lightsource_Cycle_State_Definitions_Day",
      "components": {
        "Components": {
          "BlackoutCycleState": {
            "OnState": "Day",
            "OffState": "Night"
          }
        }
      },
      "rotation": 2
    },
    {
      "x": -1,
      "y": 14,
      "z": 2,
      "name": "BO_Pool_Surface00",
      "rotation": 2
    },
    {
      "x": -1,
      "y": 15,
      "z": 2,
      "name": "Build_Black_Cube"
    },
    {
      "x": -1,
      "y": 16,
      "z": 2,
      "name": "Soil_Dirt_Tilled",
      "components": {
        "Components": {
          "PlacedByInteraction": {
            "WhoPlacedUuid": {
              "$binary": "KMPE5JWxSQGC8WI/IkVLQQ==",
              "$type": "04"
            }
          },
          "TilledSoil": {
            "Version": 1,
            "DecayTime": "0001-01-02T22:44:51Z"
          }
        }
      }
    },
    {
      "x": -1,
      "y": 17,
      "z": 2,
      "name": "*Plant_Crop_Wheat_Block_Eternal_State_Definitions_StageFinal"
    },
    {
      "x": -1,
      "y": 0,
      "z": 3,
      "name": "BO_Pool_Surface00",
      "rotation": 4
    },
    {
      "x": -1,
      "y": 9,
      "z": 3,
      "name": "BO_Pool_Surface00",
      "rotation": 4
    },
    {
      "x": -1,
      "y": 10,
      "z": 3,
      "name": "*BO_Lightsource_Cycle_State_Definitions_Day",
      "components": {
        "Components": {
          "BlackoutCycleState": {
            "OnState": "Day",
            "OffState": "Night"
          }
        }
      },
      "rotation": 2
    },
    {
      "x": -1,
      "y": 14,
      "z": 3,
      "name": "BO_Pool_Surface00",
      "rotation": 2
    },
    {
      "x": -1,
      "y": 15,
      "z": 3,
      "name": "Build_Black_Cube"
    },
    {
      "x": -1,
      "y": 16,
      "z": 3,
      "name": "Soil_Dirt_Tilled",
      "components": {
        "Components": {
          "PlacedByInteraction": {
            "WhoPlacedUuid": {
              "$binary": "KMPE5JWxSQGC8WI/IkVLQQ==",
              "$type": "04"
            }
          },
          "TilledSoil": {
            "Version": 1,
            "DecayTime": "0001-01-02T22:44:51Z"
          }
        }
      }
    },
    {
      "x": -1,
      "y": 17,
      "z": 3,
      "name": "*Plant_Crop_Wheat_Block_Eternal_State_Definitions_StageFinal"
    },
    {
      "x": -1,
      "y": 0,
      "z": 4,
      "name": "BO_Pool_Surface00",
      "rotation": 4
    },
    {
      "x": -1,
      "y": 9,
      "z": 4,
      "name": "BO_Pool_Surface00",
      "rotation": 4
    },
    {
      "x": -1,
      "y": 10,
      "z": 4,
      "name": "*BO_Lightsource_Cycle_State_Definitions_Day",
      "components": {
        "Components": {
          "BlackoutCycleState": {
            "OnState": "Day",
            "OffState": "Night"
          }
        }
      },
      "rotation": 2
    },
    {
      "x": -1,
      "y": 14,
      "z": 4,
      "name": "BO_Pool_Surface00",
      "rotation": 2
    },
    {
      "x": -1,
      "y": 15,
      "z": 4,
      "name": "Build_Black_Cube"
    },
    {
      "x": -1,
      "y": 16,
      "z": 4,
      "name": "Soil_Dirt_Tilled",
      "components": {
        "Components": {
          "PlacedByInteraction": {
            "WhoPlacedUuid": {
              "$binary": "KMPE5JWxSQGC8WI/IkVLQQ==",
              "$type": "04"
            }
          },
          "TilledSoil": {
            "Version": 1,
            "DecayTime": "0001-01-02T22:44:51Z"
          }
        }
      }
    },
    {
      "x": -1,
      "y": 17,
      "z": 4,
      "name": "*Plant_Crop_Wheat_Block_Eternal_State_Definitions_StageFinal"
    },
    {
      "x": -1,
      "y": 0,
      "z": 5,
      "name": "BO_Pool_Surface00",
      "rotation": 4
    },
    {
      "x": -1,
      "y": 9,
      "z": 5,
      "name": "BO_Pool_Surface00",
      "rotation": 4
    },
    {
      "x": -1,
      "y": 10,
      "z": 5,
      "name": "*BO_Lightsource_Cycle_State_Definitions_Day",
      "components": {
        "Components": {
          "BlackoutCycleState": {
            "OnState": "Day",
            "OffState": "Night"
          }
        }
      },
      "rotation": 2
    },
    {
      "x": -1,
      "y": 14,
      "z": 5,
      "name": "BO_Pool_Surface00",
      "rotation": 2
    },
    {
      "x": -1,
      "y": 15,
      "z": 5,
      "name": "Build_Black_Cube"
    },
    {
      "x": -1,
      "y": 16,
      "z": 5,
      "name": "Soil_Dirt_Tilled",
      "components": {
        "Components": {
          "PlacedByInteraction": {
            "WhoPlacedUuid": {
              "$binary": "KMPE5JWxSQGC8WI/IkVLQQ==",
              "$type": "04"
            }
          },
          "TilledSoil": {
            "Version": 1,
            "DecayTime": "0001-01-02T22:44:51Z"
          }
        }
      }
    },
    {
      "x": -1,
      "y": 17,
      "z": 5,
      "name": "*Plant_Crop_Wheat_Block_Eternal_State_Definitions_StageFinal"
    },
    {
      "x": 0,
      "y": 0,
      "z": -4,
      "name": "BO_Pool_Surface00",
      "rotation": 4
    },
    {
      "x": 0,
      "y": 9,
      "z": -4,
      "name": "BO_Pool_Surface00",
      "rotation": 4
    },
    {
      "x": 0,
      "y": 10,
      "z": -4,
      "name": "*BO_Lightsource_Cycle_State_Definitions_Day",
      "components": {
        "Components": {
          "BlackoutCycleState": {
            "OnState": "Day",
            "OffState": "Night"
          }
        }
      },
      "rotation": 2
    },
    {
      "x": 0,
      "y": 14,
      "z": -4,
      "name": "BO_Pool_Surface00",
      "rotation": 2
    },
    {
      "x": 0,
      "y": 15,
      "z": -4,
      "name": "Build_Black_Cube"
    },
    {
      "x": 0,
      "y": 16,
      "z": -4,
      "name": "Soil_Dirt_Tilled",
      "components": {
        "Components": {
          "PlacedByInteraction": {
            "WhoPlacedUuid": {
              "$binary": "KMPE5JWxSQGC8WI/IkVLQQ==",
              "$type": "04"
            }
          },
          "TilledSoil": {
            "Version": 1,
            "DecayTime": "0001-01-02T22:44:51Z"
          }
        }
      }
    },
    {
      "x": 0,
      "y": 17,
      "z": -4,
      "name": "*Plant_Crop_Wheat_Block_Eternal_State_Definitions_StageFinal"
    },
    {
      "x": 0,
      "y": 0,
      "z": -3,
      "name": "BO_Pool_Surface00",
      "rotation": 4
    },
    {
      "x": 0,
      "y": 9,
      "z": -3,
      "name": "BO_Pool_Surface00",
      "rotation": 4
    },
    {
      "x": 0,
      "y": 10,
      "z": -3,
      "name": "*BO_Lightsource_Cycle_State_Definitions_Day",
      "components": {
        "Components": {
          "BlackoutCycleState": {
            "OnState": "Day",
            "OffState": "Night"
          }
        }
      },
      "rotation": 2
    },
    {
      "x": 0,
      "y": 14,
      "z": -3,
      "name": "BO_Pool_Surface00",
      "rotation": 2
    },
    {
      "x": 0,
      "y": 15,
      "z": -3,
      "name": "Build_Black_Cube"
    },
    {
      "x": 0,
      "y": 16,
      "z": -3,
      "name": "Soil_Dirt_Tilled",
      "components": {
        "Components": {
          "PlacedByInteraction": {
            "WhoPlacedUuid": {
              "$binary": "KMPE5JWxSQGC8WI/IkVLQQ==",
              "$type": "04"
            }
          },
          "TilledSoil": {
            "Version": 1,
            "DecayTime": "0001-01-02T22:44:51Z"
          }
        }
      }
    },
    {
      "x": 0,
      "y": 17,
      "z": -3,
      "name": "*Plant_Crop_Wheat_Block_Eternal_State_Definitions_StageFinal"
    },
    {
      "x": 0,
      "y": 0,
      "z": -2,
      "name": "BO_Pool_Surface00",
      "rotation": 4
    },
    {
      "x": 0,
      "y": 10,
      "z": -2,
      "name": "*BO_Lightsource_Cycle_State_Definitions_Day",
      "components": {
        "Components": {
          "BlackoutCycleState": {
            "OnState": "Day",
            "OffState": "Night"
          }
        }
      },
      "rotation": 2
    },
    {
      "x": 0,
      "y": 14,
      "z": -2,
      "name": "BO_Pool_Surface00",
      "rotation": 2
    },
    {
      "x": 0,
      "y": 15,
      "z": -2,
      "name": "Build_Black_Cube"
    },
    {
      "x": 0,
      "y": 16,
      "z": -2,
      "name": "Soil_Dirt_Tilled",
      "components": {
        "Components": {
          "PlacedByInteraction": {
            "WhoPlacedUuid": {
              "$binary": "KMPE5JWxSQGC8WI/IkVLQQ==",
              "$type": "04"
            }
          },
          "TilledSoil": {
            "Version": 1,
            "DecayTime": "0001-01-02T22:44:51Z"
          }
        }
      }
    },
    {
      "x": 0,
      "y": 17,
      "z": -2,
      "name": "*Plant_Crop_Wheat_Block_Eternal_State_Definitions_StageFinal"
    },
    {
      "x": 0,
      "y": 0,
      "z": -1,
      "name": "BO_Pool_Surface00",
      "rotation": 4
    },
    {
      "x": 0,
      "y": 10,
      "z": -1,
      "name": "*BO_Lightsource_Cycle_State_Definitions_Day",
      "components": {
        "Components": {
          "BlackoutCycleState": {
            "OnState": "Day",
            "OffState": "Night"
          }
        }
      },
      "rotation": 2
    },
    {
      "x": 0,
      "y": 14,
      "z": -1,
      "name": "BO_Pool_Surface00",
      "rotation": 2
    },
    {
      "x": 0,
      "y": 15,
      "z": -1,
      "name": "Build_Black_Cube"
    },
    {
      "x": 0,
      "y": 16,
      "z": -1,
      "name": "Soil_Dirt_Tilled",
      "components": {
        "Components": {
          "PlacedByInteraction": {
            "WhoPlacedUuid": {
              "$binary": "KMPE5JWxSQGC8WI/IkVLQQ==",
              "$type": "04"
            }
          },
          "TilledSoil": {
            "Version": 1,
            "DecayTime": "0001-01-02T22:44:51Z"
          }
        }
      }
    },
    {
      "x": 0,
      "y": 17,
      "z": -1,
      "name": "*Plant_Crop_Wheat_Block_Eternal_State_Definitions_StageFinal"
    },
    {
      "x": 0,
      "y": 0,
      "z": 0,
      "name": "BO_Pool_Surface00",
      "rotation": 4
    },
    {
      "x": 0,
      "y": 9,
      "z": 0,
      "name": "BO_Pool_Surface00",
      "rotation": 4
    },
    {
      "x": 0,
      "y": 10,
      "z": 0,
      "name": "*BO_Lightsource_Cycle_State_Definitions_Day",
      "components": {
        "Components": {
          "BlackoutCycleState": {
            "OnState": "Day",
            "OffState": "Night"
          }
        }
      },
      "rotation": 2
    },
    {
      "x": 0,
      "y": 14,
      "z": 0,
      "name": "BO_Pool_Surface00",
      "rotation": 2
    },
    {
      "x": 0,
      "y": 15,
      "z": 0,
      "name": "Build_Black_Cube"
    },
    {
      "x": 0,
      "y": 16,
      "z": 0,
      "name": "Soil_Dirt_Tilled",
      "components": {
        "Components": {
          "PlacedByInteraction": {
            "WhoPlacedUuid": {
              "$binary": "KMPE5JWxSQGC8WI/IkVLQQ==",
              "$type": "04"
            }
          },
          "TilledSoil": {
            "Version": 1,
            "DecayTime": "0001-01-02T22:44:51Z"
          }
        }
      }
    },
    {
      "x": 0,
      "y": 17,
      "z": 0,
      "name": "*Plant_Crop_Wheat_Block_Eternal_State_Definitions_StageFinal"
    },
    {
      "x": 0,
      "y": 0,
      "z": 1,
      "name": "BO_Pool_Surface00",
      "rotation": 4
    },
    {
      "x": 0,
      "y": 9,
      "z": 1,
      "name": "BO_Pool_Surface00",
      "rotation": 4
    },
    {
      "x": 0,
      "y": 10,
      "z": 1,
      "name": "*BO_Lightsource_Cycle_State_Definitions_Day",
      "components": {
        "Components": {
          "BlackoutCycleState": {
            "OnState": "Day",
            "OffState": "Night"
          }
        }
      },
      "rotation": 2
    },
    {
      "x": 0,
      "y": 14,
      "z": 1,
      "name": "BO_Pool_Surface00",
      "rotation": 2
    },
    {
      "x": 0,
      "y": 15,
      "z": 1,
      "name": "Build_Black_Cube"
    },
    {
      "x": 0,
      "y": 16,
      "z": 1,
      "name": "Soil_Dirt_Tilled",
      "components": {
        "Components": {
          "PlacedByInteraction": {
            "WhoPlacedUuid": {
              "$binary": "KMPE5JWxSQGC8WI/IkVLQQ==",
              "$type": "04"
            }
          },
          "TilledSoil": {
            "Version": 1,
            "DecayTime": "0001-01-02T22:44:51Z"
          }
        }
      }
    },
    {
      "x": 0,
      "y": 17,
      "z": 1,
      "name": "*Plant_Crop_Wheat_Block_Eternal_State_Definitions_StageFinal"
    },
    {
      "x": 0,
      "y": 0,
      "z": 2,
      "name": "BO_Pool_Surface00",
      "rotation": 4
    },
    {
      "x": 0,
      "y": 10,
      "z": 2,
      "name": "*BO_Lightsource_Cycle_State_Definitions_Day",
      "components": {
        "Components": {
          "BlackoutCycleState": {
            "OnState": "Day",
            "OffState": "Night"
          }
        }
      },
      "rotation": 2
    },
    {
      "x": 0,
      "y": 14,
      "z": 2,
      "name": "BO_Pool_Surface00",
      "rotation": 2
    },
    {
      "x": 0,
      "y": 15,
      "z": 2,
      "name": "Build_Black_Cube"
    },
    {
      "x": 0,
      "y": 16,
      "z": 2,
      "name": "Soil_Dirt_Tilled",
      "components": {
        "Components": {
          "PlacedByInteraction": {
            "WhoPlacedUuid": {
              "$binary": "KMPE5JWxSQGC8WI/IkVLQQ==",
              "$type": "04"
            }
          },
          "TilledSoil": {
            "Version": 1,
            "DecayTime": "0001-01-02T22:44:51Z"
          }
        }
      }
    },
    {
      "x": 0,
      "y": 17,
      "z": 2,
      "name": "*Plant_Crop_Wheat_Block_Eternal_State_Definitions_StageFinal"
    },
    {
      "x": 0,
      "y": 0,
      "z": 3,
      "name": "BO_Pool_Surface00",
      "rotation": 4
    },
    {
      "x": 0,
      "y": 10,
      "z": 3,
      "name": "*BO_Lightsource_Cycle_State_Definitions_Day",
      "components": {
        "Components": {
          "BlackoutCycleState": {
            "OnState": "Day",
            "OffState": "Night"
          }
        }
      },
      "rotation": 2
    },
    {
      "x": 0,
      "y": 14,
      "z": 3,
      "name": "BO_Pool_Surface00",
      "rotation": 2
    },
    {
      "x": 0,
      "y": 15,
      "z": 3,
      "name": "Build_Black_Cube"
    },
    {
      "x": 0,
      "y": 16,
      "z": 3,
      "name": "Soil_Dirt_Tilled",
      "components": {
        "Components": {
          "PlacedByInteraction": {
            "WhoPlacedUuid": {
              "$binary": "KMPE5JWxSQGC8WI/IkVLQQ==",
              "$type": "04"
            }
          },
          "TilledSoil": {
            "Version": 1,
            "DecayTime": "0001-01-02T22:44:51Z"
          }
        }
      }
    },
    {
      "x": 0,
      "y": 17,
      "z": 3,
      "name": "*Plant_Crop_Wheat_Block_Eternal_State_Definitions_StageFinal"
    },
    {
      "x": 0,
      "y": 0,
      "z": 4,
      "name": "BO_Pool_Surface00",
      "rotation": 4
    },
    {
      "x": 0,
      "y": 9,
      "z": 4,
      "name": "BO_Pool_Surface00",
      "rotation": 4
    },
    {
      "x": 0,
      "y": 10,
      "z": 4,
      "name": "*BO_Lightsource_Cycle_State_Definitions_Day",
      "components": {
        "Components": {
          "BlackoutCycleState": {
            "OnState": "Day",
            "OffState": "Night"
          }
        }
      },
      "rotation": 2
    },
    {
      "x": 0,
      "y": 14,
      "z": 4,
      "name": "BO_Pool_Surface00",
      "rotation": 2
    },
    {
      "x": 0,
      "y": 15,
      "z": 4,
      "name": "Build_Black_Cube"
    },
    {
      "x": 0,
      "y": 16,
      "z": 4,
      "name": "Soil_Dirt_Tilled",
      "components": {
        "Components": {
          "PlacedByInteraction": {
            "WhoPlacedUuid": {
              "$binary": "KMPE5JWxSQGC8WI/IkVLQQ==",
              "$type": "04"
            }
          },
          "TilledSoil": {
            "Version": 1,
            "DecayTime": "0001-01-02T22:44:51Z"
          }
        }
      }
    },
    {
      "x": 0,
      "y": 17,
      "z": 4,
      "name": "*Plant_Crop_Wheat_Block_Eternal_State_Definitions_StageFinal"
    },
    {
      "x": 0,
      "y": 0,
      "z": 5,
      "name": "BO_Pool_Surface00",
      "rotation": 4
    },
    {
      "x": 0,
      "y": 9,
      "z": 5,
      "name": "BO_Pool_Surface00",
      "rotation": 4
    },
    {
      "x": 0,
      "y": 10,
      "z": 5,
      "name": "*BO_Lightsource_Cycle_State_Definitions_Day",
      "components": {
        "Components": {
          "BlackoutCycleState": {
            "OnState": "Day",
            "OffState": "Night"
          }
        }
      },
      "rotation": 2
    },
    {
      "x": 0,
      "y": 14,
      "z": 5,
      "name": "BO_Pool_Surface00",
      "rotation": 2
    },
    {
      "x": 0,
      "y": 15,
      "z": 5,
      "name": "Build_Black_Cube"
    },
    {
      "x": 0,
      "y": 16,
      "z": 5,
      "name": "Soil_Dirt_Tilled",
      "components": {
        "Components": {
          "PlacedByInteraction": {
            "WhoPlacedUuid": {
              "$binary": "KMPE5JWxSQGC8WI/IkVLQQ==",
              "$type": "04"
            }
          },
          "TilledSoil": {
            "Version": 1,
            "DecayTime": "0001-01-02T22:44:51Z"
          }
        }
      }
    },
    {
      "x": 0,
      "y": 17,
      "z": 5,
      "name": "*Plant_Crop_Wheat_Block_Eternal_State_Definitions_StageFinal"
    },
    {
      "x": 1,
      "y": 0,
      "z": -4,
      "name": "BO_Pool_Surface00",
      "rotation": 4
    },
    {
      "x": 1,
      "y": 9,
      "z": -4,
      "name": "BO_Pool_Surface00",
      "rotation": 4
    },
    {
      "x": 1,
      "y": 10,
      "z": -4,
      "name": "*BO_Lightsource_Cycle_State_Definitions_Day",
      "components": {
        "Components": {
          "BlackoutCycleState": {
            "OnState": "Day",
            "OffState": "Night"
          }
        }
      },
      "rotation": 2
    },
    {
      "x": 1,
      "y": 14,
      "z": -4,
      "name": "BO_Pool_Surface00",
      "rotation": 2
    },
    {
      "x": 1,
      "y": 15,
      "z": -4,
      "name": "Build_Black_Cube"
    },
    {
      "x": 1,
      "y": 16,
      "z": -4,
      "name": "Soil_Dirt_Tilled",
      "components": {
        "Components": {
          "PlacedByInteraction": {
            "WhoPlacedUuid": {
              "$binary": "KMPE5JWxSQGC8WI/IkVLQQ==",
              "$type": "04"
            }
          },
          "TilledSoil": {
            "Version": 1,
            "DecayTime": "0001-01-02T22:44:51Z"
          }
        }
      }
    },
    {
      "x": 1,
      "y": 17,
      "z": -4,
      "name": "*Plant_Crop_Wheat_Block_Eternal_State_Definitions_StageFinal"
    },
    {
      "x": 1,
      "y": 0,
      "z": -3,
      "name": "BO_Pool_Surface00",
      "rotation": 4
    },
    {
      "x": 1,
      "y": 9,
      "z": -3,
      "name": "BO_Pool_Surface00",
      "rotation": 4
    },
    {
      "x": 1,
      "y": 10,
      "z": -3,
      "name": "*BO_Lightsource_Cycle_State_Definitions_Day",
      "components": {
        "Components": {
          "BlackoutCycleState": {
            "OnState": "Day",
            "OffState": "Night"
          }
        }
      },
      "rotation": 2
    },
    {
      "x": 1,
      "y": 14,
      "z": -3,
      "name": "BO_Pool_Surface00",
      "rotation": 2
    },
    {
      "x": 1,
      "y": 15,
      "z": -3,
      "name": "Build_Black_Cube"
    },
    {
      "x": 1,
      "y": 16,
      "z": -3,
      "name": "Soil_Dirt_Tilled",
      "components": {
        "Components": {
          "PlacedByInteraction": {
            "WhoPlacedUuid": {
              "$binary": "KMPE5JWxSQGC8WI/IkVLQQ==",
              "$type": "04"
            }
          },
          "TilledSoil": {
            "Version": 1,
            "DecayTime": "0001-01-02T22:44:51Z"
          }
        }
      }
    },
    {
      "x": 1,
      "y": 17,
      "z": -3,
      "name": "*Plant_Crop_Wheat_Block_Eternal_State_Definitions_StageFinal"
    },
    {
      "x": 1,
      "y": 0,
      "z": -2,
      "name": "BO_Pool_Surface00",
      "rotation": 4
    },
    {
      "x": 1,
      "y": 10,
      "z": -2,
      "name": "*BO_Lightsource_Cycle_State_Definitions_Day",
      "components": {
        "Components": {
          "BlackoutCycleState": {
            "OnState": "Day",
            "OffState": "Night"
          }
        }
      },
      "rotation": 2
    },
    {
      "x": 1,
      "y": 14,
      "z": -2,
      "name": "BO_Pool_Surface00",
      "rotation": 2
    },
    {
      "x": 1,
      "y": 15,
      "z": -2,
      "name": "Build_Black_Cube"
    },
    {
      "x": 1,
      "y": 16,
      "z": -2,
      "name": "Soil_Dirt_Tilled",
      "components": {
        "Components": {
          "PlacedByInteraction": {
            "WhoPlacedUuid": {
              "$binary": "KMPE5JWxSQGC8WI/IkVLQQ==",
              "$type": "04"
            }
          },
          "TilledSoil": {
            "Version": 1,
            "DecayTime": "0001-01-02T22:44:51Z"
          }
        }
      }
    },
    {
      "x": 1,
      "y": 17,
      "z": -2,
      "name": "*Plant_Crop_Wheat_Block_Eternal_State_Definitions_StageFinal"
    },
    {
      "x": 1,
      "y": 0,
      "z": -1,
      "name": "BO_Pool_Surface00",
      "rotation": 4
    },
    {
      "x": 1,
      "y": 10,
      "z": -1,
      "name": "*BO_Lightsource_Cycle_State_Definitions_Day",
      "components": {
        "Components": {
          "BlackoutCycleState": {
            "OnState": "Day",
            "OffState": "Night"
          }
        }
      },
      "rotation": 2
    },
    {
      "x": 1,
      "y": 14,
      "z": -1,
      "name": "BO_Pool_Surface00",
      "rotation": 2
    },
    {
      "x": 1,
      "y": 15,
      "z": -1,
      "name": "Build_Black_Cube"
    },
    {
      "x": 1,
      "y": 16,
      "z": -1,
      "name": "Soil_Dirt_Tilled",
      "components": {
        "Components": {
          "PlacedByInteraction": {
            "WhoPlacedUuid": {
              "$binary": "KMPE5JWxSQGC8WI/IkVLQQ==",
              "$type": "04"
            }
          },
          "TilledSoil": {
            "Version": 1,
            "DecayTime": "0001-01-02T22:44:51Z"
          }
        }
      }
    },
    {
      "x": 1,
      "y": 17,
      "z": -1,
      "name": "*Plant_Crop_Wheat_Block_Eternal_State_Definitions_StageFinal"
    },
    {
      "x": 1,
      "y": 0,
      "z": 0,
      "name": "BO_Pool_Surface00",
      "rotation": 4
    },
    {
      "x": 1,
      "y": 9,
      "z": 0,
      "name": "BO_Pool_Surface00",
      "rotation": 4
    },
    {
      "x": 1,
      "y": 10,
      "z": 0,
      "name": "*BO_Lightsource_Cycle_State_Definitions_Day",
      "components": {
        "Components": {
          "BlackoutCycleState": {
            "OnState": "Day",
            "OffState": "Night"
          }
        }
      },
      "rotation": 2
    },
    {
      "x": 1,
      "y": 14,
      "z": 0,
      "name": "BO_Pool_Surface00",
      "rotation": 2
    },
    {
      "x": 1,
      "y": 15,
      "z": 0,
      "name": "Build_Black_Cube"
    },
    {
      "x": 1,
      "y": 16,
      "z": 0,
      "name": "Soil_Dirt_Tilled",
      "components": {
        "Components": {
          "PlacedByInteraction": {
            "WhoPlacedUuid": {
              "$binary": "KMPE5JWxSQGC8WI/IkVLQQ==",
              "$type": "04"
            }
          },
          "TilledSoil": {
            "Version": 1,
            "DecayTime": "0001-01-02T22:44:51Z"
          }
        }
      }
    },
    {
      "x": 1,
      "y": 17,
      "z": 0,
      "name": "*Plant_Crop_Wheat_Block_Eternal_State_Definitions_StageFinal"
    },
    {
      "x": 1,
      "y": 0,
      "z": 1,
      "name": "BO_Pool_Surface00",
      "rotation": 4
    },
    {
      "x": 1,
      "y": 9,
      "z": 1,
      "name": "BO_Pool_Surface00",
      "rotation": 4
    },
    {
      "x": 1,
      "y": 10,
      "z": 1,
      "name": "*BO_Lightsource_Cycle_State_Definitions_Day",
      "components": {
        "Components": {
          "BlackoutCycleState": {
            "OnState": "Day",
            "OffState": "Night"
          }
        }
      },
      "rotation": 2
    },
    {
      "x": 1,
      "y": 14,
      "z": 1,
      "name": "BO_Pool_Surface00",
      "rotation": 2
    },
    {
      "x": 1,
      "y": 15,
      "z": 1,
      "name": "Build_Black_Cube"
    },
    {
      "x": 1,
      "y": 16,
      "z": 1,
      "name": "Soil_Dirt_Tilled",
      "components": {
        "Components": {
          "PlacedByInteraction": {
            "WhoPlacedUuid": {
              "$binary": "KMPE5JWxSQGC8WI/IkVLQQ==",
              "$type": "04"
            }
          },
          "TilledSoil": {
            "Version": 1,
            "DecayTime": "0001-01-02T22:44:51Z"
          }
        }
      }
    },
    {
      "x": 1,
      "y": 17,
      "z": 1,
      "name": "*Plant_Crop_Wheat_Block_Eternal_State_Definitions_StageFinal"
    },
    {
      "x": 1,
      "y": 0,
      "z": 2,
      "name": "BO_Pool_Surface00",
      "rotation": 4
    },
    {
      "x": 1,
      "y": 10,
      "z": 2,
      "name": "*BO_Lightsource_Cycle_State_Definitions_Day",
      "components": {
        "Components": {
          "BlackoutCycleState": {
            "OnState": "Day",
            "OffState": "Night"
          }
        }
      },
      "rotation": 2
    },
    {
      "x": 1,
      "y": 14,
      "z": 2,
      "name": "BO_Pool_Surface00",
      "rotation": 2
    },
    {
      "x": 1,
      "y": 15,
      "z": 2,
      "name": "Build_Black_Cube"
    },
    {
      "x": 1,
      "y": 16,
      "z": 2,
      "name": "Soil_Dirt_Tilled",
      "components": {
        "Components": {
          "PlacedByInteraction": {
            "WhoPlacedUuid": {
              "$binary": "KMPE5JWxSQGC8WI/IkVLQQ==",
              "$type": "04"
            }
          },
          "TilledSoil": {
            "Version": 1,
            "DecayTime": "0001-01-02T22:44:51Z"
          }
        }
      }
    },
    {
      "x": 1,
      "y": 17,
      "z": 2,
      "name": "*Plant_Crop_Wheat_Block_Eternal_State_Definitions_StageFinal"
    },
    {
      "x": 1,
      "y": 0,
      "z": 3,
      "name": "BO_Pool_Surface00",
      "rotation": 4
    },
    {
      "x": 1,
      "y": 10,
      "z": 3,
      "name": "*BO_Lightsource_Cycle_State_Definitions_Day",
      "components": {
        "Components": {
          "BlackoutCycleState": {
            "OnState": "Day",
            "OffState": "Night"
          }
        }
      },
      "rotation": 2
    },
    {
      "x": 1,
      "y": 14,
      "z": 3,
      "name": "BO_Pool_Surface00",
      "rotation": 2
    },
    {
      "x": 1,
      "y": 15,
      "z": 3,
      "name": "Build_Black_Cube"
    },
    {
      "x": 1,
      "y": 16,
      "z": 3,
      "name": "Soil_Dirt_Tilled",
      "components": {
        "Components": {
          "PlacedByInteraction": {
            "WhoPlacedUuid": {
              "$binary": "KMPE5JWxSQGC8WI/IkVLQQ==",
              "$type": "04"
            }
          },
          "TilledSoil": {
            "Version": 1,
            "DecayTime": "0001-01-02T22:44:51Z"
          }
        }
      }
    },
    {
      "x": 1,
      "y": 17,
      "z": 3,
      "name": "*Plant_Crop_Wheat_Block_Eternal_State_Definitions_StageFinal"
    },
    {
      "x": 1,
      "y": 0,
      "z": 4,
      "name": "BO_Pool_Surface00",
      "rotation": 4
    },
    {
      "x": 1,
      "y": 9,
      "z": 4,
      "name": "BO_Pool_Surface00",
      "rotation": 4
    },
    {
      "x": 1,
      "y": 10,
      "z": 4,
      "name": "*BO_Lightsource_Cycle_State_Definitions_Day",
      "components": {
        "Components": {
          "BlackoutCycleState": {
            "OnState": "Day",
            "OffState": "Night"
          }
        }
      },
      "rotation": 2
    },
    {
      "x": 1,
      "y": 14,
      "z": 4,
      "name": "BO_Pool_Surface00",
      "rotation": 2
    },
    {
      "x": 1,
      "y": 15,
      "z": 4,
      "name": "Build_Black_Cube"
    },
    {
      "x": 1,
      "y": 16,
      "z": 4,
      "name": "Soil_Dirt_Tilled",
      "components": {
        "Components": {
          "PlacedByInteraction": {
            "WhoPlacedUuid": {
              "$binary": "KMPE5JWxSQGC8WI/IkVLQQ==",
              "$type": "04"
            }
          },
          "TilledSoil": {
            "Version": 1,
            "DecayTime": "0001-01-02T22:44:51Z"
          }
        }
      }
    },
    {
      "x": 1,
      "y": 17,
      "z": 4,
      "name": "*Plant_Crop_Wheat_Block_Eternal_State_Definitions_StageFinal"
    },
    {
      "x": 1,
      "y": 0,
      "z": 5,
      "name": "BO_Pool_Surface00",
      "rotation": 4
    },
    {
      "x": 1,
      "y": 9,
      "z": 5,
      "name": "BO_Pool_Surface00",
      "rotation": 4
    },
    {
      "x": 1,
      "y": 10,
      "z": 5,
      "name": "*BO_Lightsource_Cycle_State_Definitions_Day",
      "components": {
        "Components": {
          "BlackoutCycleState": {
            "OnState": "Day",
            "OffState": "Night"
          }
        }
      },
      "rotation": 2
    },
    {
      "x": 1,
      "y": 14,
      "z": 5,
      "name": "BO_Pool_Surface00",
      "rotation": 2
    },
    {
      "x": 1,
      "y": 15,
      "z": 5,
      "name": "Build_Black_Cube"
    },
    {
      "x": 1,
      "y": 16,
      "z": 5,
      "name": "Soil_Dirt_Tilled",
      "components": {
        "Components": {
          "PlacedByInteraction": {
            "WhoPlacedUuid": {
              "$binary": "KMPE5JWxSQGC8WI/IkVLQQ==",
              "$type": "04"
            }
          },
          "TilledSoil": {
            "Version": 1,
            "DecayTime": "0001-01-02T22:44:51Z"
          }
        }
      }
    },
    {
      "x": 1,
      "y": 17,
      "z": 5,
      "name": "*Plant_Crop_Wheat_Block_Eternal_State_Definitions_StageFinal"
    },
    {
      "x": 2,
      "y": 0,
      "z": -4,
      "name": "BO_Pool_Surface00",
      "rotation": 4
    },
    {
      "x": 2,
      "y": 9,
      "z": -4,
      "name": "BO_Pool_Surface00",
      "rotation": 4
    },
    {
      "x": 2,
      "y": 10,
      "z": -4,
      "name": "*BO_Lightsource_Cycle_State_Definitions_Day",
      "components": {
        "Components": {
          "BlackoutCycleState": {
            "OnState": "Day",
            "OffState": "Night"
          }
        }
      },
      "rotation": 2
    },
    {
      "x": 2,
      "y": 14,
      "z": -4,
      "name": "BO_Pool_Surface00",
      "rotation": 2
    },
    {
      "x": 2,
      "y": 15,
      "z": -4,
      "name": "Build_Black_Cube"
    },
    {
      "x": 2,
      "y": 16,
      "z": -4,
      "name": "Soil_Dirt_Tilled",
      "components": {
        "Components": {
          "PlacedByInteraction": {
            "WhoPlacedUuid": {
              "$binary": "KMPE5JWxSQGC8WI/IkVLQQ==",
              "$type": "04"
            }
          },
          "TilledSoil": {
            "Version": 1,
            "DecayTime": "0001-01-02T22:44:51Z"
          }
        }
      }
    },
    {
      "x": 2,
      "y": 17,
      "z": -4,
      "name": "*Plant_Crop_Wheat_Block_Eternal_State_Definitions_StageFinal"
    },
    {
      "x": 2,
      "y": 0,
      "z": -3,
      "name": "BO_Pool_Surface00",
      "rotation": 4
    },
    {
      "x": 2,
      "y": 9,
      "z": -3,
      "name": "BO_Pool_Surface00",
      "rotation": 4
    },
    {
      "x": 2,
      "y": 10,
      "z": -3,
      "name": "*BO_Lightsource_Cycle_State_Definitions_Day",
      "components": {
        "Components": {
          "BlackoutCycleState": {
            "OnState": "Day",
            "OffState": "Night"
          }
        }
      },
      "rotation": 2
    },
    {
      "x": 2,
      "y": 14,
      "z": -3,
      "name": "BO_Pool_Surface00",
      "rotation": 2
    },
    {
      "x": 2,
      "y": 15,
      "z": -3,
      "name": "Build_Black_Cube"
    },
    {
      "x": 2,
      "y": 16,
      "z": -3,
      "name": "Soil_Dirt_Tilled",
      "components": {
        "Components": {
          "PlacedByInteraction": {
            "WhoPlacedUuid": {
              "$binary": "KMPE5JWxSQGC8WI/IkVLQQ==",
              "$type": "04"
            }
          },
          "TilledSoil": {
            "Version": 1,
            "DecayTime": "0001-01-02T22:44:51Z"
          }
        }
      }
    },
    {
      "x": 2,
      "y": 17,
      "z": -3,
      "name": "*Plant_Crop_Wheat_Block_Eternal_State_Definitions_StageFinal"
    },
    {
      "x": 2,
      "y": 0,
      "z": -2,
      "name": "BO_Pool_Surface00",
      "rotation": 4
    },
    {
      "x": 2,
      "y": 9,
      "z": -2,
      "name": "BO_Pool_Surface00",
      "rotation": 4
    },
    {
      "x": 2,
      "y": 10,
      "z": -2,
      "name": "*BO_Lightsource_Cycle_State_Definitions_Day",
      "components": {
        "Components": {
          "BlackoutCycleState": {
            "OnState": "Day",
            "OffState": "Night"
          }
        }
      },
      "rotation": 2
    },
    {
      "x": 2,
      "y": 14,
      "z": -2,
      "name": "BO_Pool_Surface00",
      "rotation": 2
    },
    {
      "x": 2,
      "y": 15,
      "z": -2,
      "name": "Build_Black_Cube"
    },
    {
      "x": 2,
      "y": 16,
      "z": -2,
      "name": "Soil_Dirt_Tilled",
      "components": {
        "Components": {
          "PlacedByInteraction": {
            "WhoPlacedUuid": {
              "$binary": "KMPE5JWxSQGC8WI/IkVLQQ==",
              "$type": "04"
            }
          },
          "TilledSoil": {
            "Version": 1,
            "DecayTime": "0001-01-02T22:44:51Z"
          }
        }
      }
    },
    {
      "x": 2,
      "y": 17,
      "z": -2,
      "name": "*Plant_Crop_Wheat_Block_Eternal_State_Definitions_StageFinal"
    },
    {
      "x": 2,
      "y": 0,
      "z": -1,
      "name": "BO_Pool_Surface00",
      "rotation": 4
    },
    {
      "x": 2,
      "y": 9,
      "z": -1,
      "name": "BO_Pool_Surface00",
      "rotation": 4
    },
    {
      "x": 2,
      "y": 10,
      "z": -1,
      "name": "*BO_Lightsource_Cycle_State_Definitions_Day",
      "components": {
        "Components": {
          "BlackoutCycleState": {
            "OnState": "Day",
            "OffState": "Night"
          }
        }
      },
      "rotation": 2
    },
    {
      "x": 2,
      "y": 14,
      "z": -1,
      "name": "BO_Pool_Surface00",
      "rotation": 2
    },
    {
      "x": 2,
      "y": 15,
      "z": -1,
      "name": "Build_Black_Cube"
    },
    {
      "x": 2,
      "y": 16,
      "z": -1,
      "name": "Soil_Dirt_Tilled",
      "components": {
