{
  "version": 8,
  "blockIdVersion": 11,
  "anchorX": 0,
  "anchorY": 0,
  "anchorZ": 0,
  "blocks": [
    {
      "x": -4,
      "y": 0,
      "z": -9,
      "name": "BO_Parking_Blacktop",
      "rotation": 7
    },
    {
      "x": -4,
      "y": 1,
      "z": -9,
      "name": "BO_Parking_Blacktop",
      "rotation": 7
    },
    {
      "x": -4,
      "y": 2,
      "z": -9,
      "name": "BO_Parking_Blacktop",
      "rotation": 7
    },
    {
      "x": -4,
      "y": 3,
      "z": -9,
      "name": "BO_Parking_Blacktop",
      "rotation": 7
    },
    {
      "x": -4,
      "y": 4,
      "z": -9,
      "name": "BO_Parking_Wall00",
      "rotation": 3
    },
    {
      "x": -4,
      "y": 5,
      "z": -9,
      "name": "BO_Parking_Wall02",
      "rotation": 3
    },
    {
      "x": -4,
      "y": 6,
      "z": -9,
      "name": "BO_Parking_Wall00",
      "rotation": 3
    },
    {
      "x": -4,
      "y": 7,
      "z": -9,
      "name": "BO_Parking_Wall00",
      "rotation": 3
    },
    {
      "x": -4,
      "y": 8,
      "z": -9,
      "name": "BO_Parking_Wall00",
      "rotation": 3
    },
    {
      "x": -4,
      "y": 9,
      "z": -9,
      "name": "BO_Parking_Wall00",
      "rotation": 3
    },
    {
      "x": -4,
      "y": 10,
      "z": -9,
      "name": "BO_Parking_Wall00",
      "rotation": 3
    },
    {
      "x": -4,
      "y": 0,
      "z": -8,
      "name": "BO_Parking_Blacktop",
      "rotation": 7
    },
    {
      "x": -4,
      "y": 1,
      "z": -8,
      "name": "BO_Parking_Blacktop",
      "rotation": 7
    },
    {
      "x": -4,
      "y": 2,
      "z": -8,
      "name": "BO_Parking_Blacktop",
      "rotation": 7
    },
    {
      "x": -4,
      "y": 3,
      "z": -8,
      "name": "BO_Parking_Blacktop",
      "rotation": 7
    },
    {
      "x": -4,
      "y": 9,
      "z": -8,
      "name": "BO_Parking_Wall03",
      "rotation": 3
    },
    {
      "x": -4,
      "y": 10,
      "z": -8,
      "name": "BO_Parking_Wall00",
      "rotation": 3
    },
    {
      "x": -4,
      "y": 11,
      "z": -8,
      "name": "Build_Black_Cube",
      "rotation": 3
    },
    {
      "x": -4,
      "y": 0,
      "z": -7,
      "name": "BO_Parking_Blacktop",
      "rotation": 7
    },
    {
      "x": -4,
      "y": 1,
      "z": -7,
      "name": "BO_Parking_Blacktop",
      "rotation": 7
    },
    {
      "x": -4,
      "y": 2,
      "z": -7,
      "name": "BO_Parking_Blacktop",
      "rotation": 7
    },
    {
      "x": -4,
      "y": 3,
      "z": -7,
      "name": "BO_Parking_Blacktop",
      "rotation": 7
    },
    {
      "x": -4,
      "y": 9,
      "z": -7,
      "name": "BO_Parking_Wall03",
      "rotation": 3
    },
    {
      "x": -4,
      "y": 10,
      "z": -7,
      "name": "BO_Parking_Wall00",
      "rotation": 3
    },
    {
      "x": -4,
      "y": 0,
      "z": -6,
      "name": "BO_Parking_Blacktop",
      "rotation": 7
    },
    {
      "x": -4,
      "y": 1,
      "z": -6,
      "name": "BO_Parking_Blacktop",
      "rotation": 7
    },
    {
      "x": -4,
      "y": 2,
      "z": -6,
      "name": "BO_Parking_Blacktop",
      "rotation": 7
    },
    {
      "x": -4,
      "y": 3,
      "z": -6,
      "name": "BO_Parking_Blacktop",
      "rotation": 7
    },
    {
      "x": -4,
      "y": 9,
      "z": -6,
      "name": "BO_Parking_Wall03",
      "rotation": 3
    },
    {
      "x": -4,
      "y": 10,
      "z": -6,
      "name": "BO_Parking_Wall00",
      "rotation": 3
    },
    {
      "x": -4,
      "y": 0,
      "z": -5,
      "name": "BO_Parking_Blacktop",
      "rotation": 7
    },
    {
      "x": -4,
      "y": 1,
      "z": -5,
      "name": "BO_Parking_Blacktop",
      "rotation": 7
    },
    {
      "x": -4,
      "y": 2,
      "z": -5,
      "name": "BO_Parking_Blacktop",
      "rotation": 7
    },
    {
      "x": -4,
      "y": 3,
      "z": -5,
      "name": "BO_Parking_Blacktop",
      "rotation": 3
    },
    {
      "x": -4,
      "y": 9,
      "z": -5,
      "name": "BO_Parking_Wall03",
      "rotation": 3
    },
    {
      "x": -4,
      "y": 10,
      "z": -5,
      "name": "BO_Parking_Wall00",
      "rotation": 3
    },
    {
      "x": -4,
      "y": 0,
      "z": -4,
      "name": "BO_Parking_Blacktop",
      "rotation": 7
    },
    {
      "x": -4,
      "y": 1,
      "z": -4,
      "name": "BO_Parking_Blacktop",
      "rotation": 7
    },
    {
      "x": -4,
      "y": 2,
      "z": -4,
      "name": "BO_Parking_Blacktop",
      "rotation": 7
    },
    {
      "x": -4,
      "y": 3,
      "z": -4,
      "name": "BO_Parking_Blacktop",
      "rotation": 2
    },
    {
      "x": -4,
      "y": 9,
      "z": -4,
      "name": "BO_Parking_Wall03",
      "rotation": 3
    },
    {
      "x": -4,
      "y": 10,
      "z": -4,
      "name": "BO_Parking_Wall00",
      "rotation": 3
    },
    {
      "x": -4,
      "y": 0,
      "z": -3,
      "name": "BO_Parking_Blacktop",
      "rotation": 7
    },
    {
      "x": -4,
      "y": 1,
      "z": -3,
      "name": "BO_Parking_Blacktop",
      "rotation": 7
    },
    {
      "x": -4,
      "y": 2,
      "z": -3,
      "name": "BO_Parking_Blacktop",
      "rotation": 7
    },
    {
      "x": -4,
      "y": 3,
      "z": -3,
      "name": "BO_Parking_Blacktop",
      "rotation": 2
    },
    {
      "x": -4,
      "y": 9,
      "z": -3,
      "name": "BO_Parking_Wall03",
      "rotation": 3
    },
    {
      "x": -4,
      "y": 10,
      "z": -3,
      "name": "BO_Parking_Wall00",
      "rotation": 3
    },
    {
      "x": -4,
      "y": 0,
      "z": -2,
      "name": "BO_Parking_Blacktop",
      "rotation": 7
    },
    {
      "x": -4,
      "y": 1,
      "z": -2,
      "name": "BO_Parking_Blacktop",
      "rotation": 7
    },
    {
      "x": -4,
      "y": 2,
      "z": -2,
      "name": "BO_Parking_Blacktop",
      "rotation": 7
    },
    {
      "x": -4,
      "y": 3,
      "z": -2,
      "name": "BO_Parking_Blacktop",
      "rotation": 7
    },
    {
      "x": -4,
      "y": 9,
      "z": -2,
      "name": "BO_Parking_Wall03",
      "rotation": 3
    },
    {
      "x": -4,
      "y": 10,
      "z": -2,
      "name": "BO_Parking_Wall00",
      "rotation": 3
    },
    {
      "x": -4,
      "y": 0,
      "z": -1,
      "name": "BO_Parking_Blacktop",
      "rotation": 7
    },
    {
      "x": -4,
      "y": 1,
      "z": -1,
      "name": "BO_Parking_Blacktop",
      "rotation": 7
    },
    {
      "x": -4,
      "y": 2,
      "z": -1,
      "name": "BO_Parking_Blacktop",
      "rotation": 7
    },
    {
      "x": -4,
      "y": 3,
      "z": -1,
      "name": "BO_Parking_Blacktop",
      "rotation": 7
    },
    {
      "x": -4,
      "y": 9,
      "z": -1,
      "name": "BO_Parking_Wall03",
      "rotation": 3
    },
    {
      "x": -4,
      "y": 10,
      "z": -1,
      "name": "BO_Parking_Wall00",
      "rotation": 3
    },
    {
      "x": -4,
      "y": 11,
      "z": -1,
      "name": "Build_Black_Cube",
      "rotation": 3
    },
    {
      "x": -4,
      "y": 0,
      "z": 0,
      "name": "BO_Parking_Blacktop",
      "rotation": 7
    },
    {
      "x": -4,
      "y": 1,
      "z": 0,
      "name": "BO_Parking_Blacktop",
      "rotation": 7
    },
    {
      "x": -4,
      "y": 2,
      "z": 0,
      "name": "BO_Parking_Blacktop",
      "rotation": 7
    },
    {
      "x": -4,
      "y": 3,
      "z": 0,
      "name": "BO_Parking_Blacktop",
      "rotation": 7
    },
    {
      "x": -4,
      "y": 4,
      "z": 0,
      "name": "BO_Parking_Wall00",
      "rotation": 3
    },
    {
      "x": -4,
      "y": 5,
      "z": 0,
      "name": "BO_Parking_Wall02",
      "rotation": 3
    },
    {
      "x": -4,
      "y": 6,
      "z": 0,
      "name": "BO_Parking_Wall00",
      "rotation": 3
    },
    {
      "x": -4,
      "y": 7,
      "z": 0,
      "name": "BO_Parking_Wall00",
      "rotation": 3
    },
    {
      "x": -4,
      "y": 8,
      "z": 0,
      "name": "BO_Parking_Wall00",
      "rotation": 3
    },
    {
      "x": -4,
      "y": 9,
      "z": 0,
      "name": "BO_Parking_Wall00",
      "rotation": 3
    },
    {
      "x": -4,
      "y": 10,
      "z": 0,
      "name": "BO_Parking_Wall00",
      "rotation": 3
    },
    {
      "x": -4,
      "y": 0,
      "z": 1,
      "name": "BO_Parking_Blacktop",
      "rotation": 7
    },
    {
      "x": -4,
      "y": 1,
      "z": 1,
      "name": "BO_Parking_Blacktop",
      "rotation": 7
    },
    {
      "x": -4,
      "y": 2,
      "z": 1,
      "name": "BO_Parking_Blacktop",
      "rotation": 7
    },
    {
      "x": -4,
      "y": 3,
      "z": 1,
      "name": "BO_Parking_Blacktop",
      "rotation": 7
    },
    {
      "x": -4,
      "y": 4,
      "z": 1,
      "name": "BO_Parking_Wall00",
      "rotation": 3
    },
    {
      "x": -4,
      "y": 5,
      "z": 1,
      "name": "BO_Parking_Wall02",
      "rotation": 3
    },
    {
      "x": -4,
      "y": 6,
      "z": 1,
      "name": "BO_Parking_Wall00",
      "rotation": 3
    },
    {
      "x": -4,
      "y": 7,
      "z": 1,
      "name": "BO_Parking_Wall00",
      "rotation": 3
    },
    {
      "x": -4,
      "y": 8,
      "z": 1,
      "name": "BO_Parking_Wall00",
      "rotation": 3
    },
    {
      "x": -4,
      "y": 9,
      "z": 1,
      "name": "BO_Parking_Wall00",
      "rotation": 3
    },
    {
      "x": -4,
      "y": 10,
      "z": 1,
      "name": "BO_Parking_Wall00",
      "rotation": 3
    },
    {
      "x": -4,
      "y": 0,
      "z": 2,
      "name": "BO_Parking_Blacktop",
      "rotation": 7
    },
    {
      "x": -4,
      "y": 1,
      "z": 2,
      "name": "BO_Parking_Blacktop",
      "rotation": 7
    },
    {
      "x": -4,
      "y": 2,
      "z": 2,
      "name": "BO_Parking_Blacktop",
      "rotation": 7
    },
    {
      "x": -4,
      "y": 3,
      "z": 2,
      "name": "BO_Parking_Blacktop",
      "rotation": 7
    },
    {
      "x": -4,
      "y": 9,
      "z": 2,
      "name": "BO_Parking_Wall03",
      "rotation": 3
    },
    {
      "x": -4,
      "y": 10,
      "z": 2,
      "name": "BO_Parking_Wall00",
      "rotation": 3
    },
    {
      "x": -4,
      "y": 11,
      "z": 2,
      "name": "Build_Black_Cube",
      "rotation": 3
    },
    {
      "x": -4,
      "y": 0,
      "z": 3,
      "name": "BO_Parking_Blacktop",
      "rotation": 7
    },
    {
      "x": -4,
      "y": 1,
      "z": 3,
      "name": "BO_Parking_Blacktop",
      "rotation": 7
    },
    {
      "x": -4,
      "y": 2,
      "z": 3,
      "name": "BO_Parking_Blacktop",
      "rotation": 7
    },
    {
      "x": -4,
      "y": 3,
      "z": 3,
      "name": "BO_Parking_Blacktop",
      "rotation": 3
    },
    {
      "x": -4,
      "y": 9,
      "z": 3,
      "name": "BO_Parking_Wall03",
      "rotation": 3
    },
    {
      "x": -4,
      "y": 10,
      "z": 3,
      "name": "BO_Parking_Wall00",
      "rotation": 3
    },
    {
      "x": -4,
      "y": 0,
      "z": 4,
      "name": "BO_Parking_Blacktop",
      "rotation": 7
    },
    {
      "x": -4,
      "y": 1,
      "z": 4,
      "name": "BO_Parking_Blacktop",
      "rotation": 7
    },
    {
      "x": -4,
      "y": 2,
      "z": 4,
      "name": "BO_Parking_Blacktop",
      "rotation": 7
    },
    {
      "x": -4,
      "y": 3,
      "z": 4,
      "name": "BO_Parking_Blacktop",
      "rotation": 7
    },
    {
      "x": -4,
      "y": 9,
      "z": 4,
      "name": "BO_Parking_Wall03",
      "rotation": 3
    },
    {
      "x": -4,
      "y": 10,
      "z": 4,
      "name": "BO_Parking_Wall00",
      "rotation": 3
    },
    {
      "x": -4,
      "y": 0,
      "z": 5,
      "name": "BO_Parking_Blacktop",
      "rotation": 7
    },
    {
      "x": -4,
      "y": 1,
      "z": 5,
      "name": "BO_Parking_Blacktop",
      "rotation": 7
    },
    {
      "x": -4,
      "y": 2,
      "z": 5,
      "name": "BO_Parking_Blacktop",
      "rotation": 7
    },
    {
      "x": -4,
      "y": 3,
      "z": 5,
      "name": "BO_Parking_Blacktop",
      "rotation": 7
    },
    {
      "x": -4,
      "y": 9,
      "z": 5,
      "name": "BO_Parking_Wall03",
      "rotation": 3
    },
    {
      "x": -4,
      "y": 10,
      "z": 5,
      "name": "BO_Parking_Wall00",
      "rotation": 3
    },
    {
      "x": -4,
      "y": 0,
      "z": 6,
      "name": "BO_Parking_Blacktop",
      "rotation": 7
    },
    {
      "x": -4,
      "y": 1,
      "z": 6,
      "name": "BO_Parking_Blacktop",
      "rotation": 7
    },
    {
      "x": -4,
      "y": 2,
      "z": 6,
      "name": "BO_Parking_Blacktop",
      "rotation": 7
    },
    {
      "x": -4,
      "y": 3,
      "z": 6,
      "name": "BO_Parking_Blacktop",
      "rotation": 7
    },
    {
      "x": -4,
      "y": 9,
      "z": 6,
      "name": "BO_Parking_Wall03",
      "rotation": 3
    },
    {
      "x": -4,
      "y": 10,
      "z": 6,
      "name": "BO_Parking_Wall00",
      "rotation": 3
    },
    {
      "x": -4,
      "y": 0,
      "z": 7,
      "name": "BO_Parking_Blacktop",
      "rotation": 7
    },
    {
      "x": -4,
      "y": 1,
      "z": 7,
      "name": "BO_Parking_Blacktop",
      "rotation": 7
    },
    {
      "x": -4,
      "y": 2,
      "z": 7,
      "name": "BO_Parking_Blacktop",
      "rotation": 7
    },
    {
      "x": -4,
      "y": 3,
      "z": 7,
      "name": "BO_Parking_Blacktop",
      "rotation": 3
    },
    {
      "x": -4,
      "y": 9,
      "z": 7,
      "name": "BO_Parking_Wall03",
      "rotation": 3
    },
    {
      "x": -4,
      "y": 10,
      "z": 7,
      "name": "BO_Parking_Wall00",
      "rotation": 3
    },
    {
      "x": -4,
      "y": 0,
      "z": 8,
      "name": "BO_Parking_Blacktop",
      "rotation": 7
    },
    {
      "x": -4,
      "y": 1,
      "z": 8,
      "name": "BO_Parking_Blacktop",
      "rotation": 7
    },
    {
      "x": -4,
      "y": 2,
      "z": 8,
      "name": "BO_Parking_Blacktop",
      "rotation": 7
    },
    {
      "x": -4,
      "y": 3,
      "z": 8,
      "name": "BO_Parking_Blacktop",
      "rotation": 7
    },
    {
      "x": -4,
      "y": 9,
      "z": 8,
      "name": "BO_Parking_Wall03",
      "rotation": 3
    },
    {
      "x": -4,
      "y": 10,
      "z": 8,
      "name": "BO_Parking_Wall00",
      "rotation": 3
    },
    {
      "x": -4,
      "y": 0,
      "z": 9,
      "name": "BO_Parking_Blacktop",
      "rotation": 7
    },
    {
      "x": -4,
      "y": 1,
      "z": 9,
      "name": "BO_Parking_Blacktop",
      "rotation": 7
    },
    {
      "x": -4,
      "y": 2,
      "z": 9,
      "name": "BO_Parking_Blacktop",
      "rotation": 7
    },
    {
      "x": -4,
      "y": 3,
      "z": 9,
      "name": "BO_Parking_Blacktop",
      "rotation": 7
    },
    {
      "x": -4,
      "y": 9,
      "z": 9,
      "name": "BO_Parking_Wall03",
      "rotation": 3
    },
    {
      "x": -4,
      "y": 10,
      "z": 9,
      "name": "BO_Parking_Wall00",
      "rotation": 3
    },
    {
      "x": -4,
      "y": 11,
      "z": 9,
      "name": "Build_Black_Cube",
      "rotation": 3
    },
    {
      "x": -4,
      "y": 0,
      "z": 10,
      "name": "BO_Parking_Blacktop",
      "rotation": 7
    },
    {
      "x": -4,
      "y": 1,
      "z": 10,
      "name": "BO_Parking_Blacktop",
      "rotation": 7
    },
    {
      "x": -4,
      "y": 2,
      "z": 10,
      "name": "BO_Parking_Blacktop",
      "rotation": 7
    },
    {
      "x": -4,
      "y": 3,
      "z": 10,
      "name": "BO_Parking_Blacktop",
      "rotation": 7
    },
    {
      "x": -4,
      "y": 4,
      "z": 10,
      "name": "BO_Parking_Wall00",
      "rotation": 3
    },
    {
      "x": -4,
      "y": 5,
      "z": 10,
      "name": "BO_Parking_Wall02",
      "rotation": 3
    },
    {
      "x": -4,
      "y": 6,
      "z": 10,
      "name": "BO_Parking_Wall00",
      "rotation": 3
    },
    {
      "x": -4,
      "y": 7,
      "z": 10,
      "name": "BO_Parking_Wall00",
      "rotation": 3
    },
    {
      "x": -4,
      "y": 8,
      "z": 10,
      "name": "BO_Parking_Wall00",
      "rotation": 3
    },
    {
      "x": -4,
      "y": 9,
      "z": 10,
      "name": "BO_Parking_Wall00",
      "rotation": 3
    },
    {
      "x": -4,
      "y": 10,
      "z": 10,
      "name": "BO_Parking_Wall00",
      "rotation": 3
    },
    {
      "x": -3,
      "y": 0,
      "z": -9,
      "name": "BO_Parking_Blacktop",
      "rotation": 7
    },
    {
      "x": -3,
      "y": 1,
      "z": -9,
      "name": "BO_Parking_Blacktop",
      "rotation": 7
    },
    {
      "x": -3,
      "y": 2,
      "z": -9,
      "name": "BO_Parking_Blacktop",
      "rotation": 7
    },
    {
      "x": -3,
      "y": 3,
      "z": -9,
      "name": "BO_Parking_Blacktop",
      "rotation": 7
    },
    {
      "x": -3,
      "y": 9,
      "z": -9,
      "name": "BO_Parking_Wall03",
      "rotation": 3
    },
    {
      "x": -3,
      "y": 10,
      "z": -9,
      "name": "BO_Parking_Wall00",
      "rotation": 3
    },
    {
      "x": -3,
      "y": 11,
      "z": -9,
      "name": "Build_Black_Cube",
      "rotation": 3
    },
    {
      "x": -3,
      "y": 0,
      "z": -8,
      "name": "BO_Parking_Blacktop",
      "rotation": 7
    },
    {
      "x": -3,
      "y": 1,
      "z": -8,
      "name": "BO_Parking_Blacktop",
      "rotation": 7
    },
    {
      "x": -3,
      "y": 2,
      "z": -8,
      "name": "BO_Parking_Blacktop",
      "rotation": 7
    },
    {
      "x": -3,
      "y": 3,
      "z": -8,
      "name": "BO_Parking_Blacktop",
      "rotation": 7
    },
    {
      "x": -3,
      "y": 9,
      "z": -8,
      "name": "*BO_Garage_Overhead_Lights_State_Definitions_Inactive",
      "components": {
        "Components": {
          "BlackoutCycleState": {
            "OnState": "Inactive",
            "OffState": "Active",
            "OnSound": "Garage_Alarm_Disable"
          },
          "PlacedByInteraction": {
            "WhoPlacedUuid": {
              "$binary": "KMPE5JWxSQGC8WI/IkVLQQ==",
              "$type": "04"
            }
          }
        }
      },
      "rotation": 7
    },
    {
      "x": -3,
      "y": 10,
      "z": -8,
      "name": "BO_Parking_Wall00",
      "rotation": 3
    },
    {
      "x": -3,
      "y": 11,
      "z": -8,
      "name": "Build_Black_Cube",
      "rotation": 3
    },
    {
      "x": -3,
      "y": 0,
      "z": -7,
      "name": "BO_Parking_Blacktop",
      "rotation": 7
    },
    {
      "x": -3,
      "y": 1,
      "z": -7,
      "name": "BO_Parking_Blacktop",
      "rotation": 7
    },
    {
      "x": -3,
      "y": 2,
      "z": -7,
      "name": "BO_Parking_Blacktop",
      "rotation": 7
    },
    {
      "x": -3,
      "y": 3,
      "z": -7,
      "name": "BO_Parking_Blacktop",
      "rotation": 7
    },
    {
      "x": -3,
      "y": 9,
      "z": -7,
      "name": "*BO_Garage_Overhead_Lights_State_Definitions_Inactive",
      "components": {
        "Components": {
          "BlackoutCycleState": {
            "OnState": "Inactive",
            "OffState": "Active",
            "OnSound": "Garage_Alarm_Disable"
          },
          "PlacedByInteraction": {
            "WhoPlacedUuid": {
              "$binary": "KMPE5JWxSQGC8WI/IkVLQQ==",
              "$type": "04"
            }
          }
        }
      },
      "rotation": 3
    },
    {
      "x": -3,
      "y": 10,
      "z": -7,
      "name": "BO_Parking_Wall00",
      "rotation": 3
    },
    {
      "x": -3,
      "y": 0,
      "z": -6,
      "name": "BO_Parking_Blacktop",
      "rotation": 7
    },
    {
      "x": -3,
      "y": 1,
      "z": -6,
      "name": "BO_Parking_Blacktop",
      "rotation": 7
    },
    {
      "x": -3,
      "y": 2,
      "z": -6,
      "name": "BO_Parking_Blacktop",
      "rotation": 7
    },
    {
      "x": -3,
      "y": 3,
      "z": -6,
      "name": "BO_Parking_Blacktop",
      "rotation": 3
    },
    {
      "x": -3,
      "y": 9,
      "z": -6,
      "name": "BO_Parking_Wall_Half",
      "rotation": 11
    },
    {
      "x": -3,
      "y": 10,
      "z": -6,
      "name": "BO_Parking_Wall00",
      "rotation": 3
    },
    {
      "x": -3,
      "y": 0,
      "z": -5,
      "name": "BO_Parking_Blacktop",
      "rotation": 7
    },
    {
      "x": -3,
      "y": 1,
      "z": -5,
      "name": "BO_Parking_Blacktop",
      "rotation": 7
    },
    {
      "x": -3,
      "y": 2,
      "z": -5,
      "name": "BO_Parking_Blacktop",
      "rotation": 7
    },
    {
      "x": -3,
      "y": 3,
      "z": -5,
      "name": "BO_Parking_Blacktop",
      "rotation": 3
    },
    {
      "x": -3,
      "y": 9,
      "z": -5,
      "name": "BO_Parking_Wall_Half",
      "rotation": 11
    },
    {
      "x": -3,
      "y": 10,
      "z": -5,
      "name": "BO_Parking_Wall00",
      "rotation": 3
    },
    {
      "x": -3,
      "y": 0,
      "z": -4,
      "name": "BO_Parking_Blacktop",
      "rotation": 7
    },
    {
      "x": -3,
      "y": 1,
      "z": -4,
      "name": "BO_Parking_Blacktop",
      "rotation": 7
    },
    {
      "x": -3,
      "y": 2,
      "z": -4,
      "name": "BO_Parking_Blacktop",
      "rotation": 7
    },
    {
      "x": -3,
      "y": 3,
      "z": -4,
      "name": "BO_Parking_Blacktop",
      "rotation": 3
    },
    {
      "x": -3,
      "y": 9,
      "z": -4,
      "name": "BO_Parking_Wall_Half",
      "rotation": 11
    },
    {
      "x": -3,
      "y": 10,
      "z": -4,
      "name": "BO_Parking_Wall00",
      "rotation": 3
    },
    {
      "x": -3,
      "y": 0,
      "z": -3,
      "name": "BO_Parking_Blacktop",
      "rotation": 7
    },
    {
      "x": -3,
      "y": 1,
      "z": -3,
      "name": "BO_Parking_Blacktop",
      "rotation": 7
    },
    {
      "x": -3,
      "y": 2,
      "z": -3,
      "name": "BO_Parking_Blacktop",
      "rotation": 7
    },
    {
      "x": -3,
      "y": 3,
      "z": -3,
      "name": "BO_Parking_Blacktop",
      "rotation": 3
    },
    {
      "x": -3,
      "y": 9,
      "z": -3,
      "name": "BO_Parking_Wall_Half",
      "rotation": 11
    },
    {
      "x": -3,
      "y": 10,
      "z": -3,
      "name": "BO_Parking_Wall00",
      "rotation": 3
    },
    {
      "x": -3,
      "y": 0,
      "z": -2,
      "name": "BO_Parking_Blacktop",
      "rotation": 7
    },
    {
      "x": -3,
      "y": 1,
      "z": -2,
      "name": "BO_Parking_Blacktop",
      "rotation": 7
    },
    {
      "x": -3,
      "y": 2,
      "z": -2,
      "name": "BO_Parking_Blacktop",
      "rotation": 7
    },
    {
      "x": -3,
      "y": 3,
      "z": -2,
      "name": "BO_Parking_Blacktop",
      "rotation": 7
    },
    {
      "x": -3,
      "y": 9,
      "z": -2,
      "name": "BO_Parking_Wall_Half",
      "rotation": 11
    },
    {
      "x": -3,
      "y": 10,
      "z": -2,
      "name": "BO_Parking_Wall00",
      "rotation": 3
    },
    {
      "x": -3,
      "y": 0,
      "z": -1,
      "name": "BO_Parking_Blacktop",
      "rotation": 7
    },
    {
      "x": -3,
      "y": 1,
      "z": -1,
      "name": "BO_Parking_Blacktop",
      "rotation": 7
    },
    {
      "x": -3,
      "y": 2,
      "z": -1,
      "name": "BO_Parking_Blacktop",
      "rotation": 7
    },
    {
      "x": -3,
      "y": 3,
      "z": -1,
      "name": "BO_Parking_Blacktop",
      "rotation": 7
    },
    {
      "x": -3,
      "y": 9,
      "z": -1,
      "name": "BO_Parking_Wall_Half",
      "rotation": 11
    },
    {
      "x": -3,
      "y": 10,
      "z": -1,
      "name": "BO_Parking_Wall00",
      "rotation": 3
    },
    {
      "x": -3,
      "y": 11,
      "z": -1,
      "name": "Build_Black_Cube",
      "rotation": 3
    },
    {
      "x": -3,
      "y": 0,
      "z": 0,
      "name": "BO_Parking_Blacktop",
      "rotation": 7
    },
    {
      "x": -3,
      "y": 1,
      "z": 0,
      "name": "BO_Parking_Blacktop",
      "rotation": 7
    },
    {
      "x": -3,
      "y": 2,
      "z": 0,
      "name": "BO_Parking_Blacktop",
      "rotation": 7
    },
    {
      "x": -3,
      "y": 3,
      "z": 0,
      "name": "BO_Parking_Blacktop",
      "rotation": 7
    },
    {
      "x": -3,
      "y": 9,
      "z": 0,
      "name": "BO_Parking_Wall03",
      "rotation": 3
    },
    {
      "x": -3,
      "y": 10,
      "z": 0,
      "name": "BO_Parking_Wall00",
      "rotation": 3
    },
    {
      "x": -3,
      "y": 11,
      "z": 0,
      "name": "Build_Black_Cube",
      "rotation": 3
    },
    {
      "x": -3,
      "y": 0,
      "z": 1,
      "name": "BO_Parking_Blacktop",
      "rotation": 7
    },
    {
      "x": -3,
      "y": 1,
      "z": 1,
      "name": "*Garage_Slime_Light_State_Definitions_Day",
      "components": {
        "Components": {
          "BlackoutCycleState": {
            "OnState": "Day",
            "OffState": "Night"
          },
          "PlacedByInteraction": {
            "WhoPlacedUuid": {
              "$binary": "KMPE5JWxSQGC8WI/IkVLQQ==",
              "$type": "04"
            }
          }
        }
      },
      "rotation": 3
    },
    {
      "x": -3,
      "y": 3,
      "z": 1,
      "name": "*BO_Iron_Trapdoor_State_Definitions_CloseDoorOut",
      "components": {
        "Components": {
          "BlackoutBunkerHatch": {},
          "PlacedByInteraction": {
            "WhoPlacedUuid": {
              "$binary": "KMPE5JWxSQGC8WI/IkVLQQ==",
              "$type": "04"
            }
          }
        }
      },
      "rotation": 1
    },
    {
      "x": -3,
      "y": 9,
      "z": 1,
      "name": "BO_Parking_Wall03",
      "rotation": 3
    },
    {
      "x": -3,
      "y": 10,
      "z": 1,
      "name": "BO_Parking_Wall00",
      "rotation": 3
    },
    {
      "x": -3,
      "y": 11,
      "z": 1,
      "name": "Build_Black_Cube",
      "rotation": 3
    },
    {
      "x": -3,
      "y": 0,
      "z": 2,
      "name": "BO_Parking_Blacktop",
      "rotation": 7
    },
    {
      "x": -3,
      "y": 1,
      "z": 2,
      "name": "BO_Parking_Blacktop",
      "rotation": 7
    },
    {
      "x": -3,
      "y": 2,
      "z": 2,
      "name": "BO_Parking_Blacktop",
      "rotation": 7
    },
    {
      "x": -3,
      "y": 3,
      "z": 2,
      "name": "BO_Parking_Blacktop",
      "rotation": 3
    },
    {
      "x": -3,
      "y": 9,
      "z": 2,
      "name": "*BO_Garage_Overhead_Lights_State_Definitions_Inactive",
      "components": {
        "Components": {
          "BlackoutCycleState": {
            "OnState": "Inactive",
            "OffState": "Active",
            "OnSound": "Garage_Alarm_Disable"
          },
          "PlacedByInteraction": {
            "WhoPlacedUuid": {
              "$binary": "KMPE5JWxSQGC8WI/IkVLQQ==",
              "$type": "04"
            }
          }
        }
      },
      "rotation": 7
    },
    {
      "x": -3,
      "y": 10,
      "z": 2,
      "name": "BO_Parking_Wall00",
      "rotation": 3
    },
    {
      "x": -3,
      "y": 11,
      "z": 2,
      "name": "Build_Black_Cube",
      "rotation": 3
    },
    {
      "x": -3,
      "y": 0,
      "z": 3,
      "name": "BO_Parking_Blacktop",
      "rotation": 7
    },
    {
      "x": -3,
      "y": 1,
      "z": 3,
      "name": "BO_Parking_Blacktop",
      "rotation": 7
    },
    {
      "x": -3,
      "y": 2,
      "z": 3,
      "name": "BO_Parking_Blacktop",
      "rotation": 7
    },
    {
      "x": -3,
      "y": 3,
      "z": 3,
      "name": "BO_Parking_Blacktop",
      "rotation": 3
    },
    {
      "x": -3,
      "y": 9,
      "z": 3,
      "name": "*BO_Garage_Overhead_Lights_State_Definitions_Inactive",
      "components": {
        "Components": {
          "BlackoutCycleState": {
            "OnState": "Inactive",
            "OffState": "Active",
            "OnSound": "Garage_Alarm_Disable"
          },
          "PlacedByInteraction": {
            "WhoPlacedUuid": {
              "$binary": "KMPE5JWxSQGC8WI/IkVLQQ==",
              "$type": "04"
            }
          }
        }
      },
      "rotation": 7
    },
    {
      "x": -3,
      "y": 10,
      "z": 3,
      "name": "BO_Parking_Wall00",
      "rotation": 3
    },
    {
      "x": -3,
      "y": 0,
      "z": 4,
      "name": "BO_Parking_Blacktop",
      "rotation": 7
    },
    {
      "x": -3,
      "y": 1,
      "z": 4,
      "name": "BO_Parking_Blacktop",
      "rotation": 7
    },
    {
      "x": -3,
      "y": 2,
      "z": 4,
      "name": "BO_Parking_Blacktop",
      "rotation": 7
    },
    {
      "x": -3,
      "y": 3,
      "z": 4,
      "name": "BO_Parking_Blacktop",
      "rotation": 3
    },
    {
      "x": -3,
      "y": 9,
      "z": 4,
      "name": "BO_Parking_Wall_Half",
      "rotation": 11
    },
    {
      "x": -3,
      "y": 10,
      "z": 4,
      "name": "BO_Parking_Wall00",
      "rotation": 3
    },
    {
      "x": -3,
      "y": 0,
      "z": 5,
      "name": "BO_Parking_Blacktop",
      "rotation": 7
    },
    {
      "x": -3,
      "y": 1,
      "z": 5,
      "name": "BO_Parking_Blacktop",
      "rotation": 7
    },
    {
      "x": -3,
      "y": 2,
      "z": 5,
      "name": "BO_Parking_Blacktop",
      "rotation": 7
    },
    {
      "x": -3,
      "y": 3,
      "z": 5,
      "name": "BO_Parking_Blacktop",
      "rotation": 3
    },
    {
      "x": -3,
      "y": 9,
      "z": 5,
      "name": "BO_Parking_Wall_Half",
      "rotation": 11
    },
    {
      "x": -3,
      "y": 10,
      "z": 5,
      "name": "BO_Parking_Wall00",
      "rotation": 3
    },
    {
      "x": -3,
      "y": 0,
      "z": 6,
      "name": "BO_Parking_Blacktop",
      "rotation": 7
    },
    {
      "x": -3,
      "y": 1,
      "z": 6,
      "name": "BO_Parking_Blacktop",
      "rotation": 7
    },
    {
      "x": -3,
      "y": 2,
      "z": 6,
      "name": "BO_Parking_Blacktop",
      "rotation": 7
    },
    {
      "x": -3,
      "y": 3,
      "z": 6,
      "name": "BO_Parking_Blacktop",
      "rotation": 3
    },
    {
      "x": -3,
      "y": 9,
      "z": 6,
      "name": "BO_Parking_Wall_Half",
      "rotation": 11
    },
    {
      "x": -3,
      "y": 10,
      "z": 6,
      "name": "BO_Parking_Wall00",
      "rotation": 3
    },
    {
      "x": -3,
      "y": 0,
      "z": 7,
      "name": "BO_Parking_Blacktop",
      "rotation": 7
    },
    {
      "x": -3,
      "y": 1,
      "z": 7,
      "name": "BO_Parking_Blacktop",
      "rotation": 7
    },
    {
      "x": -3,
      "y": 2,
      "z": 7,
      "name": "BO_Parking_Blacktop",
      "rotation": 7
    },
    {
      "x": -3,
      "y": 3,
      "z": 7,
      "name": "BO_Parking_Blacktop",
      "rotation": 3
    },
    {
      "x": -3,
      "y": 9,
      "z": 7,
      "name": "BO_Parking_Wall_Half",
      "rotation": 11
    },
    {
      "x": -3,
      "y": 10,
      "z": 7,
      "name": "BO_Parking_Wall00",
      "rotation": 3
    },
    {
      "x": -3,
      "y": 0,
      "z": 8,
      "name": "BO_Parking_Blacktop",
      "rotation": 7
    },
    {
      "x": -3,
      "y": 1,
      "z": 8,
      "name": "BO_Parking_Blacktop",
      "rotation": 7
    },
    {
      "x": -3,
      "y": 2,
      "z": 8,
      "name": "BO_Parking_Blacktop",
      "rotation": 7
    },
    {
      "x": -3,
      "y": 3,
      "z": 8,
      "name": "BO_Parking_Blacktop",
      "rotation": 2
    },
    {
      "x": -3,
      "y": 9,
      "z": 8,
      "name": "BO_Parking_Wall_Half",
      "rotation": 11
    },
    {
      "x": -3,
      "y": 10,
      "z": 8,
      "name": "BO_Parking_Wall00",
      "rotation": 3
    },
    {
      "x": -3,
      "y": 0,
      "z": 9,
      "name": "BO_Parking_Blacktop",
      "rotation": 7
    },
    {
      "x": -3,
      "y": 1,
      "z": 9,
      "name": "BO_Parking_Blacktop",
      "rotation": 7
    },
    {
      "x": -3,
      "y": 2,
      "z": 9,
      "name": "BO_Parking_Blacktop",
      "rotation": 7
    },
    {
      "x": -3,
      "y": 3,
      "z": 9,
      "name": "BO_Parking_Blacktop",
      "rotation": 3
    },
    {
      "x": -3,
      "y": 9,
      "z": 9,
      "name": "BO_Parking_Wall03",
      "rotation": 3
    },
    {
      "x": -3,
      "y": 10,
      "z": 9,
      "name": "BO_Parking_Wall00",
      "rotation": 3
    },
    {
      "x": -3,
      "y": 11,
      "z": 9,
      "name": "Build_Black_Cube",
      "rotation": 3
    },
    {
      "x": -3,
      "y": 0,
      "z": 10,
      "name": "BO_Parking_Blacktop",
      "rotation": 7
    },
    {
      "x": -3,
      "y": 1,
      "z": 10,
      "name": "BO_Parking_Blacktop",
      "rotation": 7
    },
    {
      "x": -3,
      "y": 2,
      "z": 10,
      "name": "BO_Parking_Blacktop",
      "rotation": 7
    },
    {
      "x": -3,
      "y": 3,
      "z": 10,
      "name": "BO_Parking_Blacktop",
      "rotation": 3
    },
    {
      "x": -3,
      "y": 4,
      "z": 10,
      "name": "BO_Parking_Wall00",
      "rotation": 3
    },
    {
      "x": -3,
      "y": 5,
      "z": 10,
      "name": "BO_Parking_Wall02",
      "rotation": 3
    },
    {
      "x": -3,
      "y": 6,
      "z": 10,
      "name": "BO_Parking_Wall00",
      "rotation": 3
    },
    {
      "x": -3,
      "y": 7,
      "z": 10,
      "name": "BO_Parking_Wall00",
      "rotation": 3
    },
    {
      "x": -3,
      "y": 8,
      "z": 10,
      "name": "BO_Parking_Wall00",
      "rotation": 3
    },
    {
      "x": -3,
      "y": 9,
      "z": 10,
      "name": "BO_Parking_Wall_Half",
      "rotation": 3
    },
    {
      "x": -3,
      "y": 10,
      "z": 10,
      "name": "BO_Parking_Wall00",
      "rotation": 3
    },
    {
      "x": -2,
      "y": 0,
      "z": -9,
      "name": "BO_Parking_Blacktop",
      "rotation": 7
    },
    {
      "x": -2,
      "y": 1,
      "z": -9,
      "name": "BO_Parking_Blacktop",
      "rotation": 7
    },
    {
      "x": -2,
      "y": 2,
      "z": -9,
      "name": "BO_Parking_Blacktop",
      "rotation": 7
    },
    {
      "x": -2,
      "y": 3,
      "z": -9,
      "name": "BO_Parking_Blacktop",
      "rotation": 7
    },
    {
      "x": -2,
      "y": 9,
      "z": -9,
      "name": "BO_Parking_Wall03",
      "rotation": 3
    },
    {
      "x": -2,
      "y": 10,
      "z": -9,
      "name": "BO_Parking_Wall00",
      "rotation": 3
    },
    {
      "x": -2,
      "y": 0,
      "z": -8,
      "name": "BO_Parking_Blacktop",
      "rotation": 7
    },
    {
      "x": -2,
      "y": 1,
      "z": -8,
      "name": "BO_Parking_Blacktop",
      "rotation": 7
    },
    {
      "x": -2,
      "y": 2,
      "z": -8,
      "name": "BO_Parking_Blacktop",
      "rotation": 7
    },
    {
      "x": -2,
      "y": 3,
      "z": -8,
      "name": "BO_Parking_Blacktop",
      "rotation": 7
    },
    {
      "x": -2,
      "y": 9,
      "z": -8,
      "name": "BO_Parking_Wall_Half",
      "rotation": 11
    },
    {
      "x": -2,
      "y": 10,
      "z": -8,
      "name": "BO_Parking_Wall00",
      "rotation": 3
    },
    {
      "x": -2,
      "y": 0,
      "z": -7,
      "name": "BO_Parking_Blacktop",
      "rotation": 7
    },
    {
      "x": -2,
      "y": 1,
      "z": -7,
      "name": "BO_Parking_Blacktop",
      "rotation": 7
    },
    {
      "x": -2,
      "y": 2,
      "z": -7,
      "name": "BO_Parking_Blacktop",
      "rotation": 7
    },
    {
      "x": -2,
      "y": 3,
      "z": -7,
      "name": "BO_Parking_Blacktop",
      "rotation": 7
    },
    {
      "x": -2,
      "y": 9,
      "z": -7,
      "name": "BO_Parking_Wall_Half",
      "rotation": 11
    },
    {
      "x": -2,
      "y": 10,
      "z": -7,
      "name": "BO_Parking_Wall00",
      "rotation": 3
    },
    {
      "x": -2,
      "y": 0,
      "z": -6,
      "name": "BO_Parking_Blacktop",
      "rotation": 7
    },
    {
      "x": -2,
      "y": 1,
      "z": -6,
      "name": "BO_Parking_Blacktop",
      "rotation": 7
    },
    {
      "x": -2,
      "y": 2,
      "z": -6,
      "name": "BO_Parking_Blacktop",
      "rotation": 7
    },
    {
      "x": -2,
      "y": 3,
      "z": -6,
      "name": "BO_Parking_Blacktop",
      "rotation": 7
    },
    {
      "x": -2,
      "y": 9,
      "z": -6,
      "name": "BO_Parking_Wall_Half",
      "rotation": 11
    },
    {
      "x": -2,
      "y": 10,
      "z": -6,
      "name": "BO_Parking_Wall00",
      "rotation": 3
    },
    {
      "x": -2,
      "y": 0,
      "z": -5,
      "name": "BO_Parking_Blacktop",
      "rotation": 7
    },
    {
      "x": -2,
      "y": 1,
      "z": -5,
      "name": "BO_Parking_Blacktop",
      "rotation": 7
    },
    {
      "x": -2,
      "y": 2,
      "z": -5,
      "name": "BO_Parking_Blacktop",
      "rotation": 7
    },
    {
      "x": -2,
      "y": 3,
      "z": -5,
      "name": "BO_Parking_Blacktop",
      "rotation": 7
    },
    {
      "x": -2,
      "y": 9,
      "z": -5,
      "name": "BO_Parking_Wall_Half",
      "rotation": 11
    },
    {
      "x": -2,
      "y": 10,
      "z": -5,
      "name": "BO_Parking_Wall00",
      "rotation": 3
    },
    {
      "x": -2,
      "y": 0,
      "z": -4,
      "name": "BO_Parking_Blacktop",
      "rotation": 7
    },
    {
      "x": -2,
      "y": 1,
      "z": -4,
      "name": "BO_Parking_Blacktop",
      "rotation": 7
    },
    {
      "x": -2,
      "y": 2,
      "z": -4,
      "name": "BO_Parking_Blacktop",
      "rotation": 7
    },
    {
      "x": -2,
      "y": 3,
      "z": -4,
      "name": "BO_Parking_Blacktop",
      "rotation": 7
    },
    {
      "x": -2,
      "y": 9,
      "z": -4,
      "name": "BO_Parking_Wall_Half",
      "rotation": 11
    },
    {
      "x": -2,
      "y": 10,
      "z": -4,
      "name": "BO_Parking_Wall00",
      "rotation": 3
    },
    {
      "x": -2,
      "y": 0,
      "z": -3,
      "name": "BO_Parking_Blacktop",
      "rotation": 7
    },
    {
      "x": -2,
      "y": 1,
      "z": -3,
      "name": "BO_Parking_Blacktop",
      "rotation": 7
    },
    {
      "x": -2,
      "y": 2,
      "z": -3,
      "name": "BO_Parking_Blacktop",
      "rotation": 7
    },
    {
      "x": -2,
      "y": 3,
      "z": -3,
      "name": "BO_Parking_Blacktop",
      "rotation": 7
    },
    {
      "x": -2,
      "y": 9,
      "z": -3,
      "name": "BO_Parking_Wall_Half",
      "rotation": 11
    },
    {
      "x": -2,
      "y": 10,
      "z": -3,
      "name": "BO_Parking_Wall00",
      "rotation": 3
    },
    {
      "x": -2,
      "y": 0,
      "z": -2,
      "name": "BO_Parking_Blacktop",
      "rotation": 7
    },
    {
      "x": -2,
      "y": 1,
      "z": -2,
      "name": "BO_Parking_Blacktop",
      "rotation": 7
    },
    {
      "x": -2,
      "y": 2,
      "z": -2,
      "name": "BO_Parking_Blacktop",
      "rotation": 7
    },
    {
      "x": -2,
      "y": 3,
      "z": -2,
      "name": "BO_Parking_Blacktop",
      "rotation": 7
    },
    {
      "x": -2,
      "y": 9,
      "z": -2,
      "name": "BO_Parking_Wall_Half",
      "rotation": 11
    },
    {
      "x": -2,
      "y": 10,
      "z": -2,
      "name": "BO_Parking_Wall00",
      "rotation": 3
    },
    {
      "x": -2,
      "y": 0,
      "z": -1,
      "name": "BO_Parking_Blacktop",
      "rotation": 7
    },
    {
      "x": -2,
      "y": 1,
      "z": -1,
      "name": "BO_Parking_Blacktop",
      "rotation": 7
    },
    {
      "x": -2,
      "y": 2,
      "z": -1,
      "name": "BO_Parking_Blacktop",
      "rotation": 7
    },
    {
      "x": -2,
      "y": 3,
      "z": -1,
      "name": "BO_Parking_Blacktop",
      "rotation": 7
    },
    {
      "x": -2,
      "y": 9,
      "z": -1,
      "name": "BO_Parking_Wall_Half",
      "rotation": 11
    },
    {
      "x": -2,
      "y": 10,
      "z": -1,
      "name": "BO_Parking_Wall00",
      "rotation": 3
    },
    {
      "x": -2,
      "y": 0,
      "z": 0,
      "name": "BO_Parking_Blacktop",
      "rotation": 7
    },
    {
      "x": -2,
      "y": 1,
      "z": 0,
      "name": "BO_Parking_Blacktop",
      "rotation": 7
    },
    {
      "x": -2,
      "y": 2,
      "z": 0,
      "name": "BO_Parking_Blacktop",
      "rotation": 7
    },
    {
      "x": -2,
      "y": 3,
      "z": 0,
      "name": "BO_Parking_Blacktop",
      "rotation": 7
    },
    {
      "x": -2,
      "y": 9,
      "z": 0,
      "name": "BO_Parking_Wall03",
      "rotation": 3
    },
    {
      "x": -2,
      "y": 10,
      "z": 0,
      "name": "BO_Parking_Wall00",
      "rotation": 3
    },
    {
      "x": -2,
      "y": 0,
      "z": 1,
      "name": "BO_Parking_Blacktop",
      "rotation": 7
    },
    {
      "x": -2,
      "y": 1,
      "z": 1,
      "name": "BO_Parking_Blacktop",
      "rotation": 7
    },
    {
      "x": -2,
      "y": 2,
      "z": 1,
      "name": "BO_Parking_Blacktop",
      "rotation": 7
    },
    {
      "x": -2,
      "y": 3,
      "z": 1,
      "name": "BO_Parking_Blacktop",
      "rotation": 7
    },
    {
      "x": -2,
      "y": 9,
      "z": 1,
      "name": "BO_Parking_Wall03",
      "rotation": 3
    },
    {
      "x": -2,
      "y": 10,
      "z": 1,
      "name": "BO_Parking_Wall00",
      "rotation": 3
    },
    {
      "x": -2,
      "y": 0,
      "z": 2,
      "name": "BO_Parking_Blacktop",
      "rotation": 7
    },
    {
      "x": -2,
      "y": 1,
      "z": 2,
      "name": "BO_Parking_Blacktop",
      "rotation": 7
    },
    {
      "x": -2,
      "y": 2,
      "z": 2,
      "name": "BO_Parking_Blacktop",
      "rotation": 7
    },
    {
      "x": -2,
      "y": 3,
      "z": 2,
      "name": "BO_Parking_Blacktop",
      "rotation": 7
    },
    {
      "x": -2,
      "y": 9,
      "z": 2,
      "name": "BO_Parking_Wall_Half",
      "rotation": 11
    },
    {
      "x": -2,
      "y": 10,
      "z": 2,
      "name": "BO_Parking_Wall00",
      "rotation": 3
    },
    {
      "x": -2,
      "y": 0,
      "z": 3,
      "name": "BO_Parking_Blacktop",
      "rotation": 7
    },
    {
      "x": -2,
      "y": 1,
      "z": 3,
      "name": "BO_Parking_Blacktop",
      "rotation": 7
    },
    {
      "x": -2,
      "y": 2,
      "z": 3,
      "name": "BO_Parking_Blacktop",
      "rotation": 7
    },
    {
      "x": -2,
      "y": 3,
      "z": 3,
      "name": "BO_Parking_Blacktop",
      "rotation": 7
    },
    {
      "x": -2,
      "y": 9,
      "z": 3,
      "name": "BO_Parking_Wall_Half",
      "rotation": 11
    },
    {
      "x": -2,
      "y": 10,
      "z": 3,
      "name": "BO_Parking_Wall00",
      "rotation": 3
    },
    {
      "x": -2,
      "y": 0,
      "z": 4,
      "name": "BO_Parking_Blacktop",
      "rotation": 7
    },
    {
      "x": -2,
      "y": 1,
      "z": 4,
      "name": "BO_Parking_Blacktop",
      "rotation": 7
    },
    {
      "x": -2,
      "y": 2,
      "z": 4,
      "name": "BO_Parking_Blacktop",
      "rotation": 7
    },
    {
      "x": -2,
      "y": 3,
      "z": 4,
      "name": "BO_Parking_Blacktop",
      "rotation": 7
    },
    {
      "x": -2,
      "y": 9,
      "z": 4,
      "name": "BO_Parking_Wall_Half",
      "rotation": 11
    },
    {
      "x": -2,
      "y": 10,
      "z": 4,
      "name": "BO_Parking_Wall00",
      "rotation": 3
    },
    {
      "x": -2,
      "y": 0,
      "z": 5,
      "name": "BO_Parking_Blacktop",
      "rotation": 7
    },
    {
      "x": -2,
      "y": 1,
      "z": 5,
      "name": "BO_Parking_Blacktop",
      "rotation": 7
    },
    {
      "x": -2,
      "y": 2,
      "z": 5,
      "name": "BO_Parking_Blacktop",
      "rotation": 7
    },
    {
      "x": -2,
      "y": 3,
      "z": 5,
      "name": "BO_Parking_Blacktop01",
      "rotation": 3
    },
    {
      "x": -2,
      "y": 4,
      "z": 5,
      "name": "BO_Parking_Bollard",
      "rotation": 2
    },
    {
      "x": -2,
      "y": 5,
      "z": 5,
      "name": "BO_Parking_Bollard",
      "filler": 1024,
      "rotation": 2
    },
    {
      "x": -2,
      "y": 9,
      "z": 5,
      "name": "BO_Parking_Wall_Half",
      "rotation": 11
    },
    {
      "x": -2,
      "y": 10,
      "z": 5,
      "name": "BO_Parking_Wall00",
      "rotation": 3
    },
    {
      "x": -2,
      "y": 0,
      "z": 6,
      "name": "BO_Parking_Blacktop",
      "rotation": 7
    },
    {
      "x": -2,
      "y": 1,
      "z": 6,
      "name": "BO_Parking_Blacktop",
      "rotation": 7
    },
    {
      "x": -2,
      "y": 2,
      "z": 6,
      "name": "BO_Parking_Blacktop",
      "rotation": 7
    },
    {
      "x": -2,
      "y": 3,
      "z": 6,
      "name": "BO_Parking_Blacktop01",
      "rotation": 3
    },
    {
      "x": -2,
      "y": 9,
      "z": 6,
      "name": "BO_Parking_Wall_Half",
      "rotation": 11
    },
    {
      "x": -2,
      "y": 10,
      "z": 6,
      "name": "BO_Parking_Wall00",
      "rotation": 3
    },
    {
      "x": -2,
      "y": 0,
      "z": 7,
      "name": "BO_Parking_Blacktop",
      "rotation": 7
    },
    {
      "x": -2,
      "y": 1,
      "z": 7,
      "name": "BO_Parking_Blacktop",
      "rotation": 7
    },
    {
      "x": -2,
      "y": 2,
      "z": 7,
      "name": "BO_Parking_Blacktop",
      "rotation": 7
    },
    {
      "x": -2,
      "y": 3,
      "z": 7,
      "name": "BO_Parking_Blacktop01",
      "rotation": 3
    },
    {
      "x": -2,
      "y": 9,
      "z": 7,
      "name": "BO_Parking_Wall_Half",
      "rotation": 11
    },
    {
      "x": -2,
      "y": 10,
      "z": 7,
      "name": "BO_Parking_Wall00",
      "rotation": 3
    },
    {
      "x": -2,
      "y": 0,
      "z": 8,
      "name": "BO_Parking_Blacktop",
      "rotation": 7
    },
    {
      "x": -2,
      "y": 1,
      "z": 8,
      "name": "BO_Parking_Blacktop",
      "rotation": 7
    },
    {
      "x": -2,
      "y": 2,
      "z": 8,
      "name": "BO_Parking_Blacktop",
      "rotation": 7
    },
    {
      "x": -2,
      "y": 3,
      "z": 8,
      "name": "BO_Parking_Blacktop01",
      "rotation": 3
    },
    {
      "x": -2,
      "y": 9,
      "z": 8,
      "name": "BO_Parking_Wall_Half",
      "rotation": 11
    },
    {
      "x": -2,
      "y": 10,
      "z": 8,
      "name": "BO_Parking_Wall00",
      "rotation": 3
    },
    {
      "x": -2,
      "y": 0,
      "z": 9,
      "name": "BO_Parking_Blacktop",
      "rotation": 7
    },
    {
      "x": -2,
      "y": 1,
      "z": 9,
      "name": "BO_Parking_Blacktop",
      "rotation": 7
    },
    {
      "x": -2,
      "y": 2,
      "z": 9,
      "name": "BO_Parking_Blacktop",
      "rotation": 7
    },
    {
      "x": -2,
      "y": 3,
      "z": 9,
      "name": "BO_Parking_Blacktop01",
      "rotation": 3
    },
    {
      "x": -2,
      "y": 9,
      "z": 9,
      "name": "BO_Parking_Wall03",
      "rotation": 3
    },
    {
      "x": -2,
      "y": 10,
      "z": 9,
      "name": "BO_Parking_Wall00",
      "rotation": 3
    },
    {
      "x": -2,
      "y": 11,
      "z": 9,
      "name": "Build_Black_Cube",
      "rotation": 3
    },
    {
      "x": -2,
      "y": 0,
      "z": 10,
      "name": "BO_Parking_Blacktop",
      "rotation": 7
    },
    {
      "x": -2,
      "y": 1,
      "z": 10,
      "name": "BO_Parking_Blacktop",
      "rotation": 7
    },
    {
      "x": -2,
      "y": 2,
      "z": 10,
      "name": "BO_Parking_Blacktop",
      "rotation": 7
    },
    {
      "x": -2,
      "y": 3,
      "z": 10,
      "name": "BO_Parking_Blacktop",
      "rotation": 7
    },
    {
      "x": -2,
      "y": 4,
      "z": 10,
      "name": "BO_Parking_Wall00",
      "rotation": 3
    },
    {
      "x": -2,
      "y": 5,
      "z": 10,
      "name": "BO_Parking_Wall02",
      "rotation": 3
    },
    {
      "x": -2,
      "y": 6,
      "z": 10,
      "name": "BO_Parking_Wall00",
      "rotation": 3
    },
    {
      "x": -2,
      "y": 7,
      "z": 10,
      "name": "BO_Parking_Wall00",
      "rotation": 3
    },
    {
      "x": -2,
      "y": 8,
      "z": 10,
      "name": "BO_Parking_Wall00",
      "rotation": 3
    },
    {
      "x": -2,
      "y": 9,
      "z": 10,
      "name": "BO_Parking_Wall_Half",
      "rotation": 3
    },
    {
      "x": -2,
      "y": 10,
      "z": 10,
      "name": "BO_Parking_Wall00",
      "rotation": 3
    },
    {
      "x": -1,
      "y": 0,
      "z": -9,
      "name": "BO_Parking_Blacktop",
      "rotation": 7
    },
    {
      "x": -1,
      "y": 1,
      "z": -9,
      "name": "BO_Parking_Blacktop",
      "rotation": 7
    },
    {
      "x": -1,
      "y": 2,
      "z": -9,
      "name": "BO_Parking_Blacktop",
      "rotation": 7
    },
    {
      "x": -1,
      "y": 3,
      "z": -9,
      "name": "BO_Parking_Blacktop",
      "rotation": 7
    },
    {
      "x": -1,
      "y": 9,
      "z": -9,
      "name": "BO_Parking_Wall03",
      "rotation": 3
    },
    {
      "x": -1,
      "y": 10,
      "z": -9,
      "name": "BO_Parking_Wall00",
      "rotation": 3
    },
    {
      "x": -1,
      "y": 0,
      "z": -8,
      "name": "BO_Parking_Blacktop",
      "rotation": 7
    },
    {
      "x": -1,
      "y": 1,
      "z": -8,
      "name": "BO_Parking_Blacktop",
      "rotation": 7
    },
    {
      "x": -1,
      "y": 2,
      "z": -8,
      "name": "BO_Parking_Blacktop",
      "rotation": 7
    },
    {
      "x": -1,
      "y": 3,
      "z": -8,
      "name": "BO_Parking_Blacktop",
      "rotation": 7
    },
    {
      "x": -1,
      "y": 9,
      "z": -8,
      "name": "BO_Parking_Wall_Half",
      "rotation": 11
    },
    {
      "x": -1,
      "y": 10,
      "z": -8,
      "name": "BO_Parking_Wall00",
      "rotation": 3
    },
    {
      "x": -1,
      "y": 0,
      "z": -7,
      "name": "BO_Parking_Blacktop",
      "rotation": 7
    },
    {
      "x": -1,
      "y": 1,
      "z": -7,
      "name": "BO_Parking_Blacktop",
      "rotation": 7
    },
    {
      "x": -1,
      "y": 2,
      "z": -7,
      "name": "BO_Parking_Blacktop",
      "rotation": 7
    },
    {
      "x": -1,
      "y": 3,
      "z": -7,
      "name": "BO_Parking_Blacktop",
      "rotation": 7
    },
    {
      "x": -1,
      "y": 9,
      "z": -7,
      "name": "BO_Parking_Wall_Half",
      "rotation": 11
    },
    {
      "x": -1,
      "y": 10,
      "z": -7,
      "name": "BO_Parking_Wall00",
      "rotation": 3
    },
    {
      "x": -1,
      "y": 0,
      "z": -6,
      "name": "BO_Parking_Blacktop",
      "rotation": 7
    },
    {
      "x": -1,
      "y": 1,
      "z": -6,
      "name": "BO_Parking_Blacktop",
      "rotation": 7
    },
    {
      "x": -1,
      "y": 2,
      "z": -6,
      "name": "BO_Parking_Blacktop",
      "rotation": 7
    },
    {
      "x": -1,
      "y": 3,
      "z": -6,
      "name": "BO_Parking_Blacktop",
      "rotation": 7
    },
    {
      "x": -1,
      "y": 9,
      "z": -6,
      "name": "BO_Parking_Wall_Half",
      "rotation": 11
    },
    {
      "x": -1,
      "y": 10,
      "z": -6,
      "name": "BO_Parking_Wall00",
      "rotation": 3
    },
    {
      "x": -1,
      "y": 0,
      "z": -5,
      "name": "BO_Parking_Blacktop",
      "rotation": 7
    },
    {
      "x": -1,
      "y": 1,
      "z": -5,
      "name": "BO_Parking_Blacktop",
      "rotation": 7
    },
    {
      "x": -1,
      "y": 2,
      "z": -5,
      "name": "BO_Parking_Blacktop",
      "rotation": 7
    },
    {
      "x": -1,
      "y": 3,
      "z": -5,
      "name": "BO_Parking_Blacktop",
      "rotation": 7
    },
    {
      "x": -1,
      "y": 9,
      "z": -5,
      "name": "BO_Parking_Wall_Half",
      "rotation": 11
    },
    {
      "x": -1,
      "y": 10,
      "z": -5,
      "name": "BO_Parking_Wall00",
      "rotation": 3
    },
    {
      "x": -1,
      "y": 0,
      "z": -4,
      "name": "BO_Parking_Blacktop",
      "rotation": 7
    },
    {
      "x": -1,
      "y": 1,
      "z": -4,
      "name": "BO_Parking_Blacktop",
      "rotation": 7
    },
    {
      "x": -1,
      "y": 2,
      "z": -4,
      "name": "BO_Parking_Blacktop",
      "rotation": 7
    },
    {
      "x": -1,
      "y": 3,
      "z": -4,
      "name": "BO_Parking_Blacktop",
      "rotation": 7
    },
    {
      "x": -1,
      "y": 9,
      "z": -4,
      "name": "BO_Parking_Wall_Half",
      "rotation": 11
    },
    {
      "x": -1,
      "y": 10,
      "z": -4,
      "name": "BO_Parking_Wall00",
      "rotation": 3
    },
    {
      "x": -1,
      "y": 0,
      "z": -3,
      "name": "BO_Parking_Blacktop",
      "rotation": 7
    },
    {
      "x": -1,
      "y": 1,
      "z": -3,
      "name": "BO_Parking_Blacktop",
      "rotation": 7
    },
    {
      "x": -1,
      "y": 2,
      "z": -3,
      "name": "BO_Parking_Blacktop",
      "rotation": 7
    },
    {
      "x": -1,
      "y": 3,
      "z": -3,
      "name": "BO_Parking_Blacktop",
      "rotation": 7
    },
    {
      "x": -1,
      "y": 9,
      "z": -3,
      "name": "BO_Parking_Wall_Half",
      "rotation": 11
    },
    {
      "x": -1,
      "y": 10,
      "z": -3,
      "name": "BO_Parking_Wall00",
      "rotation": 3
    },
    {
      "x": -1,
      "y": 0,
      "z": -2,
      "name": "BO_Parking_Blacktop",
      "rotation": 7
    },
    {
      "x": -1,
      "y": 1,
      "z": -2,
      "name": "BO_Parking_Blacktop",
      "rotation": 7
    },
    {
      "x": -1,
      "y": 2,
      "z": -2,
      "name": "BO_Parking_Blacktop",
      "rotation": 7
    },
    {
      "x": -1,
      "y": 3,
      "z": -2,
      "name": "BO_Parking_Blacktop",
      "rotation": 7
    },
    {
      "x": -1,
      "y": 9,
      "z": -2,
      "name": "BO_Parking_Wall_Half",
      "rotation": 11
    },
    {
      "x": -1,
      "y": 10,
      "z": -2,
      "name": "BO_Parking_Wall00",
      "rotation": 3
    },
    {
      "x": -1,
      "y": 0,
      "z": -1,
      "name": "BO_Parking_Blacktop",
      "rotation": 7
    },
    {
      "x": -1,
      "y": 1,
      "z": -1,
      "name": "BO_Parking_Blacktop",
      "rotation": 7
    },
    {
      "x": -1,
      "y": 2,
      "z": -1,
      "name": "BO_Parking_Blacktop",
      "rotation": 7
    },
    {
      "x": -1,
      "y": 3,
      "z": -1,
      "name": "BO_Parking_Blacktop",
      "rotation": 7
    },
    {
      "x": -1,
      "y": 9,
      "z": -1,
      "name": "BO_Parking_Wall_Half",
      "rotation": 11
    },
    {
      "x": -1,
      "y": 10,
      "z": -1,
      "name": "BO_Parking_Wall00",
      "rotation": 3
    },
    {
      "x": -1,
      "y": 0,
      "z": 0,
      "name": "BO_Parking_Blacktop",
      "rotation": 7
    },
    {
      "x": -1,
      "y": 1,
      "z": 0,
      "name": "BO_Parking_Blacktop",
      "rotation": 7
    },
    {
      "x": -1,
      "y": 2,
      "z": 0,
      "name": "BO_Parking_Blacktop",
      "rotation": 7
    },
    {
      "x": -1,
      "y": 3,
      "z": 0,
      "name": "BO_Parking_Blacktop",
      "rotation": 7
    },
    {
      "x": -1,
      "y": 9,
      "z": 0,
      "name": "BO_Parking_Wall03",
      "rotation": 3
    },
    {
      "x": -1,
      "y": 10,
      "z": 0,
      "name": "BO_Parking_Wall00",
      "rotation": 3
    },
    {
      "x": -1,
      "y": 0,
      "z": 1,
      "name": "BO_Parking_Blacktop",
      "rotation": 7
    },
    {
      "x": -1,
      "y": 1,
      "z": 1,
      "name": "BO_Parking_Blacktop",
      "rotation": 7
    },
    {
      "x": -1,
      "y": 2,
      "z": 1,
      "name": "BO_Parking_Blacktop",
      "rotation": 7
    },
    {
      "x": -1,
      "y": 3,
      "z": 1,
      "name": "BO_Parking_Blacktop",
      "rotation": 7
    },
    {
      "x": -1,
      "y": 9,
      "z": 1,
      "name": "BO_Parking_Wall03",
      "rotation": 3
    },
    {
      "x": -1,
      "y": 10,
      "z": 1,
      "name": "BO_Parking_Wall00",
      "rotation": 3
    },
    {
      "x": -1,
      "y": 0,
      "z": 2,
      "name": "BO_Parking_Blacktop",
      "rotation": 7
    },
    {
      "x": -1,
      "y": 1,
      "z": 2,
      "name": "BO_Parking_Blacktop",
      "rotation": 7
    },
    {
      "x": -1,
      "y": 2,
      "z": 2,
      "name": "BO_Parking_Blacktop",
      "rotation": 7
    },
    {
      "x": -1,
      "y": 3,
      "z": 2,
      "name": "BO_Parking_Blacktop",
      "rotation": 3
    },
    {
      "x": -1,
      "y": 9,
      "z": 2,
      "name": "BO_Parking_Wall_Half",
      "rotation": 11
    },
    {
      "x": -1,
      "y": 10,
      "z": 2,
      "name": "BO_Parking_Wall00",
      "rotation": 3
    },
    {
      "x": -1,
      "y": 0,
      "z": 3,
      "name": "BO_Parking_Blacktop",
      "rotation": 7
    },
    {
      "x": -1,
      "y": 1,
      "z": 3,
      "name": "BO_Parking_Blacktop",
      "rotation": 7
    },
    {
      "x": -1,
      "y": 2,
      "z": 3,
      "name": "BO_Parking_Blacktop",
      "rotation": 7
    },
    {
      "x": -1,
      "y": 3,
      "z": 3,
      "name": "BO_Parking_Blacktop",
      "rotation": 3
    },
    {
      "x": -1,
      "y": 9,
      "z": 3,
      "name": "BO_Parking_Wall_Half",
      "rotation": 11
    },
    {
      "x": -1,
      "y": 10,
      "z": 3,
      "name": "BO_Parking_Wall00",
      "rotation": 3
    },
    {
      "x": -1,
      "y": 0,
      "z": 4,
      "name": "BO_Parking_Blacktop",
      "rotation": 7
    },
    {
      "x": -1,
      "y": 1,
      "z": 4,
      "name": "BO_Parking_Blacktop",
      "rotation": 7
    },
    {
      "x": -1,
      "y": 2,
      "z": 4,
      "name": "BO_Parking_Blacktop",
      "rotation": 7
    },
    {
      "x": -1,
      "y": 3,
      "z": 4,
      "name": "BO_Parking_Blacktop",
      "rotation": 3
    },
    {
      "x": -1,
      "y": 9,
      "z": 4,
      "name": "BO_Parking_Wall_Half",
      "rotation": 11
    },
    {
      "x": -1,
      "y": 10,
      "z": 4,
      "name": "BO_Parking_Wall00",
      "rotation": 3
    },
    {
      "x": -1,
      "y": 0,
      "z": 5,
      "name": "BO_Parking_Blacktop",
      "rotation": 7
    },
    {
      "x": -1,
      "y": 1,
      "z": 5,
      "name": "BO_Parking_Blacktop",
      "rotation": 7
    },
    {
      "x": -1,
      "y": 2,
      "z": 5,
      "name": "BO_Parking_Blacktop",
      "rotation": 7
    },
    {
      "x": -1,
      "y": 3,
      "z": 5,
      "name": "BO_Parking_Blacktop",
      "rotation": 2
    },
    {
      "x": -1,
      "y": 9,
      "z": 5,
      "name": "BO_Parking_Wall_Half",
      "rotation": 11
    },
    {
      "x": -1,
      "y": 10,
      "z": 5,
      "name": "BO_Parking_Wall00",
      "rotation": 3
    },
    {
      "x": -1,
      "y": 0,
      "z": 6,
      "name": "BO_Parking_Blacktop",
      "rotation": 7
    },
    {
      "x": -1,
      "y": 1,
      "z": 6,
      "name": "BO_Parking_Blacktop",
      "rotation": 7
    },
    {
      "x": -1,
      "y": 2,
      "z": 6,
      "name": "BO_Parking_Blacktop",
      "rotation": 7
    },
    {
      "x": -1,
      "y": 3,
      "z": 6,
      "name": "BO_Parking_Blacktop",
      "rotation": 3
    },
    {
      "x": -1,
      "y": 9,
      "z": 6,
      "name": "BO_Parking_Wall_Half",
      "rotation": 11
    },
    {
      "x": -1,
      "y": 10,
      "z": 6,
      "name": "BO_Parking_Wall00",
      "rotation": 3
    },
    {
      "x": -1,
      "y": 0,
      "z": 7,
      "name": "BO_Parking_Blacktop",
      "rotation": 7
    },
    {
      "x": -1,
      "y": 1,
      "z": 7,
      "name": "BO_Parking_Blacktop",
      "rotation": 7
    },
    {
      "x": -1,
      "y": 2,
      "z": 7,
      "name": "BO_Parking_Blacktop",
      "rotation": 7
    },
    {
      "x": -1,
      "y": 3,
      "z": 7,
      "name": "BO_Parking_Blacktop",
      "rotation": 3
    },
    {
      "x": -1,
      "y": 9,
      "z": 7,
      "name": "BO_Parking_Wall_Half",
      "rotation": 11
    },
    {
      "x": -1,
      "y": 10,
      "z": 7,
      "name": "BO_Parking_Wall00",
      "rotation": 3
    },
    {
      "x": -1,
      "y": 0,
      "z": 8,
      "name": "BO_Parking_Blacktop",
      "rotation": 7
    },
    {
      "x": -1,
      "y": 1,
      "z": 8,
      "name": "BO_Parking_Blacktop",
      "rotation": 7
    },
    {
      "x": -1,
      "y": 2,
      "z": 8,
      "name": "BO_Parking_Blacktop",
      "rotation": 7
    },
    {
      "x": -1,
      "y": 3,
      "z": 8,
      "name": "BO_Parking_Blacktop",
      "rotation": 3
    },
    {
      "x": -1,
      "y": 9,
      "z": 8,
      "name": "BO_Parking_Wall_Half",
      "rotation": 11
    },
    {
      "x": -1,
      "y": 10,
      "z": 8,
      "name": "BO_Parking_Wall00",
      "rotation": 3
    },
    {
      "x": -1,
      "y": 0,
      "z": 9,
      "name": "BO_Parking_Blacktop",
      "rotation": 7
    },
    {
      "x": -1,
      "y": 1,
      "z": 9,
      "name": "BO_Parking_Blacktop",
      "rotation": 7
    },
    {
      "x": -1,
      "y": 2,
      "z": 9,
      "name": "BO_Parking_Blacktop",
      "rotation": 7
    },
    {
      "x": -1,
      "y": 3,
      "z": 9,
      "name": "BO_Parking_Blacktop",
      "rotation": 2
    },
    {
      "x": -1,
      "y": 9,
      "z": 9,
      "name": "BO_Parking_Wall03",
      "rotation": 3
    },
    {
      "x": -1,
      "y": 10,
      "z": 9,
      "name": "BO_Parking_Wall00",
      "rotation": 3
    },
    {
      "x": -1,
      "y": 11,
      "z": 9,
      "name": "Build_Black_Cube",
      "rotation": 3
    },
    {
      "x": -1,
      "y": 0,
      "z": 10,
      "name": "BO_Parking_Blacktop",
      "rotation": 7
    },
    {
      "x": -1,
      "y": 1,
      "z": 10,
      "name": "BO_Parking_Blacktop",
      "rotation": 7
    },
    {
      "x": -1,
      "y": 2,
      "z": 10,
      "name": "BO_Parking_Blacktop",
      "rotation": 7
    },
    {
      "x": -1,
      "y": 3,
      "z": 10,
      "name": "Build_White_Cube",
      "rotation": 3
    },
    {
      "x": -1,
      "y": 4,
      "z": 10,
      "name": "BO_Parking_Wall00",
      "rotation": 3
    },
    {
      "x": -1,
      "y": 5,
      "z": 10,
      "name": "BO_Parking_Wall02",
      "rotation": 3
    },
    {
      "x": -1,
      "y": 6,
      "z": 10,
      "name": "BO_Parking_Wall00",
      "rotation": 3
    },
    {
      "x": -1,
      "y": 7,
      "z": 10,
      "name": "BO_Parking_Wall00",
      "rotation": 3
    },
    {
      "x": -1,
      "y": 8,
      "z": 10,
      "name": "BO_Parking_Wall00",
      "rotation": 3
    },
    {
      "x": -1,
      "y": 9,
      "z": 10,
      "name": "BO_Parking_Wall_Half",
      "rotation": 3
    },
    {
      "x": -1,
      "y": 10,
      "z": 10,
      "name": "BO_Parking_Wall00",
      "rotation": 3
    },
    {
      "x": 0,
      "y": 0,
      "z": -9,
      "name": "BO_Parking_Blacktop",
      "rotation": 7
    },
    {
      "x": 0,
      "y": 1,
      "z": -9,
      "name": "BO_Parking_Blacktop",
      "rotation": 7
    },
    {
      "x": 0,
      "y": 2,
      "z": -9,
      "name": "BO_Parking_Blacktop",
      "rotation": 7
    },
    {
      "x": 0,
      "y": 3,
      "z": -9,
      "name": "BO_Parking_Blacktop",
      "rotation": 7
    },
    {
      "x": 0,
      "y": 9,
      "z": -9,
      "name": "BO_Parking_Wall03",
      "rotation": 3
    },
    {
      "x": 0,
      "y": 10,
      "z": -9,
      "name": "BO_Parking_Wall00",
      "rotation": 3
    },
    {
      "x": 0,
      "y": 0,
      "z": -8,
      "name": "BO_Parking_Blacktop",
      "rotation": 7
    },
    {
      "x": 0,
      "y": 1,
      "z": -8,
      "name": "BO_Parking_Blacktop",
      "rotation": 7
    },
    {
      "x": 0,
      "y": 2,
      "z": -8,
      "name": "BO_Parking_Blacktop",
      "rotation": 7
    },
    {
      "x": 0,
      "y": 3,
      "z": -8,
      "name": "BO_Parking_Blacktop",
      "rotation": 7
    },
    {
      "x": 0,
      "y": 9,
      "z": -8,
      "name": "BO_Parking_Wall_Half",
      "rotation": 11
    },
    {
      "x": 0,
      "y": 10,
      "z": -8,
      "name": "BO_Parking_Wall00",
      "rotation": 3
    },
    {
      "x": 0,
      "y": 0,
      "z": -7,
      "name": "BO_Parking_Blacktop",
      "rotation": 7
    },
    {
      "x": 0,
      "y": 1,
      "z": -7,
      "name": "BO_Parking_Blacktop",
      "rotation": 7
    },
    {
      "x": 0,
      "y": 2,
      "z": -7,
      "name": "BO_Parking_Blacktop",
      "rotation": 7
    },
    {
      "x": 0,
      "y": 3,
      "z": -7,
      "name": "BO_Parking_Blacktop",
      "rotation": 7
    },
    {
      "x": 0,
      "y": 9,
      "z": -7,
      "name": "BO_Parking_Wall_Half",
      "rotation": 11
    },
    {
      "x": 0,
      "y": 10,
      "z": -7,
      "name": "BO_Parking_Wall00",
      "rotation": 3
    },
    {
      "x": 0,
      "y": 0,
      "z": -6,
      "name": "BO_Parking_Blacktop",
      "rotation": 7
    },
    {
      "x": 0,
      "y": 1,
      "z": -6,
      "name": "BO_Parking_Blacktop",
      "rotation": 7
    },
    {
      "x": 0,
      "y": 2,
      "z": -6,
      "name": "BO_Parking_Blacktop",
      "rotation": 7
    },
    {
      "x": 0,
      "y": 3,
      "z": -6,
      "name": "BO_Parking_Blacktop",
      "rotation": 7
    },
    {
      "x": 0,
      "y": 9,
      "z": -6,
      "name": "BO_Parking_Wall_Half",
      "rotation": 11
    },
    {
      "x": 0,
      "y": 10,
      "z": -6,
      "name": "BO_Parking_Wall00",
      "rotation": 3
    },
    {
      "x": 0,
      "y": 0,
      "z": -5,
      "name": "Rock_Stone_Brick",
      "rotation": 7
    },
    {
      "x": 0,
      "y": 1,
      "z": -5,
      "name": "Rock_Stone_Brick",
      "rotation": 7
    },
    {
      "x": 0,
      "y": 2,
      "z": -5,
      "name": "Rock_Stone_Brick",
      "rotation": 7
    },
    {
      "x": 0,
      "y": 3,
      "z": -5,
      "name": "BO_Parking_Blacktop",
      "rotation": 7
    },
    {
      "x": 0,
      "y": 9,
      "z": -5,
      "name": "BO_Parking_Wall_Half",
      "rotation": 11
    },
    {
      "x": 0,
      "y": 10,
      "z": -5,
      "name": "BO_Parking_Wall00",
      "rotation": 3
    },
    {
      "x": 0,
      "y": 0,
      "z": -4,
      "name": "Rock_Stone_Brick",
      "rotation": 7
    },
    {
      "x": 0,
      "y": 1,
      "z": -4,
      "name": "Rock_Stone_Brick",
      "rotation": 7
    },
    {
      "x": 0,
      "y": 2,
      "z": -4,
      "name": "Rock_Stone_Brick",
      "rotation": 7
    },
    {
      "x": 0,
      "y": 3,
      "z": -4,
      "name": "BO_Parking_Blacktop",
      "rotation": 7
    },
    {
      "x": 0,
      "y": 9,
      "z": -4,
      "name": "BO_Parking_Wall_Half",
      "rotation": 11
    },
    {
      "x": 0,
      "y": 10,
      "z": -4,
      "name": "BO_Parking_Wall00",
      "rotation": 3
    },
    {
      "x": 0,
      "y": 0,
      "z": -3,
      "name": "Rock_Stone_Brick",
      "rotation": 3
    },
    {
      "x": 0,
      "y": 1,
      "z": -3,
      "name": "Rock_Stone_Brick",
      "rotation": 3
    },
    {
      "x": 0,
      "y": 2,
      "z": -3,
      "name": "Rock_Stone_Brick",
      "rotation": 3
    },
    {
      "x": 0,
      "y": 3,
      "z": -3,
      "name": "BO_Parking_Blacktop",
      "rotation": 3
    },
    {
      "x": 0,
      "y": 9,
      "z": -3,
      "name": "BO_Parking_Wall_Half",
      "rotation": 11
    },
    {
      "x": 0,
      "y": 10,
      "z": -3,
      "name": "BO_Parking_Wall00",
      "rotation": 3
    },
    {
      "x": 0,
      "y": 0,
      "z": -2,
      "name": "BO_Parking_Blacktop",
      "rotation": 7
    },
    {
      "x": 0,
      "y": 1,
      "z": -2,
      "name": "BO_Parking_Blacktop",
      "rotation": 7
    },
    {
      "x": 0,
      "y": 2,
      "z": -2,
      "name": "BO_Parking_Blacktop",
      "rotation": 7
    },
    {
      "x": 0,
      "y": 3,
      "z": -2,
      "name": "BO_Parking_Blacktop",
      "rotation": 7
    },
    {
      "x": 0,
      "y": 9,
      "z": -2,
      "name": "BO_Parking_Wall_Half",
      "rotation": 11
    },
    {
      "x": 0,
      "y": 10,
      "z": -2,
      "name": "BO_Parking_Wall00",
      "rotation": 3
    },
    {
      "x": 0,
      "y": 0,
      "z": -1,
      "name": "BO_Parking_Blacktop",
      "rotation": 7
    },
    {
      "x": 0,
      "y": 1,
      "z": -1,
      "name": "BO_Parking_Blacktop",
      "rotation": 7
    },
    {
      "x": 0,
      "y": 2,
      "z": -1,
      "name": "BO_Parking_Blacktop",
      "rotation": 7
    },
    {
      "x": 0,
      "y": 3,
      "z": -1,
      "name": "BO_Parking_Blacktop",
      "rotation": 7
    },
    {
      "x": 0,
      "y": 9,
      "z": -1,
      "name": "BO_Parking_Wall_Half",
      "rotation": 11
    },
    {
      "x": 0,
      "y": 10,
      "z": -1,
      "name": "BO_Parking_Wall00",
      "rotation": 3
    },
    {
      "x": 0,
      "y": 0,
      "z": 0,
      "name": "BO_Parking_Blacktop",
      "rotation": 7
    },
    {
      "x": 0,
      "y": 1,
      "z": 0,
      "name": "BO_Parking_Blacktop",
      "rotation": 7
    },
    {
      "x": 0,
      "y": 2,
      "z": 0,
      "name": "BO_Parking_Blacktop",
      "rotation": 7
    },
    {
      "x": 0,
      "y": 3,
      "z": 0,
      "name": "BO_Parking_Blacktop",
      "rotation": 7
    },
    {
      "x": 0,
      "y": 9,
      "z": 0,
      "name": "BO_Parking_Wall03",
      "rotation": 3
    },
    {
      "x": 0,
      "y": 10,
      "z": 0,
      "name": "BO_Parking_Wall03",
      "rotation": 3
    },
    {
      "x": 0,
      "y": 0,
      "z": 1,
      "name": "BO_Parking_Blacktop",
      "rotation": 7
    },
    {
      "x": 0,
      "y": 1,
      "z": 1,
      "name": "BO_Parking_Blacktop",
      "rotation": 7
    },
    {
      "x": 0,
      "y": 2,
      "z": 1,
      "name": "BO_Parking_Blacktop",
      "rotation": 7
    },
    {
      "x": 0,
      "y": 3,
      "z": 1,
      "name": "BO_Parking_Blacktop",
      "rotation": 7
    },
    {
      "x": 0,
      "y": 9,
      "z": 1,
      "name": "BO_Parking_Wall03",
      "rotation": 3
    },
    {
      "x": 0,
      "y": 10,
      "z": 1,
      "name": "BO_Parking_Wall00",
      "rotation": 3
    },
    {
      "x": 0,
      "y": 0,
      "z": 2,
      "name": "BO_Parking_Blacktop",
      "rotation": 7
    },
    {
      "x": 0,
      "y": 1,
      "z": 2,
      "name": "BO_Parking_Blacktop",
      "rotation": 7
    },
    {
      "x": 0,
      "y": 2,
      "z": 2,
      "name": "BO_Parking_Blacktop",
      "rotation": 7
    },
    {
      "x": 0,
      "y": 3,
      "z": 2,
      "name": "BO_Parking_Blacktop",
      "rotation": 3
    },
    {
      "x": 0,
      "y": 9,
      "z": 2,
      "name": "BO_Parking_Wall_Half",
      "rotation": 11
    },
    {
      "x": 0,
      "y": 10,
      "z": 2,
      "name": "BO_Parking_Wall00",
      "rotation": 3
    },
    {
      "x": 0,
      "y": 0,
      "z": 3,
      "name": "BO_Parking_Blacktop",
      "rotation": 7
    },
    {
      "x": 0,
      "y": 1,
      "z": 3,
      "name": "BO_Parking_Blacktop",
      "rotation": 7
    },
    {
      "x": 0,
      "y": 2,
      "z": 3,
      "name": "BO_Parking_Blacktop",
      "rotation": 7
    },
    {
      "x": 0,
      "y": 3,
      "z": 3,
      "name": "BO_Parking_Blacktop",
      "rotation": 3
    },
    {
      "x": 0,
      "y": 9,
      "z": 3,
      "name": "BO_Parking_Wall_Half",
      "rotation": 11
    },
    {
      "x": 0,
      "y": 10,
      "z": 3,
      "name": "BO_Parking_Wall00",
      "rotation": 3
    },
    {
      "x": 0,
      "y": 0,
      "z": 4,
      "name": "BO_Parking_Blacktop",
      "rotation": 7
    },
    {
      "x": 0,
      "y": 1,
      "z": 4,
      "name": "BO_Parking_Blacktop",
      "rotation": 7
    },
    {
      "x": 0,
      "y": 2,
      "z": 4,
      "name": "BO_Parking_Blacktop",
      "rotation": 7
    },
    {
      "x": 0,
      "y": 3,
      "z": 4,
      "name": "BO_Parking_Blacktop",
      "rotation": 7
    },
    {
      "x": 0,
      "y": 9,
      "z": 4,
      "name": "BO_Parking_Wall_Half",
      "rotation": 11
    },
    {
      "x": 0,
      "y": 10,
      "z": 4,
      "name": "BO_Parking_Wall00",
      "rotation": 3
    },
    {
      "x": 0,
      "y": 0,
      "z": 5,
      "name": "Rock_Stone_Brick",
      "rotation": 7
    },
    {
      "x": 0,
      "y": 1,
      "z": 5,
      "name": "Rock_Stone_Brick",
      "rotation": 7
    },
    {
      "x": 0,
      "y": 2,
      "z": 5,
      "name": "Rock_Stone_Brick",
      "rotation": 7
    },
    {
      "x": 0,
      "y": 3,
      "z": 5,
      "name": "BO_Parking_Blacktop",
      "rotation": 7
    },
    {
      "x": 0,
      "y": 9,
      "z": 5,
      "name": "BO_Parking_Wall_Half",
      "rotation": 11
    },
    {
      "x": 0,
      "y": 10,
      "z": 5,
      "name": "BO_Parking_Wall00",
      "rotation": 3
    },
    {
      "x": 0,
      "y": 0,
      "z": 6,
      "name": "Rock_Stone_Brick",
      "rotation": 7
    },
    {
      "x": 0,
      "y": 1,
      "z": 6,
      "name": "Rock_Stone_Brick",
      "rotation": 7
    },
    {
      "x": 0,
      "y": 2,
      "z": 6,
      "name": "Rock_Stone_Brick",
      "rotation": 7
    },
    {
      "x": 0,
      "y": 3,
      "z": 6,
      "name": "BO_Parking_Blacktop",
      "rotation": 7
    },
    {
      "x": 0,
      "y": 9,
      "z": 6,
      "name": "BO_Parking_Wall_Half",
      "rotation": 11
    },
    {
      "x": 0,
      "y": 10,
      "z": 6,
      "name": "BO_Parking_Wall00",
      "rotation": 3
    },
    {
      "x": 0,
      "y": 0,
      "z": 7,
      "name": "Rock_Stone_Brick",
      "rotation": 3
    },
    {
      "x": 0,
      "y": 1,
      "z": 7,
      "name": "Rock_Stone_Brick",
      "rotation": 3
    },
    {
      "x": 0,
      "y": 2,
      "z": 7,
      "name": "Rock_Stone_Brick",
      "rotation": 3
    },
    {
      "x": 0,
      "y": 3,
      "z": 7,
      "name": "BO_Parking_Blacktop",
      "rotation": 3
    },
    {
      "x": 0,
      "y": 9,
      "z": 7,
      "name": "BO_Parking_Wall_Half",
      "rotation": 11
    },
    {
      "x": 0,
      "y": 10,
      "z": 7,
      "name": "BO_Parking_Wall00",
      "rotation": 3
    },
    {
      "x": 0,
      "y": 0,
      "z": 8,
      "name": "BO_Parking_Blacktop",
      "rotation": 7
    },
    {
      "x": 0,
      "y": 1,
      "z": 8,
      "name": "BO_Parking_Blacktop",
      "rotation": 7
    },
    {
      "x": 0,
      "y": 2,
      "z": 8,
      "name": "BO_Parking_Blacktop",
      "rotation": 7
    },
    {
      "x": 0,
      "y": 3,
      "z": 8,
      "name": "BO_Parking_Blacktop",
      "rotation": 7
    },
    {
      "x": 0,
      "y": 9,
      "z": 8,
      "name": "BO_Parking_Wall_Half",
      "rotation": 11
    },
    {
      "x": 0,
      "y": 10,
      "z": 8,
      "name": "BO_Parking_Wall00",
      "rotation": 3
    },
    {
      "x": 0,
      "y": 0,
      "z": 9,
      "name": "BO_Parking_Blacktop",
      "rotation": 7
    },
    {
      "x": 0,
      "y": 1,
      "z": 9,
      "name": "BO_Parking_Blacktop",
      "rotation": 7
    },
    {
      "x": 0,
      "y": 2,
      "z": 9,
      "name": "BO_Parking_Blacktop",
      "rotation": 7
    },
    {
      "x": 0,
      "y": 3,
      "z": 9,
      "name": "BO_Parking_Blacktop",
      "rotation": 7
    },
    {
      "x": 0,
      "y": 9,
      "z": 9,
      "name": "BO_Parking_Wall03",
      "rotation": 3
    },
    {
      "x": 0,
      "y": 10,
      "z": 9,
      "name": "BO_Parking_Wall00",
      "rotation": 3
    },
    {
      "x": 0,
      "y": 11,
      "z": 9,
      "name": "Build_Black_Cube",
      "rotation": 3
    },
    {
      "x": 0,
      "y": 0,
      "z": 10,
      "name": "BO_Parking_Blacktop",
      "rotation": 7
    },
    {
      "x": 0,
      "y": 1,
      "z": 10,
      "name": "BO_Parking_Blacktop",
      "rotation": 7
    },
    {
      "x": 0,
      "y": 2,
      "z": 10,
      "name": "BO_Parking_Blacktop",
      "rotation": 7
    },
    {
      "x": 0,
      "y": 3,
      "z": 10,
      "name": "BO_Parking_Blacktop",
      "rotation": 7
    },
    {
      "x": 0,
      "y": 4,
      "z": 10,
      "name": "BO_Parking_Wall_Half",
      "rotation": 6
    },
    {
      "x": 0,
      "y": 5,
      "z": 10,
      "name": "BO_Parking_Wall_Half",
      "rotation": 6
    },
    {
      "x": 0,
      "y": 6,
      "z": 10,
      "name": "BO_Parking_Wall_Half",
      "rotation": 6
    },
    {
      "x": 0,
      "y": 7,
      "z": 10,
      "name": "BO_Parking_Wall00",
      "rotation": 3
    },
    {
      "x": 0,
      "y": 8,
      "z": 10,
      "name": "BO_Parking_Wall00",
      "rotation": 3
    },
    {
      "x": 0,
      "y": 9,
      "z": 10,
      "name": "BO_Parking_Wall_Half",
      "rotation": 3
    },
    {
      "x": 0,
      "y": 10,
      "z": 10,
      "name": "BO_Parking_Wall00",
      "rotation": 3
    },
    {
      "x": 1,
      "y": 0,
      "z": -9,
      "name": "BO_Parking_Blacktop",
      "rotation": 7
    },
    {
      "x": 1,
      "y": 1,
      "z": -9,
      "name": "BO_Parking_Blacktop",
      "rotation": 7
    },
    {
      "x": 1,
      "y": 2,
      "z": -9,
      "name": "BO_Parking_Blacktop",
      "rotation": 7
    },
    {
      "x": 1,
      "y": 3,
      "z": -9,
      "name": "BO_Parking_Blacktop",
      "rotation": 7
    },
    {
      "x": 1,
      "y": 9,
      "z": -9,
      "name": "BO_Parking_Wall03",
      "rotation": 3
    },
    {
      "x": 1,
      "y": 10,
      "z": -9,
      "name": "BO_Parking_Wall00",
      "rotation": 3
    },
    {
      "x": 1,
      "y": 0,
      "z": -8,
      "name": "BO_Parking_Blacktop",
      "rotation": 7
    },
    {
      "x": 1,
      "y": 1,
      "z": -8,
      "name": "BO_Parking_Blacktop",
      "rotation": 7
    },
    {
      "x": 1,
      "y": 2,
      "z": -8,
      "name": "BO_Parking_Blacktop",
      "rotation": 7
    },
    {
      "x": 1,
      "y": 3,
      "z": -8,
      "name": "BO_Parking_Blacktop",
      "rotation": 7
    },
    {
      "x": 1,
      "y": 9,
      "z": -8,
      "name": "BO_Parking_Wall_Half",
      "rotation": 11
    },
    {
      "x": 1,
      "y": 10,
      "z": -8,
      "name": "BO_Parking_Wall00",
      "rotation": 3
    },
    {
      "x": 1,
      "y": 0,
      "z": -7,
      "name": "BO_Parking_Blacktop",
      "rotation": 7
    },
    {
      "x": 1,
      "y": 1,
      "z": -7,
      "name": "BO_Parking_Blacktop",
      "rotation": 7
    },
    {
      "x": 1,
      "y": 2,
      "z": -7,
      "name": "BO_Parking_Blacktop",
      "rotation": 7
    },
    {
      "x": 1,
      "y": 3,
      "z": -7,
      "name": "BO_Parking_Blacktop",
      "rotation": 7
    },
    {
      "x": 1,
      "y": 9,
      "z": -7,
      "name": "BO_Parking_Wall_Half",
      "rotation": 11
    },
    {
      "x": 1,
      "y": 10,
      "z": -7,
      "name": "BO_Parking_Wall00",
      "rotation": 3
    },
    {
      "x": 1,
      "y": 0,
      "z": -6,
      "name": "BO_Parking_Blacktop",
      "rotation": 7
    },
    {
      "x": 1,
      "y": 1,
      "z": -6,
      "name": "BO_Parking_Blacktop",
      "rotation": 7
    },
    {
      "x": 1,
      "y": 2,
      "z": -6,
      "name": "BO_Parking_Blacktop",
      "rotation": 7
    },
    {
      "x": 1,
      "y": 3,
      "z": -6,
      "name": "BO_Parking_Blacktop",
      "rotation": 7
    },
    {
      "x": 1,
      "y": 9,
      "z": -6,
      "name": "BO_Parking_Wall_Half",
      "rotation": 11
    },
    {
      "x": 1,
      "y": 10,
      "z": -6,
      "name": "BO_Parking_Wall00",
      "rotation": 3
    },
    {
      "x": 1,
      "y": 0,
      "z": -5,
      "name": "Rock_Stone_Brick",
      "rotation": 7
    },
    {
      "x": 1,
      "y": 1,
      "z": -5,
      "name": "Rock_Stone_Brick",
      "rotation": 7
    },
    {
      "x": 1,
      "y": 2,
      "z": -5,
      "name": "Rock_Stone_Brick",
      "rotation": 7
    },
    {
      "x": 1,
      "y": 3,
      "z": -5,
      "name": "BO_Parking_Blacktop",
      "rotation": 7
    },
    {
      "x": 1,
      "y": 9,
      "z": -5,
      "name": "BO_Parking_Wall_Half",
      "rotation": 11
    },
    {
      "x": 1,
      "y": 10,
      "z": -5,
      "name": "BO_Parking_Wall00",
      "rotation": 3
    },
    {
      "x": 1,
      "y": 0,
      "z": -4,
      "name": "BO_Parking_Blacktop",
      "rotation": 7
    },
    {
      "x": 1,
      "y": 1,
      "z": -4,
      "name": "BO_Parking_Blacktop",
      "rotation": 7
    },
    {
      "x": 1,
      "y": 2,
      "z": -4,
      "name": "BO_Parking_Blacktop",
      "rotation": 7
    },
    {
      "x": 1,
      "y": 3,
      "z": -4,
      "name": "BO_Parking_Blacktop",
      "rotation": 7
    },
    {
      "x": 1,
      "y": 9,
      "z": -4,
      "name": "BO_Parking_Wall_Half",
      "rotation": 11
    },
    {
      "x": 1,
      "y": 10,
      "z": -4,
      "name": "BO_Parking_Wall00",
      "rotation": 3
    },
    {
      "x": 1,
      "y": 0,
      "z": -3,
      "name": "Rock_Stone_Brick",
      "rotation": 3
    },
    {
      "x": 1,
      "y": 1,
      "z": -3,
      "name": "Rock_Stone_Brick",
      "rotation": 3
    },
    {
      "x": 1,
      "y": 2,
      "z": -3,
      "name": "Rock_Stone_Brick",
      "rotation": 3
    },
    {
      "x": 1,
      "y": 3,
      "z": -3,
      "name": "BO_Parking_Blacktop",
      "rotation": 3
    },
    {
      "x": 1,
      "y": 9,
      "z": -3,
      "name": "BO_Parking_Wall_Half",
      "rotation": 11
    },
    {
      "x": 1,
      "y": 10,
      "z": -3,
      "name": "BO_Parking_Wall00",
      "rotation": 3
    },
    {
      "x": 1,
      "y": 0,
      "z": -2,
      "name": "BO_Parking_Blacktop",
      "rotation": 7
    },
    {
      "x": 1,
      "y": 1,
      "z": -2,
      "name": "BO_Parking_Blacktop",
      "rotation": 7
    },
    {
      "x": 1,
      "y": 2,
      "z": -2,
      "name": "BO_Parking_Blacktop",
      "rotation": 7
    },
    {
      "x": 1,
      "y": 3,
      "z": -2,
      "name": "BO_Parking_Blacktop",
      "rotation": 7
    },
    {
      "x": 1,
      "y": 9,
      "z": -2,
      "name": "BO_Parking_Wall_Half",
      "rotation": 11
    },
    {
      "x": 1,
      "y": 10,
      "z": -2,
      "name": "BO_Parking_Wall00",
      "rotation": 3
    },
    {
      "x": 1,
      "y": 0,
      "z": -1,
      "name": "BO_Parking_Blacktop",
      "rotation": 7
    },
    {
      "x": 1,
      "y": 1,
      "z": -1,
      "name": "BO_Parking_Blacktop",
      "rotation": 7
    },
    {
      "x": 1,
      "y": 2,
      "z": -1,
      "name": "BO_Parking_Blacktop",
      "rotation": 7
    },
    {
      "x": 1,
      "y": 3,
      "z": -1,
      "name": "BO_Parking_Blacktop",
      "rotation": 7
    },
    {
      "x": 1,
      "y": 9,
      "z": -1,
      "name": "BO_Parking_Wall_Half",
      "rotation": 11
    },
    {
      "x": 1,
      "y": 10,
      "z": -1,
      "name": "BO_Parking_Wall00",
      "rotation": 3
    },
    {
      "x": 1,
      "y": 0,
      "z": 0,
      "name": "BO_Parking_Blacktop",
      "rotation": 7
    },
    {
      "x": 1,
      "y": 1,
      "z": 0,
      "name": "BO_Parking_Blacktop",
      "rotation": 7
    },
    {
      "x": 1,
      "y": 2,
      "z": 0,
      "name": "BO_Parking_Blacktop",
      "rotation": 7
    },
    {
      "x": 1,
      "y": 3,
      "z": 0,
      "name": "BO_Parking_Blacktop",
      "rotation": 7
    },
    {
      "x": 1,
      "y": 9,
      "z": 0,
      "name": "BO_Parking_Wall03",
      "rotation": 3
    },
    {
      "x": 1,
      "y": 10,
      "z": 0,
      "name": "BO_Parking_Wall00",
      "rotation": 3
    },
    {
      "x": 1,
      "y": 0,
      "z": 1,
      "name": "BO_Parking_Blacktop",
      "rotation": 7
    },
    {
      "x": 1,
      "y": 1,
      "z": 1,
      "name": "BO_Parking_Blacktop",
      "rotation": 7
    },
    {
      "x": 1,
      "y": 2,
      "z": 1,
      "name": "BO_Parking_Blacktop",
      "rotation": 7
    },
    {
      "x": 1,
      "y": 3,
      "z": 1,
      "name": "BO_Parking_Blacktop",
      "rotation": 7
    },
    {
      "x": 1,
      "y": 9,
      "z": 1,
      "name": "BO_Parking_Wall03",
      "rotation": 3
    },
    {
      "x": 1,
      "y": 10,
      "z": 1,
      "name": "BO_Parking_Wall00",
      "rotation": 3
    },
    {
      "x": 1,
      "y": 0,
      "z": 2,
      "name": "BO_Parking_Blacktop",
      "rotation": 7
    },
    {
      "x": 1,
      "y": 1,
      "z": 2,
      "name": "BO_Parking_Blacktop",
      "rotation": 7
    },
    {
      "x": 1,
      "y": 2,
      "z": 2,
      "name": "BO_Parking_Blacktop",
      "rotation": 7
    },
    {
      "x": 1,
      "y": 3,
      "z": 2,
      "name": "BO_Parking_Blacktop",
      "rotation": 7
    },
    {
      "x": 1,
      "y": 9,
      "z": 2,
      "name": "BO_Parking_Wall_Half",
      "rotation": 11
    },
    {
      "x": 1,
      "y": 10,
      "z": 2,
      "name": "BO_Parking_Wall00",
      "rotation": 3
    },
    {
      "x": 1,
      "y": 0,
      "z": 3,
      "name": "BO_Parking_Blacktop",
      "rotation": 7
    },
    {
      "x": 1,
      "y": 1,
      "z": 3,
      "name": "BO_Parking_Blacktop",
      "rotation": 7
    },
    {
      "x": 1,
      "y": 2,
      "z": 3,
      "name": "BO_Parking_Blacktop",
      "rotation": 7
    },
    {
      "x": 1,
      "y": 3,
      "z": 3,
      "name": "BO_Parking_Blacktop",
      "rotation": 3
    },
    {
      "x": 1,
      "y": 9,
      "z": 3,
      "name": "BO_Parking_Wall_Half",
      "rotation": 11
    },
    {
      "x": 1,
      "y": 10,
      "z": 3,
      "name": "BO_Parking_Wall00",
      "rotation": 3
    },
    {
      "x": 1,
      "y": 0,
      "z": 4,
      "name": "BO_Parking_Blacktop",
      "rotation": 7
    },
    {
      "x": 1,
      "y": 1,
      "z": 4,
      "name": "BO_Parking_Blacktop",
      "rotation": 7
    },
    {
      "x": 1,
      "y": 2,
      "z": 4,
      "name": "BO_Parking_Blacktop",
      "rotation": 7
    },
    {
      "x": 1,
      "y": 3,
      "z": 4,
      "name": "BO_Parking_Blacktop",
      "rotation": 3
    },
    {
      "x": 1,
      "y": 9,
      "z": 4,
      "name": "BO_Parking_Wall_Half",
      "rotation": 11
    },
    {
      "x": 1,
      "y": 10,
      "z": 4,
      "name": "BO_Parking_Wall00",
      "rotation": 3
    },
    {
      "x": 1,
      "y": 0,
      "z": 5,
      "name": "Rock_Stone_Brick",
      "rotation": 7
    },
    {
      "x": 1,
      "y": 1,
      "z": 5,
      "name": "Rock_Stone_Brick",
      "rotation": 7
    },
    {
      "x": 1,
      "y": 2,
      "z": 5,
      "name": "Rock_Stone_Brick",
      "rotation": 7
    },
    {
      "x": 1,
      "y": 3,
      "z": 5,
      "name": "BO_Parking_Blacktop",
      "rotation": 3
    },
    {
      "x": 1,
      "y": 9,
      "z": 5,
      "name": "BO_Parking_Wall_Half",
      "rotation": 11
    },
    {
      "x": 1,
      "y": 10,
      "z": 5,
      "name": "BO_Parking_Wall00",
      "rotation": 3
    },
    {
      "x": 1,
      "y": 0,
      "z": 6,
      "name": "BO_Parking_Blacktop",
      "rotation": 7
    },
    {
      "x": 1,
      "y": 1,
      "z": 6,
      "name": "BO_Parking_Blacktop",
      "rotation": 7
    },
    {
      "x": 1,
      "y": 2,
      "z": 6,
      "name": "BO_Parking_Blacktop",
      "rotation": 7
    },
    {
      "x": 1,
      "y": 3,
      "z": 6,
      "name": "BO_Parking_Blacktop",
      "rotation": 3
    },
    {
      "x": 1,
      "y": 9,
      "z": 6,
      "name": "BO_Parking_Wall_Half",
      "rotation": 11
    },
    {
      "x": 1,
      "y": 10,
      "z": 6,
      "name": "BO_Parking_Wall00",
      "rotation": 3
    },
    {
      "x": 1,
      "y": 0,
      "z": 7,
      "name": "Rock_Stone_Brick",
      "rotation": 3
    },
    {
      "x": 1,
      "y": 1,
      "z": 7,
      "name": "Rock_Stone_Brick",
      "rotation": 3
    },
    {
      "x": 1,
      "y": 2,
      "z": 7,
      "name": "Rock_Stone_Brick",
      "rotation": 3
    },
    {
      "x": 1,
      "y": 3,
      "z": 7,
      "name": "BO_Parking_Blacktop",
      "rotation": 3
    },
    {
      "x": 1,
      "y": 9,
      "z": 7,
      "name": "BO_Parking_Wall_Half",
      "rotation": 11
    },
    {
      "x": 1,
      "y": 10,
      "z": 7,
      "name": "BO_Parking_Wall00",
      "rotation": 3
    },
    {
      "x": 1,
      "y": 0,
      "z": 8,
      "name": "BO_Parking_Blacktop",
      "rotation": 7
    },
    {
      "x": 1,
      "y": 1,
      "z": 8,
      "name": "BO_Parking_Blacktop",
      "rotation": 7
    },
    {
      "x": 1,
      "y": 2,
      "z": 8,
      "name": "BO_Parking_Blacktop",
      "rotation": 7
    },
    {
      "x": 1,
      "y": 3,
      "z": 8,
      "name": "BO_Parking_Blacktop",
      "rotation": 3
    },
    {
      "x": 1,
      "y": 9,
      "z": 8,
      "name": "BO_Parking_Wall_Half",
      "rotation": 11
    },
    {
      "x": 1,
      "y": 10,
      "z": 8,
      "name": "BO_Parking_Wall00",
      "rotation": 3
    },
    {
      "x": 1,
      "y": 0,
      "z": 9,
      "name": "BO_Parking_Blacktop",
      "rotation": 7
    },
    {
      "x": 1,
      "y": 1,
      "z": 9,
      "name": "BO_Parking_Blacktop",
      "rotation": 7
    },
    {
      "x": 1,
      "y": 2,
      "z": 9,
      "name": "BO_Parking_Blacktop",
      "rotation": 7
    },
    {
      "x": 1,
      "y": 3,
      "z": 9,
      "name": "BO_Parking_Blacktop",
      "rotation": 3
    },
    {
      "x": 1,
      "y": 7,
      "z": 9,
      "name": "*BO_PA_State_Definitions_Active",
      "components": {
        "Components": {
          "BlackoutCycleState": {
            "OnState": "Active",
            "OffState": "Inactive"
          },
          "PlacedByInteraction": {
            "WhoPlacedUuid": {
              "$binary": "KMPE5JWxSQGC8WI/IkVLQQ==",
              "$type": "04"
            }
          }
        }
      },
      "rotation": 2
    },
    {
      "x": 1,
      "y": 9,
      "z": 9,
      "name": "BO_Parking_Wall03",
      "rotation": 3
    },
    {
      "x": 1,
      "y": 10,
      "z": 9,
      "name": "BO_Parking_Wall00",
      "rotation": 3
    },
    {
      "x": 1,
      "y": 11,
      "z": 9,
      "name": "Build_Black_Cube",
      "rotation": 3
    },
    {
      "x": 1,
      "y": 0,
      "z": 10,
      "name": "BO_Parking_Blacktop",
      "rotation": 7
    },
    {
      "x": 1,
      "y": 1,
      "z": 10,
      "name": "BO_Parking_Blacktop",
      "rotation": 7
    },
    {
      "x": 1,
      "y": 2,
      "z": 10,
      "name": "BO_Parking_Blacktop",
      "rotation": 7
    },
    {
      "x": 1,
      "y": 3,
      "z": 10,
      "name": "BO_Parking_Blacktop",
      "rotation": 3
    },
    {
      "x": 1,
      "y": 4,
      "z": 10,
      "name": "BO_Parking_Wall_Half",
      "rotation": 6
    },
    {
      "x": 1,
      "y": 5,
      "z": 10,
      "name": "BO_Parking_Wall_Half",
      "rotation": 6
    },
    {
      "x": 1,
      "y": 6,
      "z": 10,
      "name": "BO_Parking_Wall_Half",
      "rotation": 6
    },
    {
      "x": 1,
      "y": 7,
      "z": 10,
      "name": "BO_Parking_Wall00",
      "rotation": 3
    },
    {
      "x": 1,
      "y": 8,
      "z": 10,
      "name": "BO_Parking_Wall00",
      "rotation": 3
    },
    {
      "x": 1,
      "y": 9,
      "z": 10,
      "name": "BO_Parking_Wall_Half",
      "rotation": 3
    },
    {
      "x": 1,
      "y": 10,
      "z": 10,
      "name": "BO_Parking_Wall00",
      "rotation": 3
    },
    {
      "x": 2,
      "y": 0,
      "z": -9,
      "name": "BO_Parking_Blacktop",
      "rotation": 7
    },
    {
      "x": 2,
      "y": 1,
      "z": -9,
      "name": "BO_Parking_Blacktop",
      "rotation": 7
    },
    {
      "x": 2,
      "y": 2,
      "z": -9,
      "name": "BO_Parking_Blacktop",
      "rotation": 7
    },
    {
      "x": 2,
      "y": 3,
      "z": -9,
      "name": "BO_Parking_Blacktop",
      "rotation": 7
    },
    {
      "x": 2,
      "y": 9,
      "z": -9,
      "name": "BO_Parking_Wall03",
      "rotation": 3
    },
    {
      "x": 2,
      "y": 10,
      "z": -9,
      "name": "BO_Parking_Wall00",
      "rotation": 3
    },
    {
      "x": 2,
      "y": 0,
      "z": -8,
      "name": "BO_Parking_Blacktop",
      "rotation": 7
    },
    {
      "x": 2,
      "y": 1,
      "z": -8,
      "name": "BO_Parking_Blacktop",
      "rotation": 7
    },
    {
      "x": 2,
      "y": 2,
      "z": -8,
      "name": "BO_Parking_Blacktop",
      "rotation": 7
    },
    {
      "x": 2,
      "y": 3,
      "z": -8,
      "name": "BO_Parking_Blacktop",
      "rotation": 7
    },
    {
      "x": 2,
      "y": 9,
      "z": -8,
      "name": "BO_Parking_Wall_Half",
      "rotation": 11
    },
    {
      "x": 2,
      "y": 10,
      "z": -8,
      "name": "BO_Parking_Wall00",
      "rotation": 3
    },
    {
      "x": 2,
      "y": 0,
      "z": -7,
      "name": "BO_Parking_Blacktop",
      "rotation": 7
    },
    {
      "x": 2,
      "y": 1,
      "z": -7,
      "name": "BO_Parking_Blacktop",
      "rotation": 7
    },
    {
      "x": 2,
      "y": 2,
      "z": -7,
      "name": "BO_Parking_Blacktop",
      "rotation": 7
    },
    {
      "x": 2,
      "y": 3,
      "z": -7,
      "name": "BO_Parking_Blacktop",
      "rotation": 7
    },
    {
      "x": 2,
      "y": 9,
      "z": -7,
      "name": "BO_Parking_Wall_Half",
      "rotation": 11
    },
    {
      "x": 2,
      "y": 10,
      "z": -7,
      "name": "BO_Parking_Wall00",
      "rotation": 3
    },
    {
      "x": 2,
      "y": 0,
      "z": -6,
      "name": "BO_Parking_Blacktop",
      "rotation": 7
    },
    {
      "x": 2,
      "y": 1,
      "z": -6,
      "name": "BO_Parking_Blacktop",
      "rotation": 7
    },
    {
      "x": 2,
      "y": 2,
      "z": -6,
      "name": "BO_Parking_Blacktop",
      "rotation": 7
    },
    {
      "x": 2,
      "y": 3,
      "z": -6,
      "name": "BO_Parking_Blacktop",
      "rotation": 7
    },
    {
      "x": 2,
      "y": 9,
      "z": -6,
      "name": "BO_Parking_Wall_Half",
      "rotation": 11
    },
    {
      "x": 2,
      "y": 10,
      "z": -6,
      "name": "BO_Parking_Wall00",
      "rotation": 3
    },
    {
      "x": 2,
      "y": 0,
      "z": -5,
      "name": "Rock_Stone_Brick",
      "rotation": 4
    },
    {
      "x": 2,
      "y": 1,
      "z": -5,
      "name": "Rock_Stone_Brick",
      "rotation": 4
    },
    {
      "x": 2,
      "y": 2,
      "z": -5,
      "name": "Rock_Stone_Brick",
      "rotation": 4
    },
    {
      "x": 2,
      "y": 3,
      "z": -5,
      "name": "BO_Parking_Blacktop",
      "rotation": 3
    },
    {
      "x": 2,
      "y": 9,
      "z": -5,
      "name": "BO_Parking_Wall_Half",
      "rotation": 11
    },
    {
      "x": 2,
      "y": 10,
      "z": -5,
      "name": "BO_Parking_Wall00",
      "rotation": 3
    },
    {
      "x": 2,
      "y": 0,
      "z": -4,
      "name": "Rock_Stone_Brick",
      "rotation": 7
    },
    {
      "x": 2,
      "y": 1,
      "z": -4,
      "name": "Rock_Stone_Brick",
      "rotation": 7
    },
    {
      "x": 2,
      "y": 2,
      "z": -4,
      "name": "Rock_Stone_Brick",
      "rotation": 7
    },
    {
      "x": 2,
      "y": 3,
      "z": -4,
      "name": "BO_Parking_Blacktop",
      "rotation": 3
    },
    {
      "x": 2,
      "y": 9,
      "z": -4,
      "name": "BO_Parking_Wall_Half",
      "rotation": 11
    },
    {
      "x": 2,
      "y": 10,
      "z": -4,
      "name": "BO_Parking_Wall00",
      "rotation": 3
    },
    {
      "x": 2,
      "y": 0,
      "z": -3,
      "name": "Rock_Stone_Brick",
      "rotation": 3
    },
    {
      "x": 2,
      "y": 1,
      "z": -3,
      "name": "Rock_Stone_Brick",
      "rotation": 3
    },
    {
      "x": 2,
      "y": 2,
      "z": -3,
      "name": "Rock_Stone_Brick",
      "rotation": 3
    },
    {
      "x": 2,
      "y": 3,
      "z": -3,
      "name": "BO_Parking_Blacktop",
      "rotation": 3
    },
    {
      "x": 2,
      "y": 9,
      "z": -3,
      "name": "BO_Parking_Wall_Half",
      "rotation": 11
    },
    {
      "x": 2,
      "y": 10,
      "z": -3,
      "name": "BO_Parking_Wall00",
      "rotation": 3
    },
    {
      "x": 2,
      "y": 0,
      "z": -2,
      "name": "BO_Parking_Blacktop",
      "rotation": 7
    },
    {
      "x": 2,
      "y": 1,
      "z": -2,
      "name": "BO_Parking_Blacktop",
      "rotation": 7
    },
    {
      "x": 2,
      "y": 2,
      "z": -2,
      "name": "BO_Parking_Blacktop",
      "rotation": 7
    },
    {
      "x": 2,
      "y": 3,
      "z": -2,
      "name": "BO_Parking_Blacktop",
      "rotation": 7
    },
    {
      "x": 2,
      "y": 9,
      "z": -2,
      "name": "BO_Parking_Wall_Half",
      "rotation": 11
    },
    {
      "x": 2,
      "y": 10,
      "z": -2,
      "name": "BO_Parking_Wall00",
      "rotation": 3
    },
    {
      "x": 2,
      "y": 0,
      "z": -1,
      "name": "BO_Parking_Blacktop",
      "rotation": 7
    },
    {
      "x": 2,
      "y": 1,
      "z": -1,
      "name": "BO_Parking_Blacktop",
      "rotation": 7
    },
    {
      "x": 2,
      "y": 2,
      "z": -1,
      "name": "BO_Parking_Blacktop",
      "rotation": 7
    },
    {
      "x": 2,
      "y": 3,
      "z": -1,
      "name": "BO_Parking_Blacktop",
      "rotation": 7
    },
    {
      "x": 2,
      "y": 9,
      "z": -1,
      "name": "BO_Parking_Wall_Half",
      "rotation": 11
    },
    {
      "x": 2,
      "y": 10,
      "z": -1,
      "name": "BO_Parking_Wall00",
      "rotation": 3
    },
    {
      "x": 2,
      "y": 0,
      "z": 0,
      "name": "BO_Parking_Blacktop",
      "rotation": 7
    },
    {
      "x": 2,
      "y": 1,
      "z": 0,
      "name": "BO_Parking_Blacktop",
      "rotation": 7
    },
    {
      "x": 2,
      "y": 2,
      "z": 0,
      "name": "BO_Parking_Blacktop",
      "rotation": 7
    },
    {
      "x": 2,
      "y": 3,
      "z": 0,
      "name": "BO_Parking_Blacktop",
      "rotation": 7
    },
    {
      "x": 2,
      "y": 9,
      "z": 0,
      "name": "BO_Parking_Wall03",
      "rotation": 3
    },
    {
      "x": 2,
      "y": 10,
      "z": 0,
      "name": "BO_Parking_Wall00",
      "rotation": 3
    },
    {
      "x": 2,
      "y": 0,
      "z": 1,
      "name": "BO_Parking_Blacktop",
      "rotation": 7
    },
    {
      "x": 2,
      "y": 1,
      "z": 1,
      "name": "BO_Parking_Blacktop",
      "rotation": 7
    },
    {
      "x": 2,
      "y": 2,
      "z": 1,
      "name": "BO_Parking_Blacktop",
      "rotation": 7
    },
    {
      "x": 2,
      "y": 3,
      "z": 1,
      "name": "BO_Parking_Blacktop",
      "rotation": 7
    },
    {
      "x": 2,
      "y": 9,
      "z": 1,
      "name": "BO_Parking_Wall03",
      "rotation": 3
    },
    {
      "x": 2,
      "y": 10,
      "z": 1,
      "name": "BO_Parking_Wall00",
      "rotation": 3
    },
    {
      "x": 2,
      "y": 0,
      "z": 2,
      "name": "BO_Parking_Blacktop",
      "rotation": 7
    },
    {
      "x": 2,
      "y": 1,
      "z": 2,
      "name": "BO_Parking_Blacktop",
      "rotation": 7
    },
    {
      "x": 2,
      "y": 2,
      "z": 2,
      "name": "BO_Parking_Blacktop",
      "rotation": 7
    },
    {
      "x": 2,
      "y": 3,
      "z": 2,
      "name": "BO_Parking_Blacktop",
      "rotation": 3
    },
    {
      "x": 2,
      "y": 9,
      "z": 2,
      "name": "BO_Parking_Wall_Half",
      "rotation": 11
    },
    {
      "x": 2,
      "y": 10,
      "z": 2,
      "name": "BO_Parking_Wall00",
      "rotation": 3
    },
    {
      "x": 2,
      "y": 0,
      "z": 3,
      "name": "BO_Parking_Blacktop",
      "rotation": 7
    },
    {
      "x": 2,
      "y": 1,
      "z": 3,
      "name": "BO_Parking_Blacktop",
      "rotation": 7
    },
    {
      "x": 2,
      "y": 2,
      "z": 3,
      "name": "BO_Parking_Blacktop",
      "rotation": 7
    },
    {
      "x": 2,
      "y": 3,
      "z": 3,
      "name": "BO_Parking_Blacktop",
      "rotation": 3
    },
    {
      "x": 2,
      "y": 9,
      "z": 3,
      "name": "BO_Parking_Wall_Half",
      "rotation": 11
    },
    {
      "x": 2,
      "y": 10,
      "z": 3,
      "name": "BO_Parking_Wall00",
      "rotation": 3
    },
    {
      "x": 2,
      "y": 0,
      "z": 4,
