{
  "version": 8,
  "blockIdVersion": 11,
  "anchorX": 0,
  "anchorY": 0,
  "anchorZ": 0,
  "blocks": [
    {
      "x": -15,
      "y": 0,
      "z": -10,
      "name": "Rock_Chalk_Brick_Smooth"
    },
    {
      "x": -15,
      "y": 1,
      "z": -10,
      "name": "Rock_Chalk_Brick_Smooth"
    },
    {
      "x": -15,
      "y": 2,
      "z": -10,
      "name": "Rock_Chalk_Brick_Smooth"
    },
    {
      "x": -15,
      "y": 3,
      "z": -10,
      "name": "Rock_Chalk_Brick_Smooth"
    },
    {
      "x": -15,
      "y": 4,
      "z": -10,
      "name": "Rock_Chalk_Beam"
    },
    {
      "x": -15,
      "y": 5,
      "z": -10,
      "name": "Rock_Chalk_Beam"
    },
    {
      "x": -15,
      "y": 6,
      "z": -10,
      "name": "Rock_Chalk_Beam"
    },
    {
      "x": -15,
      "y": 7,
      "z": -10,
      "name": "Rock_Chalk_Beam"
    },
    {
      "x": -15,
      "y": 8,
      "z": -10,
      "name": "Rock_Chalk_Brick_Smooth"
    },
    {
      "x": -15,
      "y": 9,
      "z": -10,
      "name": "Rock_Chalk_Brick_Smooth"
    },
    {
      "x": -15,
      "y": 10,
      "z": -10,
      "name": "Rock_Chalk_Brick_Smooth"
    },
    {
      "x": -15,
      "y": 11,
      "z": -10,
      "name": "Rock_Chalk_Brick_Smooth"
    },
    {
      "x": -15,
      "y": 0,
      "z": -9,
      "name": "Rock_Chalk_Brick_Smooth"
    },
    {
      "x": -15,
      "y": 1,
      "z": -9,
      "name": "Rock_Chalk_Brick_Smooth"
    },
    {
      "x": -15,
      "y": 2,
      "z": -9,
      "name": "Rock_Chalk_Brick_Smooth"
    },
    {
      "x": -15,
      "y": 3,
      "z": -9,
      "name": "Rock_Chalk_Brick_Smooth"
    },
    {
      "x": -15,
      "y": 8,
      "z": -9,
      "name": "Rock_Chalk_Brick_Smooth"
    },
    {
      "x": -15,
      "y": 9,
      "z": -9,
      "name": "Rock_Chalk_Brick_Smooth"
    },
    {
      "x": -15,
      "y": 10,
      "z": -9,
      "name": "Rock_Chalk_Brick_Smooth"
    },
    {
      "x": -15,
      "y": 11,
      "z": -9,
      "name": "Rock_Chalk_Brick_Smooth"
    },
    {
      "x": -15,
      "y": 0,
      "z": -8,
      "name": "Rock_Chalk_Brick_Smooth"
    },
    {
      "x": -15,
      "y": 1,
      "z": -8,
      "name": "Rock_Chalk_Brick_Smooth"
    },
    {
      "x": -15,
      "y": 2,
      "z": -8,
      "name": "Rock_Chalk_Brick_Smooth"
    },
    {
      "x": -15,
      "y": 3,
      "z": -8,
      "name": "Rock_Chalk_Brick_Smooth"
    },
    {
      "x": -15,
      "y": 8,
      "z": -8,
      "name": "Rock_Chalk_Brick_Smooth"
    },
    {
      "x": -15,
      "y": 9,
      "z": -8,
      "name": "Rock_Chalk_Brick_Smooth"
    },
    {
      "x": -15,
      "y": 10,
      "z": -8,
      "name": "Rock_Chalk_Brick_Smooth"
    },
    {
      "x": -15,
      "y": 11,
      "z": -8,
      "name": "Rock_Chalk_Brick_Smooth"
    },
    {
      "x": -15,
      "y": 0,
      "z": -7,
      "name": "Rock_Chalk_Brick_Smooth"
    },
    {
      "x": -15,
      "y": 1,
      "z": -7,
      "name": "Rock_Chalk_Brick_Smooth"
    },
    {
      "x": -15,
      "y": 2,
      "z": -7,
      "name": "Rock_Chalk_Brick_Smooth"
    },
    {
      "x": -15,
      "y": 3,
      "z": -7,
      "name": "Rock_Chalk_Brick_Smooth"
    },
    {
      "x": -15,
      "y": 8,
      "z": -7,
      "name": "Rock_Chalk_Brick_Smooth"
    },
    {
      "x": -15,
      "y": 9,
      "z": -7,
      "name": "Rock_Chalk_Brick_Smooth"
    },
    {
      "x": -15,
      "y": 10,
      "z": -7,
      "name": "Rock_Chalk_Brick_Smooth"
    },
    {
      "x": -15,
      "y": 11,
      "z": -7,
      "name": "Rock_Chalk_Brick_Smooth"
    },
    {
      "x": -15,
      "y": 0,
      "z": -6,
      "name": "Rock_Chalk_Brick_Smooth"
    },
    {
      "x": -15,
      "y": 1,
      "z": -6,
      "name": "Rock_Chalk_Brick_Smooth"
    },
    {
      "x": -15,
      "y": 2,
      "z": -6,
      "name": "Rock_Chalk_Brick_Smooth"
    },
    {
      "x": -15,
      "y": 3,
      "z": -6,
      "name": "Rock_Chalk_Brick_Smooth"
    },
    {
      "x": -15,
      "y": 8,
      "z": -6,
      "name": "Rock_Chalk_Brick_Smooth"
    },
    {
      "x": -15,
      "y": 9,
      "z": -6,
      "name": "Rock_Chalk_Brick_Smooth"
    },
    {
      "x": -15,
      "y": 10,
      "z": -6,
      "name": "Rock_Chalk_Brick_Smooth"
    },
    {
      "x": -15,
      "y": 11,
      "z": -6,
      "name": "Rock_Chalk_Brick_Smooth"
    },
    {
      "x": -15,
      "y": 0,
      "z": -5,
      "name": "Rock_Chalk_Brick_Smooth"
    },
    {
      "x": -15,
      "y": 1,
      "z": -5,
      "name": "Rock_Chalk_Brick_Smooth"
    },
    {
      "x": -15,
      "y": 2,
      "z": -5,
      "name": "Rock_Chalk_Brick_Smooth"
    },
    {
      "x": -15,
      "y": 3,
      "z": -5,
      "name": "Rock_Chalk_Brick_Smooth"
    },
    {
      "x": -15,
      "y": 8,
      "z": -5,
      "name": "Rock_Chalk_Brick_Smooth"
    },
    {
      "x": -15,
      "y": 9,
      "z": -5,
      "name": "Rock_Chalk_Brick_Smooth"
    },
    {
      "x": -15,
      "y": 10,
      "z": -5,
      "name": "Rock_Chalk_Brick_Smooth"
    },
    {
      "x": -15,
      "y": 11,
      "z": -5,
      "name": "Rock_Chalk_Brick_Smooth"
    },
    {
      "x": -15,
      "y": 0,
      "z": -4,
      "name": "Rock_Chalk_Brick_Smooth"
    },
    {
      "x": -15,
      "y": 1,
      "z": -4,
      "name": "Rock_Chalk_Brick_Smooth"
    },
    {
      "x": -15,
      "y": 2,
      "z": -4,
      "name": "Rock_Chalk_Brick_Smooth"
    },
    {
      "x": -15,
      "y": 3,
      "z": -4,
      "name": "Rock_Chalk_Brick_Smooth"
    },
    {
      "x": -15,
      "y": 8,
      "z": -4,
      "name": "Rock_Chalk_Brick_Smooth"
    },
    {
      "x": -15,
      "y": 9,
      "z": -4,
      "name": "Rock_Chalk_Brick_Smooth"
    },
    {
      "x": -15,
      "y": 10,
      "z": -4,
      "name": "Rock_Chalk_Brick_Smooth"
    },
    {
      "x": -15,
      "y": 11,
      "z": -4,
      "name": "Rock_Chalk_Brick_Smooth"
    },
    {
      "x": -15,
      "y": 0,
      "z": -3,
      "name": "Rock_Chalk_Brick_Smooth"
    },
    {
      "x": -15,
      "y": 1,
      "z": -3,
      "name": "Rock_Chalk_Brick_Smooth"
    },
    {
      "x": -15,
      "y": 2,
      "z": -3,
      "name": "Rock_Chalk_Brick_Smooth"
    },
    {
      "x": -15,
      "y": 3,
      "z": -3,
      "name": "Rock_Chalk_Brick_Smooth"
    },
    {
      "x": -15,
      "y": 8,
      "z": -3,
      "name": "Rock_Chalk_Brick_Smooth"
    },
    {
      "x": -15,
      "y": 9,
      "z": -3,
      "name": "Rock_Chalk_Brick_Smooth"
    },
    {
      "x": -15,
      "y": 10,
      "z": -3,
      "name": "Rock_Chalk_Brick_Smooth"
    },
    {
      "x": -15,
      "y": 11,
      "z": -3,
      "name": "Rock_Chalk_Brick_Smooth"
    },
    {
      "x": -15,
      "y": 0,
      "z": -2,
      "name": "Rock_Chalk_Brick_Smooth"
    },
    {
      "x": -15,
      "y": 1,
      "z": -2,
      "name": "Rock_Chalk_Brick_Smooth"
    },
    {
      "x": -15,
      "y": 2,
      "z": -2,
      "name": "Rock_Chalk_Brick_Smooth"
    },
    {
      "x": -15,
      "y": 3,
      "z": -2,
      "name": "Rock_Chalk_Brick_Smooth"
    },
    {
      "x": -15,
      "y": 8,
      "z": -2,
      "name": "Rock_Chalk_Brick_Smooth"
    },
    {
      "x": -15,
      "y": 9,
      "z": -2,
      "name": "Rock_Chalk_Brick_Smooth"
    },
    {
      "x": -15,
      "y": 10,
      "z": -2,
      "name": "Rock_Chalk_Brick_Smooth"
    },
    {
      "x": -15,
      "y": 11,
      "z": -2,
      "name": "Rock_Chalk_Brick_Smooth"
    },
    {
      "x": -15,
      "y": 0,
      "z": -1,
      "name": "Rock_Chalk_Brick_Smooth"
    },
    {
      "x": -15,
      "y": 1,
      "z": -1,
      "name": "Rock_Chalk_Brick_Smooth"
    },
    {
      "x": -15,
      "y": 2,
      "z": -1,
      "name": "Rock_Chalk_Brick_Smooth"
    },
    {
      "x": -15,
      "y": 3,
      "z": -1,
      "name": "Rock_Chalk_Brick_Smooth"
    },
    {
      "x": -15,
      "y": 8,
      "z": -1,
      "name": "Rock_Chalk_Brick_Smooth"
    },
    {
      "x": -15,
      "y": 9,
      "z": -1,
      "name": "Rock_Chalk_Brick_Smooth"
    },
    {
      "x": -15,
      "y": 10,
      "z": -1,
      "name": "Rock_Chalk_Brick_Smooth"
    },
    {
      "x": -15,
      "y": 11,
      "z": -1,
      "name": "Rock_Chalk_Brick_Smooth"
    },
    {
      "x": -15,
      "y": 0,
      "z": 0,
      "name": "Rock_Calcite"
    },
    {
      "x": -15,
      "y": 1,
      "z": 0,
      "name": "Rock_Calcite"
    },
    {
      "x": -15,
      "y": 2,
      "z": 0,
      "name": "Rock_Calcite"
    },
    {
      "x": -15,
      "y": 3,
      "z": 0,
      "name": "Rock_Calcite"
    },
    {
      "x": -15,
      "y": 8,
      "z": 0,
      "name": "Rock_Calcite"
    },
    {
      "x": -15,
      "y": 9,
      "z": 0,
      "name": "Rock_Calcite"
    },
    {
      "x": -15,
      "y": 10,
      "z": 0,
      "name": "Rock_Calcite"
    },
    {
      "x": -15,
      "y": 11,
      "z": 0,
      "name": "Rock_Calcite"
    },
    {
      "x": -15,
      "y": 0,
      "z": 1,
      "name": "Rock_Chalk_Brick_Smooth"
    },
    {
      "x": -15,
      "y": 1,
      "z": 1,
      "name": "Rock_Chalk_Brick_Smooth"
    },
    {
      "x": -15,
      "y": 2,
      "z": 1,
      "name": "Rock_Chalk_Brick_Smooth"
    },
    {
      "x": -15,
      "y": 3,
      "z": 1,
      "name": "Rock_Chalk_Brick_Smooth"
    },
    {
      "x": -15,
      "y": 8,
      "z": 1,
      "name": "Rock_Chalk_Brick_Smooth"
    },
    {
      "x": -15,
      "y": 9,
      "z": 1,
      "name": "Rock_Chalk_Brick_Smooth"
    },
    {
      "x": -15,
      "y": 10,
      "z": 1,
      "name": "Rock_Chalk_Brick_Smooth"
    },
    {
      "x": -15,
      "y": 11,
      "z": 1,
      "name": "Rock_Chalk_Brick_Smooth"
    },
    {
      "x": -15,
      "y": 0,
      "z": 2,
      "name": "Rock_Chalk_Brick_Smooth"
    },
    {
      "x": -15,
      "y": 1,
      "z": 2,
      "name": "Rock_Chalk_Brick_Smooth"
    },
    {
      "x": -15,
      "y": 2,
      "z": 2,
      "name": "Rock_Chalk_Brick_Smooth"
    },
    {
      "x": -15,
      "y": 3,
      "z": 2,
      "name": "Rock_Chalk_Brick_Smooth"
    },
    {
      "x": -15,
      "y": 8,
      "z": 2,
      "name": "Rock_Chalk_Brick_Smooth"
    },
    {
      "x": -15,
      "y": 9,
      "z": 2,
      "name": "Rock_Chalk_Brick_Smooth"
    },
    {
      "x": -15,
      "y": 10,
      "z": 2,
      "name": "Rock_Chalk_Brick_Smooth"
    },
    {
      "x": -15,
      "y": 11,
      "z": 2,
      "name": "Rock_Chalk_Brick_Smooth"
    },
    {
      "x": -15,
      "y": 0,
      "z": 3,
      "name": "Rock_Chalk_Brick_Smooth"
    },
    {
      "x": -15,
      "y": 1,
      "z": 3,
      "name": "Rock_Chalk_Brick_Smooth"
    },
    {
      "x": -15,
      "y": 2,
      "z": 3,
      "name": "Rock_Chalk_Brick_Smooth"
    },
    {
      "x": -15,
      "y": 3,
      "z": 3,
      "name": "Rock_Chalk_Brick_Smooth"
    },
    {
      "x": -15,
      "y": 8,
      "z": 3,
      "name": "Rock_Chalk_Brick_Smooth"
    },
    {
      "x": -15,
      "y": 9,
      "z": 3,
      "name": "Rock_Chalk_Brick_Smooth"
    },
    {
      "x": -15,
      "y": 10,
      "z": 3,
      "name": "Rock_Chalk_Brick_Smooth"
    },
    {
      "x": -15,
      "y": 11,
      "z": 3,
      "name": "Rock_Chalk_Brick_Smooth"
    },
    {
      "x": -15,
      "y": 0,
      "z": 4,
      "name": "Rock_Chalk_Brick_Smooth"
    },
    {
      "x": -15,
      "y": 1,
      "z": 4,
      "name": "Rock_Chalk_Brick_Smooth"
    },
    {
      "x": -15,
      "y": 2,
      "z": 4,
      "name": "Rock_Chalk_Brick_Smooth"
    },
    {
      "x": -15,
      "y": 3,
      "z": 4,
      "name": "Rock_Chalk_Brick_Smooth"
    },
    {
      "x": -15,
      "y": 8,
      "z": 4,
      "name": "Rock_Chalk_Brick_Smooth"
    },
    {
      "x": -15,
      "y": 9,
      "z": 4,
      "name": "Rock_Chalk_Brick_Smooth"
    },
    {
      "x": -15,
      "y": 10,
      "z": 4,
      "name": "Rock_Chalk_Brick_Smooth"
    },
    {
      "x": -15,
      "y": 11,
      "z": 4,
      "name": "Rock_Chalk_Brick_Smooth"
    },
    {
      "x": -15,
      "y": 0,
      "z": 5,
      "name": "Rock_Chalk_Brick_Smooth"
    },
    {
      "x": -15,
      "y": 1,
      "z": 5,
      "name": "Rock_Chalk_Brick_Smooth"
    },
    {
      "x": -15,
      "y": 2,
      "z": 5,
      "name": "Rock_Chalk_Brick_Smooth"
    },
    {
      "x": -15,
      "y": 3,
      "z": 5,
      "name": "Rock_Chalk_Brick_Smooth"
    },
    {
      "x": -15,
      "y": 8,
      "z": 5,
      "name": "Rock_Chalk_Brick_Smooth"
    },
    {
      "x": -15,
      "y": 9,
      "z": 5,
      "name": "Rock_Chalk_Brick_Smooth"
    },
    {
      "x": -15,
      "y": 10,
      "z": 5,
      "name": "Rock_Chalk_Brick_Smooth"
    },
    {
      "x": -15,
      "y": 11,
      "z": 5,
      "name": "Rock_Chalk_Brick_Smooth"
    },
    {
      "x": -15,
      "y": 0,
      "z": 6,
      "name": "Rock_Chalk_Brick_Smooth"
    },
    {
      "x": -15,
      "y": 1,
      "z": 6,
      "name": "Rock_Chalk_Brick_Smooth"
    },
    {
      "x": -15,
      "y": 2,
      "z": 6,
      "name": "Rock_Chalk_Brick_Smooth"
    },
    {
      "x": -15,
      "y": 3,
      "z": 6,
      "name": "Rock_Chalk_Brick_Smooth"
    },
    {
      "x": -15,
      "y": 8,
      "z": 6,
      "name": "Rock_Chalk_Brick_Smooth"
    },
    {
      "x": -15,
      "y": 9,
      "z": 6,
      "name": "Rock_Chalk_Brick_Smooth"
    },
    {
      "x": -15,
      "y": 10,
      "z": 6,
      "name": "Rock_Chalk_Brick_Smooth"
    },
    {
      "x": -15,
      "y": 11,
      "z": 6,
      "name": "Rock_Chalk_Brick_Smooth"
    },
    {
      "x": -15,
      "y": 0,
      "z": 7,
      "name": "Rock_Chalk_Brick_Smooth"
    },
    {
      "x": -15,
      "y": 1,
      "z": 7,
      "name": "Rock_Chalk_Brick_Smooth"
    },
    {
      "x": -15,
      "y": 2,
      "z": 7,
      "name": "Rock_Chalk_Brick_Smooth"
    },
    {
      "x": -15,
      "y": 3,
      "z": 7,
      "name": "Rock_Chalk_Brick_Smooth"
    },
    {
      "x": -15,
      "y": 8,
      "z": 7,
      "name": "Rock_Chalk_Brick_Smooth"
    },
    {
      "x": -15,
      "y": 9,
      "z": 7,
      "name": "Rock_Chalk_Brick_Smooth"
    },
    {
      "x": -15,
      "y": 10,
      "z": 7,
      "name": "Rock_Chalk_Brick_Smooth"
    },
    {
      "x": -15,
      "y": 11,
      "z": 7,
      "name": "Rock_Chalk_Brick_Smooth"
    },
    {
      "x": -15,
      "y": 0,
      "z": 8,
      "name": "Rock_Chalk_Brick_Smooth"
    },
    {
      "x": -15,
      "y": 1,
      "z": 8,
      "name": "Rock_Chalk_Brick_Smooth"
    },
    {
      "x": -15,
      "y": 2,
      "z": 8,
      "name": "Rock_Chalk_Brick_Smooth"
    },
    {
      "x": -15,
      "y": 3,
      "z": 8,
      "name": "Rock_Chalk_Brick_Smooth"
    },
    {
      "x": -15,
      "y": 8,
      "z": 8,
      "name": "Rock_Chalk_Brick_Smooth"
    },
    {
      "x": -15,
      "y": 9,
      "z": 8,
      "name": "Rock_Chalk_Brick_Smooth"
    },
    {
      "x": -15,
      "y": 10,
      "z": 8,
      "name": "Rock_Chalk_Brick_Smooth"
    },
    {
      "x": -15,
      "y": 11,
      "z": 8,
      "name": "Rock_Chalk_Brick_Smooth"
    },
    {
      "x": -15,
      "y": 0,
      "z": 9,
      "name": "Rock_Chalk_Brick_Smooth"
    },
    {
      "x": -15,
      "y": 1,
      "z": 9,
      "name": "Rock_Chalk_Brick_Smooth"
    },
    {
      "x": -15,
      "y": 2,
      "z": 9,
      "name": "Rock_Chalk_Brick_Smooth"
    },
    {
      "x": -15,
      "y": 3,
      "z": 9,
      "name": "Rock_Chalk_Brick_Smooth"
    },
    {
      "x": -15,
      "y": 8,
      "z": 9,
      "name": "Rock_Chalk_Brick_Smooth"
    },
    {
      "x": -15,
      "y": 9,
      "z": 9,
      "name": "Rock_Chalk_Brick_Smooth"
    },
    {
      "x": -15,
      "y": 10,
      "z": 9,
      "name": "Rock_Chalk_Brick_Smooth"
    },
    {
      "x": -15,
      "y": 11,
      "z": 9,
      "name": "Rock_Chalk_Brick_Smooth"
    },
    {
      "x": -15,
      "y": 0,
      "z": 10,
      "name": "Rock_Chalk_Brick_Smooth"
    },
    {
      "x": -15,
      "y": 1,
      "z": 10,
      "name": "Rock_Chalk_Brick_Smooth"
    },
    {
      "x": -15,
      "y": 2,
      "z": 10,
      "name": "Rock_Chalk_Brick_Smooth"
    },
    {
      "x": -15,
      "y": 3,
      "z": 10,
      "name": "Rock_Chalk_Brick_Smooth"
    },
    {
      "x": -15,
      "y": 4,
      "z": 10,
      "name": "Rock_Chalk_Beam"
    },
    {
      "x": -15,
      "y": 5,
      "z": 10,
      "name": "Rock_Chalk_Beam"
    },
    {
      "x": -15,
      "y": 6,
      "z": 10,
      "name": "Rock_Chalk_Beam"
    },
    {
      "x": -15,
      "y": 7,
      "z": 10,
      "name": "Rock_Chalk_Beam"
    },
    {
      "x": -15,
      "y": 8,
      "z": 10,
      "name": "Rock_Chalk_Brick_Smooth"
    },
    {
      "x": -15,
      "y": 9,
      "z": 10,
      "name": "Rock_Chalk_Brick_Smooth"
    },
    {
      "x": -15,
      "y": 10,
      "z": 10,
      "name": "Rock_Chalk_Brick_Smooth"
    },
    {
      "x": -15,
      "y": 11,
      "z": 10,
      "name": "Rock_Chalk_Brick_Smooth"
    },
    {
      "x": -14,
      "y": 0,
      "z": -10,
      "name": "Rock_Chalk_Brick_Smooth"
    },
    {
      "x": -14,
      "y": 1,
      "z": -10,
      "name": "Rock_Chalk_Brick_Smooth"
    },
    {
      "x": -14,
      "y": 2,
      "z": -10,
      "name": "Rock_Chalk_Brick_Smooth"
    },
    {
      "x": -14,
      "y": 3,
      "z": -10,
      "name": "Rock_Chalk_Brick_Smooth"
    },
    {
      "x": -14,
      "y": 8,
      "z": -10,
      "name": "Rock_Chalk_Brick_Smooth"
    },
    {
      "x": -14,
      "y": 9,
      "z": -10,
      "name": "Rock_Chalk_Brick_Smooth"
    },
    {
      "x": -14,
      "y": 10,
      "z": -10,
      "name": "Rock_Chalk_Brick_Smooth"
    },
    {
      "x": -14,
      "y": 11,
      "z": -10,
      "name": "Rock_Chalk_Brick_Smooth"
    },
    {
      "x": -14,
      "y": 3,
      "z": -9,
      "name": "Rock_Calcite"
    },
    {
      "x": -14,
      "y": 4,
      "z": -9,
      "name": "Rock_Calcite"
    },
    {
      "x": -14,
      "y": 5,
      "z": -9,
      "name": "Rock_Calcite"
    },
    {
      "x": -14,
      "y": 6,
      "z": -9,
      "name": "Rock_Calcite"
    },
    {
      "x": -14,
      "y": 7,
      "z": -9,
      "name": "Rock_Calcite"
    },
    {
      "x": -14,
      "y": 8,
      "z": -9,
      "name": "Rock_Calcite"
    },
    {
      "x": -14,
      "y": 3,
      "z": -8,
      "name": "Rock_Calcite"
    },
    {
      "x": -14,
      "y": 4,
      "z": -8,
      "name": "Rock_Calcite"
    },
    {
      "x": -14,
      "y": 5,
      "z": -8,
      "name": "Rock_Calcite"
    },
    {
      "x": -14,
      "y": 6,
      "z": -8,
      "name": "Rock_Calcite"
    },
    {
      "x": -14,
      "y": 7,
      "z": -8,
      "name": "Rock_Calcite"
    },
    {
      "x": -14,
      "y": 8,
      "z": -8,
      "name": "Rock_Calcite"
    },
    {
      "x": -14,
      "y": 3,
      "z": -7,
      "name": "Rock_Calcite"
    },
    {
      "x": -14,
      "y": 8,
      "z": -7,
      "name": "Rock_Calcite"
    },
    {
      "x": -14,
      "y": 3,
      "z": -6,
      "name": "Rock_Calcite"
    },
    {
      "x": -14,
      "y": 8,
      "z": -6,
      "name": "Rock_Calcite"
    },
    {
      "x": -14,
      "y": 3,
      "z": -5,
      "name": "Rock_Calcite"
    },
    {
      "x": -14,
      "y": 4,
      "z": -5,
      "name": "Rock_Calcite"
    },
    {
      "x": -14,
      "y": 5,
      "z": -5,
      "name": "Rock_Calcite"
    },
    {
      "x": -14,
      "y": 6,
      "z": -5,
      "name": "Rock_Calcite"
    },
    {
      "x": -14,
      "y": 7,
      "z": -5,
      "name": "Rock_Calcite"
    },
    {
      "x": -14,
      "y": 8,
      "z": -5,
      "name": "Rock_Calcite"
    },
    {
      "x": -14,
      "y": 3,
      "z": -4,
      "name": "Rock_Calcite"
    },
    {
      "x": -14,
      "y": 4,
      "z": -4,
      "name": "Rock_Calcite"
    },
    {
      "x": -14,
      "y": 5,
      "z": -4,
      "name": "Rock_Calcite"
    },
    {
      "x": -14,
      "y": 6,
      "z": -4,
      "name": "Rock_Calcite"
    },
    {
      "x": -14,
      "y": 7,
      "z": -4,
      "name": "Rock_Calcite"
    },
    {
      "x": -14,
      "y": 8,
      "z": -4,
      "name": "Rock_Calcite"
    },
    {
      "x": -14,
      "y": 3,
      "z": -3,
      "name": "Rock_Calcite"
    },
    {
      "x": -14,
      "y": 8,
      "z": -3,
      "name": "Rock_Calcite"
    },
    {
      "x": -14,
      "y": 3,
      "z": -2,
      "name": "Rock_Calcite"
    },
    {
      "x": -14,
      "y": 8,
      "z": -2,
      "name": "Rock_Calcite"
    },
    {
      "x": -14,
      "y": 3,
      "z": -1,
      "name": "Rock_Calcite"
    },
    {
      "x": -14,
      "y": 4,
      "z": -1,
      "name": "Rock_Calcite"
    },
    {
      "x": -14,
      "y": 5,
      "z": -1,
      "name": "Rock_Calcite"
    },
    {
      "x": -14,
      "y": 6,
      "z": -1,
      "name": "Rock_Calcite"
    },
    {
      "x": -14,
      "y": 7,
      "z": -1,
      "name": "Rock_Calcite"
    },
    {
      "x": -14,
      "y": 8,
      "z": -1,
      "name": "Rock_Calcite"
    },
    {
      "x": -14,
      "y": 3,
      "z": 0,
      "name": "Rock_Calcite"
    },
    {
      "x": -14,
      "y": 4,
      "z": 0,
      "name": "Rock_Calcite"
    },
    {
      "x": -14,
      "y": 5,
      "z": 0,
      "name": "Rock_Calcite"
    },
    {
      "x": -14,
      "y": 6,
      "z": 0,
      "name": "Rock_Calcite"
    },
    {
      "x": -14,
      "y": 7,
      "z": 0,
      "name": "Rock_Calcite"
    },
    {
      "x": -14,
      "y": 8,
      "z": 0,
      "name": "Rock_Calcite"
    },
    {
      "x": -14,
      "y": 3,
      "z": 1,
      "name": "Rock_Calcite"
    },
    {
      "x": -14,
      "y": 4,
      "z": 1,
      "name": "Rock_Calcite"
    },
    {
      "x": -14,
      "y": 5,
      "z": 1,
      "name": "Rock_Calcite"
    },
    {
      "x": -14,
      "y": 6,
      "z": 1,
      "name": "Rock_Calcite"
    },
    {
      "x": -14,
      "y": 7,
      "z": 1,
      "name": "Rock_Calcite"
    },
    {
      "x": -14,
      "y": 8,
      "z": 1,
      "name": "Rock_Calcite"
    },
    {
      "x": -14,
      "y": 3,
      "z": 2,
      "name": "Rock_Calcite"
    },
    {
      "x": -14,
      "y": 8,
      "z": 2,
      "name": "Rock_Calcite"
    },
    {
      "x": -14,
      "y": 3,
      "z": 3,
      "name": "Rock_Calcite"
    },
    {
      "x": -14,
      "y": 8,
      "z": 3,
      "name": "Rock_Calcite"
    },
    {
      "x": -14,
      "y": 3,
      "z": 4,
      "name": "Rock_Calcite"
    },
    {
      "x": -14,
      "y": 4,
      "z": 4,
      "name": "Rock_Calcite"
    },
    {
      "x": -14,
      "y": 5,
      "z": 4,
      "name": "Rock_Calcite"
    },
    {
      "x": -14,
      "y": 6,
      "z": 4,
      "name": "Rock_Calcite"
    },
    {
      "x": -14,
      "y": 7,
      "z": 4,
      "name": "Rock_Calcite"
    },
    {
      "x": -14,
      "y": 8,
      "z": 4,
      "name": "Rock_Calcite"
    },
    {
      "x": -14,
      "y": 3,
      "z": 5,
      "name": "Rock_Calcite"
    },
    {
      "x": -14,
      "y": 4,
      "z": 5,
      "name": "Rock_Calcite"
    },
    {
      "x": -14,
      "y": 5,
      "z": 5,
      "name": "Rock_Calcite"
    },
    {
      "x": -14,
      "y": 6,
      "z": 5,
      "name": "Rock_Calcite"
    },
    {
      "x": -14,
      "y": 7,
      "z": 5,
      "name": "Rock_Calcite"
    },
    {
      "x": -14,
      "y": 8,
      "z": 5,
      "name": "Rock_Calcite"
    },
    {
      "x": -14,
      "y": 3,
      "z": 6,
      "name": "Rock_Calcite"
    },
    {
      "x": -14,
      "y": 8,
      "z": 6,
      "name": "Rock_Calcite"
    },
    {
      "x": -14,
      "y": 3,
      "z": 7,
      "name": "Rock_Calcite"
    },
    {
      "x": -14,
      "y": 8,
      "z": 7,
      "name": "Rock_Calcite"
    },
    {
      "x": -14,
      "y": 3,
      "z": 8,
      "name": "Rock_Calcite"
    },
    {
      "x": -14,
      "y": 4,
      "z": 8,
      "name": "Rock_Calcite"
    },
    {
      "x": -14,
      "y": 5,
      "z": 8,
      "name": "Rock_Calcite"
    },
    {
      "x": -14,
      "y": 6,
      "z": 8,
      "name": "Rock_Calcite"
    },
    {
      "x": -14,
      "y": 7,
      "z": 8,
      "name": "Rock_Calcite"
    },
    {
      "x": -14,
      "y": 8,
      "z": 8,
      "name": "Rock_Calcite"
    },
    {
      "x": -14,
      "y": 3,
      "z": 9,
      "name": "Rock_Calcite"
    },
    {
      "x": -14,
      "y": 4,
      "z": 9,
      "name": "Rock_Calcite"
    },
    {
      "x": -14,
      "y": 5,
      "z": 9,
      "name": "Rock_Calcite"
    },
    {
      "x": -14,
      "y": 6,
      "z": 9,
      "name": "Rock_Calcite"
    },
    {
      "x": -14,
      "y": 7,
      "z": 9,
      "name": "Rock_Calcite"
    },
    {
      "x": -14,
      "y": 8,
      "z": 9,
      "name": "Rock_Calcite"
    },
    {
      "x": -14,
      "y": 0,
      "z": 10,
      "name": "Rock_Chalk_Brick_Smooth"
    },
    {
      "x": -14,
      "y": 1,
      "z": 10,
      "name": "Rock_Chalk_Brick_Smooth"
    },
    {
      "x": -14,
      "y": 2,
      "z": 10,
      "name": "Rock_Chalk_Brick_Smooth"
    },
    {
      "x": -14,
      "y": 3,
      "z": 10,
      "name": "Rock_Chalk_Brick_Smooth"
    },
    {
      "x": -14,
      "y": 8,
      "z": 10,
      "name": "Rock_Chalk_Brick_Smooth"
    },
    {
      "x": -14,
      "y": 9,
      "z": 10,
      "name": "Rock_Chalk_Brick_Smooth"
    },
    {
      "x": -14,
      "y": 10,
      "z": 10,
      "name": "Rock_Chalk_Brick_Smooth"
    },
    {
      "x": -14,
      "y": 11,
      "z": 10,
      "name": "Rock_Chalk_Brick_Smooth"
    },
    {
      "x": -13,
      "y": 0,
      "z": -10,
      "name": "Rock_Chalk_Brick_Smooth"
    },
    {
      "x": -13,
      "y": 1,
      "z": -10,
      "name": "Rock_Chalk_Brick_Smooth"
    },
    {
      "x": -13,
      "y": 2,
      "z": -10,
      "name": "Rock_Chalk_Brick_Smooth"
    },
    {
      "x": -13,
      "y": 3,
      "z": -10,
      "name": "Rock_Chalk_Brick_Smooth"
    },
    {
      "x": -13,
      "y": 8,
      "z": -10,
      "name": "Rock_Chalk_Brick_Smooth"
    },
    {
      "x": -13,
      "y": 9,
      "z": -10,
      "name": "Rock_Chalk_Brick_Smooth"
    },
    {
      "x": -13,
      "y": 10,
      "z": -10,
      "name": "Rock_Chalk_Brick_Smooth"
    },
    {
      "x": -13,
      "y": 11,
      "z": -10,
      "name": "Rock_Chalk_Brick_Smooth"
    },
    {
      "x": -13,
      "y": 3,
      "z": -9,
      "name": "Rock_Calcite"
    },
    {
      "x": -13,
      "y": 4,
      "z": -9,
      "name": "Rock_Calcite"
    },
    {
      "x": -13,
      "y": 5,
      "z": -9,
      "name": "Rock_Calcite"
    },
    {
      "x": -13,
      "y": 6,
      "z": -9,
      "name": "Rock_Calcite"
    },
    {
      "x": -13,
      "y": 7,
      "z": -9,
      "name": "Rock_Calcite"
    },
    {
      "x": -13,
      "y": 8,
      "z": -9,
      "name": "Rock_Calcite"
    },
    {
      "x": -13,
      "y": 4,
      "z": -8,
      "name": "Cloth_Block_Wool_Black"
    },
    {
      "x": -13,
      "y": 5,
      "z": -8,
      "name": "Cloth_Block_Wool_Black"
    },
    {
      "x": -13,
      "y": 6,
      "z": -8,
      "name": "Cloth_Block_Wool_Black"
    },
    {
      "x": -13,
      "y": 7,
      "z": -8,
      "name": "Cloth_Block_Wool_Black"
    },
    {
      "x": -13,
      "y": 4,
      "z": -7,
      "name": "Cloth_Block_Wool_Black"
    },
    {
      "x": -13,
      "y": 5,
      "z": -7,
      "name": "Cloth_Block_Wool_Black"
    },
    {
      "x": -13,
      "y": 6,
      "z": -7,
      "name": "Cloth_Block_Wool_Black"
    },
    {
      "x": -13,
      "y": 7,
      "z": -7,
      "name": "Cloth_Block_Wool_Black"
    },
    {
      "x": -13,
      "y": 4,
      "z": -6,
      "name": "Cloth_Block_Wool_Black"
    },
    {
      "x": -13,
      "y": 5,
      "z": -6,
      "name": "Cloth_Block_Wool_Black"
    },
    {
      "x": -13,
      "y": 6,
      "z": -6,
      "name": "Cloth_Block_Wool_Black"
    },
    {
      "x": -13,
      "y": 7,
      "z": -6,
      "name": "Cloth_Block_Wool_Black"
    },
    {
      "x": -13,
      "y": 4,
      "z": -5,
      "name": "Cloth_Block_Wool_Black"
    },
    {
      "x": -13,
      "y": 5,
      "z": -5,
      "name": "Cloth_Block_Wool_Black"
    },
    {
      "x": -13,
      "y": 6,
      "z": -5,
      "name": "Cloth_Block_Wool_Black"
    },
    {
      "x": -13,
      "y": 7,
      "z": -5,
      "name": "Cloth_Block_Wool_Black"
    },
    {
      "x": -13,
      "y": 4,
      "z": -4,
      "name": "Cloth_Block_Wool_Black"
    },
    {
      "x": -13,
      "y": 5,
      "z": -4,
      "name": "Cloth_Block_Wool_Black"
    },
    {
      "x": -13,
      "y": 6,
      "z": -4,
      "name": "Cloth_Block_Wool_Black"
    },
    {
      "x": -13,
      "y": 7,
      "z": -4,
      "name": "Cloth_Block_Wool_Black"
    },
    {
      "x": -13,
      "y": 4,
      "z": -3,
      "name": "Cloth_Block_Wool_Black"
    },
    {
      "x": -13,
      "y": 5,
      "z": -3,
      "name": "Cloth_Block_Wool_Black"
    },
    {
      "x": -13,
      "y": 6,
      "z": -3,
      "name": "Cloth_Block_Wool_Black"
    },
    {
      "x": -13,
      "y": 7,
      "z": -3,
      "name": "Cloth_Block_Wool_Black"
    },
    {
      "x": -13,
      "y": 4,
      "z": -2,
      "name": "Cloth_Block_Wool_Black"
    },
    {
      "x": -13,
      "y": 5,
      "z": -2,
      "name": "Cloth_Block_Wool_Black"
    },
    {
      "x": -13,
      "y": 6,
      "z": -2,
      "name": "Cloth_Block_Wool_Black"
    },
    {
      "x": -13,
      "y": 7,
      "z": -2,
      "name": "Cloth_Block_Wool_Black"
    },
    {
      "x": -13,
      "y": 4,
      "z": -1,
      "name": "Cloth_Block_Wool_Black"
    },
    {
      "x": -13,
      "y": 5,
      "z": -1,
      "name": "Cloth_Block_Wool_Black"
    },
    {
      "x": -13,
      "y": 6,
      "z": -1,
      "name": "Cloth_Block_Wool_Black"
    },
    {
      "x": -13,
      "y": 7,
      "z": -1,
      "name": "Cloth_Block_Wool_Black"
    },
    {
      "x": -13,
      "y": 4,
      "z": 0,
      "name": "Cloth_Block_Wool_Black"
    },
    {
      "x": -13,
      "y": 5,
      "z": 0,
      "name": "Cloth_Block_Wool_Black"
    },
    {
      "x": -13,
      "y": 6,
      "z": 0,
      "name": "Cloth_Block_Wool_Black"
    },
    {
      "x": -13,
      "y": 7,
      "z": 0,
      "name": "Cloth_Block_Wool_Black"
    },
    {
      "x": -13,
      "y": 4,
      "z": 1,
      "name": "Cloth_Block_Wool_Black"
    },
    {
      "x": -13,
      "y": 5,
      "z": 1,
      "name": "Cloth_Block_Wool_Black"
    },
    {
      "x": -13,
      "y": 6,
      "z": 1,
      "name": "Cloth_Block_Wool_Black"
    },
    {
      "x": -13,
      "y": 7,
      "z": 1,
      "name": "Cloth_Block_Wool_Black"
    },
    {
      "x": -13,
      "y": 4,
      "z": 2,
      "name": "Cloth_Block_Wool_Black"
    },
    {
      "x": -13,
      "y": 5,
      "z": 2,
      "name": "Cloth_Block_Wool_Black"
    },
    {
      "x": -13,
      "y": 6,
      "z": 2,
      "name": "Cloth_Block_Wool_Black"
    },
    {
      "x": -13,
      "y": 7,
      "z": 2,
      "name": "Cloth_Block_Wool_Black"
    },
    {
      "x": -13,
      "y": 4,
      "z": 3,
      "name": "Cloth_Block_Wool_Black"
    },
    {
      "x": -13,
      "y": 5,
      "z": 3,
      "name": "Cloth_Block_Wool_Black"
    },
    {
      "x": -13,
      "y": 6,
      "z": 3,
      "name": "Cloth_Block_Wool_Black"
    },
    {
      "x": -13,
      "y": 7,
      "z": 3,
      "name": "Cloth_Block_Wool_Black"
    },
    {
      "x": -13,
      "y": 4,
      "z": 4,
      "name": "Cloth_Block_Wool_Black"
    },
    {
      "x": -13,
      "y": 5,
      "z": 4,
      "name": "Cloth_Block_Wool_Black"
    },
    {
      "x": -13,
      "y": 6,
      "z": 4,
      "name": "Cloth_Block_Wool_Black"
    },
    {
      "x": -13,
      "y": 7,
      "z": 4,
      "name": "Cloth_Block_Wool_Black"
    },
    {
      "x": -13,
      "y": 4,
      "z": 5,
      "name": "Cloth_Block_Wool_Black"
    },
    {
      "x": -13,
      "y": 5,
      "z": 5,
      "name": "Cloth_Block_Wool_Black"
    },
    {
      "x": -13,
      "y": 6,
      "z": 5,
      "name": "Cloth_Block_Wool_Black"
    },
    {
      "x": -13,
      "y": 7,
      "z": 5,
      "name": "Cloth_Block_Wool_Black"
    },
    {
      "x": -13,
      "y": 4,
      "z": 6,
      "name": "Cloth_Block_Wool_Black"
    },
    {
      "x": -13,
      "y": 5,
      "z": 6,
      "name": "Cloth_Block_Wool_Black"
    },
    {
      "x": -13,
      "y": 6,
      "z": 6,
      "name": "Cloth_Block_Wool_Black"
    },
    {
      "x": -13,
      "y": 7,
      "z": 6,
      "name": "Cloth_Block_Wool_Black"
    },
    {
      "x": -13,
      "y": 4,
      "z": 7,
      "name": "Cloth_Block_Wool_Black"
    },
    {
      "x": -13,
      "y": 5,
      "z": 7,
      "name": "Cloth_Block_Wool_Black"
    },
    {
      "x": -13,
      "y": 6,
      "z": 7,
      "name": "Cloth_Block_Wool_Black"
    },
    {
      "x": -13,
      "y": 7,
      "z": 7,
      "name": "Cloth_Block_Wool_Black"
    },
    {
      "x": -13,
      "y": 4,
      "z": 8,
      "name": "Cloth_Block_Wool_Black"
    },
    {
      "x": -13,
      "y": 5,
      "z": 8,
      "name": "Cloth_Block_Wool_Black"
    },
    {
      "x": -13,
      "y": 6,
      "z": 8,
      "name": "Cloth_Block_Wool_Black"
    },
    {
      "x": -13,
      "y": 7,
      "z": 8,
      "name": "Cloth_Block_Wool_Black"
    },
    {
      "x": -13,
      "y": 3,
      "z": 9,
      "name": "Rock_Calcite"
    },
    {
      "x": -13,
      "y": 4,
      "z": 9,
      "name": "Rock_Calcite"
    },
    {
      "x": -13,
      "y": 5,
      "z": 9,
      "name": "Rock_Calcite"
    },
    {
      "x": -13,
      "y": 6,
      "z": 9,
      "name": "Rock_Calcite"
    },
    {
      "x": -13,
      "y": 7,
      "z": 9,
      "name": "Rock_Calcite"
    },
    {
      "x": -13,
      "y": 8,
      "z": 9,
      "name": "Rock_Calcite"
    },
    {
      "x": -13,
      "y": 0,
      "z": 10,
      "name": "Rock_Chalk_Brick_Smooth"
    },
    {
      "x": -13,
      "y": 1,
      "z": 10,
      "name": "Rock_Chalk_Brick_Smooth"
    },
    {
      "x": -13,
      "y": 2,
      "z": 10,
      "name": "Rock_Chalk_Brick_Smooth"
    },
    {
      "x": -13,
      "y": 3,
      "z": 10,
      "name": "Rock_Chalk_Brick_Smooth"
    },
    {
      "x": -13,
      "y": 8,
      "z": 10,
      "name": "Rock_Chalk_Brick_Smooth"
    },
    {
      "x": -13,
      "y": 9,
      "z": 10,
      "name": "Rock_Chalk_Brick_Smooth"
    },
    {
      "x": -13,
      "y": 10,
      "z": 10,
      "name": "Rock_Chalk_Brick_Smooth"
    },
    {
      "x": -13,
      "y": 11,
      "z": 10,
      "name": "Rock_Chalk_Brick_Smooth"
    },
    {
      "x": -12,
      "y": 0,
      "z": -10,
      "name": "Rock_Chalk_Brick_Smooth"
    },
    {
      "x": -12,
      "y": 1,
      "z": -10,
      "name": "Rock_Chalk_Brick_Smooth"
    },
    {
      "x": -12,
      "y": 2,
      "z": -10,
      "name": "Rock_Chalk_Brick_Smooth"
    },
    {
      "x": -12,
      "y": 3,
      "z": -10,
      "name": "Rock_Chalk_Brick_Smooth"
    },
    {
      "x": -12,
      "y": 8,
      "z": -10,
      "name": "Rock_Chalk_Brick_Smooth"
    },
    {
      "x": -12,
      "y": 9,
      "z": -10,
      "name": "Rock_Chalk_Brick_Smooth"
    },
    {
      "x": -12,
      "y": 10,
      "z": -10,
      "name": "Rock_Chalk_Brick_Smooth"
    },
    {
      "x": -12,
      "y": 11,
      "z": -10,
      "name": "Rock_Chalk_Brick_Smooth"
    },
    {
      "x": -12,
      "y": 3,
      "z": -9,
      "name": "Rock_Calcite"
    },
    {
      "x": -12,
      "y": 8,
      "z": -9,
      "name": "Rock_Calcite"
    },
    {
      "x": -12,
      "y": 4,
      "z": -8,
      "name": "Cloth_Block_Wool_Black"
    },
    {
      "x": -12,
      "y": 5,
      "z": -8,
      "name": "Cloth_Block_Wool_Black"
    },
    {
      "x": -12,
      "y": 6,
      "z": -8,
      "name": "Cloth_Block_Wool_Black"
    },
    {
      "x": -12,
      "y": 7,
      "z": -8,
      "name": "Cloth_Block_Wool_Black"
    },
    {
      "x": -12,
      "y": 4,
      "z": 8,
      "name": "Cloth_Block_Wool_Black"
    },
    {
      "x": -12,
      "y": 5,
      "z": 8,
      "name": "Cloth_Block_Wool_Black"
    },
    {
      "x": -12,
      "y": 6,
      "z": 8,
      "name": "Cloth_Block_Wool_Black"
    },
    {
      "x": -12,
      "y": 7,
      "z": 8,
      "name": "Cloth_Block_Wool_Black"
    },
    {
      "x": -12,
      "y": 3,
      "z": 9,
      "name": "Rock_Calcite"
    },
    {
      "x": -12,
      "y": 8,
      "z": 9,
      "name": "Rock_Calcite"
    },
    {
      "x": -12,
      "y": 0,
      "z": 10,
      "name": "Rock_Chalk_Brick_Smooth"
    },
    {
      "x": -12,
      "y": 1,
      "z": 10,
      "name": "Rock_Chalk_Brick_Smooth"
    },
    {
      "x": -12,
      "y": 2,
      "z": 10,
      "name": "Rock_Chalk_Brick_Smooth"
    },
    {
      "x": -12,
      "y": 3,
      "z": 10,
      "name": "Rock_Chalk_Brick_Smooth"
    },
    {
      "x": -12,
      "y": 8,
      "z": 10,
      "name": "Rock_Chalk_Brick_Smooth"
    },
    {
      "x": -12,
      "y": 9,
      "z": 10,
      "name": "Rock_Chalk_Brick_Smooth"
    },
    {
      "x": -12,
      "y": 10,
      "z": 10,
      "name": "Rock_Chalk_Brick_Smooth"
    },
    {
      "x": -12,
      "y": 11,
      "z": 10,
      "name": "Rock_Chalk_Brick_Smooth"
    },
    {
      "x": -11,
      "y": 0,
      "z": -10,
      "name": "Rock_Chalk_Brick_Smooth"
    },
    {
      "x": -11,
      "y": 1,
      "z": -10,
      "name": "Rock_Chalk_Brick_Smooth"
    },
    {
      "x": -11,
      "y": 2,
      "z": -10,
      "name": "Rock_Chalk_Brick_Smooth"
    },
    {
      "x": -11,
      "y": 3,
      "z": -10,
      "name": "Rock_Chalk_Brick_Smooth"
    },
    {
      "x": -11,
      "y": 8,
      "z": -10,
      "name": "Rock_Chalk_Brick_Smooth"
    },
    {
      "x": -11,
      "y": 9,
      "z": -10,
      "name": "Rock_Chalk_Brick_Smooth"
    },
    {
      "x": -11,
      "y": 10,
      "z": -10,
      "name": "Rock_Chalk_Brick_Smooth"
    },
    {
      "x": -11,
      "y": 11,
      "z": -10,
      "name": "Rock_Chalk_Brick_Smooth"
    },
    {
      "x": -11,
      "y": 3,
      "z": -9,
      "name": "Rock_Calcite"
    },
    {
      "x": -11,
      "y": 8,
      "z": -9,
      "name": "Rock_Calcite"
    },
    {
      "x": -11,
      "y": 4,
      "z": -8,
      "name": "Cloth_Block_Wool_Black"
    },
    {
      "x": -11,
      "y": 5,
      "z": -8,
      "name": "Cloth_Block_Wool_Black"
    },
    {
      "x": -11,
      "y": 6,
      "z": -8,
      "name": "Cloth_Block_Wool_Black"
    },
    {
      "x": -11,
      "y": 7,
      "z": -8,
      "name": "Cloth_Block_Wool_Black"
    },
    {
      "x": -11,
      "y": 4,
      "z": 8,
      "name": "Cloth_Block_Wool_Black"
    },
    {
      "x": -11,
      "y": 5,
      "z": 8,
      "name": "Cloth_Block_Wool_Black"
    },
    {
      "x": -11,
      "y": 6,
      "z": 8,
      "name": "Cloth_Block_Wool_Black"
    },
    {
      "x": -11,
      "y": 7,
      "z": 8,
      "name": "Cloth_Block_Wool_Black"
    },
    {
      "x": -11,
      "y": 3,
      "z": 9,
      "name": "Rock_Calcite"
    },
    {
      "x": -11,
      "y": 8,
      "z": 9,
      "name": "Rock_Calcite"
    },
    {
      "x": -11,
      "y": 0,
      "z": 10,
      "name": "Rock_Chalk_Brick_Smooth"
    },
    {
      "x": -11,
      "y": 1,
      "z": 10,
      "name": "Rock_Chalk_Brick_Smooth"
    },
    {
      "x": -11,
      "y": 2,
      "z": 10,
      "name": "Rock_Chalk_Brick_Smooth"
    },
    {
      "x": -11,
      "y": 3,
      "z": 10,
      "name": "Rock_Chalk_Brick_Smooth"
    },
    {
      "x": -11,
      "y": 8,
      "z": 10,
      "name": "Rock_Chalk_Brick_Smooth"
    },
    {
      "x": -11,
      "y": 9,
      "z": 10,
      "name": "Rock_Chalk_Brick_Smooth"
    },
    {
      "x": -11,
      "y": 10,
      "z": 10,
      "name": "Rock_Chalk_Brick_Smooth"
    },
    {
      "x": -11,
      "y": 11,
      "z": 10,
      "name": "Rock_Chalk_Brick_Smooth"
    },
    {
      "x": -10,
      "y": 0,
      "z": -10,
      "name": "Rock_Chalk_Brick_Smooth"
    },
    {
      "x": -10,
      "y": 1,
      "z": -10,
      "name": "Rock_Chalk_Brick_Smooth"
    },
    {
      "x": -10,
      "y": 2,
      "z": -10,
      "name": "Rock_Chalk_Brick_Smooth"
    },
    {
      "x": -10,
      "y": 3,
      "z": -10,
      "name": "Rock_Chalk_Brick_Smooth"
    },
    {
      "x": -10,
      "y": 8,
      "z": -10,
      "name": "Rock_Chalk_Brick_Smooth"
    },
    {
      "x": -10,
      "y": 9,
      "z": -10,
      "name": "Rock_Chalk_Brick_Smooth"
    },
    {
      "x": -10,
      "y": 10,
      "z": -10,
      "name": "Rock_Chalk_Brick_Smooth"
    },
    {
      "x": -10,
      "y": 11,
      "z": -10,
      "name": "Rock_Chalk_Brick_Smooth"
    },
    {
      "x": -10,
      "y": 3,
      "z": -9,
      "name": "Rock_Calcite"
    },
    {
      "x": -10,
      "y": 4,
      "z": -9,
      "name": "Rock_Calcite"
    },
    {
      "x": -10,
      "y": 5,
      "z": -9,
      "name": "Rock_Calcite"
    },
    {
      "x": -10,
      "y": 6,
      "z": -9,
      "name": "Rock_Calcite"
    },
    {
      "x": -10,
      "y": 7,
      "z": -9,
      "name": "Rock_Calcite"
    },
    {
      "x": -10,
      "y": 8,
      "z": -9,
      "name": "Rock_Calcite"
    },
    {
      "x": -10,
      "y": 4,
      "z": -8,
      "name": "Cloth_Block_Wool_Black"
    },
    {
      "x": -10,
      "y": 5,
      "z": -8,
      "name": "Cloth_Block_Wool_Black"
    },
    {
      "x": -10,
      "y": 6,
      "z": -8,
      "name": "Cloth_Block_Wool_Black"
    },
    {
      "x": -10,
      "y": 7,
      "z": -8,
      "name": "Cloth_Block_Wool_Black"
    },
    {
      "x": -10,
      "y": 4,
      "z": 8,
      "name": "Cloth_Block_Wool_Black"
    },
    {
      "x": -10,
      "y": 5,
      "z": 8,
      "name": "Cloth_Block_Wool_Black"
    },
    {
      "x": -10,
      "y": 6,
      "z": 8,
      "name": "Cloth_Block_Wool_Black"
    },
    {
      "x": -10,
      "y": 7,
      "z": 8,
      "name": "Cloth_Block_Wool_Black"
    },
    {
      "x": -10,
      "y": 3,
      "z": 9,
      "name": "Rock_Calcite"
    },
    {
      "x": -10,
      "y": 4,
      "z": 9,
      "name": "Rock_Calcite"
    },
    {
      "x": -10,
      "y": 5,
      "z": 9,
      "name": "Rock_Calcite"
    },
    {
      "x": -10,
      "y": 6,
      "z": 9,
      "name": "Rock_Calcite"
    },
    {
      "x": -10,
      "y": 7,
      "z": 9,
      "name": "Rock_Calcite"
    },
    {
      "x": -10,
      "y": 8,
      "z": 9,
      "name": "Rock_Calcite"
    },
    {
      "x": -10,
      "y": 0,
      "z": 10,
      "name": "Rock_Chalk_Brick_Smooth"
    },
    {
      "x": -10,
      "y": 1,
      "z": 10,
      "name": "Rock_Chalk_Brick_Smooth"
    },
    {
      "x": -10,
      "y": 2,
      "z": 10,
      "name": "Rock_Chalk_Brick_Smooth"
    },
    {
      "x": -10,
      "y": 3,
      "z": 10,
      "name": "Rock_Chalk_Brick_Smooth"
    },
    {
      "x": -10,
      "y": 8,
      "z": 10,
      "name": "Rock_Chalk_Brick_Smooth"
    },
    {
      "x": -10,
      "y": 9,
      "z": 10,
      "name": "Rock_Chalk_Brick_Smooth"
    },
    {
      "x": -10,
      "y": 10,
      "z": 10,
      "name": "Rock_Chalk_Brick_Smooth"
    },
    {
      "x": -10,
      "y": 11,
      "z": 10,
      "name": "Rock_Chalk_Brick_Smooth"
    },
    {
      "x": -9,
      "y": 0,
      "z": -10,
      "name": "Rock_Chalk_Brick_Smooth"
    },
    {
      "x": -9,
      "y": 1,
      "z": -10,
      "name": "Rock_Chalk_Brick_Smooth"
    },
    {
      "x": -9,
      "y": 2,
      "z": -10,
      "name": "Rock_Chalk_Brick_Smooth"
    },
    {
      "x": -9,
      "y": 3,
      "z": -10,
      "name": "Rock_Chalk_Brick_Smooth"
    },
    {
      "x": -9,
      "y": 8,
      "z": -10,
      "name": "Rock_Chalk_Brick_Smooth"
    },
    {
      "x": -9,
      "y": 9,
      "z": -10,
      "name": "Rock_Chalk_Brick_Smooth"
    },
    {
      "x": -9,
      "y": 10,
      "z": -10,
      "name": "Rock_Chalk_Brick_Smooth"
    },
    {
      "x": -9,
      "y": 11,
      "z": -10,
      "name": "Rock_Chalk_Brick_Smooth"
    },
    {
      "x": -9,
      "y": 3,
      "z": -9,
      "name": "Rock_Calcite"
    },
    {
      "x": -9,
      "y": 4,
      "z": -9,
      "name": "Rock_Calcite"
    },
    {
      "x": -9,
      "y": 5,
      "z": -9,
      "name": "Rock_Calcite"
    },
    {
      "x": -9,
      "y": 6,
      "z": -9,
      "name": "Rock_Calcite"
    },
    {
      "x": -9,
      "y": 7,
      "z": -9,
      "name": "Rock_Calcite"
    },
    {
      "x": -9,
      "y": 8,
      "z": -9,
      "name": "Rock_Calcite"
    },
    {
      "x": -9,
      "y": 4,
      "z": -8,
      "name": "Cloth_Block_Wool_Black"
    },
    {
      "x": -9,
      "y": 5,
      "z": -8,
      "name": "Cloth_Block_Wool_Black"
    },
    {
      "x": -9,
      "y": 6,
      "z": -8,
      "name": "Cloth_Block_Wool_Black"
    },
    {
      "x": -9,
      "y": 7,
      "z": -8,
      "name": "Cloth_Block_Wool_Black"
    },
    {
      "x": -9,
      "y": 4,
      "z": 8,
      "name": "Cloth_Block_Wool_Black"
    },
    {
      "x": -9,
      "y": 5,
      "z": 8,
      "name": "Cloth_Block_Wool_Black"
    },
    {
      "x": -9,
      "y": 6,
      "z": 8,
      "name": "Cloth_Block_Wool_Black"
    },
    {
      "x": -9,
      "y": 7,
      "z": 8,
      "name": "Cloth_Block_Wool_Black"
    },
    {
      "x": -9,
      "y": 3,
      "z": 9,
      "name": "Rock_Calcite"
    },
    {
      "x": -9,
      "y": 4,
      "z": 9,
      "name": "Rock_Calcite"
    },
    {
      "x": -9,
      "y": 5,
      "z": 9,
      "name": "Rock_Calcite"
    },
    {
      "x": -9,
      "y": 6,
      "z": 9,
      "name": "Rock_Calcite"
    },
    {
      "x": -9,
      "y": 7,
      "z": 9,
      "name": "Rock_Calcite"
    },
    {
      "x": -9,
      "y": 8,
      "z": 9,
      "name": "Rock_Calcite"
    },
    {
      "x": -9,
      "y": 0,
      "z": 10,
      "name": "Rock_Chalk_Brick_Smooth"
    },
    {
      "x": -9,
      "y": 1,
      "z": 10,
      "name": "Rock_Chalk_Brick_Smooth"
    },
    {
      "x": -9,
      "y": 2,
      "z": 10,
      "name": "Rock_Chalk_Brick_Smooth"
    },
    {
      "x": -9,
      "y": 3,
      "z": 10,
      "name": "Rock_Chalk_Brick_Smooth"
    },
    {
      "x": -9,
      "y": 8,
      "z": 10,
      "name": "Rock_Chalk_Brick_Smooth"
    },
    {
      "x": -9,
      "y": 9,
      "z": 10,
      "name": "Rock_Chalk_Brick_Smooth"
    },
    {
      "x": -9,
      "y": 10,
      "z": 10,
      "name": "Rock_Chalk_Brick_Smooth"
    },
    {
      "x": -9,
      "y": 11,
      "z": 10,
      "name": "Rock_Chalk_Brick_Smooth"
    },
    {
      "x": -8,
      "y": 0,
      "z": -10,
      "name": "Rock_Chalk_Brick_Smooth"
    },
    {
      "x": -8,
      "y": 1,
      "z": -10,
      "name": "Rock_Chalk_Brick_Smooth"
    },
    {
      "x": -8,
      "y": 2,
      "z": -10,
      "name": "Rock_Chalk_Brick_Smooth"
    },
    {
      "x": -8,
      "y": 3,
      "z": -10,
      "name": "Rock_Chalk_Brick_Smooth"
    },
    {
      "x": -8,
      "y": 8,
      "z": -10,
      "name": "Rock_Chalk_Brick_Smooth"
    },
    {
      "x": -8,
      "y": 9,
      "z": -10,
      "name": "Rock_Chalk_Brick_Smooth"
    },
    {
      "x": -8,
      "y": 10,
      "z": -10,
      "name": "Rock_Chalk_Brick_Smooth"
    },
    {
      "x": -8,
      "y": 11,
      "z": -10,
      "name": "Rock_Chalk_Brick_Smooth"
    },
    {
      "x": -8,
      "y": 3,
      "z": -9,
      "name": "Rock_Calcite"
    },
    {
      "x": -8,
      "y": 8,
      "z": -9,
      "name": "Rock_Calcite"
    },
    {
      "x": -8,
      "y": 4,
      "z": -8,
      "name": "Cloth_Block_Wool_Black"
    },
    {
      "x": -8,
      "y": 5,
      "z": -8,
      "name": "Cloth_Block_Wool_Black"
    },
    {
      "x": -8,
      "y": 6,
      "z": -8,
      "name": "Cloth_Block_Wool_Black"
    },
    {
      "x": -8,
      "y": 7,
      "z": -8,
      "name": "Cloth_Block_Wool_Black"
    },
    {
      "x": -8,
      "y": 4,
      "z": 8,
      "name": "Cloth_Block_Wool_Black"
    },
    {
      "x": -8,
      "y": 5,
      "z": 8,
      "name": "Cloth_Block_Wool_Black"
    },
    {
      "x": -8,
      "y": 6,
      "z": 8,
      "name": "Cloth_Block_Wool_Black"
    },
    {
      "x": -8,
      "y": 7,
      "z": 8,
      "name": "Cloth_Block_Wool_Black"
    },
    {
      "x": -8,
      "y": 3,
      "z": 9,
      "name": "Rock_Calcite"
    },
    {
      "x": -8,
      "y": 8,
      "z": 9,
      "name": "Rock_Calcite"
    },
    {
      "x": -8,
      "y": 0,
      "z": 10,
      "name": "Rock_Chalk_Brick_Smooth"
    },
    {
      "x": -8,
      "y": 1,
      "z": 10,
      "name": "Rock_Chalk_Brick_Smooth"
    },
    {
      "x": -8,
      "y": 2,
      "z": 10,
      "name": "Rock_Chalk_Brick_Smooth"
    },
    {
      "x": -8,
      "y": 3,
      "z": 10,
      "name": "Rock_Chalk_Brick_Smooth"
    },
    {
      "x": -8,
      "y": 8,
      "z": 10,
      "name": "Rock_Chalk_Brick_Smooth"
    },
    {
      "x": -8,
      "y": 9,
      "z": 10,
      "name": "Rock_Chalk_Brick_Smooth"
    },
    {
      "x": -8,
      "y": 10,
      "z": 10,
      "name": "Rock_Chalk_Brick_Smooth"
    },
    {
      "x": -8,
      "y": 11,
      "z": 10,
      "name": "Rock_Chalk_Brick_Smooth"
    },
    {
      "x": -7,
      "y": 0,
      "z": -10,
      "name": "Rock_Chalk_Brick_Smooth"
    },
    {
      "x": -7,
      "y": 1,
      "z": -10,
      "name": "Rock_Chalk_Brick_Smooth"
    },
    {
      "x": -7,
      "y": 2,
      "z": -10,
      "name": "Rock_Chalk_Brick_Smooth"
    },
    {
      "x": -7,
      "y": 3,
      "z": -10,
      "name": "Rock_Chalk_Brick_Smooth"
    },
    {
      "x": -7,
      "y": 8,
      "z": -10,
      "name": "Rock_Chalk_Brick_Smooth"
    },
    {
      "x": -7,
      "y": 9,
      "z": -10,
      "name": "Rock_Chalk_Brick_Smooth"
    },
    {
      "x": -7,
      "y": 10,
      "z": -10,
      "name": "Rock_Chalk_Brick_Smooth"
    },
    {
      "x": -7,
      "y": 11,
      "z": -10,
      "name": "Rock_Chalk_Brick_Smooth"
    },
    {
      "x": -7,
      "y": 3,
      "z": -9,
      "name": "Rock_Calcite"
    },
    {
      "x": -7,
      "y": 8,
      "z": -9,
      "name": "Rock_Calcite"
    },
    {
      "x": -7,
      "y": 4,
      "z": -8,
      "name": "Cloth_Block_Wool_Black"
    },
    {
      "x": -7,
      "y": 5,
      "z": -8,
      "name": "Cloth_Block_Wool_Black"
    },
    {
      "x": -7,
      "y": 6,
      "z": -8,
      "name": "Cloth_Block_Wool_Black"
    },
    {
      "x": -7,
      "y": 7,
      "z": -8,
      "name": "Cloth_Block_Wool_Black"
    },
    {
      "x": -7,
      "y": 4,
      "z": 8,
      "name": "Cloth_Block_Wool_Black"
    },
    {
      "x": -7,
      "y": 5,
      "z": 8,
      "name": "Cloth_Block_Wool_Black"
    },
    {
      "x": -7,
      "y": 6,
      "z": 8,
      "name": "Cloth_Block_Wool_Black"
    },
    {
      "x": -7,
      "y": 7,
      "z": 8,
      "name": "Cloth_Block_Wool_Black"
    },
    {
      "x": -7,
      "y": 3,
      "z": 9,
      "name": "Rock_Calcite"
    },
    {
      "x": -7,
      "y": 8,
      "z": 9,
      "name": "Rock_Calcite"
    },
    {
      "x": -7,
      "y": 0,
      "z": 10,
      "name": "Rock_Chalk_Brick_Smooth"
    },
    {
      "x": -7,
      "y": 1,
      "z": 10,
      "name": "Rock_Chalk_Brick_Smooth"
    },
    {
      "x": -7,
      "y": 2,
      "z": 10,
      "name": "Rock_Chalk_Brick_Smooth"
    },
    {
      "x": -7,
      "y": 3,
      "z": 10,
      "name": "Rock_Chalk_Brick_Smooth"
    },
    {
      "x": -7,
      "y": 8,
      "z": 10,
      "name": "Rock_Chalk_Brick_Smooth"
    },
    {
      "x": -7,
      "y": 9,
      "z": 10,
      "name": "Rock_Chalk_Brick_Smooth"
    },
    {
      "x": -7,
      "y": 10,
      "z": 10,
      "name": "Rock_Chalk_Brick_Smooth"
    },
    {
      "x": -7,
      "y": 11,
      "z": 10,
      "name": "Rock_Chalk_Brick_Smooth"
    },
    {
      "x": -6,
      "y": 0,
      "z": -10,
      "name": "Rock_Chalk_Brick_Smooth"
    },
    {
      "x": -6,
      "y": 1,
      "z": -10,
      "name": "Rock_Chalk_Brick_Smooth"
    },
    {
      "x": -6,
      "y": 2,
      "z": -10,
      "name": "Rock_Chalk_Brick_Smooth"
    },
    {
      "x": -6,
      "y": 3,
      "z": -10,
      "name": "Rock_Chalk_Brick_Smooth"
    },
    {
      "x": -6,
      "y": 8,
      "z": -10,
      "name": "Rock_Chalk_Brick_Smooth"
    },
    {
      "x": -6,
      "y": 9,
      "z": -10,
      "name": "Rock_Chalk_Brick_Smooth"
    },
    {
      "x": -6,
      "y": 10,
      "z": -10,
      "name": "Rock_Chalk_Brick_Smooth"
    },
    {
      "x": -6,
      "y": 11,
      "z": -10,
      "name": "Rock_Chalk_Brick_Smooth"
    },
    {
      "x": -6,
      "y": 3,
      "z": -9,
      "name": "Rock_Calcite"
    },
    {
      "x": -6,
      "y": 4,
      "z": -9,
      "name": "Rock_Calcite"
    },
    {
      "x": -6,
      "y": 5,
      "z": -9,
      "name": "Rock_Calcite"
    },
    {
      "x": -6,
      "y": 6,
      "z": -9,
      "name": "Rock_Calcite"
    },
    {
      "x": -6,
      "y": 7,
      "z": -9,
      "name": "Rock_Calcite"
    },
    {
      "x": -6,
      "y": 8,
      "z": -9,
      "name": "Rock_Calcite"
    },
    {
      "x": -6,
      "y": 4,
      "z": -8,
      "name": "Cloth_Block_Wool_Black"
    },
    {
      "x": -6,
      "y": 5,
      "z": -8,
      "name": "Cloth_Block_Wool_Black"
    },
    {
      "x": -6,
      "y": 6,
      "z": -8,
      "name": "Cloth_Block_Wool_Black"
    },
    {
      "x": -6,
      "y": 7,
      "z": -8,
      "name": "Cloth_Block_Wool_Black"
    },
    {
      "x": -6,
      "y": 4,
      "z": 8,
      "name": "Cloth_Block_Wool_Black"
    },
    {
      "x": -6,
      "y": 5,
      "z": 8,
      "name": "Cloth_Block_Wool_Black"
    },
    {
      "x": -6,
      "y": 6,
      "z": 8,
      "name": "Cloth_Block_Wool_Black"
    },
    {
      "x": -6,
      "y": 7,
      "z": 8,
      "name": "Cloth_Block_Wool_Black"
    },
    {
      "x": -6,
      "y": 3,
      "z": 9,
      "name": "Rock_Calcite"
    },
    {
      "x": -6,
      "y": 4,
      "z": 9,
      "name": "Rock_Calcite"
    },
    {
      "x": -6,
      "y": 5,
      "z": 9,
      "name": "Rock_Calcite"
    },
    {
      "x": -6,
      "y": 6,
      "z": 9,
      "name": "Rock_Calcite"
    },
    {
      "x": -6,
      "y": 7,
      "z": 9,
      "name": "Rock_Calcite"
    },
    {
      "x": -6,
      "y": 8,
      "z": 9,
      "name": "Rock_Calcite"
    },
    {
      "x": -6,
      "y": 0,
      "z": 10,
      "name": "Rock_Chalk_Brick_Smooth"
    },
    {
      "x": -6,
      "y": 1,
      "z": 10,
      "name": "Rock_Chalk_Brick_Smooth"
    },
    {
      "x": -6,
      "y": 2,
      "z": 10,
      "name": "Rock_Chalk_Brick_Smooth"
    },
    {
      "x": -6,
      "y": 3,
      "z": 10,
      "name": "Rock_Chalk_Brick_Smooth"
    },
    {
      "x": -6,
      "y": 8,
      "z": 10,
      "name": "Rock_Chalk_Brick_Smooth"
    },
    {
      "x": -6,
      "y": 9,
      "z": 10,
      "name": "Rock_Chalk_Brick_Smooth"
    },
    {
      "x": -6,
      "y": 10,
      "z": 10,
      "name": "Rock_Chalk_Brick_Smooth"
    },
    {
      "x": -6,
      "y": 11,
      "z": 10,
      "name": "Rock_Chalk_Brick_Smooth"
    },
    {
      "x": -5,
      "y": 0,
      "z": -10,
      "name": "Rock_Chalk_Brick_Smooth"
    },
    {
      "x": -5,
      "y": 1,
      "z": -10,
      "name": "Rock_Chalk_Brick_Smooth"
    },
    {
      "x": -5,
      "y": 2,
      "z": -10,
      "name": "Rock_Chalk_Brick_Smooth"
    },
    {
      "x": -5,
      "y": 3,
      "z": -10,
      "name": "Rock_Chalk_Brick_Smooth"
    },
    {
      "x": -5,
      "y": 8,
      "z": -10,
      "name": "Rock_Chalk_Brick_Smooth"
    },
    {
      "x": -5,
      "y": 9,
      "z": -10,
      "name": "Rock_Chalk_Brick_Smooth"
    },
    {
      "x": -5,
      "y": 10,
      "z": -10,
      "name": "Rock_Chalk_Brick_Smooth"
    },
    {
      "x": -5,
      "y": 11,
      "z": -10,
      "name": "Rock_Chalk_Brick_Smooth"
    },
    {
      "x": -5,
      "y": 3,
      "z": -9,
      "name": "Rock_Calcite"
    },
    {
      "x": -5,
      "y": 4,
      "z": -9,
      "name": "Rock_Calcite"
    },
    {
      "x": -5,
      "y": 5,
      "z": -9,
      "name": "Rock_Calcite"
    },
    {
      "x": -5,
      "y": 6,
      "z": -9,
      "name": "Rock_Calcite"
    },
    {
      "x": -5,
      "y": 7,
      "z": -9,
      "name": "Rock_Calcite"
    },
    {
      "x": -5,
      "y": 8,
      "z": -9,
      "name": "Rock_Calcite"
    },
    {
      "x": -5,
      "y": 4,
      "z": -8,
      "name": "Cloth_Block_Wool_Black"
    },
    {
      "x": -5,
      "y": 5,
      "z": -8,
      "name": "Cloth_Block_Wool_Black"
    },
    {
      "x": -5,
      "y": 6,
      "z": -8,
      "name": "Cloth_Block_Wool_Black"
    },
    {
      "x": -5,
      "y": 7,
      "z": -8,
      "name": "Cloth_Block_Wool_Black"
    },
    {
      "x": -5,
      "y": 4,
      "z": 8,
      "name": "Cloth_Block_Wool_Black"
    },
    {
      "x": -5,
      "y": 5,
      "z": 8,
      "name": "Cloth_Block_Wool_Black"
    },
    {
      "x": -5,
      "y": 6,
      "z": 8,
      "name": "Cloth_Block_Wool_Black"
    },
    {
      "x": -5,
      "y": 7,
      "z": 8,
      "name": "Cloth_Block_Wool_Black"
    },
    {
      "x": -5,
      "y": 3,
      "z": 9,
      "name": "Rock_Calcite"
    },
    {
      "x": -5,
      "y": 4,
      "z": 9,
      "name": "Rock_Calcite"
    },
    {
      "x": -5,
      "y": 5,
      "z": 9,
      "name": "Rock_Calcite"
    },
    {
      "x": -5,
      "y": 6,
      "z": 9,
      "name": "Rock_Calcite"
    },
    {
      "x": -5,
      "y": 7,
      "z": 9,
      "name": "Rock_Calcite"
    },
    {
      "x": -5,
      "y": 8,
      "z": 9,
      "name": "Rock_Calcite"
    },
    {
      "x": -5,
      "y": 0,
      "z": 10,
      "name": "Rock_Chalk_Brick_Smooth"
    },
    {
      "x": -5,
      "y": 1,
      "z": 10,
      "name": "Rock_Chalk_Brick_Smooth"
    },
    {
      "x": -5,
      "y": 2,
      "z": 10,
      "name": "Rock_Chalk_Brick_Smooth"
    },
    {
      "x": -5,
      "y": 3,
      "z": 10,
      "name": "Rock_Chalk_Brick_Smooth"
    },
    {
      "x": -5,
      "y": 8,
      "z": 10,
      "name": "Rock_Chalk_Brick_Smooth"
    },
    {
      "x": -5,
      "y": 9,
      "z": 10,
      "name": "Rock_Chalk_Brick_Smooth"
    },
    {
      "x": -5,
      "y": 10,
      "z": 10,
      "name": "Rock_Chalk_Brick_Smooth"
    },
    {
      "x": -5,
      "y": 11,
      "z": 10,
      "name": "Rock_Chalk_Brick_Smooth"
    },
    {
      "x": -4,
      "y": 0,
      "z": -10,
      "name": "Rock_Chalk_Brick_Smooth"
    },
    {
      "x": -4,
      "y": 1,
      "z": -10,
      "name": "Rock_Chalk_Brick_Smooth"
    },
    {
      "x": -4,
      "y": 2,
      "z": -10,
      "name": "Rock_Chalk_Brick_Smooth"
    },
    {
      "x": -4,
      "y": 3,
      "z": -10,
      "name": "Rock_Chalk_Brick_Smooth"
    },
    {
      "x": -4,
      "y": 8,
      "z": -10,
      "name": "Rock_Chalk_Brick_Smooth"
    },
    {
      "x": -4,
      "y": 9,
      "z": -10,
      "name": "Rock_Chalk_Brick_Smooth"
    },
    {
      "x": -4,
      "y": 10,
      "z": -10,
      "name": "Rock_Chalk_Brick_Smooth"
    },
    {
      "x": -4,
      "y": 11,
      "z": -10,
      "name": "Rock_Chalk_Brick_Smooth"
    },
    {
      "x": -4,
      "y": 3,
      "z": -9,
      "name": "Rock_Calcite"
    },
    {
      "x": -4,
      "y": 8,
      "z": -9,
      "name": "Rock_Calcite"
    },
    {
      "x": -4,
      "y": 4,
      "z": -8,
      "name": "Cloth_Block_Wool_Black"
    },
    {
      "x": -4,
      "y": 5,
      "z": -8,
      "name": "Cloth_Block_Wool_Black"
    },
    {
      "x": -4,
      "y": 6,
      "z": -8,
      "name": "Cloth_Block_Wool_Black"
    },
    {
      "x": -4,
      "y": 7,
      "z": -8,
      "name": "Cloth_Block_Wool_Black"
    },
    {
      "x": -4,
      "y": 4,
      "z": 8,
      "name": "Cloth_Block_Wool_Black"
    },
    {
      "x": -4,
      "y": 5,
      "z": 8,
      "name": "Cloth_Block_Wool_Black"
    },
    {
      "x": -4,
      "y": 6,
      "z": 8,
      "name": "Cloth_Block_Wool_Black"
    },
    {
      "x": -4,
      "y": 7,
      "z": 8,
      "name": "Cloth_Block_Wool_Black"
    },
    {
      "x": -4,
      "y": 3,
      "z": 9,
      "name": "Rock_Calcite"
    },
    {
      "x": -4,
      "y": 8,
      "z": 9,
      "name": "Rock_Calcite"
    },
    {
      "x": -4,
      "y": 0,
      "z": 10,
      "name": "Rock_Chalk_Brick_Smooth"
    },
    {
      "x": -4,
      "y": 1,
      "z": 10,
      "name": "Rock_Chalk_Brick_Smooth"
    },
    {
      "x": -4,
      "y": 2,
      "z": 10,
      "name": "Rock_Chalk_Brick_Smooth"
    },
    {
      "x": -4,
      "y": 3,
      "z": 10,
      "name": "Rock_Chalk_Brick_Smooth"
    },
    {
      "x": -4,
      "y": 8,
      "z": 10,
      "name": "Rock_Chalk_Brick_Smooth"
    },
    {
      "x": -4,
      "y": 9,
      "z": 10,
      "name": "Rock_Chalk_Brick_Smooth"
    },
    {
      "x": -4,
      "y": 10,
      "z": 10,
      "name": "Rock_Chalk_Brick_Smooth"
    },
    {
      "x": -4,
      "y": 11,
      "z": 10,
      "name": "Rock_Chalk_Brick_Smooth"
    },
    {
      "x": -3,
      "y": 0,
      "z": -10,
      "name": "Rock_Calcite"
    },
    {
      "x": -3,
      "y": 1,
      "z": -10,
      "name": "Rock_Calcite"
    },
    {
      "x": -3,
      "y": 2,
      "z": -10,
      "name": "Rock_Calcite"
    },
    {
      "x": -3,
      "y": 3,
      "z": -10,
      "name": "Rock_Calcite"
    },
    {
      "x": -3,
      "y": 8,
      "z": -10,
      "name": "Rock_Calcite"
    },
    {
      "x": -3,
      "y": 9,
      "z": -10,
      "name": "Rock_Calcite"
    },
    {
      "x": -3,
      "y": 10,
      "z": -10,
      "name": "Rock_Calcite"
    },
    {
      "x": -3,
      "y": 11,
      "z": -10,
      "name": "Rock_Calcite"
    },
    {
      "x": -3,
      "y": 3,
      "z": -9,
      "name": "Rock_Calcite"
    },
    {
      "x": -3,
      "y": 8,
      "z": -9,
      "name": "Rock_Calcite"
    },
    {
      "x": -3,
      "y": 4,
      "z": -8,
      "name": "Cloth_Block_Wool_Black"
    },
    {
      "x": -3,
      "y": 5,
      "z": -8,
      "name": "Cloth_Block_Wool_Black"
    },
    {
      "x": -3,
      "y": 6,
      "z": -8,
      "name": "Cloth_Block_Wool_Black"
    },
    {
      "x": -3,
      "y": 7,
      "z": -8,
      "name": "Cloth_Block_Wool_Black"
    },
    {
      "x": -3,
      "y": 4,
      "z": 8,
      "name": "Cloth_Block_Wool_Black"
    },
    {
      "x": -3,
      "y": 5,
      "z": 8,
      "name": "Cloth_Block_Wool_Black"
    },
    {
      "x": -3,
      "y": 6,
      "z": 8,
      "name": "Cloth_Block_Wool_Black"
    },
    {
      "x": -3,
      "y": 7,
      "z": 8,
      "name": "Cloth_Block_Wool_Black"
    },
    {
      "x": -3,
      "y": 3,
      "z": 9,
      "name": "Rock_Calcite"
    },
    {
      "x": -3,
      "y": 8,
      "z": 9,
      "name": "Rock_Calcite"
    },
    {
      "x": -3,
      "y": 0,
      "z": 10,
      "name": "Rock_Calcite"
    },
    {
      "x": -3,
      "y": 1,
      "z": 10,
      "name": "Rock_Calcite"
    },
    {
      "x": -3,
      "y": 2,
      "z": 10,
      "name": "Rock_Calcite"
    },
    {
      "x": -3,
      "y": 3,
      "z": 10,
      "name": "Rock_Calcite"
    },
    {
      "x": -3,
      "y": 8,
      "z": 10,
      "name": "Rock_Calcite"
    },
    {
      "x": -3,
      "y": 9,
      "z": 10,
      "name": "Rock_Calcite"
    },
    {
      "x": -3,
      "y": 10,
      "z": 10,
      "name": "Rock_Calcite"
    },
    {
      "x": -3,
      "y": 11,
      "z": 10,
      "name": "Rock_Calcite"
    },
    {
      "x": -2,
      "y": 0,
      "z": -10,
      "name": "Rock_Chalk_Brick_Smooth"
    },
    {
      "x": -2,
      "y": 1,
      "z": -10,
      "name": "Rock_Chalk_Brick_Smooth"
    },
    {
      "x": -2,
      "y": 2,
      "z": -10,
      "name": "Rock_Chalk_Brick_Smooth"
    },
    {
      "x": -2,
      "y": 3,
      "z": -10,
      "name": "Rock_Chalk_Brick_Smooth"
    },
    {
      "x": -2,
      "y": 8,
      "z": -10,
      "name": "Rock_Chalk_Brick_Smooth"
    },
    {
      "x": -2,
      "y": 9,
      "z": -10,
      "name": "Rock_Chalk_Brick_Smooth"
    },
    {
      "x": -2,
      "y": 10,
      "z": -10,
      "name": "Rock_Chalk_Brick_Smooth"
    },
    {
      "x": -2,
      "y": 11,
      "z": -10,
      "name": "Rock_Chalk_Brick_Smooth"
    },
    {
      "x": -2,
      "y": 3,
      "z": -9,
      "name": "Rock_Calcite"
    },
    {
      "x": -2,
      "y": 4,
      "z": -9,
      "name": "Rock_Calcite"
    },
    {
      "x": -2,
      "y": 5,
      "z": -9,
      "name": "Rock_Calcite"
    },
    {
      "x": -2,
      "y": 6,
      "z": -9,
      "name": "Rock_Calcite"
    },
    {
      "x": -2,
      "y": 7,
      "z": -9,
      "name": "Rock_Calcite"
    },
    {
      "x": -2,
      "y": 8,
      "z": -9,
      "name": "Rock_Calcite"
    },
    {
      "x": -2,
      "y": 4,
      "z": -8,
      "name": "Cloth_Block_Wool_Black"
    },
    {
      "x": -2,
      "y": 5,
      "z": -8,
      "name": "Cloth_Block_Wool_Black"
    },
    {
      "x": -2,
      "y": 6,
      "z": -8,
      "name": "Cloth_Block_Wool_Black"
    },
    {
      "x": -2,
      "y": 7,
      "z": -8,
      "name": "Cloth_Block_Wool_Black"
    },
    {
      "x": -2,
      "y": 4,
      "z": 8,
      "name": "Cloth_Block_Wool_Black"
    },
    {
      "x": -2,
      "y": 5,
      "z": 8,
      "name": "Cloth_Block_Wool_Black"
    },
    {
      "x": -2,
      "y": 6,
      "z": 8,
      "name": "Cloth_Block_Wool_Black"
    },
    {
      "x": -2,
      "y": 7,
      "z": 8,
      "name": "Cloth_Block_Wool_Black"
    },
    {
      "x": -2,
      "y": 3,
      "z": 9,
      "name": "Rock_Calcite"
    },
    {
      "x": -2,
      "y": 4,
      "z": 9,
      "name": "Rock_Calcite"
    },
    {
      "x": -2,
      "y": 5,
      "z": 9,
      "name": "Rock_Calcite"
    },
    {
      "x": -2,
      "y": 6,
      "z": 9,
      "name": "Rock_Calcite"
    },
    {
      "x": -2,
      "y": 7,
      "z": 9,
      "name": "Rock_Calcite"
    },
    {
      "x": -2,
      "y": 8,
      "z": 9,
      "name": "Rock_Calcite"
    },
    {
      "x": -2,
      "y": 0,
      "z": 10,
      "name": "Rock_Chalk_Brick_Smooth"
    },
    {
      "x": -2,
      "y": 1,
      "z": 10,
      "name": "Rock_Chalk_Brick_Smooth"
    },
    {
      "x": -2,
      "y": 2,
      "z": 10,
      "name": "Rock_Chalk_Brick_Smooth"
    },
    {
      "x": -2,
      "y": 3,
      "z": 10,
      "name": "Rock_Chalk_Brick_Smooth"
    },
    {
      "x": -2,
      "y": 8,
      "z": 10,
      "name": "Rock_Chalk_Brick_Smooth"
    },
    {
      "x": -2,
      "y": 9,
      "z": 10,
      "name": "Rock_Chalk_Brick_Smooth"
    },
    {
      "x": -2,
      "y": 10,
      "z": 10,
      "name": "Rock_Chalk_Brick_Smooth"
    },
    {
      "x": -2,
      "y": 11,
      "z": 10,
      "name": "Rock_Chalk_Brick_Smooth"
    },
    {
      "x": -1,
      "y": 0,
      "z": -10,
      "name": "Rock_Chalk_Brick_Smooth"
    },
    {
      "x": -1,
      "y": 1,
      "z": -10,
      "name": "Rock_Chalk_Brick_Smooth"
    },
    {
      "x": -1,
      "y": 2,
      "z": -10,
      "name": "Rock_Chalk_Brick_Smooth"
    },
    {
      "x": -1,
      "y": 3,
      "z": -10,
      "name": "Rock_Chalk_Brick_Smooth"
    },
    {
      "x": -1,
      "y": 8,
      "z": -10,
      "name": "Rock_Chalk_Brick_Smooth"
    },
    {
      "x": -1,
      "y": 9,
      "z": -10,
      "name": "Rock_Chalk_Brick_Smooth"
    },
    {
      "x": -1,
      "y": 10,
      "z": -10,
      "name": "Rock_Chalk_Brick_Smooth"
    },
    {
      "x": -1,
      "y": 11,
      "z": -10,
      "name": "Rock_Chalk_Brick_Smooth"
    },
    {
      "x": -1,
      "y": 3,
      "z": -9,
      "name": "Rock_Calcite"
    },
    {
      "x": -1,
      "y": 4,
      "z": -9,
      "name": "Rock_Calcite"
    },
    {
      "x": -1,
      "y": 5,
      "z": -9,
      "name": "Rock_Calcite"
    },
    {
      "x": -1,
      "y": 6,
      "z": -9,
      "name": "Rock_Calcite"
    },
    {
      "x": -1,
      "y": 7,
      "z": -9,
      "name": "Rock_Calcite"
    },
    {
      "x": -1,
      "y": 8,
      "z": -9,
      "name": "Rock_Calcite"
    },
    {
      "x": -1,
      "y": 4,
      "z": -8,
      "name": "Cloth_Block_Wool_Black"
    },
    {
      "x": -1,
      "y": 5,
      "z": -8,
      "name": "Cloth_Block_Wool_Black"
    },
    {
      "x": -1,
      "y": 6,
      "z": -8,
      "name": "Cloth_Block_Wool_Black"
    },
    {
      "x": -1,
      "y": 7,
      "z": -8,
      "name": "Cloth_Block_Wool_Black"
    },
    {
      "x": -1,
      "y": 4,
      "z": 8,
      "name": "Cloth_Block_Wool_Black"
    },
    {
      "x": -1,
      "y": 5,
      "z": 8,
      "name": "Cloth_Block_Wool_Black"
    },
    {
      "x": -1,
      "y": 6,
      "z": 8,
      "name": "Cloth_Block_Wool_Black"
    },
    {
      "x": -1,
      "y": 7,
      "z": 8,
      "name": "Cloth_Block_Wool_Black"
    },
    {
      "x": -1,
      "y": 3,
      "z": 9,
      "name": "Rock_Calcite"
    },
    {
      "x": -1,
      "y": 4,
      "z": 9,
      "name": "Rock_Calcite"
    },
    {
      "x": -1,
      "y": 5,
      "z": 9,
      "name": "Rock_Calcite"
    },
    {
      "x": -1,
      "y": 6,
      "z": 9,
      "name": "Rock_Calcite"
    },
    {
      "x": -1,
      "y": 7,
      "z": 9,
      "name": "Rock_Calcite"
    },
    {
      "x": -1,
      "y": 8,
      "z": 9,
      "name": "Rock_Calcite"
    },
    {
      "x": -1,
      "y": 0,
      "z": 10,
      "name": "Rock_Chalk_Brick_Smooth"
    },
    {
      "x": -1,
      "y": 1,
      "z": 10,
      "name": "Rock_Chalk_Brick_Smooth"
    },
    {
      "x": -1,
      "y": 2,
      "z": 10,
      "name": "Rock_Chalk_Brick_Smooth"
    },
    {
      "x": -1,
      "y": 3,
      "z": 10,
      "name": "Rock_Chalk_Brick_Smooth"
    },
    {
      "x": -1,
      "y": 8,
      "z": 10,
      "name": "Rock_Chalk_Brick_Smooth"
    },
    {
      "x": -1,
      "y": 9,
      "z": 10,
      "name": "Rock_Chalk_Brick_Smooth"
    },
    {
      "x": -1,
      "y": 10,
      "z": 10,
      "name": "Rock_Chalk_Brick_Smooth"
    },
    {
      "x": -1,
      "y": 11,
      "z": 10,
      "name": "Rock_Chalk_Brick_Smooth"
    },
    {
      "x": 0,
      "y": 0,
      "z": -10,
      "name": "Rock_Chalk_Brick_Smooth"
    },
    {
      "x": 0,
      "y": 1,
      "z": -10,
      "name": "Rock_Chalk_Brick_Smooth"
    },
    {
      "x": 0,
      "y": 2,
      "z": -10,
      "name": "Rock_Chalk_Brick_Smooth"
    },
    {
      "x": 0,
      "y": 3,
      "z": -10,
      "name": "Rock_Chalk_Brick_Smooth"
    },
    {
      "x": 0,
      "y": 8,
      "z": -10,
      "name": "Rock_Chalk_Brick_Smooth"
    },
    {
      "x": 0,
      "y": 9,
      "z": -10,
      "name": "Rock_Chalk_Brick_Smooth"
    },
    {
      "x": 0,
      "y": 10,
      "z": -10,
      "name": "Rock_Chalk_Brick_Smooth"
    },
    {
      "x": 0,
      "y": 11,
      "z": -10,
      "name": "Rock_Chalk_Brick_Smooth"
    },
    {
      "x": 0,
      "y": 3,
      "z": -9,
      "name": "Rock_Calcite"
    },
    {
      "x": 0,
      "y": 8,
      "z": -9,
      "name": "Rock_Calcite"
    },
    {
      "x": 0,
      "y": 4,
      "z": -8,
      "name": "Cloth_Block_Wool_Black"
    },
    {
      "x": 0,
      "y": 5,
      "z": -8,
      "name": "Cloth_Block_Wool_Black"
    },
    {
      "x": 0,
      "y": 6,
      "z": -8,
      "name": "Cloth_Block_Wool_Black"
    },
    {
      "x": 0,
      "y": 7,
      "z": -8,
      "name": "Cloth_Block_Wool_Black"
    },
    {
      "x": 0,
      "y": 4,
      "z": 8,
      "name": "Cloth_Block_Wool_Black"
    },
    {
      "x": 0,
      "y": 5,
      "z": 8,
      "name": "Cloth_Block_Wool_Black"
    },
    {
      "x": 0,
      "y": 6,
      "z": 8,
      "name": "Cloth_Block_Wool_Black"
    },
    {
      "x": 0,
      "y": 7,
      "z": 8,
      "name": "Cloth_Block_Wool_Black"
    },
    {
      "x": 0,
      "y": 3,
      "z": 9,
      "name": "Rock_Calcite"
    },
    {
      "x": 0,
      "y": 8,
      "z": 9,
      "name": "Rock_Calcite"
    },
    {
      "x": 0,
      "y": 0,
      "z": 10,
      "name": "Rock_Chalk_Brick_Smooth"
    },
    {
      "x": 0,
      "y": 1,
      "z": 10,
      "name": "Rock_Chalk_Brick_Smooth"
    },
    {
      "x": 0,
      "y": 2,
      "z": 10,
      "name": "Rock_Chalk_Brick_Smooth"
    },
    {
      "x": 0,
      "y": 3,
      "z": 10,
      "name": "Rock_Chalk_Brick_Smooth"
    },
    {
      "x": 0,
      "y": 8,
      "z": 10,
      "name": "Rock_Chalk_Brick_Smooth"
    },
    {
      "x": 0,
      "y": 9,
      "z": 10,
      "name": "Rock_Chalk_Brick_Smooth"
    },
    {
      "x": 0,
      "y": 10,
      "z": 10,
      "name": "Rock_Chalk_Brick_Smooth"
    },
    {
      "x": 0,
      "y": 11,
      "z": 10,
      "name": "Rock_Chalk_Brick_Smooth"
    },
    {
      "x": 1,
      "y": 0,
      "z": -10,
      "name": "Rock_Chalk_Brick_Smooth"
    },
    {
      "x": 1,
      "y": 1,
      "z": -10,
      "name": "Rock_Chalk_Brick_Smooth"
    },
    {
      "x": 1,
      "y": 2,
      "z": -10,
      "name": "Rock_Chalk_Brick_Smooth"
    },
    {
      "x": 1,
      "y": 3,
      "z": -10,
      "name": "Rock_Chalk_Brick_Smooth"
    },
    {
      "x": 1,
      "y": 8,
      "z": -10,
      "name": "Rock_Chalk_Brick_Smooth"
    },
    {
      "x": 1,
      "y": 9,
      "z": -10,
      "name": "Rock_Chalk_Brick_Smooth"
    },
    {
      "x": 1,
      "y": 10,
      "z": -10,
      "name": "Rock_Chalk_Brick_Smooth"
    },
    {
      "x": 1,
      "y": 11,
      "z": -10,
      "name": "Rock_Chalk_Brick_Smooth"
    },
    {
      "x": 1,
      "y": 3,
      "z": -9,
      "name": "Rock_Calcite"
    },
    {
      "x": 1,
      "y": 8,
      "z": -9,
      "name": "Rock_Calcite"
    },
    {
      "x": 1,
      "y": 4,
      "z": -8,
      "name": "Cloth_Block_Wool_Black"
    },
    {
      "x": 1,
      "y": 5,
      "z": -8,
      "name": "Cloth_Block_Wool_Black"
    },
    {
      "x": 1,
      "y": 6,
      "z": -8,
      "name": "Cloth_Block_Wool_Black"
    },
    {
      "x": 1,
      "y": 7,
      "z": -8,
      "name": "Cloth_Block_Wool_Black"
    },
    {
      "x": 1,
      "y": 4,
      "z": 8,
      "name": "Cloth_Block_Wool_Black"
    },
    {
      "x": 1,
      "y": 5,
      "z": 8,
      "name": "Cloth_Block_Wool_Black"
    },
    {
      "x": 1,
      "y": 6,
      "z": 8,
      "name": "Cloth_Block_Wool_Black"
    },
    {
      "x": 1,
      "y": 7,
      "z": 8,
      "name": "Cloth_Block_Wool_Black"
    },
    {
      "x": 1,
      "y": 3,
      "z": 9,
      "name": "Rock_Calcite"
    },
    {
      "x": 1,
      "y": 8,
      "z": 9,
      "name": "Rock_Calcite"
    },
    {
      "x": 1,
      "y": 0,
      "z": 10,
      "name": "Rock_Chalk_Brick_Smooth"
    },
    {
      "x": 1,
      "y": 1,
      "z": 10,
      "name": "Rock_Chalk_Brick_Smooth"
    },
    {
      "x": 1,
      "y": 2,
      "z": 10,
      "name": "Rock_Chalk_Brick_Smooth"
    },
    {
      "x": 1,
      "y": 3,
      "z": 10,
      "name": "Rock_Chalk_Brick_Smooth"
    },
    {
      "x": 1,
      "y": 8,
      "z": 10,
      "name": "Rock_Chalk_Brick_Smooth"
    },
    {
      "x": 1,
      "y": 9,
      "z": 10,
      "name": "Rock_Chalk_Brick_Smooth"
    },
    {
      "x": 1,
      "y": 10,
      "z": 10,
      "name": "Rock_Chalk_Brick_Smooth"
    },
    {
      "x": 1,
      "y": 11,
      "z": 10,
      "name": "Rock_Chalk_Brick_Smooth"
    },
    {
      "x": 2,
      "y": 0,
      "z": -10,
      "name": "Rock_Chalk_Brick_Smooth"
    },
    {
      "x": 2,
      "y": 1,
      "z": -10,
      "name": "Rock_Chalk_Brick_Smooth"
    },
    {
      "x": 2,
      "y": 2,
      "z": -10,
      "name": "Rock_Chalk_Brick_Smooth"
    },
    {
      "x": 2,
      "y": 3,
      "z": -10,
      "name": "Rock_Chalk_Brick_Smooth"
    },
    {
      "x": 2,
      "y": 8,
      "z": -10,
      "name": "Rock_Chalk_Brick_Smooth"
    },
    {
      "x": 2,
      "y": 9,
      "z": -10,
      "name": "Rock_Chalk_Brick_Smooth"
    },
    {
      "x": 2,
      "y": 10,
      "z": -10,
      "name": "Rock_Chalk_Brick_Smooth"
    },
    {
      "x": 2,
      "y": 11,
      "z": -10,
      "name": "Rock_Chalk_Brick_Smooth"
    },
    {
      "x": 2,
      "y": 3,
      "z": -9,
      "name": "Rock_Calcite"
    },
    {
      "x": 2,
      "y": 4,
      "z": -9,
      "name": "Rock_Calcite"
    },
    {
      "x": 2,
      "y": 5,
      "z": -9,
      "name": "Rock_Calcite"
    },
    {
      "x": 2,
      "y": 6,
      "z": -9,
      "name": "Rock_Calcite"
    },
    {
      "x": 2,
      "y": 7,
      "z": -9,
      "name": "Rock_Calcite"
    },
    {
      "x": 2,
      "y": 8,
      "z": -9,
      "name": "Rock_Calcite"
    },
    {
      "x": 2,
      "y": 4,
      "z": -8,
      "name": "Cloth_Block_Wool_Black"
    },
    {
      "x": 2,
      "y": 5,
      "z": -8,
      "name": "Cloth_Block_Wool_Black"
    },
    {
      "x": 2,
      "y": 6,
      "z": -8,
      "name": "Cloth_Block_Wool_Black"
    },
    {
      "x": 2,
      "y": 7,
      "z": -8,
      "name": "Cloth_Block_Wool_Black"
    },
    {
      "x": 2,
      "y": 4,
      "z": 8,
      "name": "Cloth_Block_Wool_Black"
    },
    {
      "x": 2,
      "y": 5,
      "z": 8,
      "name": "Cloth_Block_Wool_Black"
    },
    {
      "x": 2,
      "y": 6,
      "z": 8,
      "name": "Cloth_Block_Wool_Black"
    },
    {
      "x": 2,
      "y": 7,
      "z": 8,
      "name": "Cloth_Block_Wool_Black"
    },
    {
      "x": 2,
      "y": 3,
      "z": 9,
      "name": "Rock_Calcite"
    },
    {
      "x": 2,
      "y": 4,
      "z": 9,
      "name": "Rock_Calcite"
    },
    {
      "x": 2,
      "y": 5,
      "z": 9,
      "name": "Rock_Calcite"
    },
    {
      "x": 2,
      "y": 6,
      "z": 9,
      "name": "Rock_Calcite"
    },
    {
      "x": 2,
      "y": 7,
      "z": 9,
      "name": "Rock_Calcite"
    },
    {
      "x": 2,
      "y": 8,
      "z": 9,
      "name": "Rock_Calcite"
    },
    {
      "x": 2,
      "y": 0,
      "z": 10,
      "name": "Rock_Chalk_Brick_Smooth"
    },
    {
      "x": 2,
      "y": 1,
      "z": 10,
      "name": "Rock_Chalk_Brick_Smooth"
    },
    {
      "x": 2,
      "y": 2,
      "z": 10,
      "name": "Rock_Chalk_Brick_Smooth"
    },
    {
      "x": 2,
      "y": 3,
      "z": 10,
      "name": "Rock_Chalk_Brick_Smooth"
    },
    {
      "x": 2,
      "y": 8,
      "z": 10,
      "name": "Rock_Chalk_Brick_Smooth"
    },
    {
      "x": 2,
      "y": 9,
      "z": 10,
      "name": "Rock_Chalk_Brick_Smooth"
    },
    {
      "x": 2,
      "y": 10,
      "z": 10,
      "name": "Rock_Chalk_Brick_Smooth"
    },
    {
      "x": 2,
      "y": 11,
      "z": 10,
      "name": "Rock_Chalk_Brick_Smooth"
    },
    {
      "x": 3,
      "y": 0,
      "z": -10,
      "name": "Rock_Chalk_Brick_Smooth"
    },
    {
      "x": 3,
      "y": 1,
      "z": -10,
      "name": "Rock_Chalk_Brick_Smooth"
    },
    {
      "x": 3,
      "y": 2,
      "z": -10,
      "name": "Rock_Chalk_Brick_Smooth"
    },
    {
      "x": 3,
      "y": 3,
      "z": -10,
      "name": "Rock_Chalk_Brick_Smooth"
    },
    {
      "x": 3,
      "y": 8,
      "z": -10,
      "name": "Rock_Chalk_Brick_Smooth"
    },
    {
      "x": 3,
      "y": 9,
      "z": -10,
      "name": "Rock_Chalk_Brick_Smooth"
    },
    {
      "x": 3,
      "y": 10,
      "z": -10,
      "name": "Rock_Chalk_Brick_Smooth"
    },
    {
      "x": 3,
      "y": 11,
      "z": -10,
      "name": "Rock_Chalk_Brick_Smooth"
    },
    {
      "x": 3,
      "y": 3,
      "z": -9,
      "name": "Rock_Calcite"
    },
    {
      "x": 3,
      "y": 4,
      "z": -9,
      "name": "Rock_Calcite"
    },
    {
      "x": 3,
      "y": 5,
      "z": -9,
      "name": "Rock_Calcite"
    },
    {
      "x": 3,
      "y": 6,
      "z": -9,
      "name": "Rock_Calcite"
    },
    {
      "x": 3,
      "y": 7,
      "z": -9,
      "name": "Rock_Calcite"
    },
    {
      "x": 3,
      "y": 8,
      "z": -9,
      "name": "Rock_Calcite"
    },
    {
      "x": 3,
      "y": 4,
      "z": -8,
      "name": "Cloth_Block_Wool_Black"
    },
    {
      "x": 3,
      "y": 5,
      "z": -8,
      "name": "Cloth_Block_Wool_Black"
    },
    {
      "x": 3,
      "y": 6,
      "z": -8,
      "name": "Cloth_Block_Wool_Black"
    },
    {
      "x": 3,
      "y": 7,
      "z": -8,
      "name": "Cloth_Block_Wool_Black"
    },
    {
      "x": 3,
      "y": 1,
      "z": -2,
      "name": "Rock_Stone"
    },
    {
      "x": 3,
      "y": 4,
      "z": 8,
      "name": "Cloth_Block_Wool_Black"
    },
    {
      "x": 3,
      "y": 5,
      "z": 8,
      "name": "Cloth_Block_Wool_Black"
    },
    {
      "x": 3,
      "y": 6,
      "z": 8,
      "name": "Cloth_Block_Wool_Black"
    },
    {
      "x": 3,
      "y": 7,
      "z": 8,
      "name": "Cloth_Block_Wool_Black"
    },
    {
      "x": 3,
      "y": 3,
      "z": 9,
      "name": "Rock_Calcite"
    },
    {
      "x": 3,
      "y": 4,
      "z": 9,
      "name": "Rock_Calcite"
    },
    {
      "x": 3,
      "y": 5,
      "z": 9,
      "name": "Rock_Calcite"
    },
    {
      "x": 3,
      "y": 6,
      "z": 9,
      "name": "Rock_Calcite"
    },
    {
      "x": 3,
      "y": 7,
      "z": 9,
      "name": "Rock_Calcite"
    },
    {
      "x": 3,
      "y": 8,
      "z": 9,
      "name": "Rock_Calcite"
    },
    {
      "x": 3,
      "y": 0,
      "z": 10,
      "name": "Rock_Chalk_Brick_Smooth"
    },
    {
      "x": 3,
      "y": 1,
      "z": 10,
      "name": "Rock_Chalk_Brick_Smooth"
    },
    {
      "x": 3,
      "y": 2,
      "z": 10,
      "name": "Rock_Chalk_Brick_Smooth"
    },
    {
      "x": 3,
      "y": 3,
      "z": 10,
      "name": "Rock_Chalk_Brick_Smooth"
    },
    {
      "x": 3,
      "y": 8,
      "z": 10,
      "name": "Rock_Chalk_Brick_Smooth"
    },
    {
      "x": 3,
      "y": 9,
      "z": 10,
      "name": "Rock_Chalk_Brick_Smooth"
    },
    {
      "x": 3,
      "y": 10,
      "z": 10,
      "name": "Rock_Chalk_Brick_Smooth"
    },
    {
      "x": 3,
      "y": 11,
      "z": 10,
      "name": "Rock_Chalk_Brick_Smooth"
    },
    {
      "x": 4,
      "y": 0,
      "z": -10,
      "name": "Rock_Calcite"
    },
    {
      "x": 4,
      "y": 1,
      "z": -10,
      "name": "Rock_Calcite"
    },
    {
      "x": 4,
      "y": 2,
      "z": -10,
      "name": "Rock_Calcite"
    },
    {
      "x": 4,
      "y": 3,
      "z": -10,
      "name": "Rock_Calcite"
    },
    {
      "x": 4,
      "y": 8,
      "z": -10,
      "name": "Rock_Calcite"
    },
    {
      "x": 4,
      "y": 9,
      "z": -10,
      "name": "Rock_Calcite"
    },
    {
      "x": 4,
      "y": 10,
      "z": -10,
      "name": "Rock_Calcite"
    },
    {
      "x": 4,
      "y": 11,
      "z": -10,
      "name": "Rock_Calcite"
    },
    {
      "x": 4,
      "y": 3,
      "z": -9,
      "name": "Rock_Calcite"
    },
    {
      "x": 4,
      "y": 8,
      "z": -9,
      "name": "Rock_Calcite"
    },
    {
      "x": 4,
      "y": 4,
      "z": -8,
      "name": "Cloth_Block_Wool_Black"
    },
    {
      "x": 4,
      "y": 5,
      "z": -8,
      "name": "Cloth_Block_Wool_Black"
    },
    {
      "x": 4,
      "y": 6,
      "z": -8,
      "name": "Cloth_Block_Wool_Black"
    },
    {
      "x": 4,
      "y": 7,
      "z": -8,
      "name": "Cloth_Block_Wool_Black"
    },
    {
      "x": 4,
      "y": 4,
      "z": 8,
      "name": "Cloth_Block_Wool_Black"
    },
    {
      "x": 4,
      "y": 5,
      "z": 8,
      "name": "Cloth_Block_Wool_Black"
    },
    {
      "x": 4,
      "y": 6,
      "z": 8,
      "name": "Cloth_Block_Wool_Black"
    },
    {
      "x": 4,
      "y": 7,
      "z": 8,
      "name": "Cloth_Block_Wool_Black"
    },
    {
      "x": 4,
      "y": 3,
      "z": 9,
      "name": "Rock_Calcite"
    },
    {
      "x": 4,
      "y": 8,
      "z": 9,
      "name": "Rock_Calcite"
    },
    {
      "x": 4,
      "y": 0,
      "z": 10,
      "name": "Rock_Calcite"
    },
    {
      "x": 4,
      "y": 1,
      "z": 10,
      "name": "Rock_Calcite"
    },
    {
      "x": 4,
      "y": 2,
      "z": 10,
      "name": "Rock_Calcite"
    },
    {
      "x": 4,
      "y": 3,
      "z": 10,
      "name": "Rock_Calcite"
    },
    {
      "x": 4,
      "y": 8,
      "z": 10,
      "name": "Rock_Calcite"
    },
    {
      "x": 4,
      "y": 9,
      "z": 10,
      "name": "Rock_Calcite"
    },
    {
      "x": 4,
      "y": 10,
      "z": 10,
      "name": "Rock_Calcite"
    },
    {
      "x": 4,
      "y": 11,
      "z": 10,
      "name": "Rock_Calcite"
    },
    {
      "x": 5,
      "y": 0,
      "z": -10,
      "name": "Rock_Chalk_Brick_Smooth"
    },
    {
      "x": 5,
      "y": 1,
      "z": -10,
      "name": "Rock_Chalk_Brick_Smooth"
    },
    {
      "x": 5,
      "y": 2,
      "z": -10,
      "name": "Rock_Chalk_Brick_Smooth"
    },
    {
      "x": 5,
      "y": 3,
      "z": -10,
      "name": "Rock_Chalk_Brick_Smooth"
    },
    {
      "x": 5,
      "y": 8,
      "z": -10,
      "name": "Rock_Chalk_Brick_Smooth"
    },
    {
      "x": 5,
      "y": 9,
      "z": -10,
      "name": "Rock_Chalk_Brick_Smooth"
    },
    {
      "x": 5,
      "y": 10,
      "z": -10,
      "name": "Rock_Chalk_Brick_Smooth"
    },
    {
      "x": 5,
      "y": 11,
      "z": -10,
      "name": "Rock_Chalk_Brick_Smooth"
    },
    {
      "x": 5,
      "y": 3,
      "z": -9,
      "name": "Rock_Calcite"
    },
    {
      "x": 5,
      "y": 8,
      "z": -9,
      "name": "Rock_Calcite"
    },
    {
      "x": 5,
      "y": 4,
      "z": -8,
      "name": "Cloth_Block_Wool_Black"
    },
    {
      "x": 5,
      "y": 5,
      "z": -8,
      "name": "Cloth_Block_Wool_Black"
    },
    {
      "x": 5,
      "y": 6,
      "z": -8,
      "name": "Cloth_Block_Wool_Black"
    },
    {
      "x": 5,
      "y": 7,
      "z": -8,
      "name": "Cloth_Block_Wool_Black"
    },
    {
      "x": 5,
      "y": 4,
      "z": 8,
      "name": "Cloth_Block_Wool_Black"
    },
    {
      "x": 5,
      "y": 5,
      "z": 8,
      "name": "Cloth_Block_Wool_Black"
    },
    {
      "x": 5,
      "y": 6,
      "z": 8,
      "name": "Cloth_Block_Wool_Black"
    },
    {
      "x": 5,
      "y": 7,
      "z": 8,
      "name": "Cloth_Block_Wool_Black"
    },
    {
      "x": 5,
      "y": 3,
      "z": 9,
      "name": "Rock_Calcite"
    },
    {
      "x": 5,
      "y": 8,
      "z": 9,
      "name": "Rock_Calcite"
    },
    {
      "x": 5,
      "y": 0,
      "z": 10,
      "name": "Rock_Chalk_Brick_Smooth"
    },
    {
      "x": 5,
      "y": 1,
      "z": 10,
      "name": "Rock_Chalk_Brick_Smooth"
    },
    {
      "x": 5,
      "y": 2,
      "z": 10,
      "name": "Rock_Chalk_Brick_Smooth"
    },
    {
      "x": 5,
      "y": 3,
      "z": 10,
      "name": "Rock_Chalk_Brick_Smooth"
    },
    {
      "x": 5,
      "y": 8,
      "z": 10,
      "name": "Rock_Chalk_Brick_Smooth"
    },
    {
      "x": 5,
      "y": 9,
      "z": 10,
      "name": "Rock_Chalk_Brick_Smooth"
    },
    {
      "x": 5,
      "y": 10,
      "z": 10,
      "name": "Rock_Chalk_Brick_Smooth"
    },
    {
      "x": 5,
      "y": 11,
      "z": 10,
      "name": "Rock_Chalk_Brick_Smooth"
    },
    {
      "x": 6,
      "y": 0,
      "z": -10,
      "name": "Rock_Chalk_Brick_Smooth"
    },
    {
      "x": 6,
      "y": 1,
      "z": -10,
      "name": "Rock_Chalk_Brick_Smooth"
    },
    {
      "x": 6,
      "y": 2,
      "z": -10,
      "name": "Rock_Chalk_Brick_Smooth"
    },
    {
      "x": 6,
      "y": 3,
      "z": -10,
      "name": "Rock_Chalk_Brick_Smooth"
    },
    {
      "x": 6,
      "y": 8,
      "z": -10,
      "name": "Rock_Chalk_Brick_Smooth"
    },
    {
      "x": 6,
      "y": 9,
      "z": -10,
      "name": "Rock_Chalk_Brick_Smooth"
    },
    {
      "x": 6,
      "y": 10,
      "z": -10,
      "name": "Rock_Chalk_Brick_Smooth"
    },
    {
      "x": 6,
      "y": 11,
      "z": -10,
      "name": "Rock_Chalk_Brick_Smooth"
    },
    {
      "x": 6,
      "y": 3,
      "z": -9,
      "name": "Rock_Calcite"
    },
    {
      "x": 6,
      "y": 4,
      "z": -9,
      "name": "Rock_Calcite"
    },
    {
      "x": 6,
      "y": 5,
      "z": -9,
      "name": "Rock_Calcite"
    },
    {
      "x": 6,
      "y": 6,
      "z": -9,
      "name": "Rock_Calcite"
    },
    {
      "x": 6,
      "y": 7,
      "z": -9,
      "name": "Rock_Calcite"
    },
    {
      "x": 6,
      "y": 8,
      "z": -9,
      "name": "Rock_Calcite"
    },
    {
      "x": 6,
      "y": 4,
      "z": -8,
      "name": "Cloth_Block_Wool_Black"
    },
    {
      "x": 6,
      "y": 5,
      "z": -8,
      "name": "Cloth_Block_Wool_Black"
    },
    {
      "x": 6,
      "y": 6,
      "z": -8,
      "name": "Cloth_Block_Wool_Black"
    },
    {
      "x": 6,
      "y": 7,
      "z": -8,
      "name": "Cloth_Block_Wool_Black"
    },
    {
      "x": 6,
      "y": 4,
      "z": 8,
      "name": "Cloth_Block_Wool_Black"
    },
    {
      "x": 6,
      "y": 5,
      "z": 8,
      "name": "Cloth_Block_Wool_Black"
    },
    {
      "x": 6,
      "y": 6,
      "z": 8,
      "name": "Cloth_Block_Wool_Black"
    },
    {
      "x": 6,
      "y": 7,
      "z": 8,
      "name": "Cloth_Block_Wool_Black"
    },
    {
      "x": 6,
      "y": 3,
      "z": 9,
      "name": "Rock_Calcite"
    },
    {
      "x": 6,
      "y": 4,
      "z": 9,
      "name": "Rock_Calcite"
    },
    {
      "x": 6,
      "y": 5,
      "z": 9,
      "name": "Rock_Calcite"
    },
    {
      "x": 6,
      "y": 6,
      "z": 9,
      "name": "Rock_Calcite"
    },
    {
      "x": 6,
      "y": 7,
      "z": 9,
      "name": "Rock_Calcite"
    },
    {
      "x": 6,
      "y": 8,
      "z": 9,
      "name": "Rock_Calcite"
    },
    {
      "x": 6,
      "y": 0,
      "z": 10,
      "name": "Rock_Chalk_Brick_Smooth"
    },
    {
      "x": 6,
      "y": 1,
      "z": 10,
      "name": "Rock_Chalk_Brick_Smooth"
    },
    {
      "x": 6,
      "y": 2,
      "z": 10,
      "name": "Rock_Chalk_Brick_Smooth"
    },
    {
      "x": 6,
      "y": 3,
      "z": 10,
      "name": "Rock_Chalk_Brick_Smooth"
    },
    {
      "x": 6,
      "y": 8,
      "z": 10,
      "name": "Rock_Chalk_Brick_Smooth"
    },
    {
      "x": 6,
      "y": 9,
      "z": 10,
      "name": "Rock_Chalk_Brick_Smooth"
    },
    {
      "x": 6,
      "y": 10,
      "z": 10,
      "name": "Rock_Chalk_Brick_Smooth"
    },
    {
      "x": 6,
      "y": 11,
      "z": 10,
      "name": "Rock_Chalk_Brick_Smooth"
    },
    {
      "x": 7,
      "y": 0,
      "z": -10,
      "name": "Rock_Chalk_Brick_Smooth"
    },
    {
      "x": 7,
      "y": 1,
      "z": -10,
      "name": "Rock_Chalk_Brick_Smooth"
    },
    {
      "x": 7,
      "y": 2,
      "z": -10,
      "name": "Rock_Chalk_Brick_Smooth"
    },
    {
      "x": 7,
      "y": 3,
      "z": -10,
      "name": "Rock_Chalk_Brick_Smooth"
    },
    {
      "x": 7,
      "y": 8,
      "z": -10,
      "name": "Rock_Chalk_Brick_Smooth"
    },
    {
      "x": 7,
      "y": 9,
      "z": -10,
      "name": "Rock_Chalk_Brick_Smooth"
    },
    {
      "x": 7,
      "y": 10,
      "z": -10,
      "name": "Rock_Chalk_Brick_Smooth"
    },
    {
      "x": 7,
      "y": 11,
      "z": -10,
      "name": "Rock_Chalk_Brick_Smooth"
    },
    {
      "x": 7,
      "y": 3,
      "z": -9,
      "name": "Rock_Calcite"
    },
    {
      "x": 7,
      "y": 4,
      "z": -9,
      "name": "Rock_Calcite"
    },
    {
      "x": 7,
      "y": 5,
      "z": -9,
      "name": "Rock_Calcite"
    },
    {
      "x": 7,
      "y": 6,
      "z": -9,
      "name": "Rock_Calcite"
    },
    {
      "x": 7,
      "y": 7,
      "z": -9,
      "name": "Rock_Calcite"
    },
    {
      "x": 7,
      "y": 8,
      "z": -9,
      "name": "Rock_Calcite"
    },
    {
      "x": 7,
      "y": 4,
      "z": -8,
      "name": "Cloth_Block_Wool_Black"
    },
    {
      "x": 7,
      "y": 5,
      "z": -8,
      "name": "Cloth_Block_Wool_Black"
    },
    {
      "x": 7,
      "y": 6,
      "z": -8,
      "name": "Cloth_Block_Wool_Black"
    },
    {
      "x": 7,
      "y": 7,
      "z": -8,
      "name": "Cloth_Block_Wool_Black"
    },
    {
      "x": 7,
      "y": 4,
      "z": 8,
      "name": "Cloth_Block_Wool_Black"
    },
    {
      "x": 7,
      "y": 5,
      "z": 8,
      "name": "Cloth_Block_Wool_Black"
    },
    {
      "x": 7,
      "y": 6,
      "z": 8,
      "name": "Cloth_Block_Wool_Black"
    },
    {
      "x": 7,
      "y": 7,
      "z": 8,
      "name": "Cloth_Block_Wool_Black"
    },
    {
      "x": 7,
      "y": 3,
      "z": 9,
      "name": "Rock_Calcite"
    },
    {
      "x": 7,
      "y": 4,
      "z": 9,
      "name": "Rock_Calcite"
    },
    {
      "x": 7,
      "y": 5,
      "z": 9,
      "name": "Rock_Calcite"
    },
    {
      "x": 7,
      "y": 6,
      "z": 9,
      "name": "Rock_Calcite"
    },
    {
      "x": 7,
      "y": 7,
      "z": 9,
      "name": "Rock_Calcite"
    },
    {
      "x": 7,
      "y": 8,
      "z": 9,
      "name": "Rock_Calcite"
    },
    {
      "x": 7,
      "y": 0,
      "z": 10,
      "name": "Rock_Chalk_Brick_Smooth"
    },
    {
      "x": 7,
      "y": 1,
      "z": 10,
      "name": "Rock_Chalk_Brick_Smooth"
    },
    {
      "x": 7,
      "y": 2,
      "z": 10,
      "name": "Rock_Chalk_Brick_Smooth"
    },
    {
      "x": 7,
      "y": 3,
      "z": 10,
      "name": "Rock_Chalk_Brick_Smooth"
    },
    {
      "x": 7,
      "y": 8,
      "z": 10,
      "name": "Rock_Chalk_Brick_Smooth"
    },
    {
      "x": 7,
      "y": 9,
      "z": 10,
      "name": "Rock_Chalk_Brick_Smooth"
    },
    {
      "x": 7,
      "y": 10,
      "z": 10,
      "name": "Rock_Chalk_Brick_Smooth"
    },
    {
      "x": 7,
      "y": 11,
      "z": 10,
      "name": "Rock_Chalk_Brick_Smooth"
    },
    {
      "x": 8,
      "y": 0,
      "z": -10,
      "name": "Rock_Chalk_Brick_Smooth"
    },
    {
      "x": 8,
      "y": 1,
      "z": -10,
      "name": "Rock_Chalk_Brick_Smooth"
    },
    {
      "x": 8,
      "y": 2,
      "z": -10,
      "name": "Rock_Chalk_Brick_Smooth"
    },
    {
      "x": 8,
      "y": 3,
      "z": -10,
      "name": "Rock_Chalk_Brick_Smooth"
    },
    {
      "x": 8,
      "y": 8,
      "z": -10,
      "name": "Rock_Chalk_Brick_Smooth"
    },
    {
      "x": 8,
      "y": 9,
      "z": -10,
      "name": "Rock_Chalk_Brick_Smooth"
    },
    {
      "x": 8,
      "y": 10,
      "z": -10,
      "name": "Rock_Chalk_Brick_Smooth"
    },
    {
      "x": 8,
      "y": 11,
      "z": -10,
      "name": "Rock_Chalk_Brick_Smooth"
    },
    {
      "x": 8,
      "y": 3,
      "z": -9,
      "name": "Rock_Calcite"
    },
    {
      "x": 8,
      "y": 8,
      "z": -9,
      "name": "Rock_Calcite"
    },
    {
      "x": 8,
      "y": 4,
      "z": -8,
      "name": "Cloth_Block_Wool_Black"
    },
    {
      "x": 8,
      "y": 5,
      "z": -8,
      "name": "Cloth_Block_Wool_Black"
    },
    {
      "x": 8,
      "y": 6,
      "z": -8,
      "name": "Cloth_Block_Wool_Black"
    },
    {
      "x": 8,
      "y": 7,
      "z": -8,
      "name": "Cloth_Block_Wool_Black"
    },
    {
      "x": 8,
      "y": 4,
      "z": 8,
      "name": "Cloth_Block_Wool_Black"
    },
    {
      "x": 8,
      "y": 5,
      "z": 8,
      "name": "Cloth_Block_Wool_Black"
    },
    {
      "x": 8,
      "y": 6,
      "z": 8,
      "name": "Cloth_Block_Wool_Black"
    },
    {
      "x": 8,
      "y": 7,
      "z": 8,
      "name": "Cloth_Block_Wool_Black"
    },
    {
      "x": 8,
      "y": 3,
      "z": 9,
      "name": "Rock_Calcite"
    },
    {
      "x": 8,
      "y": 8,
      "z": 9,
      "name": "Rock_Calcite"
    },
    {
      "x": 8,
      "y": 0,
      "z": 10,
      "name": "Rock_Chalk_Brick_Smooth"
    },
    {
      "x": 8,
      "y": 1,
      "z": 10,
      "name": "Rock_Chalk_Brick_Smooth"
    },
    {
      "x": 8,
      "y": 2,
      "z": 10,
      "name": "Rock_Chalk_Brick_Smooth"
    },
    {
      "x": 8,
      "y": 3,
      "z": 10,
      "name": "Rock_Chalk_Brick_Smooth"
    },
    {
      "x": 8,
      "y": 8,
      "z": 10,
      "name": "Rock_Chalk_Brick_Smooth"
    },
    {
      "x": 8,
      "y": 9,
      "z": 10,
      "name": "Rock_Chalk_Brick_Smooth"
    },
    {
      "x": 8,
      "y": 10,
      "z": 10,
      "name": "Rock_Chalk_Brick_Smooth"
    },
    {
      "x": 8,
      "y": 11,
      "z": 10,
      "name": "Rock_Chalk_Brick_Smooth"
    },
    {
      "x": 9,
      "y": 0,
      "z": -10,
      "name": "Rock_Chalk_Brick_Smooth"
    },
    {
      "x": 9,
      "y": 1,
      "z": -10,
      "name": "Rock_Chalk_Brick_Smooth"
    },
    {
      "x": 9,
      "y": 2,
      "z": -10,
      "name": "Rock_Chalk_Brick_Smooth"
    },
    {
      "x": 9,
      "y": 3,
      "z": -10,
      "name": "Rock_Chalk_Brick_Smooth"
    },
    {
      "x": 9,
      "y": 8,
      "z": -10,
      "name": "Rock_Chalk_Brick_Smooth"
    },
    {
      "x": 9,
      "y": 9,
      "z": -10,
      "name": "Rock_Chalk_Brick_Smooth"
    },
    {
      "x": 9,
      "y": 10,
      "z": -10,
      "name": "Rock_Chalk_Brick_Smooth"
    },
    {
      "x": 9,
      "y": 11,
      "z": -10,
      "name": "Rock_Chalk_Brick_Smooth"
    },
    {
      "x": 9,
      "y": 3,
      "z": -9,
      "name": "Rock_Calcite"
    },
    {
      "x": 9,
      "y": 8,
      "z": -9,
      "name": "Rock_Calcite"
    },
    {
      "x": 9,
      "y": 4,
      "z": -8,
      "name": "Cloth_Block_Wool_Black"
    },
    {
      "x": 9,
      "y": 5,
      "z": -8,
      "name": "Cloth_Block_Wool_Black"
    },
    {
      "x": 9,
      "y": 6,
      "z": -8,
      "name": "Cloth_Block_Wool_Black"
    },
    {
      "x": 9,
      "y": 7,
      "z": -8,
      "name": "Cloth_Block_Wool_Black"
    },
    {
      "x": 9,
      "y": 4,
      "z": 8,
      "name": "Cloth_Block_Wool_Black"
    },
    {
      "x": 9,
      "y": 5,
      "z": 8,
      "name": "Cloth_Block_Wool_Black"
    },
    {
      "x": 9,
      "y": 6,
      "z": 8,
      "name": "Cloth_Block_Wool_Black"
    },
    {
      "x": 9,
      "y": 7,
      "z": 8,
      "name": "Cloth_Block_Wool_Black"
    },
    {
      "x": 9,
      "y": 3,
      "z": 9,
      "name": "Rock_Calcite"
    },
    {
      "x": 9,
      "y": 8,
      "z": 9,
      "name": "Rock_Calcite"
    },
    {
      "x": 9,
      "y": 0,
      "z": 10,
      "name": "Rock_Chalk_Brick_Smooth"
    },
    {
      "x": 9,
      "y": 1,
      "z": 10,
      "name": "Rock_Chalk_Brick_Smooth"
    },
    {
      "x": 9,
      "y": 2,
      "z": 10,
      "name": "Rock_Chalk_Brick_Smooth"
    },
    {
      "x": 9,
      "y": 3,
      "z": 10,
      "name": "Rock_Chalk_Brick_Smooth"
    },
    {
      "x": 9,
      "y": 8,
      "z": 10,
      "name": "Rock_Chalk_Brick_Smooth"
    },
    {
      "x": 9,
      "y": 9,
      "z": 10,
      "name": "Rock_Chalk_Brick_Smooth"
    },
    {
      "x": 9,
      "y": 10,
      "z": 10,
