{
  "version": 8,
  "blockIdVersion": 11,
  "anchorX": 0,
  "anchorY": 0,
  "anchorZ": 0,
  "blocks": [
    {
      "x": -9,
      "y": 0,
      "z": -9,
      "name": "BO_Pool_Surface00",
      "rotation": 4
    },
    {
      "x": -9,
      "y": 1,
      "z": -9,
      "name": "BO_Pool_Surface00",
      "rotation": 4
    },
    {
      "x": -9,
      "y": 2,
      "z": -9,
      "name": "BO_Pool_Surface00",
      "rotation": 4
    },
    {
      "x": -9,
      "y": 3,
      "z": -9,
      "name": "BO_Pool_Surface00",
      "rotation": 4
    },
    {
      "x": -9,
      "y": 4,
      "z": -9,
      "name": "BO_Pool_Surface00",
      "rotation": 4
    },
    {
      "x": -9,
      "y": 5,
      "z": -9,
      "name": "BO_Pool_Surface00",
      "rotation": 4
    },
    {
      "x": -9,
      "y": 6,
      "z": -9,
      "name": "BO_Pool_Surface00",
      "rotation": 4
    },
    {
      "x": -9,
      "y": 7,
      "z": -9,
      "name": "BO_Pool_Surface00",
      "rotation": 4
    },
    {
      "x": -9,
      "y": 8,
      "z": -9,
      "name": "BO_Pool_Surface00",
      "rotation": 4
    },
    {
      "x": -9,
      "y": 9,
      "z": -9,
      "name": "BO_Pool_Surface00",
      "rotation": 4
    },
    {
      "x": -9,
      "y": 10,
      "z": -9,
      "name": "BO_Pool_Surface00",
      "rotation": 4
    },
    {
      "x": -9,
      "y": 11,
      "z": -9,
      "name": "BO_Pool_Surface00",
      "rotation": 4
    },
    {
      "x": -9,
      "y": 12,
      "z": -9,
      "name": "BO_Pool_Surface00",
      "rotation": 4
    },
    {
      "x": -9,
      "y": 13,
      "z": -9,
      "name": "BO_Pool_Surface00",
      "rotation": 4
    },
    {
      "x": -9,
      "y": 14,
      "z": -9,
      "name": "BO_Pool_Surface00",
      "rotation": 4
    },
    {
      "x": -9,
      "y": 15,
      "z": -9,
      "name": "Build_Black_Cube"
    },
    {
      "x": -9,
      "y": 0,
      "z": -8,
      "name": "BO_Pool_Surface00",
      "rotation": 4
    },
    {
      "x": -9,
      "y": 1,
      "z": -8,
      "name": "BO_Pool_Surface00",
      "rotation": 4
    },
    {
      "x": -9,
      "y": 2,
      "z": -8,
      "name": "BO_Pool_Surface00",
      "rotation": 4
    },
    {
      "x": -9,
      "y": 3,
      "z": -8,
      "name": "BO_Pool_Surface00",
      "rotation": 4
    },
    {
      "x": -9,
      "y": 4,
      "z": -8,
      "name": "BO_Pool_Surface00",
      "rotation": 4
    },
    {
      "x": -9,
      "y": 5,
      "z": -8,
      "name": "BO_Pool_Surface00",
      "rotation": 4
    },
    {
      "x": -9,
      "y": 6,
      "z": -8,
      "name": "BO_Pool_Surface00",
      "rotation": 4
    },
    {
      "x": -9,
      "y": 7,
      "z": -8,
      "name": "BO_Pool_Surface00",
      "rotation": 4
    },
    {
      "x": -9,
      "y": 8,
      "z": -8,
      "name": "BO_Pool_Surface00",
      "rotation": 4
    },
    {
      "x": -9,
      "y": 9,
      "z": -8,
      "name": "BO_Pool_Surface00",
      "rotation": 4
    },
    {
      "x": -9,
      "y": 10,
      "z": -8,
      "name": "BO_Pool_Surface00",
      "rotation": 4
    },
    {
      "x": -9,
      "y": 11,
      "z": -8,
      "name": "BO_Pool_Surface00",
      "rotation": 4
    },
    {
      "x": -9,
      "y": 12,
      "z": -8,
      "name": "BO_Pool_Surface00",
      "rotation": 4
    },
    {
      "x": -9,
      "y": 13,
      "z": -8,
      "name": "BO_Pool_Surface00",
      "rotation": 4
    },
    {
      "x": -9,
      "y": 14,
      "z": -8,
      "name": "BO_Pool_Surface00",
      "rotation": 4
    },
    {
      "x": -9,
      "y": 15,
      "z": -8,
      "name": "Build_Black_Cube"
    },
    {
      "x": -9,
      "y": 0,
      "z": -7,
      "name": "BO_Pool_Surface00",
      "rotation": 4
    },
    {
      "x": -9,
      "y": 1,
      "z": -7,
      "name": "BO_Pool_Surface00",
      "rotation": 4
    },
    {
      "x": -9,
      "y": 9,
      "z": -7,
      "name": "BO_Pool_Surface00",
      "rotation": 4
    },
    {
      "x": -9,
      "y": 10,
      "z": -7,
      "name": "BO_Pool_Surface00",
      "rotation": 4
    },
    {
      "x": -9,
      "y": 11,
      "z": -7,
      "name": "BO_Pool_Surface00",
      "rotation": 4
    },
    {
      "x": -9,
      "y": 12,
      "z": -7,
      "name": "BO_Pool_Surface00",
      "rotation": 4
    },
    {
      "x": -9,
      "y": 13,
      "z": -7,
      "name": "BO_Pool_Surface00",
      "rotation": 4
    },
    {
      "x": -9,
      "y": 14,
      "z": -7,
      "name": "BO_Pool_Surface00",
      "rotation": 4
    },
    {
      "x": -9,
      "y": 15,
      "z": -7,
      "name": "Build_Black_Cube"
    },
    {
      "x": -9,
      "y": 0,
      "z": -6,
      "name": "BO_Pool_Surface00",
      "rotation": 4
    },
    {
      "x": -9,
      "y": 9,
      "z": -6,
      "name": "BO_Pool_Surface00",
      "rotation": 4
    },
    {
      "x": -9,
      "y": 10,
      "z": -6,
      "name": "BO_Pool_Surface00",
      "rotation": 4
    },
    {
      "x": -9,
      "y": 11,
      "z": -6,
      "name": "BO_Pool_Surface00",
      "rotation": 4
    },
    {
      "x": -9,
      "y": 12,
      "z": -6,
      "name": "BO_Pool_Surface00",
      "rotation": 4
    },
    {
      "x": -9,
      "y": 13,
      "z": -6,
      "name": "BO_Pool_Surface00",
      "rotation": 4
    },
    {
      "x": -9,
      "y": 14,
      "z": -6,
      "name": "BO_Pool_Surface00",
      "rotation": 4
    },
    {
      "x": -9,
      "y": 15,
      "z": -6,
      "name": "Build_Black_Cube"
    },
    {
      "x": -9,
      "y": 0,
      "z": -5,
      "name": "BO_Pool_Surface00",
      "rotation": 4
    },
    {
      "x": -9,
      "y": 9,
      "z": -5,
      "name": "BO_Pool_Surface00",
      "rotation": 4
    },
    {
      "x": -9,
      "y": 10,
      "z": -5,
      "name": "BO_Pool_Surface00",
      "rotation": 4
    },
    {
      "x": -9,
      "y": 11,
      "z": -5,
      "name": "BO_Pool_Surface00",
      "rotation": 4
    },
    {
      "x": -9,
      "y": 12,
      "z": -5,
      "name": "BO_Pool_Surface00",
      "rotation": 4
    },
    {
      "x": -9,
      "y": 13,
      "z": -5,
      "name": "BO_Pool_Surface00",
      "rotation": 4
    },
    {
      "x": -9,
      "y": 14,
      "z": -5,
      "name": "BO_Pool_Surface00",
      "rotation": 4
    },
    {
      "x": -9,
      "y": 15,
      "z": -5,
      "name": "Build_Black_Cube"
    },
    {
      "x": -9,
      "y": 0,
      "z": -4,
      "name": "BO_Pool_Surface00",
      "rotation": 4
    },
    {
      "x": -9,
      "y": 9,
      "z": -4,
      "name": "BO_Pool_Surface00",
      "rotation": 4
    },
    {
      "x": -9,
      "y": 10,
      "z": -4,
      "name": "BO_Pool_Surface00",
      "rotation": 4
    },
    {
      "x": -9,
      "y": 11,
      "z": -4,
      "name": "BO_Pool_Surface00",
      "rotation": 4
    },
    {
      "x": -9,
      "y": 12,
      "z": -4,
      "name": "BO_Pool_Surface00",
      "rotation": 4
    },
    {
      "x": -9,
      "y": 13,
      "z": -4,
      "name": "BO_Pool_Surface00",
      "rotation": 4
    },
    {
      "x": -9,
      "y": 14,
      "z": -4,
      "name": "BO_Pool_Surface00",
      "rotation": 4
    },
    {
      "x": -9,
      "y": 15,
      "z": -4,
      "name": "Build_Black_Cube"
    },
    {
      "x": -9,
      "y": 0,
      "z": -3,
      "name": "BO_Pool_Surface00",
      "rotation": 4
    },
    {
      "x": -9,
      "y": 9,
      "z": -3,
      "name": "BO_Pool_Surface00",
      "rotation": 4
    },
    {
      "x": -9,
      "y": 10,
      "z": -3,
      "name": "BO_Pool_Surface00",
      "rotation": 4
    },
    {
      "x": -9,
      "y": 11,
      "z": -3,
      "name": "BO_Pool_Surface00",
      "rotation": 4
    },
    {
      "x": -9,
      "y": 12,
      "z": -3,
      "name": "BO_Pool_Surface00",
      "rotation": 4
    },
    {
      "x": -9,
      "y": 13,
      "z": -3,
      "name": "BO_Pool_Surface00",
      "rotation": 4
    },
    {
      "x": -9,
      "y": 14,
      "z": -3,
      "name": "BO_Pool_Surface00",
      "rotation": 4
    },
    {
      "x": -9,
      "y": 15,
      "z": -3,
      "name": "Build_Black_Cube"
    },
    {
      "x": -9,
      "y": 0,
      "z": -2,
      "name": "BO_Pool_Surface00",
      "rotation": 4
    },
    {
      "x": -9,
      "y": 1,
      "z": -2,
      "name": "BO_Pool_Surface00",
      "rotation": 4
    },
    {
      "x": -9,
      "y": 9,
      "z": -2,
      "name": "BO_Pool_Surface00",
      "rotation": 4
    },
    {
      "x": -9,
      "y": 10,
      "z": -2,
      "name": "BO_Pool_Surface00",
      "rotation": 4
    },
    {
      "x": -9,
      "y": 11,
      "z": -2,
      "name": "BO_Pool_Surface00",
      "rotation": 4
    },
    {
      "x": -9,
      "y": 12,
      "z": -2,
      "name": "BO_Pool_Surface00",
      "rotation": 4
    },
    {
      "x": -9,
      "y": 13,
      "z": -2,
      "name": "BO_Pool_Surface00",
      "rotation": 4
    },
    {
      "x": -9,
      "y": 14,
      "z": -2,
      "name": "BO_Pool_Surface00",
      "rotation": 4
    },
    {
      "x": -9,
      "y": 15,
      "z": -2,
      "name": "Build_Black_Cube"
    },
    {
      "x": -9,
      "y": 0,
      "z": -1,
      "name": "BO_Pool_Surface00",
      "rotation": 4
    },
    {
      "x": -9,
      "y": 1,
      "z": -1,
      "name": "BO_Pool_Surface00",
      "rotation": 4
    },
    {
      "x": -9,
      "y": 2,
      "z": -1,
      "name": "BO_Pool_Surface00",
      "rotation": 4
    },
    {
      "x": -9,
      "y": 3,
      "z": -1,
      "name": "BO_Pool_Surface00",
      "rotation": 4
    },
    {
      "x": -9,
      "y": 4,
      "z": -1,
      "name": "BO_Pool_Surface00",
      "rotation": 4
    },
    {
      "x": -9,
      "y": 5,
      "z": -1,
      "name": "BO_Pool_Surface00",
      "rotation": 4
    },
    {
      "x": -9,
      "y": 6,
      "z": -1,
      "name": "BO_Pool_Surface00",
      "rotation": 4
    },
    {
      "x": -9,
      "y": 7,
      "z": -1,
      "name": "BO_Pool_Surface00",
      "rotation": 4
    },
    {
      "x": -9,
      "y": 8,
      "z": -1,
      "name": "BO_Pool_Surface00",
      "rotation": 4
    },
    {
      "x": -9,
      "y": 9,
      "z": -1,
      "name": "BO_Pool_Surface00",
      "rotation": 4
    },
    {
      "x": -9,
      "y": 10,
      "z": -1,
      "name": "BO_Pool_Surface00",
      "rotation": 4
    },
    {
      "x": -9,
      "y": 11,
      "z": -1,
      "name": "BO_Pool_Surface00",
      "rotation": 4
    },
    {
      "x": -9,
      "y": 12,
      "z": -1,
      "name": "BO_Pool_Surface00",
      "rotation": 4
    },
    {
      "x": -9,
      "y": 13,
      "z": -1,
      "name": "BO_Pool_Surface00",
      "rotation": 4
    },
    {
      "x": -9,
      "y": 14,
      "z": -1,
      "name": "BO_Pool_Surface00",
      "rotation": 4
    },
    {
      "x": -9,
      "y": 15,
      "z": -1,
      "name": "Build_Black_Cube"
    },
    {
      "x": -9,
      "y": 0,
      "z": 0,
      "name": "BO_Pool_Surface00",
      "rotation": 4
    },
    {
      "x": -9,
      "y": 1,
      "z": 0,
      "name": "BO_Pool_Surface00",
      "rotation": 4
    },
    {
      "x": -9,
      "y": 2,
      "z": 0,
      "name": "BO_Pool_Surface00",
      "rotation": 4
    },
    {
      "x": -9,
      "y": 3,
      "z": 0,
      "name": "BO_Pool_Surface00",
      "rotation": 4
    },
    {
      "x": -9,
      "y": 4,
      "z": 0,
      "name": "BO_Pool_Surface00",
      "rotation": 4
    },
    {
      "x": -9,
      "y": 5,
      "z": 0,
      "name": "BO_Pool_Surface00",
      "rotation": 4
    },
    {
      "x": -9,
      "y": 6,
      "z": 0,
      "name": "BO_Pool_Surface00",
      "rotation": 4
    },
    {
      "x": -9,
      "y": 7,
      "z": 0,
      "name": "BO_Pool_Surface00",
      "rotation": 4
    },
    {
      "x": -9,
      "y": 8,
      "z": 0,
      "name": "BO_Pool_Surface00",
      "rotation": 4
    },
    {
      "x": -9,
      "y": 9,
      "z": 0,
      "name": "BO_Pool_Surface00",
      "rotation": 4
    },
    {
      "x": -9,
      "y": 10,
      "z": 0,
      "name": "BO_Pool_Surface00",
      "rotation": 4
    },
    {
      "x": -9,
      "y": 11,
      "z": 0,
      "name": "BO_Pool_Surface00",
      "rotation": 4
    },
    {
      "x": -9,
      "y": 12,
      "z": 0,
      "name": "BO_Pool_Surface00",
      "rotation": 4
    },
    {
      "x": -9,
      "y": 13,
      "z": 0,
      "name": "BO_Pool_Surface00",
      "rotation": 4
    },
    {
      "x": -9,
      "y": 14,
      "z": 0,
      "name": "BO_Pool_Surface00",
      "rotation": 4
    },
    {
      "x": -9,
      "y": 15,
      "z": 0,
      "name": "Build_Black_Cube"
    },
    {
      "x": -9,
      "y": 0,
      "z": 1,
      "name": "BO_Pool_Surface00",
      "rotation": 4
    },
    {
      "x": -9,
      "y": 1,
      "z": 1,
      "name": "BO_Pool_Surface00",
      "rotation": 4
    },
    {
      "x": -9,
      "y": 2,
      "z": 1,
      "name": "BO_Pool_Surface00",
      "rotation": 4
    },
    {
      "x": -9,
      "y": 3,
      "z": 1,
      "name": "BO_Pool_Surface00",
      "rotation": 4
    },
    {
      "x": -9,
      "y": 4,
      "z": 1,
      "name": "BO_Pool_Surface00",
      "rotation": 4
    },
    {
      "x": -9,
      "y": 5,
      "z": 1,
      "name": "BO_Pool_Surface00",
      "rotation": 4
    },
    {
      "x": -9,
      "y": 6,
      "z": 1,
      "name": "BO_Pool_Surface00",
      "rotation": 4
    },
    {
      "x": -9,
      "y": 7,
      "z": 1,
      "name": "BO_Pool_Surface00",
      "rotation": 4
    },
    {
      "x": -9,
      "y": 8,
      "z": 1,
      "name": "BO_Pool_Surface00",
      "rotation": 4
    },
    {
      "x": -9,
      "y": 9,
      "z": 1,
      "name": "BO_Pool_Surface00",
      "rotation": 4
    },
    {
      "x": -9,
      "y": 10,
      "z": 1,
      "name": "BO_Pool_Surface00",
      "rotation": 4
    },
    {
      "x": -9,
      "y": 11,
      "z": 1,
      "name": "BO_Pool_Surface00",
      "rotation": 4
    },
    {
      "x": -9,
      "y": 12,
      "z": 1,
      "name": "BO_Pool_Surface00",
      "rotation": 4
    },
    {
      "x": -9,
      "y": 13,
      "z": 1,
      "name": "BO_Pool_Surface00",
      "rotation": 4
    },
    {
      "x": -9,
      "y": 14,
      "z": 1,
      "name": "BO_Pool_Surface00",
      "rotation": 4
    },
    {
      "x": -9,
      "y": 15,
      "z": 1,
      "name": "Build_Black_Cube"
    },
    {
      "x": -9,
      "y": 0,
      "z": 2,
      "name": "BO_Pool_Surface00",
      "rotation": 4
    },
    {
      "x": -9,
      "y": 1,
      "z": 2,
      "name": "BO_Pool_Surface00",
      "rotation": 4
    },
    {
      "x": -9,
      "y": 2,
      "z": 2,
      "name": "BO_Pool_Surface00",
      "rotation": 4
    },
    {
      "x": -9,
      "y": 3,
      "z": 2,
      "name": "BO_Pool_Surface00",
      "rotation": 4
    },
    {
      "x": -9,
      "y": 4,
      "z": 2,
      "name": "BO_Pool_Surface00",
      "rotation": 4
    },
    {
      "x": -9,
      "y": 5,
      "z": 2,
      "name": "BO_Pool_Surface00",
      "rotation": 4
    },
    {
      "x": -9,
      "y": 6,
      "z": 2,
      "name": "BO_Pool_Surface00",
      "rotation": 4
    },
    {
      "x": -9,
      "y": 7,
      "z": 2,
      "name": "BO_Pool_Surface00",
      "rotation": 4
    },
    {
      "x": -9,
      "y": 8,
      "z": 2,
      "name": "BO_Pool_Surface00",
      "rotation": 4
    },
    {
      "x": -9,
      "y": 9,
      "z": 2,
      "name": "BO_Pool_Surface00",
      "rotation": 4
    },
    {
      "x": -9,
      "y": 10,
      "z": 2,
      "name": "BO_Pool_Surface00",
      "rotation": 4
    },
    {
      "x": -9,
      "y": 11,
      "z": 2,
      "name": "BO_Pool_Surface00",
      "rotation": 4
    },
    {
      "x": -9,
      "y": 12,
      "z": 2,
      "name": "BO_Pool_Surface00",
      "rotation": 4
    },
    {
      "x": -9,
      "y": 13,
      "z": 2,
      "name": "BO_Pool_Surface00",
      "rotation": 4
    },
    {
      "x": -9,
      "y": 14,
      "z": 2,
      "name": "BO_Pool_Surface00",
      "rotation": 4
    },
    {
      "x": -9,
      "y": 15,
      "z": 2,
      "name": "Build_Black_Cube"
    },
    {
      "x": -9,
      "y": 0,
      "z": 3,
      "name": "BO_Pool_Surface00",
      "rotation": 4
    },
    {
      "x": -9,
      "y": 1,
      "z": 3,
      "name": "BO_Pool_Surface00",
      "rotation": 4
    },
    {
      "x": -9,
      "y": 9,
      "z": 3,
      "name": "BO_Pool_Surface00",
      "rotation": 4
    },
    {
      "x": -9,
      "y": 10,
      "z": 3,
      "name": "BO_Pool_Surface00",
      "rotation": 4
    },
    {
      "x": -9,
      "y": 11,
      "z": 3,
      "name": "BO_Pool_Surface00",
      "rotation": 4
    },
    {
      "x": -9,
      "y": 12,
      "z": 3,
      "name": "BO_Pool_Surface00",
      "rotation": 4
    },
    {
      "x": -9,
      "y": 13,
      "z": 3,
      "name": "BO_Pool_Surface00",
      "rotation": 4
    },
    {
      "x": -9,
      "y": 14,
      "z": 3,
      "name": "BO_Pool_Surface00",
      "rotation": 4
    },
    {
      "x": -9,
      "y": 15,
      "z": 3,
      "name": "Build_Black_Cube"
    },
    {
      "x": -9,
      "y": 0,
      "z": 4,
      "name": "BO_Pool_Surface00",
      "rotation": 4
    },
    {
      "x": -9,
      "y": 9,
      "z": 4,
      "name": "BO_Pool_Surface00",
      "rotation": 4
    },
    {
      "x": -9,
      "y": 10,
      "z": 4,
      "name": "BO_Pool_Surface00",
      "rotation": 4
    },
    {
      "x": -9,
      "y": 11,
      "z": 4,
      "name": "BO_Pool_Surface00",
      "rotation": 4
    },
    {
      "x": -9,
      "y": 12,
      "z": 4,
      "name": "BO_Pool_Surface00",
      "rotation": 4
    },
    {
      "x": -9,
      "y": 13,
      "z": 4,
      "name": "BO_Pool_Surface00",
      "rotation": 4
    },
    {
      "x": -9,
      "y": 14,
      "z": 4,
      "name": "BO_Pool_Surface00",
      "rotation": 4
    },
    {
      "x": -9,
      "y": 15,
      "z": 4,
      "name": "Build_Black_Cube"
    },
    {
      "x": -9,
      "y": 0,
      "z": 5,
      "name": "BO_Pool_Surface00",
      "rotation": 4
    },
    {
      "x": -9,
      "y": 9,
      "z": 5,
      "name": "BO_Pool_Surface00",
      "rotation": 4
    },
    {
      "x": -9,
      "y": 10,
      "z": 5,
      "name": "BO_Pool_Surface00",
      "rotation": 4
    },
    {
      "x": -9,
      "y": 11,
      "z": 5,
      "name": "BO_Pool_Surface00",
      "rotation": 4
    },
    {
      "x": -9,
      "y": 12,
      "z": 5,
      "name": "BO_Pool_Surface00",
      "rotation": 4
    },
    {
      "x": -9,
      "y": 13,
      "z": 5,
      "name": "BO_Pool_Surface00",
      "rotation": 4
    },
    {
      "x": -9,
      "y": 14,
      "z": 5,
      "name": "BO_Pool_Surface00",
      "rotation": 4
    },
    {
      "x": -9,
      "y": 15,
      "z": 5,
      "name": "Build_Black_Cube"
    },
    {
      "x": -9,
      "y": 0,
      "z": 6,
      "name": "BO_Pool_Surface00",
      "rotation": 4
    },
    {
      "x": -9,
      "y": 9,
      "z": 6,
      "name": "BO_Pool_Surface00",
      "rotation": 4
    },
    {
      "x": -9,
      "y": 10,
      "z": 6,
      "name": "BO_Pool_Surface00",
      "rotation": 4
    },
    {
      "x": -9,
      "y": 11,
      "z": 6,
      "name": "BO_Pool_Surface00",
      "rotation": 4
    },
    {
      "x": -9,
      "y": 12,
      "z": 6,
      "name": "BO_Pool_Surface00",
      "rotation": 4
    },
    {
      "x": -9,
      "y": 13,
      "z": 6,
      "name": "BO_Pool_Surface00",
      "rotation": 4
    },
    {
      "x": -9,
      "y": 14,
      "z": 6,
      "name": "BO_Pool_Surface00",
      "rotation": 4
    },
    {
      "x": -9,
      "y": 15,
      "z": 6,
      "name": "Build_Black_Cube"
    },
    {
      "x": -9,
      "y": 0,
      "z": 7,
      "name": "BO_Pool_Surface00",
      "rotation": 4
    },
    {
      "x": -9,
      "y": 9,
      "z": 7,
      "name": "BO_Pool_Surface00",
      "rotation": 4
    },
    {
      "x": -9,
      "y": 10,
      "z": 7,
      "name": "BO_Pool_Surface00",
      "rotation": 4
    },
    {
      "x": -9,
      "y": 11,
      "z": 7,
      "name": "BO_Pool_Surface00",
      "rotation": 4
    },
    {
      "x": -9,
      "y": 12,
      "z": 7,
      "name": "BO_Pool_Surface00",
      "rotation": 4
    },
    {
      "x": -9,
      "y": 13,
      "z": 7,
      "name": "BO_Pool_Surface00",
      "rotation": 4
    },
    {
      "x": -9,
      "y": 14,
      "z": 7,
      "name": "BO_Pool_Surface00",
      "rotation": 4
    },
    {
      "x": -9,
      "y": 15,
      "z": 7,
      "name": "Build_Black_Cube"
    },
    {
      "x": -9,
      "y": 0,
      "z": 8,
      "name": "BO_Pool_Surface00",
      "rotation": 4
    },
    {
      "x": -9,
      "y": 1,
      "z": 8,
      "name": "BO_Pool_Surface00",
      "rotation": 4
    },
    {
      "x": -9,
      "y": 9,
      "z": 8,
      "name": "BO_Pool_Surface00",
      "rotation": 4
    },
    {
      "x": -9,
      "y": 10,
      "z": 8,
      "name": "BO_Pool_Surface00",
      "rotation": 4
    },
    {
      "x": -9,
      "y": 11,
      "z": 8,
      "name": "BO_Pool_Surface00",
      "rotation": 4
    },
    {
      "x": -9,
      "y": 12,
      "z": 8,
      "name": "BO_Pool_Surface00",
      "rotation": 4
    },
    {
      "x": -9,
      "y": 13,
      "z": 8,
      "name": "BO_Pool_Surface00",
      "rotation": 4
    },
    {
      "x": -9,
      "y": 14,
      "z": 8,
      "name": "BO_Pool_Surface00",
      "rotation": 4
    },
    {
      "x": -9,
      "y": 15,
      "z": 8,
      "name": "Build_Black_Cube"
    },
    {
      "x": -9,
      "y": 0,
      "z": 9,
      "name": "BO_Pool_Surface00",
      "rotation": 4
    },
    {
      "x": -9,
      "y": 1,
      "z": 9,
      "name": "BO_Pool_Surface00",
      "rotation": 4
    },
    {
      "x": -9,
      "y": 2,
      "z": 9,
      "name": "BO_Pool_Surface00",
      "rotation": 4
    },
    {
      "x": -9,
      "y": 3,
      "z": 9,
      "name": "BO_Pool_Surface00",
      "rotation": 4
    },
    {
      "x": -9,
      "y": 4,
      "z": 9,
      "name": "BO_Pool_Surface00",
      "rotation": 4
    },
    {
      "x": -9,
      "y": 5,
      "z": 9,
      "name": "BO_Pool_Surface00",
      "rotation": 4
    },
    {
      "x": -9,
      "y": 6,
      "z": 9,
      "name": "BO_Pool_Surface00",
      "rotation": 4
    },
    {
      "x": -9,
      "y": 7,
      "z": 9,
      "name": "BO_Pool_Surface00",
      "rotation": 4
    },
    {
      "x": -9,
      "y": 8,
      "z": 9,
      "name": "BO_Pool_Surface00",
      "rotation": 4
    },
    {
      "x": -9,
      "y": 9,
      "z": 9,
      "name": "BO_Pool_Surface00",
      "rotation": 4
    },
    {
      "x": -9,
      "y": 10,
      "z": 9,
      "name": "BO_Pool_Surface00",
      "rotation": 4
    },
    {
      "x": -9,
      "y": 11,
      "z": 9,
      "name": "BO_Pool_Surface00",
      "rotation": 4
    },
    {
      "x": -9,
      "y": 12,
      "z": 9,
      "name": "BO_Pool_Surface00",
      "rotation": 4
    },
    {
      "x": -9,
      "y": 13,
      "z": 9,
      "name": "BO_Pool_Surface00",
      "rotation": 4
    },
    {
      "x": -9,
      "y": 14,
      "z": 9,
      "name": "BO_Pool_Surface00",
      "rotation": 4
    },
    {
      "x": -9,
      "y": 15,
      "z": 9,
      "name": "Build_Black_Cube"
    },
    {
      "x": -9,
      "y": 0,
      "z": 10,
      "name": "BO_Pool_Surface00",
      "rotation": 4
    },
    {
      "x": -9,
      "y": 1,
      "z": 10,
      "name": "BO_Pool_Surface00",
      "rotation": 4
    },
    {
      "x": -9,
      "y": 2,
      "z": 10,
      "name": "BO_Pool_Surface00",
      "rotation": 4
    },
    {
      "x": -9,
      "y": 3,
      "z": 10,
      "name": "BO_Pool_Surface00",
      "rotation": 4
    },
    {
      "x": -9,
      "y": 4,
      "z": 10,
      "name": "BO_Pool_Surface00",
      "rotation": 4
    },
    {
      "x": -9,
      "y": 5,
      "z": 10,
      "name": "BO_Pool_Surface00",
      "rotation": 4
    },
    {
      "x": -9,
      "y": 6,
      "z": 10,
      "name": "BO_Pool_Surface00",
      "rotation": 4
    },
    {
      "x": -9,
      "y": 7,
      "z": 10,
      "name": "BO_Pool_Surface00",
      "rotation": 4
    },
    {
      "x": -9,
      "y": 8,
      "z": 10,
      "name": "BO_Pool_Surface00",
      "rotation": 4
    },
    {
      "x": -9,
      "y": 9,
      "z": 10,
      "name": "BO_Pool_Surface00",
      "rotation": 4
    },
    {
      "x": -9,
      "y": 10,
      "z": 10,
      "name": "BO_Pool_Surface00",
      "rotation": 4
    },
    {
      "x": -9,
      "y": 11,
      "z": 10,
      "name": "BO_Pool_Surface00",
      "rotation": 4
    },
    {
      "x": -9,
      "y": 12,
      "z": 10,
      "name": "BO_Pool_Surface00",
      "rotation": 4
    },
    {
      "x": -9,
      "y": 13,
      "z": 10,
      "name": "BO_Pool_Surface00",
      "rotation": 4
    },
    {
      "x": -9,
      "y": 14,
      "z": 10,
      "name": "BO_Pool_Surface00",
      "rotation": 4
    },
    {
      "x": -9,
      "y": 15,
      "z": 10,
      "name": "Build_Black_Cube"
    },
    {
      "x": -8,
      "y": 0,
      "z": -9,
      "name": "BO_Pool_Surface00",
      "rotation": 4
    },
    {
      "x": -8,
      "y": 1,
      "z": -9,
      "name": "BO_Pool_Surface00",
      "rotation": 4
    },
    {
      "x": -8,
      "y": 2,
      "z": -9,
      "name": "BO_Pool_Surface00",
      "rotation": 4
    },
    {
      "x": -8,
      "y": 3,
      "z": -9,
      "name": "BO_Pool_Surface00",
      "rotation": 4
    },
    {
      "x": -8,
      "y": 4,
      "z": -9,
      "name": "BO_Pool_Surface00",
      "rotation": 4
    },
    {
      "x": -8,
      "y": 5,
      "z": -9,
      "name": "BO_Pool_Surface00",
      "rotation": 4
    },
    {
      "x": -8,
      "y": 6,
      "z": -9,
      "name": "BO_Pool_Surface00",
      "rotation": 4
    },
    {
      "x": -8,
      "y": 7,
      "z": -9,
      "name": "BO_Pool_Surface00",
      "rotation": 4
    },
    {
      "x": -8,
      "y": 8,
      "z": -9,
      "name": "BO_Pool_Surface00",
      "rotation": 4
    },
    {
      "x": -8,
      "y": 9,
      "z": -9,
      "name": "BO_Pool_Surface00",
      "rotation": 4
    },
    {
      "x": -8,
      "y": 10,
      "z": -9,
      "name": "BO_Pool_Surface00",
      "rotation": 4
    },
    {
      "x": -8,
      "y": 11,
      "z": -9,
      "name": "BO_Pool_Surface00",
      "rotation": 4
    },
    {
      "x": -8,
      "y": 12,
      "z": -9,
      "name": "BO_Pool_Surface00",
      "rotation": 4
    },
    {
      "x": -8,
      "y": 13,
      "z": -9,
      "name": "BO_Pool_Surface00",
      "rotation": 4
    },
    {
      "x": -8,
      "y": 14,
      "z": -9,
      "name": "BO_Pool_Surface00",
      "rotation": 4
    },
    {
      "x": -8,
      "y": 15,
      "z": -9,
      "name": "Build_Black_Cube"
    },
    {
      "x": -8,
      "y": 0,
      "z": -8,
      "name": "BO_Pool_Surface00",
      "rotation": 4
    },
    {
      "x": -8,
      "y": 1,
      "z": -8,
      "name": "BO_Pool_Surface00",
      "rotation": 4
    },
    {
      "x": -8,
      "y": 2,
      "z": -8,
      "name": "BO_Pool_Surface00",
      "rotation": 4
    },
    {
      "x": -8,
      "y": 3,
      "z": -8,
      "name": "BO_Pool_Surface00",
      "rotation": 4
    },
    {
      "x": -8,
      "y": 4,
      "z": -8,
      "name": "BO_Pool_Surface00",
      "rotation": 4
    },
    {
      "x": -8,
      "y": 5,
      "z": -8,
      "name": "BO_Pool_Surface00",
      "rotation": 4
    },
    {
      "x": -8,
      "y": 6,
      "z": -8,
      "name": "BO_Pool_Surface00",
      "rotation": 4
    },
    {
      "x": -8,
      "y": 7,
      "z": -8,
      "name": "BO_Pool_Surface00",
      "rotation": 4
    },
    {
      "x": -8,
      "y": 8,
      "z": -8,
      "name": "BO_Pool_Surface00",
      "rotation": 4
    },
    {
      "x": -8,
      "y": 9,
      "z": -8,
      "name": "BO_Pool_Surface00",
      "support": 15
    },
    {
      "x": -8,
      "y": 10,
      "z": -8,
      "name": "BO_Pool_Surface00",
      "support": 15
    },
    {
      "x": -8,
      "y": 11,
      "z": -8,
      "name": "BO_Pool_Surface00",
      "support": 15
    },
    {
      "x": -8,
      "y": 12,
      "z": -8,
      "name": "BO_Pool_Surface00",
      "support": 15
    },
    {
      "x": -8,
      "y": 13,
      "z": -8,
      "name": "BO_Pool_Surface00",
      "support": 15
    },
    {
      "x": -8,
      "y": 14,
      "z": -8,
      "name": "*BO_Lightsource_Cycle_State_Definitions_Day",
      "components": {
        "Components": {
          "BlackoutCycleState": {
            "OnState": "Day",
            "OffState": "Night"
          }
        }
      }
    },
    {
      "x": -8,
      "y": 15,
      "z": -8,
      "name": "Build_Black_Cube"
    },
    {
      "x": -8,
      "y": 0,
      "z": -7,
      "name": "BO_Pool_Surface00",
      "rotation": 4
    },
    {
      "x": -8,
      "y": 1,
      "z": -7,
      "name": "BO_Pool_Surface00",
      "rotation": 4
    },
    {
      "x": -8,
      "y": 13,
      "z": -7,
      "name": "BO_Pool_Surface00",
      "support": 15
    },
    {
      "x": -8,
      "y": 14,
      "z": -7,
      "name": "*BO_Lightsource_Cycle_State_Definitions_Day",
      "components": {
        "Components": {
          "BlackoutCycleState": {
            "OnState": "Day",
            "OffState": "Night"
          }
        }
      }
    },
    {
      "x": -8,
      "y": 15,
      "z": -7,
      "name": "Build_Black_Cube"
    },
    {
      "x": -8,
      "y": 0,
      "z": -6,
      "name": "BO_Pool_Surface00",
      "rotation": 4
    },
    {
      "x": -8,
      "y": 13,
      "z": -6,
      "name": "BO_Pool_Surface00",
      "support": 15
    },
    {
      "x": -8,
      "y": 14,
      "z": -6,
      "name": "*BO_Lightsource_Cycle_State_Definitions_Day",
      "components": {
        "Components": {
          "BlackoutCycleState": {
            "OnState": "Day",
            "OffState": "Night"
          }
        }
      }
    },
    {
      "x": -8,
      "y": 15,
      "z": -6,
      "name": "Build_Black_Cube"
    },
    {
      "x": -8,
      "y": 0,
      "z": -5,
      "name": "BO_Pool_Surface00",
      "rotation": 4
    },
    {
      "x": -8,
      "y": 13,
      "z": -5,
      "name": "BO_Pool_Surface00",
      "support": 15
    },
    {
      "x": -8,
      "y": 14,
      "z": -5,
      "name": "*BO_Lightsource_Cycle_State_Definitions_Day",
      "components": {
        "Components": {
          "BlackoutCycleState": {
            "OnState": "Day",
            "OffState": "Night"
          }
        }
      }
    },
    {
      "x": -8,
      "y": 15,
      "z": -5,
      "name": "Build_Black_Cube"
    },
    {
      "x": -8,
      "y": 0,
      "z": -4,
      "name": "BO_Pool_Surface00",
      "rotation": 4
    },
    {
      "x": -8,
      "y": 13,
      "z": -4,
      "name": "BO_Pool_Surface00",
      "support": 15
    },
    {
      "x": -8,
      "y": 14,
      "z": -4,
      "name": "*BO_Lightsource_Cycle_State_Definitions_Day",
      "components": {
        "Components": {
          "BlackoutCycleState": {
            "OnState": "Day",
            "OffState": "Night"
          }
        }
      }
    },
    {
      "x": -8,
      "y": 15,
      "z": -4,
      "name": "Build_Black_Cube"
    },
    {
      "x": -8,
      "y": 0,
      "z": -3,
      "name": "BO_Pool_Surface00",
      "rotation": 4
    },
    {
      "x": -8,
      "y": 13,
      "z": -3,
      "name": "BO_Pool_Surface00",
      "support": 15
    },
    {
      "x": -8,
      "y": 14,
      "z": -3,
      "name": "*BO_Lightsource_Cycle_State_Definitions_Day",
      "components": {
        "Components": {
          "BlackoutCycleState": {
            "OnState": "Day",
            "OffState": "Night"
          }
        }
      }
    },
    {
      "x": -8,
      "y": 15,
      "z": -3,
      "name": "Build_Black_Cube"
    },
    {
      "x": -8,
      "y": 0,
      "z": -2,
      "name": "BO_Pool_Surface00",
      "rotation": 4
    },
    {
      "x": -8,
      "y": 1,
      "z": -2,
      "name": "BO_Pool_Surface00",
      "rotation": 4
    },
    {
      "x": -8,
      "y": 13,
      "z": -2,
      "name": "BO_Pool_Surface00",
      "support": 15
    },
    {
      "x": -8,
      "y": 14,
      "z": -2,
      "name": "*BO_Lightsource_Cycle_State_Definitions_Day",
      "components": {
        "Components": {
          "BlackoutCycleState": {
            "OnState": "Day",
            "OffState": "Night"
          }
        }
      }
    },
    {
      "x": -8,
      "y": 15,
      "z": -2,
      "name": "Build_Black_Cube"
    },
    {
      "x": -8,
      "y": 0,
      "z": -1,
      "name": "BO_Pool_Surface00",
      "rotation": 4
    },
    {
      "x": -8,
      "y": 1,
      "z": -1,
      "name": "BO_Pool_Surface00",
      "rotation": 4
    },
    {
      "x": -8,
      "y": 2,
      "z": -1,
      "name": "BO_Pool_Surface00",
      "rotation": 4
    },
    {
      "x": -8,
      "y": 3,
      "z": -1,
      "name": "BO_Pool_Surface00",
      "rotation": 4
    },
    {
      "x": -8,
      "y": 4,
      "z": -1,
      "name": "BO_Pool_Surface00",
      "rotation": 4
    },
    {
      "x": -8,
      "y": 5,
      "z": -1,
      "name": "BO_Pool_Surface00",
      "rotation": 4
    },
    {
      "x": -8,
      "y": 6,
      "z": -1,
      "name": "BO_Pool_Surface00",
      "rotation": 4
    },
    {
      "x": -8,
      "y": 7,
      "z": -1,
      "name": "BO_Pool_Surface00",
      "rotation": 4
    },
    {
      "x": -8,
      "y": 8,
      "z": -1,
      "name": "BO_Pool_Surface00",
      "rotation": 4
    },
    {
      "x": -8,
      "y": 9,
      "z": -1,
      "name": "BO_Pool_Surface00",
      "support": 15
    },
    {
      "x": -8,
      "y": 10,
      "z": -1,
      "name": "BO_Pool_Surface00",
      "support": 15
    },
    {
      "x": -8,
      "y": 11,
      "z": -1,
      "name": "BO_Pool_Surface00",
      "support": 15
    },
    {
      "x": -8,
      "y": 12,
      "z": -1,
      "name": "BO_Pool_Surface00",
      "support": 15
    },
    {
      "x": -8,
      "y": 13,
      "z": -1,
      "name": "BO_Pool_Surface00",
      "support": 15
    },
    {
      "x": -8,
      "y": 14,
      "z": -1,
      "name": "*BO_Lightsource_Cycle_State_Definitions_Day",
      "components": {
        "Components": {
          "BlackoutCycleState": {
            "OnState": "Day",
            "OffState": "Night"
          }
        }
      }
    },
    {
      "x": -8,
      "y": 15,
      "z": -1,
      "name": "Build_Black_Cube"
    },
    {
      "x": -8,
      "y": 0,
      "z": 0,
      "name": "BO_Pool_Surface00",
      "rotation": 4
    },
    {
      "x": -8,
      "y": 1,
      "z": 0,
      "name": "BO_Pool_Surface00",
      "rotation": 4
    },
    {
      "x": -8,
      "y": 2,
      "z": 0,
      "name": "BO_Pool_Surface00",
      "rotation": 4
    },
    {
      "x": -8,
      "y": 3,
      "z": 0,
      "name": "BO_Pool_Surface00",
      "rotation": 4
    },
    {
      "x": -8,
      "y": 4,
      "z": 0,
      "name": "BO_Pool_Surface00",
      "rotation": 4
    },
    {
      "x": -8,
      "y": 5,
      "z": 0,
      "name": "BO_Pool_Surface00",
      "rotation": 4
    },
    {
      "x": -8,
      "y": 6,
      "z": 0,
      "name": "BO_Pool_Surface00",
      "rotation": 4
    },
    {
      "x": -8,
      "y": 7,
      "z": 0,
      "name": "BO_Pool_Surface00",
      "rotation": 4
    },
    {
      "x": -8,
      "y": 8,
      "z": 0,
      "name": "BO_Pool_Surface00",
      "rotation": 4
    },
    {
      "x": -8,
      "y": 9,
      "z": 0,
      "name": "BO_Pool_Surface00",
      "support": 15
    },
    {
      "x": -8,
      "y": 10,
      "z": 0,
      "name": "BO_Pool_Surface00",
      "support": 15
    },
    {
      "x": -8,
      "y": 11,
      "z": 0,
      "name": "BO_Pool_Surface00",
      "support": 15
    },
    {
      "x": -8,
      "y": 12,
      "z": 0,
      "name": "BO_Pool_Surface00",
      "support": 15
    },
    {
      "x": -8,
      "y": 13,
      "z": 0,
      "name": "BO_Pool_Surface00",
      "support": 15
    },
    {
      "x": -8,
      "y": 14,
      "z": 0,
      "name": "*BO_Lightsource_Cycle_State_Definitions_Day",
      "components": {
        "Components": {
          "BlackoutCycleState": {
            "OnState": "Day",
            "OffState": "Night"
          }
        }
      }
    },
    {
      "x": -8,
      "y": 15,
      "z": 0,
      "name": "Build_Black_Cube"
    },
    {
      "x": -8,
      "y": 0,
      "z": 1,
      "name": "BO_Pool_Surface00",
      "rotation": 4
    },
    {
      "x": -8,
      "y": 1,
      "z": 1,
      "name": "BO_Pool_Surface00",
      "rotation": 4
    },
    {
      "x": -8,
      "y": 2,
      "z": 1,
      "name": "BO_Pool_Surface00",
      "rotation": 4
    },
    {
      "x": -8,
      "y": 3,
      "z": 1,
      "name": "BO_Pool_Surface00",
      "rotation": 4
    },
    {
      "x": -8,
      "y": 4,
      "z": 1,
      "name": "BO_Pool_Surface00",
      "rotation": 4
    },
    {
      "x": -8,
      "y": 5,
      "z": 1,
      "name": "BO_Pool_Surface00",
      "rotation": 4
    },
    {
      "x": -8,
      "y": 6,
      "z": 1,
      "name": "BO_Pool_Surface00",
      "rotation": 4
    },
    {
      "x": -8,
      "y": 7,
      "z": 1,
      "name": "BO_Pool_Surface00",
      "rotation": 4
    },
    {
      "x": -8,
      "y": 8,
      "z": 1,
      "name": "BO_Pool_Surface00",
      "rotation": 4
    },
    {
      "x": -8,
      "y": 9,
      "z": 1,
      "name": "BO_Pool_Surface00",
      "support": 15
    },
    {
      "x": -8,
      "y": 10,
      "z": 1,
      "name": "BO_Pool_Surface00",
      "support": 15
    },
    {
      "x": -8,
      "y": 11,
      "z": 1,
      "name": "BO_Pool_Surface00",
      "support": 15
    },
    {
      "x": -8,
      "y": 12,
      "z": 1,
      "name": "BO_Pool_Surface00",
      "support": 15
    },
    {
      "x": -8,
      "y": 13,
      "z": 1,
      "name": "BO_Pool_Surface00",
      "support": 15
    },
    {
      "x": -8,
      "y": 14,
      "z": 1,
      "name": "*BO_Lightsource_Cycle_State_Definitions_Day",
      "components": {
        "Components": {
          "BlackoutCycleState": {
            "OnState": "Day",
            "OffState": "Night"
          }
        }
      }
    },
    {
      "x": -8,
      "y": 15,
      "z": 1,
      "name": "Build_Black_Cube"
    },
    {
      "x": -8,
      "y": 0,
      "z": 2,
      "name": "BO_Pool_Surface00",
      "rotation": 4
    },
    {
      "x": -8,
      "y": 1,
      "z": 2,
      "name": "BO_Pool_Surface00",
      "rotation": 4
    },
    {
      "x": -8,
      "y": 2,
      "z": 2,
      "name": "BO_Pool_Surface00",
      "rotation": 4
    },
    {
      "x": -8,
      "y": 3,
      "z": 2,
      "name": "BO_Pool_Surface00",
      "rotation": 4
    },
    {
      "x": -8,
      "y": 4,
      "z": 2,
      "name": "BO_Pool_Surface00",
      "rotation": 4
    },
    {
      "x": -8,
      "y": 5,
      "z": 2,
      "name": "BO_Pool_Surface00",
      "rotation": 4
    },
    {
      "x": -8,
      "y": 6,
      "z": 2,
      "name": "BO_Pool_Surface00",
      "rotation": 4
    },
    {
      "x": -8,
      "y": 7,
      "z": 2,
      "name": "BO_Pool_Surface00",
      "rotation": 4
    },
    {
      "x": -8,
      "y": 8,
      "z": 2,
      "name": "BO_Pool_Surface00",
      "rotation": 4
    },
    {
      "x": -8,
      "y": 9,
      "z": 2,
      "name": "BO_Pool_Surface00",
      "support": 15
    },
    {
      "x": -8,
      "y": 10,
      "z": 2,
      "name": "BO_Pool_Surface00",
      "support": 15
    },
    {
      "x": -8,
      "y": 11,
      "z": 2,
      "name": "BO_Pool_Surface00",
      "support": 15
    },
    {
      "x": -8,
      "y": 12,
      "z": 2,
      "name": "BO_Pool_Surface00",
      "support": 15
    },
    {
      "x": -8,
      "y": 13,
      "z": 2,
      "name": "BO_Pool_Surface00",
      "support": 15
    },
    {
      "x": -8,
      "y": 14,
      "z": 2,
      "name": "*BO_Lightsource_Cycle_State_Definitions_Day",
      "components": {
        "Components": {
          "BlackoutCycleState": {
            "OnState": "Day",
            "OffState": "Night"
          }
        }
      }
    },
    {
      "x": -8,
      "y": 15,
      "z": 2,
      "name": "Build_Black_Cube"
    },
    {
      "x": -8,
      "y": 0,
      "z": 3,
      "name": "BO_Pool_Surface00",
      "rotation": 4
    },
    {
      "x": -8,
      "y": 1,
      "z": 3,
      "name": "BO_Pool_Surface00",
      "rotation": 4
    },
    {
      "x": -8,
      "y": 13,
      "z": 3,
      "name": "BO_Pool_Surface00",
      "support": 15
    },
    {
      "x": -8,
      "y": 14,
      "z": 3,
      "name": "*BO_Lightsource_Cycle_State_Definitions_Day",
      "components": {
        "Components": {
          "BlackoutCycleState": {
            "OnState": "Day",
            "OffState": "Night"
          }
        }
      }
    },
    {
      "x": -8,
      "y": 15,
      "z": 3,
      "name": "Build_Black_Cube"
    },
    {
      "x": -8,
      "y": 0,
      "z": 4,
      "name": "BO_Pool_Surface00",
      "rotation": 4
    },
    {
      "x": -8,
      "y": 13,
      "z": 4,
      "name": "BO_Pool_Surface00",
      "support": 15
    },
    {
      "x": -8,
      "y": 14,
      "z": 4,
      "name": "*BO_Lightsource_Cycle_State_Definitions_Day",
      "components": {
        "Components": {
          "BlackoutCycleState": {
            "OnState": "Day",
            "OffState": "Night"
          }
        }
      }
    },
    {
      "x": -8,
      "y": 15,
      "z": 4,
      "name": "Build_Black_Cube"
    },
    {
      "x": -8,
      "y": 0,
      "z": 5,
      "name": "BO_Pool_Surface00",
      "rotation": 4
    },
    {
      "x": -8,
      "y": 13,
      "z": 5,
      "name": "BO_Pool_Surface00",
      "support": 15
    },
    {
      "x": -8,
      "y": 14,
      "z": 5,
      "name": "*BO_Lightsource_Cycle_State_Definitions_Day",
      "components": {
        "Components": {
          "BlackoutCycleState": {
            "OnState": "Day",
            "OffState": "Night"
          }
        }
      }
    },
    {
      "x": -8,
      "y": 15,
      "z": 5,
      "name": "Build_Black_Cube"
    },
    {
      "x": -8,
      "y": 0,
      "z": 6,
      "name": "BO_Pool_Surface00",
      "rotation": 4
    },
    {
      "x": -8,
      "y": 13,
      "z": 6,
      "name": "BO_Pool_Surface00",
      "support": 15
    },
    {
      "x": -8,
      "y": 14,
      "z": 6,
      "name": "*BO_Lightsource_Cycle_State_Definitions_Day",
      "components": {
        "Components": {
          "BlackoutCycleState": {
            "OnState": "Day",
            "OffState": "Night"
          }
        }
      }
    },
    {
      "x": -8,
      "y": 15,
      "z": 6,
      "name": "Build_Black_Cube"
    },
    {
      "x": -8,
      "y": 0,
      "z": 7,
      "name": "BO_Pool_Surface00",
      "rotation": 4
    },
    {
      "x": -8,
      "y": 13,
      "z": 7,
      "name": "BO_Pool_Surface00",
      "support": 15
    },
    {
      "x": -8,
      "y": 14,
      "z": 7,
      "name": "*BO_Lightsource_Cycle_State_Definitions_Day",
      "components": {
        "Components": {
          "BlackoutCycleState": {
            "OnState": "Day",
            "OffState": "Night"
          }
        }
      }
    },
    {
      "x": -8,
      "y": 15,
      "z": 7,
      "name": "Build_Black_Cube"
    },
    {
      "x": -8,
      "y": 0,
      "z": 8,
      "name": "BO_Pool_Surface00",
      "rotation": 4
    },
    {
      "x": -8,
      "y": 1,
      "z": 8,
      "name": "BO_Pool_Surface00",
      "rotation": 4
    },
    {
      "x": -8,
      "y": 13,
      "z": 8,
      "name": "BO_Pool_Surface00",
      "support": 15
    },
    {
      "x": -8,
      "y": 14,
      "z": 8,
      "name": "*BO_Lightsource_Cycle_State_Definitions_Day",
      "components": {
        "Components": {
          "BlackoutCycleState": {
            "OnState": "Day",
            "OffState": "Night"
          }
        }
      }
    },
    {
      "x": -8,
      "y": 15,
      "z": 8,
      "name": "Build_Black_Cube"
    },
    {
      "x": -8,
      "y": 0,
      "z": 9,
      "name": "BO_Pool_Surface00",
      "rotation": 4
    },
    {
      "x": -8,
      "y": 1,
      "z": 9,
      "name": "BO_Pool_Surface00",
      "rotation": 4
    },
    {
      "x": -8,
      "y": 2,
      "z": 9,
      "name": "BO_Pool_Surface00",
      "rotation": 4
    },
    {
      "x": -8,
      "y": 3,
      "z": 9,
      "name": "BO_Pool_Surface00",
      "rotation": 4
    },
    {
      "x": -8,
      "y": 4,
      "z": 9,
      "name": "BO_Pool_Surface00",
      "rotation": 4
    },
    {
      "x": -8,
      "y": 5,
      "z": 9,
      "name": "BO_Pool_Surface00",
      "rotation": 4
    },
    {
      "x": -8,
      "y": 6,
      "z": 9,
      "name": "BO_Pool_Surface00",
      "rotation": 4
    },
    {
      "x": -8,
      "y": 7,
      "z": 9,
      "name": "BO_Pool_Surface00",
      "rotation": 4
    },
    {
      "x": -8,
      "y": 8,
      "z": 9,
      "name": "BO_Pool_Surface00",
      "rotation": 4
    },
    {
      "x": -8,
      "y": 9,
      "z": 9,
      "name": "BO_Pool_Surface00",
      "support": 15
    },
    {
      "x": -8,
      "y": 10,
      "z": 9,
      "name": "BO_Pool_Surface00",
      "support": 15
    },
    {
      "x": -8,
      "y": 11,
      "z": 9,
      "name": "BO_Pool_Surface00",
      "support": 15
    },
    {
      "x": -8,
      "y": 12,
      "z": 9,
      "name": "BO_Pool_Surface00",
      "support": 15
    },
    {
      "x": -8,
      "y": 13,
      "z": 9,
      "name": "BO_Pool_Surface00",
      "support": 15
    },
    {
      "x": -8,
      "y": 14,
      "z": 9,
      "name": "*BO_Lightsource_Cycle_State_Definitions_Day",
      "components": {
        "Components": {
          "BlackoutCycleState": {
            "OnState": "Day",
            "OffState": "Night"
          }
        }
      }
    },
    {
      "x": -8,
      "y": 15,
      "z": 9,
      "name": "Build_Black_Cube"
    },
    {
      "x": -8,
      "y": 0,
      "z": 10,
      "name": "BO_Pool_Surface00",
      "rotation": 4
    },
    {
      "x": -8,
      "y": 1,
      "z": 10,
      "name": "BO_Pool_Surface00",
      "rotation": 4
    },
    {
      "x": -8,
      "y": 2,
      "z": 10,
      "name": "BO_Pool_Surface00",
      "rotation": 4
    },
    {
      "x": -8,
      "y": 3,
      "z": 10,
      "name": "BO_Pool_Surface00",
      "rotation": 4
    },
    {
      "x": -8,
      "y": 4,
      "z": 10,
      "name": "BO_Pool_Surface00",
      "rotation": 4
    },
    {
      "x": -8,
      "y": 5,
      "z": 10,
      "name": "BO_Pool_Surface00",
      "rotation": 4
    },
    {
      "x": -8,
      "y": 6,
      "z": 10,
      "name": "BO_Pool_Surface00",
      "rotation": 4
    },
    {
      "x": -8,
      "y": 7,
      "z": 10,
      "name": "BO_Pool_Surface00",
      "rotation": 4
    },
    {
      "x": -8,
      "y": 8,
      "z": 10,
      "name": "BO_Pool_Surface00",
      "rotation": 4
    },
    {
      "x": -8,
      "y": 9,
      "z": 10,
      "name": "BO_Pool_Surface00",
      "rotation": 4
    },
    {
      "x": -8,
      "y": 10,
      "z": 10,
      "name": "BO_Pool_Surface00",
      "rotation": 4
    },
    {
      "x": -8,
      "y": 11,
      "z": 10,
      "name": "BO_Pool_Surface00",
      "rotation": 4
    },
    {
      "x": -8,
      "y": 12,
      "z": 10,
      "name": "BO_Pool_Surface00",
      "rotation": 4
    },
    {
      "x": -8,
      "y": 13,
      "z": 10,
      "name": "BO_Pool_Surface00",
      "rotation": 4
    },
    {
      "x": -8,
      "y": 14,
      "z": 10,
      "name": "BO_Pool_Surface00",
      "rotation": 4
    },
    {
      "x": -8,
      "y": 15,
      "z": 10,
      "name": "Build_Black_Cube"
    },
    {
      "x": -7,
      "y": 0,
      "z": -9,
      "name": "BO_Pool_Surface00",
      "rotation": 4
    },
    {
      "x": -7,
      "y": 1,
      "z": -9,
      "name": "BO_Pool_Surface00",
      "rotation": 4
    },
    {
      "x": -7,
      "y": 9,
      "z": -9,
      "name": "BO_Pool_Surface00",
      "rotation": 4
    },
    {
      "x": -7,
      "y": 10,
      "z": -9,
      "name": "BO_Pool_Surface00",
      "rotation": 4
    },
    {
      "x": -7,
      "y": 11,
      "z": -9,
      "name": "BO_Pool_Surface00",
      "rotation": 4
    },
    {
      "x": -7,
      "y": 12,
      "z": -9,
      "name": "BO_Pool_Surface00",
      "rotation": 4
    },
    {
      "x": -7,
      "y": 13,
      "z": -9,
      "name": "BO_Pool_Surface00",
      "rotation": 4
    },
    {
      "x": -7,
      "y": 14,
      "z": -9,
      "name": "BO_Pool_Surface00",
      "rotation": 4
    },
    {
      "x": -7,
      "y": 15,
      "z": -9,
      "name": "Build_Black_Cube"
    },
    {
      "x": -7,
      "y": 0,
      "z": -8,
      "name": "BO_Pool_Surface00",
      "rotation": 4
    },
    {
      "x": -7,
      "y": 1,
      "z": -8,
      "name": "BO_Pool_Surface00",
      "rotation": 4
    },
    {
      "x": -7,
      "y": 13,
      "z": -8,
      "name": "BO_Pool_Surface00",
      "support": 15
    },
    {
      "x": -7,
      "y": 14,
      "z": -8,
      "name": "*BO_Lightsource_Cycle_State_Definitions_Day",
      "components": {
        "Components": {
          "BlackoutCycleState": {
            "OnState": "Day",
            "OffState": "Night"
          }
        }
      }
    },
    {
      "x": -7,
      "y": 15,
      "z": -8,
      "name": "Build_Black_Cube"
    },
    {
      "x": -7,
      "y": 0,
      "z": -7,
      "name": "BO_Pool_Surface00",
      "rotation": 4
    },
    {
      "x": -7,
      "y": 1,
      "z": -7,
      "name": "BO_Pool_Surface00",
      "rotation": 4
    },
    {
      "x": -7,
      "y": 14,
      "z": -7,
      "name": "*BO_Lightsource_Cycle_State_Definitions_Day",
      "components": {
        "Components": {
          "BlackoutCycleState": {
            "OnState": "Day",
            "OffState": "Night"
          }
        }
      }
    },
    {
      "x": -7,
      "y": 15,
      "z": -7,
      "name": "Build_Black_Cube"
    },
    {
      "x": -7,
      "y": 0,
      "z": -6,
      "name": "BO_Pool_Surface00",
      "rotation": 4
    },
    {
      "x": -7,
      "y": 14,
      "z": -6,
      "name": "*BO_Lightsource_Cycle_State_Definitions_Day",
      "components": {
        "Components": {
          "BlackoutCycleState": {
            "OnState": "Day",
            "OffState": "Night"
          }
        }
      }
    },
    {
      "x": -7,
      "y": 15,
      "z": -6,
      "name": "Build_Black_Cube"
    },
    {
      "x": -7,
      "y": 0,
      "z": -5,
      "name": "BO_Pool_Surface00",
      "rotation": 4
    },
    {
      "x": -7,
      "y": 14,
      "z": -5,
      "name": "*BO_Lightsource_Cycle_State_Definitions_Day",
      "components": {
        "Components": {
          "BlackoutCycleState": {
            "OnState": "Day",
            "OffState": "Night"
          }
        }
      }
    },
    {
      "x": -7,
      "y": 15,
      "z": -5,
      "name": "Build_Black_Cube"
    },
    {
      "x": -7,
      "y": 0,
      "z": -4,
      "name": "BO_Pool_Surface00",
      "rotation": 4
    },
    {
      "x": -7,
      "y": 14,
      "z": -4,
      "name": "*BO_Lightsource_Cycle_State_Definitions_Day",
      "components": {
        "Components": {
          "BlackoutCycleState": {
            "OnState": "Day",
            "OffState": "Night"
          }
        }
      }
    },
    {
      "x": -7,
      "y": 15,
      "z": -4,
      "name": "Build_Black_Cube"
    },
    {
      "x": -7,
      "y": 0,
      "z": -3,
      "name": "BO_Pool_Surface00",
      "rotation": 4
    },
    {
      "x": -7,
      "y": 14,
      "z": -3,
      "name": "*BO_Lightsource_Cycle_State_Definitions_Day",
      "components": {
        "Components": {
          "BlackoutCycleState": {
            "OnState": "Day",
            "OffState": "Night"
          }
        }
      }
    },
    {
      "x": -7,
      "y": 15,
      "z": -3,
      "name": "Build_Black_Cube"
    },
    {
      "x": -7,
      "y": 0,
      "z": -2,
      "name": "BO_Pool_Surface00",
      "rotation": 4
    },
    {
      "x": -7,
      "y": 1,
      "z": -2,
      "name": "BO_Pool_Surface00",
      "rotation": 4
    },
    {
      "x": -7,
      "y": 14,
      "z": -2,
      "name": "*BO_Lightsource_Cycle_State_Definitions_Day",
      "components": {
        "Components": {
          "BlackoutCycleState": {
            "OnState": "Day",
            "OffState": "Night"
          }
        }
      }
    },
    {
      "x": -7,
      "y": 15,
      "z": -2,
      "name": "Build_Black_Cube"
    },
    {
      "x": -7,
      "y": 0,
      "z": -1,
      "name": "BO_Pool_Surface00",
      "rotation": 4
    },
    {
      "x": -7,
      "y": 1,
      "z": -1,
      "name": "BO_Pool_Surface00",
      "rotation": 4
    },
    {
      "x": -7,
      "y": 14,
      "z": -1,
      "name": "*BO_Lightsource_Cycle_State_Definitions_Day",
      "components": {
        "Components": {
          "BlackoutCycleState": {
            "OnState": "Day",
            "OffState": "Night"
          }
        }
      }
    },
    {
      "x": -7,
      "y": 15,
      "z": -1,
      "name": "Build_Black_Cube"
    },
    {
      "x": -7,
      "y": 0,
      "z": 0,
      "name": "BO_Pool_Surface00",
      "rotation": 4
    },
    {
      "x": -7,
      "y": 1,
      "z": 0,
      "name": "BO_Pool_Surface00",
      "rotation": 4
    },
    {
      "x": -7,
      "y": 14,
      "z": 0,
      "name": "*BO_Lightsource_Cycle_State_Definitions_Day",
      "components": {
        "Components": {
          "BlackoutCycleState": {
            "OnState": "Day",
            "OffState": "Night"
          }
        }
      }
    },
    {
      "x": -7,
      "y": 15,
      "z": 0,
      "name": "Build_Black_Cube"
    },
    {
      "x": -7,
      "y": 0,
      "z": 1,
      "name": "BO_Pool_Surface00",
      "rotation": 4
    },
    {
      "x": -7,
      "y": 1,
      "z": 1,
      "name": "BO_Pool_Surface00",
      "rotation": 4
    },
    {
      "x": -7,
      "y": 14,
      "z": 1,
      "name": "*BO_Lightsource_Cycle_State_Definitions_Day",
      "components": {
        "Components": {
          "BlackoutCycleState": {
            "OnState": "Day",
            "OffState": "Night"
          }
        }
      }
    },
    {
      "x": -7,
      "y": 15,
      "z": 1,
      "name": "Build_Black_Cube"
    },
    {
      "x": -7,
      "y": 0,
      "z": 2,
      "name": "BO_Pool_Surface00",
      "rotation": 4
    },
    {
      "x": -7,
      "y": 1,
      "z": 2,
      "name": "BO_Pool_Surface00",
      "rotation": 4
    },
    {
      "x": -7,
      "y": 14,
      "z": 2,
      "name": "*BO_Lightsource_Cycle_State_Definitions_Day",
      "components": {
        "Components": {
          "BlackoutCycleState": {
            "OnState": "Day",
            "OffState": "Night"
          }
        }
      }
    },
    {
      "x": -7,
      "y": 15,
      "z": 2,
      "name": "Build_Black_Cube"
    },
    {
      "x": -7,
      "y": 0,
      "z": 3,
      "name": "BO_Pool_Surface00",
      "rotation": 4
    },
    {
      "x": -7,
      "y": 1,
      "z": 3,
      "name": "BO_Pool_Surface00",
      "rotation": 4
    },
    {
      "x": -7,
      "y": 14,
      "z": 3,
      "name": "*BO_Lightsource_Cycle_State_Definitions_Day",
      "components": {
        "Components": {
          "BlackoutCycleState": {
            "OnState": "Day",
            "OffState": "Night"
          }
        }
      }
    },
    {
      "x": -7,
      "y": 15,
      "z": 3,
      "name": "Build_Black_Cube"
    },
    {
      "x": -7,
      "y": 0,
      "z": 4,
      "name": "BO_Pool_Surface00",
      "rotation": 4
    },
    {
      "x": -7,
      "y": 14,
      "z": 4,
      "name": "*BO_Lightsource_Cycle_State_Definitions_Day",
      "components": {
        "Components": {
          "BlackoutCycleState": {
            "OnState": "Day",
            "OffState": "Night"
          }
        }
      }
    },
    {
      "x": -7,
      "y": 15,
      "z": 4,
      "name": "Build_Black_Cube"
    },
    {
      "x": -7,
      "y": 0,
      "z": 5,
      "name": "BO_Pool_Surface00",
      "rotation": 4
    },
    {
      "x": -7,
      "y": 14,
      "z": 5,
      "name": "*BO_Lightsource_Cycle_State_Definitions_Day",
      "components": {
        "Components": {
          "BlackoutCycleState": {
            "OnState": "Day",
            "OffState": "Night"
          }
        }
      }
    },
    {
      "x": -7,
      "y": 15,
      "z": 5,
      "name": "Build_Black_Cube"
    },
    {
      "x": -7,
      "y": 0,
      "z": 6,
      "name": "BO_Pool_Surface00",
      "rotation": 4
    },
    {
      "x": -7,
      "y": 14,
      "z": 6,
      "name": "*BO_Lightsource_Cycle_State_Definitions_Day",
      "components": {
        "Components": {
          "BlackoutCycleState": {
            "OnState": "Day",
            "OffState": "Night"
          }
        }
      }
    },
    {
      "x": -7,
      "y": 15,
      "z": 6,
      "name": "Build_Black_Cube"
    },
    {
      "x": -7,
      "y": 0,
      "z": 7,
      "name": "BO_Pool_Surface00",
      "rotation": 4
    },
    {
      "x": -7,
      "y": 14,
      "z": 7,
      "name": "*BO_Lightsource_Cycle_State_Definitions_Day",
      "components": {
        "Components": {
          "BlackoutCycleState": {
            "OnState": "Day",
            "OffState": "Night"
          }
        }
      }
    },
    {
      "x": -7,
      "y": 15,
      "z": 7,
      "name": "Build_Black_Cube"
    },
    {
      "x": -7,
      "y": 0,
      "z": 8,
      "name": "BO_Pool_Surface00",
      "rotation": 4
    },
    {
      "x": -7,
      "y": 1,
      "z": 8,
      "name": "BO_Pool_Surface00",
      "rotation": 4
    },
    {
      "x": -7,
      "y": 14,
      "z": 8,
      "name": "*BO_Lightsource_Cycle_State_Definitions_Day",
      "components": {
        "Components": {
          "BlackoutCycleState": {
            "OnState": "Day",
            "OffState": "Night"
          }
        }
      }
    },
    {
      "x": -7,
      "y": 15,
      "z": 8,
      "name": "Build_Black_Cube"
    },
    {
      "x": -7,
      "y": 0,
      "z": 9,
      "name": "BO_Pool_Surface00",
      "rotation": 4
    },
    {
      "x": -7,
      "y": 1,
      "z": 9,
      "name": "BO_Pool_Surface00",
      "rotation": 4
    },
    {
      "x": -7,
      "y": 13,
      "z": 9,
      "name": "BO_Pool_Surface00",
      "support": 15
    },
    {
      "x": -7,
      "y": 14,
      "z": 9,
      "name": "*BO_Lightsource_Cycle_State_Definitions_Day",
      "components": {
        "Components": {
          "BlackoutCycleState": {
            "OnState": "Day",
            "OffState": "Night"
          }
        }
      }
    },
    {
      "x": -7,
      "y": 15,
      "z": 9,
      "name": "Build_Black_Cube"
    },
    {
      "x": -7,
      "y": 0,
      "z": 10,
      "name": "BO_Pool_Surface00",
      "rotation": 4
    },
    {
      "x": -7,
      "y": 1,
      "z": 10,
      "name": "BO_Pool_Surface00",
      "rotation": 4
    },
    {
      "x": -7,
      "y": 9,
      "z": 10,
      "name": "BO_Pool_Surface00",
      "rotation": 4
    },
    {
      "x": -7,
      "y": 10,
      "z": 10,
      "name": "BO_Pool_Surface00",
      "rotation": 4
    },
    {
      "x": -7,
      "y": 11,
      "z": 10,
      "name": "BO_Pool_Surface00",
      "rotation": 4
    },
    {
      "x": -7,
      "y": 12,
      "z": 10,
      "name": "BO_Pool_Surface00",
      "rotation": 4
    },
    {
      "x": -7,
      "y": 13,
      "z": 10,
      "name": "BO_Pool_Surface00",
      "rotation": 4
    },
    {
      "x": -7,
      "y": 14,
      "z": 10,
      "name": "BO_Pool_Surface00",
      "rotation": 4
    },
    {
      "x": -7,
      "y": 15,
      "z": 10,
      "name": "Build_Black_Cube"
    },
    {
      "x": -6,
      "y": 0,
      "z": -9,
      "name": "BO_Pool_Surface00",
      "rotation": 4
    },
    {
      "x": -6,
      "y": 9,
      "z": -9,
      "name": "BO_Pool_Surface00",
      "rotation": 4
    },
    {
      "x": -6,
      "y": 10,
      "z": -9,
      "name": "BO_Pool_Surface00",
      "rotation": 4
    },
    {
      "x": -6,
      "y": 11,
      "z": -9,
      "name": "BO_Pool_Surface00",
      "rotation": 4
    },
    {
      "x": -6,
      "y": 12,
      "z": -9,
      "name": "BO_Pool_Surface00",
      "rotation": 4
    },
    {
      "x": -6,
      "y": 13,
      "z": -9,
      "name": "BO_Pool_Surface00",
      "rotation": 4
    },
    {
      "x": -6,
      "y": 14,
      "z": -9,
      "name": "BO_Pool_Surface00",
      "rotation": 4
    },
    {
      "x": -6,
      "y": 15,
      "z": -9,
      "name": "Build_Black_Cube"
    },
    {
      "x": -6,
      "y": 0,
      "z": -8,
      "name": "BO_Pool_Surface00",
      "rotation": 4
    },
    {
      "x": -6,
      "y": 13,
      "z": -8,
      "name": "BO_Pool_Surface00",
      "support": 15
    },
    {
      "x": -6,
      "y": 14,
      "z": -8,
      "name": "*BO_Lightsource_Cycle_State_Definitions_Day",
      "components": {
        "Components": {
          "BlackoutCycleState": {
            "OnState": "Day",
            "OffState": "Night"
          }
        }
      }
    },
    {
      "x": -6,
      "y": 15,
      "z": -8,
      "name": "Build_Black_Cube"
    },
    {
      "x": -6,
      "y": 0,
      "z": -7,
      "name": "BO_Pool_Surface00",
      "rotation": 4
    },
    {
      "x": -6,
      "y": 14,
      "z": -7,
      "name": "*BO_Lightsource_Cycle_State_Definitions_Day",
      "components": {
        "Components": {
          "BlackoutCycleState": {
            "OnState": "Day",
            "OffState": "Night"
          }
        }
      }
    },
    {
      "x": -6,
      "y": 15,
      "z": -7,
      "name": "Build_Black_Cube"
    },
    {
      "x": -6,
      "y": 0,
      "z": -6,
      "name": "BO_Pool_Surface00",
      "rotation": 4
    },
    {
      "x": -6,
      "y": 14,
      "z": -6,
      "name": "*BO_Lightsource_Cycle_State_Definitions_Day",
      "components": {
        "Components": {
          "BlackoutCycleState": {
            "OnState": "Day",
            "OffState": "Night"
          }
        }
      }
    },
    {
      "x": -6,
      "y": 15,
      "z": -6,
      "name": "Build_Black_Cube"
    },
    {
      "x": -6,
      "y": 0,
      "z": -5,
      "name": "BO_Pool_Surface00",
      "rotation": 4
    },
    {
      "x": -6,
      "y": 14,
      "z": -5,
      "name": "*BO_Lightsource_Cycle_State_Definitions_Day",
      "components": {
        "Components": {
          "BlackoutCycleState": {
            "OnState": "Day",
            "OffState": "Night"
          }
        }
      }
    },
    {
      "x": -6,
      "y": 15,
      "z": -5,
      "name": "Build_Black_Cube"
    },
    {
      "x": -6,
      "y": 0,
      "z": -4,
      "name": "BO_Pool_Surface00",
      "rotation": 4
    },
    {
      "x": -6,
      "y": 14,
      "z": -4,
      "name": "*BO_Lightsource_Cycle_State_Definitions_Day",
      "components": {
        "Components": {
          "BlackoutCycleState": {
            "OnState": "Day",
            "OffState": "Night"
          }
        }
      }
    },
    {
      "x": -6,
      "y": 15,
      "z": -4,
      "name": "Build_Black_Cube"
    },
    {
      "x": -6,
      "y": 0,
      "z": -3,
      "name": "BO_Pool_Surface00",
      "rotation": 4
    },
    {
      "x": -6,
      "y": 14,
      "z": -3,
      "name": "*BO_Lightsource_Cycle_State_Definitions_Day",
      "components": {
        "Components": {
          "BlackoutCycleState": {
            "OnState": "Day",
            "OffState": "Night"
          }
        }
      }
    },
    {
      "x": -6,
      "y": 15,
      "z": -3,
      "name": "Build_Black_Cube"
    },
    {
      "x": -6,
      "y": 0,
      "z": -2,
      "name": "BO_Pool_Surface00",
      "rotation": 4
    },
    {
      "x": -6,
      "y": 14,
      "z": -2,
      "name": "*BO_Lightsource_Cycle_State_Definitions_Day",
      "components": {
        "Components": {
          "BlackoutCycleState": {
            "OnState": "Day",
            "OffState": "Night"
          }
        }
      }
    },
    {
      "x": -6,
      "y": 15,
      "z": -2,
      "name": "Build_Black_Cube"
    },
    {
      "x": -6,
      "y": 0,
      "z": -1,
      "name": "BO_Pool_Surface00",
      "rotation": 4
    },
    {
      "x": -6,
      "y": 14,
      "z": -1,
      "name": "*BO_Lightsource_Cycle_State_Definitions_Day",
      "components": {
        "Components": {
          "BlackoutCycleState": {
            "OnState": "Day",
            "OffState": "Night"
          }
        }
      }
    },
    {
      "x": -6,
      "y": 15,
      "z": -1,
      "name": "Build_Black_Cube"
    },
    {
      "x": -6,
      "y": 0,
      "z": 0,
      "name": "BO_Pool_Surface00",
      "rotation": 4
    },
    {
      "x": -6,
      "y": 14,
      "z": 0,
      "name": "*BO_Lightsource_Cycle_State_Definitions_Day",
      "components": {
        "Components": {
          "BlackoutCycleState": {
            "OnState": "Day",
            "OffState": "Night"
          }
        }
      }
    },
    {
      "x": -6,
      "y": 15,
      "z": 0,
      "name": "Build_Black_Cube"
    },
    {
      "x": -6,
      "y": 0,
      "z": 1,
      "name": "BO_Pool_Surface00",
      "rotation": 4
    },
    {
      "x": -6,
      "y": 14,
      "z": 1,
      "name": "*BO_Lightsource_Cycle_State_Definitions_Day",
      "components": {
        "Components": {
          "BlackoutCycleState": {
            "OnState": "Day",
            "OffState": "Night"
          }
        }
      }
    },
    {
      "x": -6,
      "y": 15,
      "z": 1,
      "name": "Build_Black_Cube"
    },
    {
      "x": -6,
      "y": 0,
      "z": 2,
      "name": "BO_Pool_Surface00",
      "rotation": 4
    },
    {
      "x": -6,
      "y": 14,
      "z": 2,
      "name": "*BO_Lightsource_Cycle_State_Definitions_Day",
      "components": {
        "Components": {
          "BlackoutCycleState": {
            "OnState": "Day",
            "OffState": "Night"
          }
        }
      }
    },
    {
      "x": -6,
      "y": 15,
      "z": 2,
      "name": "Build_Black_Cube"
    },
    {
      "x": -6,
      "y": 0,
      "z": 3,
      "name": "BO_Pool_Surface00",
      "rotation": 4
    },
    {
      "x": -6,
      "y": 14,
      "z": 3,
      "name": "*BO_Lightsource_Cycle_State_Definitions_Day",
      "components": {
        "Components": {
          "BlackoutCycleState": {
            "OnState": "Day",
            "OffState": "Night"
          }
        }
      }
    },
    {
      "x": -6,
      "y": 15,
      "z": 3,
      "name": "Build_Black_Cube"
    },
    {
      "x": -6,
      "y": 0,
      "z": 4,
      "name": "BO_Pool_Surface00",
      "rotation": 4
    },
    {
      "x": -6,
      "y": 14,
      "z": 4,
      "name": "*BO_Lightsource_Cycle_State_Definitions_Day",
      "components": {
        "Components": {
          "BlackoutCycleState": {
            "OnState": "Day",
            "OffState": "Night"
          }
        }
      }
    },
    {
      "x": -6,
      "y": 15,
      "z": 4,
      "name": "Build_Black_Cube"
    },
    {
      "x": -6,
      "y": 0,
      "z": 5,
      "name": "BO_Pool_Surface00",
      "rotation": 4
    },
    {
      "x": -6,
      "y": 14,
      "z": 5,
      "name": "*BO_Lightsource_Cycle_State_Definitions_Day",
      "components": {
        "Components": {
          "BlackoutCycleState": {
            "OnState": "Day",
            "OffState": "Night"
          }
        }
      }
    },
    {
      "x": -6,
      "y": 15,
      "z": 5,
      "name": "Build_Black_Cube"
    },
    {
      "x": -6,
      "y": 0,
      "z": 6,
      "name": "BO_Pool_Surface00",
      "rotation": 4
    },
    {
      "x": -6,
      "y": 14,
      "z": 6,
      "name": "*BO_Lightsource_Cycle_State_Definitions_Day",
      "components": {
        "Components": {
          "BlackoutCycleState": {
            "OnState": "Day",
            "OffState": "Night"
          }
        }
      }
    },
    {
      "x": -6,
      "y": 15,
      "z": 6,
      "name": "Build_Black_Cube"
    },
    {
      "x": -6,
      "y": 0,
      "z": 7,
      "name": "BO_Pool_Surface00",
      "rotation": 4
    },
    {
      "x": -6,
      "y": 14,
      "z": 7,
      "name": "*BO_Lightsource_Cycle_State_Definitions_Day",
      "components": {
        "Components": {
          "BlackoutCycleState": {
            "OnState": "Day",
            "OffState": "Night"
          }
        }
      }
    },
    {
      "x": -6,
      "y": 15,
      "z": 7,
      "name": "Build_Black_Cube"
    },
    {
      "x": -6,
      "y": 0,
      "z": 8,
      "name": "BO_Pool_Surface00",
      "rotation": 4
    },
    {
      "x": -6,
      "y": 14,
      "z": 8,
      "name": "*BO_Lightsource_Cycle_State_Definitions_Day",
      "components": {
        "Components": {
          "BlackoutCycleState": {
            "OnState": "Day",
            "OffState": "Night"
          }
        }
      }
    },
    {
      "x": -6,
      "y": 15,
      "z": 8,
      "name": "Build_Black_Cube"
    },
    {
      "x": -6,
      "y": 0,
      "z": 9,
      "name": "BO_Pool_Surface00",
      "rotation": 4
    },
    {
      "x": -6,
      "y": 13,
      "z": 9,
      "name": "BO_Pool_Surface00",
      "support": 15
    },
    {
      "x": -6,
      "y": 14,
      "z": 9,
      "name": "*BO_Lightsource_Cycle_State_Definitions_Day",
      "components": {
        "Components": {
          "BlackoutCycleState": {
            "OnState": "Day",
            "OffState": "Night"
          }
        }
      }
    },
    {
      "x": -6,
      "y": 15,
      "z": 9,
      "name": "Build_Black_Cube"
    },
    {
      "x": -6,
      "y": 0,
      "z": 10,
      "name": "BO_Pool_Surface00",
      "rotation": 4
    },
    {
      "x": -6,
      "y": 9,
      "z": 10,
      "name": "BO_Pool_Surface00",
      "rotation": 4
    },
    {
      "x": -6,
      "y": 10,
      "z": 10,
      "name": "BO_Pool_Surface00",
      "rotation": 4
    },
    {
      "x": -6,
      "y": 11,
      "z": 10,
      "name": "BO_Pool_Surface00",
      "rotation": 4
    },
    {
      "x": -6,
      "y": 12,
      "z": 10,
      "name": "BO_Pool_Surface00",
      "rotation": 4
    },
    {
      "x": -6,
      "y": 13,
      "z": 10,
      "name": "BO_Pool_Surface00",
      "rotation": 4
    },
    {
      "x": -6,
      "y": 14,
      "z": 10,
      "name": "BO_Pool_Surface00",
      "rotation": 4
    },
    {
      "x": -6,
      "y": 15,
      "z": 10,
      "name": "Build_Black_Cube"
    },
    {
      "x": -5,
      "y": 0,
      "z": -9,
      "name": "BO_Pool_Surface00",
      "rotation": 4
    },
    {
      "x": -5,
      "y": 9,
      "z": -9,
      "name": "BO_Pool_Surface00",
      "rotation": 4
    },
    {
      "x": -5,
      "y": 10,
      "z": -9,
      "name": "BO_Pool_Surface00",
      "rotation": 4
    },
    {
      "x": -5,
      "y": 11,
      "z": -9,
      "name": "BO_Pool_Surface00",
      "rotation": 4
    },
    {
      "x": -5,
      "y": 12,
      "z": -9,
      "name": "BO_Pool_Surface00",
      "rotation": 4
    },
    {
      "x": -5,
      "y": 13,
      "z": -9,
      "name": "BO_Pool_Surface00",
      "rotation": 4
    },
    {
      "x": -5,
      "y": 14,
      "z": -9,
      "name": "BO_Pool_Surface00",
      "rotation": 4
    },
    {
      "x": -5,
      "y": 15,
      "z": -9,
      "name": "Build_Black_Cube"
    },
    {
      "x": -5,
      "y": 0,
      "z": -8,
      "name": "BO_Pool_Surface00",
      "rotation": 4
    },
    {
      "x": -5,
      "y": 13,
      "z": -8,
      "name": "BO_Pool_Surface00",
      "support": 15
    },
    {
      "x": -5,
      "y": 14,
      "z": -8,
      "name": "*BO_Lightsource_Cycle_State_Definitions_Day",
      "components": {
        "Components": {
          "BlackoutCycleState": {
            "OnState": "Day",
            "OffState": "Night"
          }
        }
      }
    },
    {
      "x": -5,
      "y": 15,
      "z": -8,
      "name": "Build_Black_Cube"
    },
    {
      "x": -5,
      "y": 0,
      "z": -7,
      "name": "BO_Pool_Surface00",
      "rotation": 4
    },
    {
      "x": -5,
      "y": 14,
      "z": -7,
      "name": "*BO_Lightsource_Cycle_State_Definitions_Day",
      "components": {
        "Components": {
          "BlackoutCycleState": {
            "OnState": "Day",
            "OffState": "Night"
          }
        }
      }
    },
    {
      "x": -5,
      "y": 15,
      "z": -7,
      "name": "Build_Black_Cube"
    },
    {
      "x": -5,
      "y": 0,
      "z": -6,
      "name": "BO_Pool_Surface00",
      "rotation": 4
    },
    {
      "x": -5,
      "y": 14,
      "z": -6,
      "name": "*BO_Lightsource_Cycle_State_Definitions_Day",
      "components": {
        "Components": {
          "BlackoutCycleState": {
            "OnState": "Day",
            "OffState": "Night"
          }
        }
      }
    },
    {
      "x": -5,
      "y": 15,
      "z": -6,
      "name": "Build_Black_Cube"
    },
    {
      "x": -5,
      "y": 0,
      "z": -5,
      "name": "BO_Pool_Surface00",
      "rotation": 4
    },
    {
      "x": -5,
      "y": 14,
      "z": -5,
      "name": "*BO_Lightsource_Cycle_State_Definitions_Day",
      "components": {
        "Components": {
          "BlackoutCycleState": {
            "OnState": "Day",
            "OffState": "Night"
          }
        }
      }
    },
    {
      "x": -5,
      "y": 15,
      "z": -5,
      "name": "Build_Black_Cube"
    },
    {
      "x": -5,
      "y": 0,
      "z": -4,
      "name": "BO_Pool_Surface00",
      "rotation": 4
    },
    {
      "x": -5,
      "y": 14,
      "z": -4,
      "name": "*BO_Lightsource_Cycle_State_Definitions_Day",
      "components": {
        "Components": {
          "BlackoutCycleState": {
            "OnState": "Day",
            "OffState": "Night"
          }
        }
      }
    },
    {
      "x": -5,
      "y": 15,
      "z": -4,
      "name": "Build_Black_Cube"
    },
    {
      "x": -5,
      "y": 0,
      "z": -3,
      "name": "BO_Pool_Surface00",
      "rotation": 4
    },
    {
      "x": -5,
      "y": 14,
      "z": -3,
      "name": "*BO_Lightsource_Cycle_State_Definitions_Day",
      "components": {
        "Components": {
          "BlackoutCycleState": {
            "OnState": "Day",
            "OffState": "Night"
          }
        }
      }
    },
    {
      "x": -5,
      "y": 15,
      "z": -3,
      "name": "Build_Black_Cube"
    },
    {
      "x": -5,
      "y": 0,
      "z": -2,
      "name": "BO_Pool_Surface00",
      "rotation": 4
    },
    {
      "x": -5,
      "y": 14,
      "z": -2,
      "name": "*BO_Lightsource_Cycle_State_Definitions_Day",
      "components": {
        "Components": {
          "BlackoutCycleState": {
            "OnState": "Day",
            "OffState": "Night"
          }
        }
      }
    },
    {
      "x": -5,
      "y": 15,
      "z": -2,
      "name": "Build_Black_Cube"
    },
    {
      "x": -5,
      "y": 0,
      "z": -1,
      "name": "BO_Pool_Surface00",
      "rotation": 4
    },
    {
      "x": -5,
      "y": 14,
      "z": -1,
      "name": "*BO_Lightsource_Cycle_State_Definitions_Day",
      "components": {
        "Components": {
          "BlackoutCycleState": {
            "OnState": "Day",
            "OffState": "Night"
          }
        }
      }
    },
    {
      "x": -5,
      "y": 15,
      "z": -1,
      "name": "Build_Black_Cube"
    },
    {
      "x": -5,
      "y": 0,
      "z": 0,
      "name": "BO_Pool_Surface00",
      "rotation": 4
    },
    {
      "x": -5,
      "y": 14,
      "z": 0,
      "name": "*BO_Lightsource_Cycle_State_Definitions_Day",
      "components": {
        "Components": {
          "BlackoutCycleState": {
            "OnState": "Day",
            "OffState": "Night"
          }
        }
      }
    },
    {
      "x": -5,
      "y": 15,
      "z": 0,
      "name": "Build_Black_Cube"
    },
    {
      "x": -5,
      "y": 0,
      "z": 1,
      "name": "BO_Pool_Surface00",
      "rotation": 4
    },
    {
      "x": -5,
      "y": 14,
      "z": 1,
      "name": "*BO_Lightsource_Cycle_State_Definitions_Day",
      "components": {
        "Components": {
          "BlackoutCycleState": {
            "OnState": "Day",
            "OffState": "Night"
          }
        }
      }
    },
    {
      "x": -5,
      "y": 15,
      "z": 1,
      "name": "Build_Black_Cube"
    },
    {
      "x": -5,
      "y": 0,
      "z": 2,
      "name": "BO_Pool_Surface00",
      "rotation": 4
    },
    {
      "x": -5,
      "y": 14,
      "z": 2,
      "name": "*BO_Lightsource_Cycle_State_Definitions_Day",
      "components": {
        "Components": {
          "BlackoutCycleState": {
            "OnState": "Day",
            "OffState": "Night"
          }
        }
      }
    },
    {
      "x": -5,
      "y": 15,
      "z": 2,
      "name": "Build_Black_Cube"
    },
    {
      "x": -5,
      "y": 0,
      "z": 3,
      "name": "BO_Pool_Surface00",
      "rotation": 4
    },
    {
      "x": -5,
      "y": 14,
      "z": 3,
      "name": "*BO_Lightsource_Cycle_State_Definitions_Day",
      "components": {
        "Components": {
          "BlackoutCycleState": {
            "OnState": "Day",
            "OffState": "Night"
          }
        }
      }
    },
    {
      "x": -5,
      "y": 15,
      "z": 3,
      "name": "Build_Black_Cube"
    },
    {
      "x": -5,
      "y": 0,
      "z": 4,
      "name": "BO_Pool_Surface00",
      "rotation": 4
    },
    {
      "x": -5,
      "y": 14,
      "z": 4,
      "name": "*BO_Lightsource_Cycle_State_Definitions_Day",
      "components": {
        "Components": {
          "BlackoutCycleState": {
            "OnState": "Day",
            "OffState": "Night"
          }
        }
      }
    },
    {
      "x": -5,
      "y": 15,
      "z": 4,
      "name": "Build_Black_Cube"
    },
    {
      "x": -5,
      "y": 0,
      "z": 5,
      "name": "BO_Pool_Surface00",
      "rotation": 4
    },
    {
      "x": -5,
      "y": 14,
      "z": 5,
      "name": "*BO_Lightsource_Cycle_State_Definitions_Day",
      "components": {
        "Components": {
          "BlackoutCycleState": {
            "OnState": "Day",
            "OffState": "Night"
          }
        }
      }
    },
    {
      "x": -5,
      "y": 15,
      "z": 5,
      "name": "Build_Black_Cube"
    },
    {
      "x": -5,
      "y": 0,
      "z": 6,
      "name": "BO_Pool_Surface00",
      "rotation": 4
    },
    {
      "x": -5,
      "y": 14,
      "z": 6,
      "name": "*BO_Lightsource_Cycle_State_Definitions_Day",
      "components": {
        "Components": {
          "BlackoutCycleState": {
            "OnState": "Day",
            "OffState": "Night"
          }
        }
      }
    },
    {
      "x": -5,
      "y": 15,
      "z": 6,
      "name": "Build_Black_Cube"
    },
    {
      "x": -5,
      "y": 0,
      "z": 7,
      "name": "BO_Pool_Surface00",
      "rotation": 4
    },
    {
      "x": -5,
      "y": 14,
      "z": 7,
      "name": "*BO_Lightsource_Cycle_State_Definitions_Day",
      "components": {
        "Components": {
          "BlackoutCycleState": {
            "OnState": "Day",
            "OffState": "Night"
          }
        }
      }
    },
    {
      "x": -5,
      "y": 15,
      "z": 7,
      "name": "Build_Black_Cube"
    },
    {
      "x": -5,
      "y": 0,
      "z": 8,
      "name": "BO_Pool_Surface00",
      "rotation": 4
    },
    {
      "x": -5,
      "y": 14,
      "z": 8,
      "name": "*BO_Lightsource_Cycle_State_Definitions_Day",
      "components": {
        "Components": {
          "BlackoutCycleState": {
            "OnState": "Day",
            "OffState": "Night"
          }
        }
      }
    },
    {
      "x": -5,
      "y": 15,
      "z": 8,
      "name": "Build_Black_Cube"
    },
    {
      "x": -5,
      "y": 0,
      "z": 9,
      "name": "BO_Pool_Surface00",
      "rotation": 4
    },
    {
      "x": -5,
      "y": 13,
      "z": 9,
      "name": "BO_Pool_Surface00",
      "support": 15
    },
    {
      "x": -5,
      "y": 14,
      "z": 9,
      "name": "*BO_Lightsource_Cycle_State_Definitions_Day",
      "components": {
        "Components": {
          "BlackoutCycleState": {
            "OnState": "Day",
            "OffState": "Night"
          }
        }
      }
    },
    {
      "x": -5,
      "y": 15,
      "z": 9,
      "name": "Build_Black_Cube"
    },
    {
      "x": -5,
      "y": 0,
      "z": 10,
      "name": "BO_Pool_Surface00",
      "rotation": 4
    },
    {
      "x": -5,
      "y": 9,
      "z": 10,
      "name": "BO_Pool_Surface00",
      "rotation": 4
    },
    {
      "x": -5,
      "y": 10,
      "z": 10,
      "name": "BO_Pool_Surface00",
      "rotation": 4
    },
    {
      "x": -5,
      "y": 11,
      "z": 10,
      "name": "BO_Pool_Surface00",
      "rotation": 4
    },
    {
      "x": -5,
      "y": 12,
      "z": 10,
      "name": "BO_Pool_Surface00",
      "rotation": 4
    },
    {
      "x": -5,
      "y": 13,
      "z": 10,
      "name": "BO_Pool_Surface00",
      "rotation": 4
    },
    {
      "x": -5,
      "y": 14,
      "z": 10,
      "name": "BO_Pool_Surface00",
      "rotation": 4
    },
    {
      "x": -5,
      "y": 15,
      "z": 10,
      "name": "Build_Black_Cube"
    },
    {
      "x": -4,
      "y": 0,
      "z": -9,
      "name": "BO_Pool_Surface00",
      "rotation": 4
    },
    {
      "x": -4,
      "y": 9,
      "z": -9,
      "name": "BO_Pool_Surface00",
      "rotation": 4
    },
    {
      "x": -4,
      "y": 10,
      "z": -9,
      "name": "BO_Pool_Surface00",
      "rotation": 4
    },
    {
      "x": -4,
      "y": 11,
      "z": -9,
      "name": "BO_Pool_Surface00",
      "rotation": 4
    },
    {
      "x": -4,
      "y": 12,
      "z": -9,
      "name": "BO_Pool_Surface00",
      "rotation": 4
    },
    {
      "x": -4,
      "y": 13,
      "z": -9,
      "name": "BO_Pool_Surface00",
      "rotation": 4
    },
    {
      "x": -4,
      "y": 14,
      "z": -9,
      "name": "BO_Pool_Surface00",
      "rotation": 4
    },
    {
      "x": -4,
      "y": 15,
      "z": -9,
      "name": "Build_Black_Cube"
    },
    {
      "x": -4,
      "y": 0,
      "z": -8,
      "name": "BO_Pool_Surface00",
      "rotation": 4
    },
    {
      "x": -4,
      "y": 13,
      "z": -8,
      "name": "BO_Pool_Surface00",
      "support": 15
    },
    {
      "x": -4,
      "y": 14,
      "z": -8,
      "name": "*BO_Lightsource_Cycle_State_Definitions_Day",
      "components": {
        "Components": {
          "BlackoutCycleState": {
            "OnState": "Day",
            "OffState": "Night"
          }
        }
      }
    },
    {
      "x": -4,
      "y": 15,
      "z": -8,
      "name": "Build_Black_Cube"
    },
    {
      "x": -4,
      "y": 0,
      "z": -7,
      "name": "BO_Pool_Surface00",
      "rotation": 4
    },
    {
      "x": -4,
      "y": 14,
      "z": -7,
      "name": "*BO_Lightsource_Cycle_State_Definitions_Day",
      "components": {
        "Components": {
          "BlackoutCycleState": {
            "OnState": "Day",
            "OffState": "Night"
          }
        }
      }
    },
    {
      "x": -4,
      "y": 15,
      "z": -7,
      "name": "Build_Black_Cube"
    },
    {
      "x": -4,
      "y": 0,
      "z": -6,
      "name": "BO_Pool_Surface00",
      "rotation": 4
    },
    {
      "x": -4,
      "y": 14,
      "z": -6,
      "name": "*BO_Lightsource_Cycle_State_Definitions_Day",
      "components": {
        "Components": {
          "BlackoutCycleState": {
            "OnState": "Day",
            "OffState": "Night"
          }
        }
      }
    },
    {
      "x": -4,
      "y": 15,
      "z": -6,
      "name": "Build_Black_Cube"
    },
    {
      "x": -4,
      "y": 0,
      "z": -5,
      "name": "BO_Pool_Surface00",
      "rotation": 4
    },
    {
      "x": -4,
      "y": 14,
      "z": -5,
      "name": "*BO_Lightsource_Cycle_State_Definitions_Day",
      "components": {
        "Components": {
          "BlackoutCycleState": {
            "OnState": "Day",
            "OffState": "Night"
          }
        }
      }
    },
    {
      "x": -4,
      "y": 15,
      "z": -5,
      "name": "Build_Black_Cube"
    },
    {
      "x": -4,
      "y": 0,
      "z": -4,
      "name": "BO_Pool_Surface00",
      "rotation": 4
    },
    {
      "x": -4,
      "y": 14,
      "z": -4,
      "name": "*BO_Lightsource_Cycle_State_Definitions_Day",
      "components": {
        "Components": {
          "BlackoutCycleState": {
            "OnState": "Day",
            "OffState": "Night"
          }
        }
      }
    },
    {
      "x": -4,
      "y": 15,
      "z": -4,
      "name": "Build_Black_Cube"
    },
    {
      "x": -4,
      "y": 0,
      "z": -3,
      "name": "BO_Pool_Surface00",
      "rotation": 4
    },
    {
      "x": -4,
      "y": 14,
      "z": -3,
      "name": "*BO_Lightsource_Cycle_State_Definitions_Day",
      "components": {
        "Components": {
          "BlackoutCycleState": {
            "OnState": "Day",
            "OffState": "Night"
          }
        }
      }
    },
    {
      "x": -4,
      "y": 15,
      "z": -3,
      "name": "Build_Black_Cube"
    },
    {
      "x": -4,
      "y": 0,
      "z": -2,
      "name": "BO_Pool_Surface00",
      "rotation": 4
    },
    {
      "x": -4,
      "y": 14,
      "z": -2,
      "name": "*BO_Lightsource_Cycle_State_Definitions_Day",
      "components": {
        "Components": {
          "BlackoutCycleState": {
            "OnState": "Day",
            "OffState": "Night"
          }
        }
      }
    },
    {
      "x": -4,
      "y": 15,
      "z": -2,
      "name": "Build_Black_Cube"
    },
    {
      "x": -4,
      "y": 0,
      "z": -1,
      "name": "BO_Pool_Surface00",
      "rotation": 4
    },
    {
      "x": -4,
      "y": 14,
      "z": -1,
      "name": "*BO_Lightsource_Cycle_State_Definitions_Day",
      "components": {
        "Components": {
          "BlackoutCycleState": {
            "OnState": "Day",
            "OffState": "Night"
          }
        }
      }
    },
    {
      "x": -4,
      "y": 15,
      "z": -1,
      "name": "Build_Black_Cube"
    },
    {
      "x": -4,
      "y": 0,
      "z": 0,
      "name": "BO_Pool_Surface00",
      "rotation": 4
    },
    {
      "x": -4,
      "y": 14,
      "z": 0,
      "name": "*BO_Lightsource_Cycle_State_Definitions_Day",
      "components": {
        "Components": {
          "BlackoutCycleState": {
            "OnState": "Day",
            "OffState": "Night"
          }
        }
      }
    },
    {
      "x": -4,
      "y": 15,
      "z": 0,
      "name": "Build_Black_Cube"
    },
    {
      "x": -4,
      "y": 0,
      "z": 1,
      "name": "BO_Pool_Surface00",
      "rotation": 4
    },
    {
      "x": -4,
      "y": 14,
      "z": 1,
      "name": "*BO_Lightsource_Cycle_State_Definitions_Day",
      "components": {
        "Components": {
          "BlackoutCycleState": {
            "OnState": "Day",
            "OffState": "Night"
          }
        }
      }
    },
    {
      "x": -4,
      "y": 15,
      "z": 1,
      "name": "Build_Black_Cube"
    },
    {
      "x": -4,
      "y": 0,
      "z": 2,
      "name": "BO_Pool_Surface00",
      "rotation": 4
    },
    {
      "x": -4,
      "y": 14,
      "z": 2,
      "name": "*BO_Lightsource_Cycle_State_Definitions_Day",
      "components": {
        "Components": {
          "BlackoutCycleState": {
            "OnState": "Day",
            "OffState": "Night"
          }
        }
      }
    },
    {
      "x": -4,
      "y": 15,
      "z": 2,
      "name": "Build_Black_Cube"
    },
    {
      "x": -4,
      "y": 0,
      "z": 3,
      "name": "BO_Pool_Surface00",
      "rotation": 4
    },
    {
      "x": -4,
      "y": 14,
      "z": 3,
      "name": "*BO_Lightsource_Cycle_State_Definitions_Day",
      "components": {
        "Components": {
          "BlackoutCycleState": {
            "OnState": "Day",
            "OffState": "Night"
          }
        }
      }
    },
    {
      "x": -4,
      "y": 15,
      "z": 3,
      "name": "Build_Black_Cube"
    },
    {
      "x": -4,
      "y": 0,
      "z": 4,
      "name": "BO_Pool_Surface00",
      "rotation": 4
    },
    {
      "x": -4,
      "y": 14,
      "z": 4,
      "name": "*BO_Lightsource_Cycle_State_Definitions_Day",
      "components": {
        "Components": {
          "BlackoutCycleState": {
            "OnState": "Day",
            "OffState": "Night"
          }
        }
      }
    },
    {
      "x": -4,
      "y": 15,
      "z": 4,
      "name": "Build_Black_Cube"
    },
    {
      "x": -4,
      "y": 0,
      "z": 5,
      "name": "BO_Pool_Surface00",
      "rotation": 4
    },
    {
      "x": -4,
      "y": 14,
      "z": 5,
      "name": "*BO_Lightsource_Cycle_State_Definitions_Day",
      "components": {
        "Components": {
          "BlackoutCycleState": {
            "OnState": "Day",
            "OffState": "Night"
          }
        }
      }
    },
    {
      "x": -4,
      "y": 15,
      "z": 5,
      "name": "Build_Black_Cube"
    },
    {
      "x": -4,
      "y": 0,
      "z": 6,
      "name": "BO_Pool_Surface00",
      "rotation": 4
    },
    {
      "x": -4,
      "y": 14,
      "z": 6,
      "name": "*BO_Lightsource_Cycle_State_Definitions_Day",
      "components": {
        "Components": {
          "BlackoutCycleState": {
            "OnState": "Day",
            "OffState": "Night"
          }
        }
      }
    },
    {
      "x": -4,
      "y": 15,
      "z": 6,
      "name": "Build_Black_Cube"
    },
    {
      "x": -4,
      "y": 0,
      "z": 7,
      "name": "BO_Pool_Surface00",
      "rotation": 4
    },
    {
      "x": -4,
      "y": 14,
      "z": 7,
      "name": "*BO_Lightsource_Cycle_State_Definitions_Day",
      "components": {
        "Components": {
          "BlackoutCycleState": {
            "OnState": "Day",
            "OffState": "Night"
          }
        }
      }
    },
    {
      "x": -4,
      "y": 15,
      "z": 7,
      "name": "Build_Black_Cube"
    },
    {
      "x": -4,
      "y": 0,
      "z": 8,
      "name": "BO_Pool_Surface00",
      "rotation": 4
    },
    {
      "x": -4,
      "y": 14,
      "z": 8,
      "name": "*BO_Lightsource_Cycle_State_Definitions_Day",
      "components": {
        "Components": {
          "BlackoutCycleState": {
            "OnState": "Day",
            "OffState": "Night"
          }
        }
      }
    },
    {
      "x": -4,
      "y": 15,
      "z": 8,
      "name": "Build_Black_Cube"
    },
    {
      "x": -4,
      "y": 0,
      "z": 9,
      "name": "BO_Pool_Surface00",
      "rotation": 4
    },
    {
      "x": -4,
      "y": 13,
      "z": 9,
      "name": "BO_Pool_Surface00",
      "support": 15
    },
    {
      "x": -4,
      "y": 14,
      "z": 9,
      "name": "*BO_Lightsource_Cycle_State_Definitions_Day",
      "components": {
        "Components": {
          "BlackoutCycleState": {
            "OnState": "Day",
            "OffState": "Night"
          }
        }
      }
    },
    {
      "x": -4,
      "y": 15,
      "z": 9,
      "name": "Build_Black_Cube"
    },
    {
      "x": -4,
      "y": 0,
      "z": 10,
      "name": "BO_Pool_Surface00",
      "rotation": 4
    },
    {
      "x": -4,
      "y": 9,
      "z": 10,
      "name": "BO_Pool_Surface00",
      "rotation": 4
    },
    {
      "x": -4,
      "y": 10,
      "z": 10,
      "name": "BO_Pool_Surface00",
      "rotation": 4
    },
    {
      "x": -4,
      "y": 11,
      "z": 10,
      "name": "BO_Pool_Surface00",
      "rotation": 4
    },
    {
      "x": -4,
      "y": 12,
      "z": 10,
      "name": "BO_Pool_Surface00",
      "rotation": 4
    },
    {
      "x": -4,
      "y": 13,
      "z": 10,
      "name": "BO_Pool_Surface00",
      "rotation": 4
    },
    {
      "x": -4,
      "y": 14,
      "z": 10,
      "name": "BO_Pool_Surface00",
      "rotation": 4
    },
    {
      "x": -4,
      "y": 15,
      "z": 10,
      "name": "Build_Black_Cube"
    },
    {
      "x": -3,
      "y": 0,
      "z": -9,
      "name": "BO_Pool_Surface00",
      "rotation": 4
    },
    {
      "x": -3,
      "y": 9,
      "z": -9,
      "name": "BO_Pool_Surface00",
      "rotation": 4
    },
    {
      "x": -3,
      "y": 10,
      "z": -9,
      "name": "BO_Pool_Surface00",
      "rotation": 4
    },
    {
      "x": -3,
      "y": 11,
      "z": -9,
      "name": "BO_Pool_Surface00",
      "rotation": 4
    },
    {
      "x": -3,
      "y": 12,
      "z": -9,
      "name": "BO_Pool_Surface00",
      "rotation": 4
    },
    {
      "x": -3,
      "y": 13,
      "z": -9,
      "name": "BO_Pool_Surface00",
      "rotation": 4
    },
    {
      "x": -3,
      "y": 14,
      "z": -9,
      "name": "BO_Pool_Surface00",
      "rotation": 4
    },
    {
      "x": -3,
      "y": 15,
      "z": -9,
      "name": "Build_Black_Cube"
    },
    {
      "x": -3,
      "y": 0,
      "z": -8,
      "name": "BO_Pool_Surface00",
      "rotation": 4
    },
    {
      "x": -3,
      "y": 13,
      "z": -8,
      "name": "BO_Pool_Surface00",
      "support": 15
    },
    {
      "x": -3,
      "y": 14,
      "z": -8,
      "name": "*BO_Lightsource_Cycle_State_Definitions_Day",
      "components": {
        "Components": {
          "BlackoutCycleState": {
            "OnState": "Day",
            "OffState": "Night"
          }
        }
      }
    },
    {
      "x": -3,
      "y": 15,
      "z": -8,
      "name": "Build_Black_Cube"
    },
    {
      "x": -3,
      "y": 0,
      "z": -7,
      "name": "BO_Pool_Surface00",
      "rotation": 4
    },
    {
      "x": -3,
      "y": 14,
      "z": -7,
      "name": "*BO_Lightsource_Cycle_State_Definitions_Day",
      "components": {
        "Components": {
          "BlackoutCycleState": {
            "OnState": "Day",
            "OffState": "Night"
          }
        }
      }
    },
    {
      "x": -3,
      "y": 15,
      "z": -7,
      "name": "Build_Black_Cube"
    },
    {
      "x": -3,
      "y": 0,
      "z": -6,
      "name": "BO_Pool_Surface00",
      "rotation": 4
    },
    {
      "x": -3,
      "y": 14,
      "z": -6,
      "name": "*BO_Lightsource_Cycle_State_Definitions_Day",
      "components": {
        "Components": {
          "BlackoutCycleState": {
            "OnState": "Day",
            "OffState": "Night"
          }
        }
      }
    },
    {
      "x": -3,
      "y": 15,
      "z": -6,
      "name": "Build_Black_Cube"
    },
    {
      "x": -3,
      "y": 0,
      "z": -5,
      "name": "BO_Pool_Surface00",
      "rotation": 4
    },
    {
      "x": -3,
      "y": 14,
      "z": -5,
      "name": "*BO_Lightsource_Cycle_State_Definitions_Day",
      "components": {
        "Components": {
          "BlackoutCycleState": {
            "OnState": "Day",
            "OffState": "Night"
          }
        }
      }
    },
    {
      "x": -3,
      "y": 15,
      "z": -5,
      "name": "Build_Black_Cube"
    },
    {
      "x": -3,
      "y": 0,
      "z": -4,
      "name": "BO_Pool_Surface00",
      "rotation": 4
    },
    {
      "x": -3,
      "y": 14,
      "z": -4,
      "name": "*BO_Lightsource_Cycle_State_Definitions_Day",
      "components": {
        "Components": {
          "BlackoutCycleState": {
            "OnState": "Day",
            "OffState": "Night"
          }
        }
      }
    },
    {
      "x": -3,
      "y": 15,
      "z": -4,
      "name": "Build_Black_Cube"
    },
    {
      "x": -3,
      "y": 0,
      "z": -3,
      "name": "BO_Pool_Surface00",
      "rotation": 4
    },
    {
      "x": -3,
      "y": 14,
      "z": -3,
      "name": "*BO_Lightsource_Cycle_State_Definitions_Day",
      "components": {
        "Components": {
          "BlackoutCycleState": {
            "OnState": "Day",
            "OffState": "Night"
          }
        }
      }
    },
    {
      "x": -3,
      "y": 15,
      "z": -3,
      "name": "Build_Black_Cube"
    },
    {
      "x": -3,
      "y": 0,
      "z": -2,
      "name": "BO_Pool_Surface00",
      "rotation": 4
    },
    {
      "x": -3,
      "y": 14,
      "z": -2,
      "name": "*BO_Lightsource_Cycle_State_Definitions_Day",
      "components": {
        "Components": {
          "BlackoutCycleState": {
            "OnState": "Day",
            "OffState": "Night"
          }
        }
      }
    },
    {
      "x": -3,
      "y": 15,
      "z": -2,
      "name": "Build_Black_Cube"
    },
    {
      "x": -3,
      "y": 0,
      "z": -1,
      "name": "BO_Pool_Surface00",
      "rotation": 4
    },
    {
      "x": -3,
      "y": 14,
      "z": -1,
      "name": "*BO_Lightsource_Cycle_State_Definitions_Day",
      "components": {
        "Components": {
          "BlackoutCycleState": {
            "OnState": "Day",
            "OffState": "Night"
          }
        }
      }
    },
    {
      "x": -3,
      "y": 15,
      "z": -1,
      "name": "Build_Black_Cube"
    },
    {
      "x": -3,
      "y": 0,
      "z": 0,
      "name": "BO_Pool_Surface00",
      "rotation": 4
    },
    {
      "x": -3,
      "y": 14,
      "z": 0,
      "name": "*BO_Lightsource_Cycle_State_Definitions_Day",
      "components": {
        "Components": {
          "BlackoutCycleState": {
            "OnState": "Day",
            "OffState": "Night"
          }
        }
      }
    },
    {
      "x": -3,
      "y": 15,
      "z": 0,
      "name": "Build_Black_Cube"
    },
    {
      "x": -3,
      "y": 0,
      "z": 1,
      "name": "BO_Pool_Surface00",
      "rotation": 4
    },
    {
      "x": -3,
      "y": 14,
      "z": 1,
      "name": "*BO_Lightsource_Cycle_State_Definitions_Day",
      "components": {
        "Components": {
          "BlackoutCycleState": {
            "OnState": "Day",
            "OffState": "Night"
          }
        }
      }
    },
    {
      "x": -3,
      "y": 15,
      "z": 1,
      "name": "Build_Black_Cube"
    },
    {
      "x": -3,
      "y": 0,
      "z": 2,
      "name": "BO_Pool_Surface00",
      "rotation": 4
    },
    {
      "x": -3,
      "y": 14,
      "z": 2,
      "name": "*BO_Lightsource_Cycle_State_Definitions_Day",
      "components": {
        "Components": {
          "BlackoutCycleState": {
            "OnState": "Day",
            "OffState": "Night"
          }
        }
      }
    },
    {
      "x": -3,
      "y": 15,
      "z": 2,
      "name": "Build_Black_Cube"
    },
    {
      "x": -3,
      "y": 0,
      "z": 3,
      "name": "BO_Pool_Surface00",
      "rotation": 4
    },
    {
      "x": -3,
      "y": 14,
      "z": 3,
      "name": "*BO_Lightsource_Cycle_State_Definitions_Day",
      "components": {
        "Components": {
          "BlackoutCycleState": {
            "OnState": "Day",
            "OffState": "Night"
          }
        }
      }
    },
    {
      "x": -3,
      "y": 15,
      "z": 3,
      "name": "Build_Black_Cube"
    },
    {
      "x": -3,
      "y": 0,
      "z": 4,
      "name": "BO_Pool_Surface00",
      "rotation": 4
    },
    {
      "x": -3,
      "y": 14,
      "z": 4,
      "name": "*BO_Lightsource_Cycle_State_Definitions_Day",
